<mujoco model="mano">
  <option iterations="50" timestep="0.001" solver="PGS" gravity="0 0 -9.81" />

  <compiler angle="radian" meshdir="meshes_left" eulerseq="zyx" autolimits="true" />

  <default>
    <joint limited="true" damping="0.01" armature="0.01" frictionloss="0.01" />
    <geom condim="4" contype="1" conaffinity="15" friction="0.9 0.2 0.2" solref="0.001 2" />
    <motor ctrllimited="true" />
    <equality solref="0.001 2" />
    <default class="visualgeom">
      <geom material="visualgeom" condim="1" contype="0" conaffinity="0" />
    </default>
  </default>

  <asset>
    <mesh name="mesh_0" file="0.obj" />
    <mesh name="mesh_1" file="1.obj" />
    <mesh name="mesh_2" file="2.obj" />
    <mesh name="mesh_3" file="3.obj" />
    <mesh name="mesh_4" file="4.obj" />
    <mesh name="mesh_5" file="5.obj" />
    <mesh name="mesh_6" file="6.obj" />
    <mesh name="mesh_7" file="7.obj" />
    <mesh name="mesh_8" file="8.obj" />
    <mesh name="mesh_9" file="9.obj" />
    <mesh name="mesh_10" file="10.obj" />
    <mesh name="mesh_11" file="11.obj" />
    <mesh name="mesh_12" file="12.obj" />
    <mesh name="mesh_13" file="13.obj" />
    <mesh name="mesh_14" file="14.obj" />
    <mesh name="mesh_15" file="15.obj" />
    <material name="visualgeom" rgba="0.5 0.9 0.2 1" />
  </asset>

  <worldbody>
    <light directional="true" diffuse="0.4 0.4 0.4" specular="0.1 0.1 0.1" pos="0 0 5.0" dir="0 0 -1" castshadow="false" />
    <light directional="true" diffuse="0.6 0.6 0.6" specular="0.2 0.2 0.2" pos="0 0 4" dir="0 0 -1" />
    <geom name="ground" type="plane" pos="0 0 0" size="100 100 0.001" quat="1 0 0 0" material="visualgeom" condim="3" conaffinity="15" />
    <camera name="fixed" pos="0 -3.0 0.5" xyaxes="1 0 0 0 0 1" />
    <camera name="track" mode="trackcom" pos="0 -3.0 0.5" xyaxes="1 0 0 0 0 1" />

    <!-- virtual_root -->
    <body name="virtual_root" pos="0 0 0" quat="1 0 0 0">
      <inertial pos="0 0 0" mass="1.0" diaginertia="0.001 0.001 0.001"/>
      <geom type="box" size="0.01 0.01 0.01" material="visualgeom"/>
      <!-- allegro_root0 chain -->
      <body name="allegro_root0">
        <inertial pos="0 0 0" mass="1.0" diaginertia="0.001 0.001 0.001"/>
        <geom type="box" size="0.01 0.01 0.01" material="visualgeom"/>
        <joint name="allegro_root0_to_virtual_root" type="free"/>
        <body name="allegro_root1">
          <inertial pos="0 0 0" mass="1.0" diaginertia="0.001 0.001 0.001"/>
          <geom type="box" size="0.01 0.01 0.01" material="visualgeom"/>
          <joint name="x_joint" type="slide" axis="1 0 0" range="-50.0 50.0"/>
          <body name="allegro_root2">
            <inertial pos="0 0 0" mass="1.0" diaginertia="0.001 0.001 0.001"/>
            <geom type="box" size="0.01 0.01 0.01" material="visualgeom"/>
            <joint name="y_joint" type="slide" axis="0 1 0" range="-50.0 50.0"/>
            <body name="allegro_root3">
              <inertial pos="0 0 0" mass="1.0" diaginertia="0.001 0.001 0.001"/>
              <geom type="box" size="0.01 0.01 0.01" material="visualgeom"/>
              <joint name="z_joint" type="slide" axis="0 0 1" range="-50.0 50.0"/>
              <body name="allegro_root4">
                <inertial pos="0 0 0" mass="1.0" diaginertia="0.001 0.001 0.001"/>
                <geom type="box" size="0.01 0.01 0.01" material="visualgeom"/>
                <joint name="x_rotation_joint" type="hinge" axis="1 0 0" range="-31.4 31.4"/>
                <body name="allegro_root5">
                  <inertial pos="0 0 0" mass="1.0" diaginertia="0.001 0.001 0.001"/>
                  <geom type="box" size="0.01 0.01 0.01" material="visualgeom"/>
                  <joint name="y_rotation_joint" type="hinge" axis="0 1 0" range="-31.4 31.4"/>
                  <body name="link1">
                    <inertial pos="0 0 0" mass="1.0" diaginertia="0.001 0.001 0.001"/>
                    <geom type="mesh" mesh="mesh_0" material="visualgeom"/>
                    <!-- Thumb -->
                    <body name="link18" pos="-0.02409 0.01552 0.02581">
                      <inertial pos="0 0 0" mass="1.0" diaginertia="0.001 0.001 0.001"/>
                      <joint name="joint18" type="hinge" axis="0 1 0" range="-0.17453292519943295 2.6179938779914944" damping="1.0" frictionloss="0.0001"/>
                      <body name="link19">
                        <inertial pos="0 0 0" mass="1.0" diaginertia="0.001 0.001 0.001"/>
                        <geom type="mesh" mesh="mesh_13" material="visualgeom"/>
                        <joint name="joint19" type="hinge" axis="0 0 1" range="-0.6981317007977318 0.6981317007977318" damping="1.0" frictionloss="0.0001"/>
                        <body name="link20" pos="-0.02526 0.01760 0">
                          <inertial pos="0 0 0" mass="1.0" diaginertia="0.001 0.001 0.001"/>
                          <geom type="mesh" mesh="mesh_14" material="visualgeom"/>
                          <joint name="joint20" type="hinge" axis="1 0 0" range="0.0 1.7453292519943295" damping="1.0" frictionloss="0.0001"/>
                          <body name="link21" pos="0 0 -0.02709">
                            <inertial pos="0 0 0" mass="1.0" diaginertia="0.001 0.001 0.001"/>
                            <geom type="mesh" mesh="mesh_15" material="visualgeom"/>
                            <joint name="joint21" type="hinge" axis="1 0 0" range="0.0 1.7453292519943295" damping="1.0" frictionloss="0.0001"/>
                          </body>
                        </body>
                      </body>
                    </body>
                    <!-- Index -->
                    <body name="link2" pos="-0.08810 0.00520 0.02069">
                      <inertial pos="0 0 0" mass="1.0" diaginertia="0.001 0.001 0.001"/>
                      <joint name="joint2" type="hinge" axis="0 1 0" range="-0.3490658503988659 0.3490658503988659" damping="1.0" frictionloss="0.0001"/>
                      <body name="link3">
                        <inertial pos="0 0 0" mass="1.0" diaginertia="0.001 0.001 0.001"/>
                        <geom type="mesh" mesh="mesh_1" material="visualgeom"/>
                        <joint name="joint3" type="hinge" axis="1 0 0" range="-0.17453292519943295 1.5707963267948966" damping="1.0" frictionloss="0.0001"/>
                        <body name="link4" pos="-0.00238 -0.00591 -0.03238">
                          <inertial pos="0 0 0" mass="1.0" diaginertia="0.001 0.001 0.001"/>
                          <geom type="mesh" mesh="mesh_2" material="visualgeom"/>
                          <joint name="joint4" type="hinge" axis="1 0 0" range="0.0 1.7453292519943295" damping="1.0" frictionloss="0.0001"/>
                          <body name="link5" pos="0 0 -0.02219">
                            <inertial pos="0 0 0" mass="1.0" diaginertia="0.001 0.001 0.001"/>
                            <geom type="mesh" mesh="mesh_3" material="visualgeom"/>
                            <joint name="joint5" type="hinge" axis="1 0 0" range="0.0 1.7453292519943295" damping="1.0" frictionloss="0.0001"/>
                          </body>
                        </body>
                      </body>
                    </body>
                    <!-- Middle -->
                    <body name="link6" pos="-0.09466 0.00148 -0.00336">
                      <inertial pos="0 0 0" mass="1.0" diaginertia="0.001 0.001 0.001"/>
                      <joint name="joint6" type="hinge" axis="0 1 0" range="-0.5235987755982988 0.3490658503988659" damping="1.0" frictionloss="0.0001"/>
                      <body name="link7">
                        <inertial pos="0 0 0" mass="1.0" diaginertia="0.001 0.001 0.001"/>
                        <geom type="mesh" mesh="mesh_4" material="visualgeom"/>
                        <joint name="joint7" type="hinge" axis="1 0 0" range="-0.17453292519943295 1.5707963267948966" damping="1.0" frictionloss="0.0001"/>
                        <body name="link8" pos="0.00032 -0.00356 -0.03153">
                          <inertial pos="0 0 0" mass="1.0" diaginertia="0.001 0.001 0.001"/>
                          <geom type="mesh" mesh="mesh_5" material="visualgeom"/>
                          <joint name="joint8" type="hinge" axis="1 0 0" range="0.0 1.7453292519943295" damping="1.0" frictionloss="0.0001"/>
                          <body name="link9" pos="0 0 -0.02328">
                            <inertial pos="0 0 0" mass="1.0" diaginertia="0.001 0.001 0.001"/>
                            <geom type="mesh" mesh="mesh_6" material="visualgeom"/>
                            <joint name="joint9" type="hinge" axis="1 0 0" range="0.0 1.7453292519943295" damping="1.0" frictionloss="0.0001"/>
                          </body>
                        </body>
                      </body>
                    </body>
                    <!-- Ring -->
                    <body name="link14" pos="-0.08174 0.00396 -0.02667">
                      <inertial pos="0 0 0" mass="1.0" diaginertia="0.001 0.001 0.001"/>
                      <joint name="joint14" type="hinge" axis="0 1 0" range="-0.5235987755982988 0.3490658503988659" damping="1.0" frictionloss="0.0001"/>
                      <body name="link15">
                        <inertial pos="0 0 0" mass="1.0" diaginertia="0.001 0.001 0.001"/>
                        <geom type="mesh" mesh="mesh_10" material="visualgeom"/>
                        <joint name="joint15" type="hinge" axis="1 0 0" range="-0.17453292519943295 1.5707963267948966" damping="1.0" frictionloss="0.0001"/>
                        <body name="link16" pos="-0.00430 -0.00356 -0.02830">
                          <inertial pos="0 0 0" mass="1.0" diaginertia="0.001 0.001 0.001"/>
                          <geom type="mesh" mesh="mesh_11" material="visualgeom"/>
                          <joint name="joint16" type="hinge" axis="1 0 0" range="0.0 1.7453292519943295" damping="1.0" frictionloss="0.0001"/>
                          <body name="link17" pos="0 0 -0.02479">
                            <inertial pos="0 0 0" mass="1.0" diaginertia="0.001 0.001 0.001"/>
                            <geom type="mesh" mesh="mesh_12" material="visualgeom"/>
                            <joint name="joint17" type="hinge" axis="1 0 0" range="0.0 1.7453292519943295" damping="1.0" frictionloss="0.0001"/>
                          </body>
                        </body>
                      </body>
                    </body>
                    <!-- Pinky -->
                    <body name="link10" pos="-0.06879 0.00994 -0.04321">
                      <inertial pos="0 0 0" mass="1.0" diaginertia="0.001 0.001 0.001"/>
                      <joint name="joint10" type="hinge" axis="0 1 0" range="-0.6981317007977318 0.3490658503988659" damping="1.0" frictionloss="0.0001"/>
                      <body name="link11">
                        <inertial pos="0 0 0" mass="1.0" diaginertia="0.001 0.001 0.001"/>
                        <geom type="mesh" mesh="mesh_7" material="visualgeom"/>
                        <joint name="joint11" type="hinge" axis="1 0 0" range="-0.17453292519943295 1.5707963267948966" damping="1.0" frictionloss="0.0001"/>
                        <body name="link12" pos="0.00091 -0.00113 -0.02106">
                          <inertial pos="0 0 0" mass="1.0" diaginertia="0.001 0.001 0.001"/>
                          <geom type="mesh" mesh="mesh_8" material="visualgeom"/>
                          <joint name="joint12" type="hinge" axis="1 0 0" range="0.0 1.7453292519943295" damping="1.0" frictionloss="0.0001"/>
                          <body name="link13" pos="0 0 -0.01895">
                            <inertial pos="0 0 0" mass="1.0" diaginertia="0.001 0.001 0.001"/>
                            <geom type="mesh" mesh="mesh_9" material="visualgeom"/>
                            <joint name="joint13" type="hinge" axis="1 0 0" range="0.0 1.7453292519943295" damping="1.0" frictionloss="0.0001"/>
                          </body>
                        </body>
                      </body>
                    </body>
                  </body>
                </body>
              </body>
            </body>
          </body>
        </body>
      </body>
      <!-- dummy_root_link and its children -->
      <body name="dummy_root_link">
        <inertial pos="0 0 0" mass="1.0" diaginertia="0.001 0.001 0.001"/>
        <geom type="box" size="0.01 0.01 0.01" material="visualgeom"/>
        <body name="link9"/>
        <body name="link5"/>
        <body name="link21"/>
        <body name="link17"/>
        <body name="link13"/>
      </body>
    </body>
  </worldbody>

  <actuator>
    <motor name="x_joint" joint="x_joint" ctrllimited="true" ctrlrange="-50 50" gear="1"/>
    <motor name="y_joint" joint="y_joint" ctrllimited="true" ctrlrange="-50 50" gear="1"/>
    <motor name="z_joint" joint="z_joint" ctrllimited="true" ctrlrange="-50 50" gear="1"/>
    <motor name="x_rotation_joint" joint="x_rotation_joint" ctrllimited="true" ctrlrange="-31.4 31.4" gear="1"/>
    <motor name="y_rotation_joint" joint="y_rotation_joint" ctrllimited="true" ctrlrange="-31.4 31.4" gear="1"/>
    <motor name="joint2" joint="joint2" ctrllimited="true" ctrlrange="-0.3490658503988659 0.3490658503988659" gear="1"/>
    <motor name="joint3" joint="joint3" ctrllimited="true" ctrlrange="-0.17453292519943295 1.5707963267948966" gear="1"/>
    <motor name="joint4" joint="joint4" ctrllimited="true" ctrlrange="0.0 1.7453292519943295" gear="1"/>
    <motor name="joint5" joint="joint5" ctrllimited="true" ctrlrange="0.0 1.7453292519943295" gear="1"/>
    <motor name="joint6" joint="joint6" ctrllimited="true" ctrlrange="-0.5235987755982988 0.3490658503988659" gear="1"/>
    <motor name="joint7" joint="joint7" ctrllimited="true" ctrlrange="-0.17453292519943295 1.5707963267948966" gear="1"/>
    <motor name="joint8" joint="joint8" ctrllimited="true" ctrlrange="0.0 1.7453292519943295" gear="1"/>
    <motor name="joint9" joint="joint9" ctrllimited="true" ctrlrange="0.0 1.7453292519943295" gear="1"/>
    <motor name="joint10" joint="joint10" ctrllimited="true" ctrlrange="-0.6981317007977318 0.3490658503988659" gear="1"/>
    <motor name="joint11" joint="joint11" ctrllimited="true" ctrlrange="-0.17453292519943295 1.5707963267948966" gear="1"/>
    <motor name="joint12" joint="joint12" ctrllimited="true" ctrlrange="0.0 1.7453292519943295" gear="1"/>
    <motor name="joint13" joint="joint13" ctrllimited="true" ctrlrange="0.0 1.7453292519943295" gear="1"/>
    <motor name="joint14" joint="joint14" ctrllimited="true" ctrlrange="-0.5235987755982988 0.3490658503988659" gear="1"/>
    <motor name="joint15" joint="joint15" ctrllimited="true" ctrlrange="-0.17453292519943295 1.5707963267948966" gear="1"/>
    <motor name="joint16" joint="joint16" ctrllimited="true" ctrlrange="0.0 1.7453292519943295" gear="1"/>
    <motor name="joint17" joint="joint17" ctrllimited="true" ctrlrange="0.0 1.7453292519943295" gear="1"/>
    <motor name="joint18" joint="joint18" ctrllimited="true" ctrlrange="-0.17453292519943295 2.6179938779914944" gear="1"/>
    <motor name="joint19" joint="joint19" ctrllimited="true" ctrlrange="-0.6981317007977318 0.6981317007977318" gear="1"/>
    <motor name="joint20" joint="joint20" ctrllimited="true" ctrlrange="0.0 1.7453292519943295" gear="1"/>
    <motor name="joint21" joint="joint21" ctrllimited="true" ctrlrange="0.0 1.7453292519943295" gear="1"/>
  </actuator>

  <sensor>
    <actuatorpos name="joint2_p" actuator="joint2" />
    <actuatorvel name="joint2_v" actuator="joint2" />
    <actuatorfrc name="joint2_f" actuator="joint2" noise="0.001" />
    <actuatorpos name="joint3_p" actuator="joint3" />
    <actuatorvel name="joint3_v" actuator="joint3" />
    <actuatorfrc name="joint3_f" actuator="joint3" noise="0.001" />
    <actuatorpos name="joint4_p" actuator="joint4" />
    <actuatorvel name="joint4_v" actuator="joint4" />
    <actuatorfrc name="joint4_f" actuator="joint4" noise="0.001" />
    <actuatorpos name="joint5_p" actuator="joint5" />
    <actuatorvel name="joint5_v" actuator="joint5" />
    <actuatorfrc name="joint5_f" actuator="joint5" noise="0.001" />
    <actuatorpos name="joint6_p" actuator="joint6" />
    <actuatorvel name="joint6_v" actuator="joint6" />
    <actuatorfrc name="joint6_f" actuator="joint6" noise="0.001" />
    <actuatorpos name="joint7_p" actuator="joint7" />
    <actuatorvel name="joint7_v" actuator="joint7" />
    <actuatorfrc name="joint7_f" actuator="joint7" noise="0.001" />
    <actuatorpos name="joint8_p" actuator="joint8" />
    <actuatorvel name="joint8_v" actuator="joint8" />
    <actuatorfrc name="joint8_f" actuator="joint8" noise="0.001" />
    <actuatorpos name="joint9_p" actuator="joint9" />
    <actuatorvel name="joint9_v" actuator="joint9" />
    <actuatorfrc name="joint9_f" actuator="joint9" noise="0.001" />
    <actuatorpos name="joint10_p" actuator="joint10" />
    <actuatorvel name="joint10_v" actuator="joint10" />
    <actuatorfrc name="joint10_f" actuator="joint10" noise="0.001" />
    <actuatorpos name="joint11_p" actuator="joint11" />
    <actuatorvel name="joint11_v" actuator="joint11" />
    <actuatorfrc name="joint11_f" actuator="joint11" noise="0.001" />
    <actuatorpos name="joint12_p" actuator="joint12" />
    <actuatorvel name="joint12_v" actuator="joint12" />
    <actuatorfrc name="joint12_f" actuator="joint12" noise="0.001" />
    <actuatorpos name="joint13_p" actuator="joint13" />
    <actuatorvel name="joint13_v" actuator="joint13" />
    <actuatorfrc name="joint13_f" actuator="joint13" noise="0.001" />
    <actuatorpos name="joint14_p" actuator="joint14" />
    <actuatorvel name="joint14_v" actuator="joint14" />
    <actuatorfrc name="joint14_f" actuator="joint14" noise="0.001" />
    <actuatorpos name="joint15_p" actuator="joint15" />
    <actuatorvel name="joint15_v" actuator="joint15" />
    <actuatorfrc name="joint15_f" actuator="joint15" noise="0.001" />
    <actuatorpos name="joint16_p" actuator="joint16" />
    <actuatorvel name="joint16_v" actuator="joint16" />
    <actuatorfrc name="joint16_f" actuator="joint16" noise="0.001" />
    <actuatorpos name="joint17_p" actuator="joint17" />
    <actuatorvel name="joint17_v" actuator="joint17" />
    <actuatorfrc name="joint17_f" actuator="joint17" noise="0.001" />
    <actuatorpos name="joint18_p" actuator="joint18" />
    <actuatorvel name="joint18_v" actuator="joint18" />
    <actuatorfrc name="joint18_f" actuator="joint18" noise="0.001" />
    <actuatorpos name="joint19_p" actuator="joint19" />
    <actuatorvel name="joint19_v" actuator="joint19" />
    <actuatorfrc name="joint19_f" actuator="joint19" noise="0.001" />
    <actuatorpos name="joint20_p" actuator="joint20" />
    <actuatorvel name="joint20_v" actuator="joint20" />
    <actuatorfrc name="joint20_f" actuator="joint20" noise="0.001" />
    <actuatorpos name="joint21_p" actuator="joint21" />
    <actuatorvel name="joint21_v" actuator="joint21" />
    <actuatorfrc name="joint21_f" actuator="joint21" noise="0.001" />
  </sensor>
</mujoco>