<mujoco model="mano">
  <option iterations="50" timestep="0.001" solver="PGS" gravity="0 0 -9.81" />
  <compiler angle="radian" meshdir="meshes" eulerseq="zyx" autolimits="true" />

  <default>
    <joint limited="true" damping="0.01" armature="0.01" frictionloss="0.01" />
    <geom condim="4" contype="1" conaffinity="15" friction="0.9 0.2 0.2" solref="0.001 2" />
    <motor ctrllimited="true" />
    <equality solref="0.001 2" />
    <default class="visualgeom">
      <geom material="visualgeom" condim="1" contype="0" conaffinity="0" />
    </default>
  </default>

  <asset>
    <mesh name="palm" file="palm.stl" />
    <mesh name="index1x" file="index1x.stl" />
    <mesh name="index2" file="index2.stl" />
    <mesh name="index3" file="index3.stl" />
    <mesh name="middle1x" file="middle1x.stl" />
    <mesh name="middle2" file="middle2.stl" />
    <mesh name="middle3" file="middle3.stl" />
    <mesh name="ring1x" file="ring1x.stl" />
    <mesh name="ring2" file="ring2.stl" />
    <mesh name="ring3" file="ring3.stl" />
    <mesh name="pinky1x" file="pinky1x.stl" />
    <mesh name="pinky2" file="pinky2.stl" />
    <mesh name="pinky3" file="pinky3.stl" />
    <mesh name="thumb1z" file="thumb1z.stl" />
    <mesh name="thumb2" file="thumb2.stl" />
    <mesh name="thumb3" file="thumb3.stl" />
    <material name="visualgeom" rgba="0.5 0.9 0.2 1" />
  </asset>

  <worldbody>
    <light directional="true" diffuse="0.4 0.4 0.4" specular="0.1 0.1 0.1" pos="0 0 5.0" dir="0 0 -1" castshadow="false" />
    <light directional="true" diffuse="0.6 0.6 0.6" specular="0.2 0.2 0.2" pos="0 0 4" dir="0 0 -1" />
    <geom name="ground" type="plane" pos="0 0 0" size="100 100 0.001" quat="1 0 0 0" material="visualgeom" condim="3" conaffinity="15" />

    <!-- Root and hierarchy -->
    <body name="virtual_root" pos="0 0 0">
      <inertial pos="0 0 0" mass="1.0" diaginertia="0.001 0.001 0.001"/>
      <geom type="box" size="0.01 0.01 0.01" material="visualgeom"/>
      <!-- allegro_root chain -->
      <body name="allegro_root0">
        <inertial pos="0 0 0" mass="1.0" diaginertia="0.001 0.001 0.001"/>
        <geom type="box" size="0.01 0.01 0.01" material="visualgeom"/>
        <body name="allegro_root1">
          <inertial pos="0 0 0" mass="1.0" diaginertia="0.001 0.001 0.001"/>
          <geom type="box" size="0.01 0.01 0.01" material="visualgeom"/>
          <joint name="x_joint" type="slide" axis="1 0 0" range="-50.0 50.0"/>
          <body name="allegro_root2">
            <inertial pos="0 0 0" mass="1.0" diaginertia="0.001 0.001 0.001"/>
            <geom type="box" size="0.01 0.01 0.01" material="visualgeom"/>
            <joint name="y_joint" type="slide" axis="0 1 0" range="-50.0 50.0"/>
            <body name="allegro_root3">
              <inertial pos="0 0 0" mass="1.0" diaginertia="0.001 0.001 0.001"/>
              <geom type="box" size="0.01 0.01 0.01" material="visualgeom"/>
              <joint name="z_joint" type="slide" axis="0 0 1" range="-50.0 50.0"/>
              <body name="allegro_root4">
                <inertial pos="0 0 0" mass="1.0" diaginertia="0.001 0.001 0.001"/>
                <geom type="box" size="0.01 0.01 0.01" material="visualgeom"/>
                <joint name="x_rotation_joint" type="hinge" axis="1 0 0" range="-31.4 31.4"/>
                <body name="allegro_root5">
                  <inertial pos="0 0 0" mass="1.0" diaginertia="0.001 0.001 0.001"/>
                  <geom type="box" size="0.01 0.01 0.01" material="visualgeom"/>
                  <joint name="y_rotation_joint" type="hinge" axis="0 1 0" range="-31.4 31.4"/>
                  <body name="palm">
                    <inertial pos="0 0 0" mass="1.0" diaginertia="0.001 0.001 0.001"/>
                    <geom type="mesh" mesh="palm" material="visualgeom"/>
                    <joint name="z_rotation_joint" type="hinge" axis="0 0 1" range="-31.4 31.4"/>
                    <!-- Index finger -->
                    <body name="index1y" pos="-0.08809724664019486 -0.0052003570684035555 0.02068598903709729">
                      <inertial pos="0 0 0" mass="1.0" diaginertia="0.001 0.001 0.001"/>
                      <joint name="j_index1y" type="hinge" axis="0 1 0" range="-0.3490658503988659 0.3490658503988659"/>
                      <body name="index1x">
                        <inertial pos="0 0 0" mass="1.0" diaginertia="0.001 0.001 0.001"/>
                        <geom type="mesh" mesh="index1x" material="visualgeom"/>
                        <joint name="j_index1x" type="hinge" axis="1 0 0" range="-0.17453292519943295 1.5707963267948966"/>
                        <body name="index2" pos="0.0023835711672753985 -0.005914318759078097 -0.03237654210665609">
                          <inertial pos="0 0 0" mass="1.0" diaginertia="0.001 0.001 0.001"/>
                          <geom type="mesh" mesh="index2" material="visualgeom"/>
                          <joint name="j_index2" type="hinge" axis="1 0 0" range="0.0 1.7453292519943295"/>
                          <body name="index3" pos="-2.1969386803155346e-21 1.0054815357582629e-19 -0.022194219361846432">
                            <inertial pos="0 0 0" mass="1.0" diaginertia="0.001 0.001 0.001"/>
                            <geom type="mesh" mesh="index3" material="visualgeom"/>
                            <joint name="j_index3" type="hinge" axis="1 0 0" range="0.0 1.7453292519943295"/>
                          </body>
                        </body>
                      </body>
                    </body>
                    <!-- Middle finger -->
                    <body name="middle1y" pos="-0.09466044139183748 -0.0014789633509431728 -0.0033575408143170205">
                      <inertial pos="0 0 0" mass="1.0" diaginertia="0.001 0.001 0.001"/>
                      <joint name="j_middle1y" type="hinge" axis="0 1 0" range="-0.5235987755982988 0.3490658503988659"/>
                      <body name="middle1x">
                        <inertial pos="0 0 0" mass="1.0" diaginertia="0.001 0.001 0.001"/>
                        <geom type="mesh" mesh="middle1x" material="visualgeom"/>
                        <joint name="j_middle1x" type="hinge" axis="1 0 0" range="-0.17453292519943295 1.5707963267948966"/>
                        <body name="middle2" pos="-0.0003207158897834246 -0.003555264565700651 -0.031533781277300055">
                          <inertial pos="0 0 0" mass="1.0" diaginertia="0.001 0.001 0.001"/>
                          <geom type="mesh" mesh="middle2" material="visualgeom"/>
                          <joint name="j_middle2" type="hinge" axis="1 0 0" range="0.0 1.7453292519943295"/>
                          <body name="middle3" pos="-5.609489609703704e-20 -7.277896970840872e-20 -0.023275512883098835">
                            <inertial pos="0 0 0" mass="1.0" diaginertia="0.001 0.001 0.001"/>
                            <geom type="mesh" mesh="middle3" material="visualgeom"/>
                            <joint name="j_middle3" type="hinge" axis="1 0 0" range="0.0 1.7453292519943295"/>
                          </body>
                        </body>
                      </body>
                    </body>
                    <!-- Pinky finger -->
                    <body name="pinky1y" pos="-0.0687869720598841 -0.00994032882044861 -0.04320934200328496">
                      <inertial pos="0 0 0" mass="1.0" diaginertia="0.001 0.001 0.001"/>
                      <joint name="j_pinky1y" type="hinge" axis="0 1 0" range="-0.6981317007977318 0.3490658503988659"/>
                      <body name="pinky1x">
                        <inertial pos="0 0 0" mass="1.0" diaginertia="0.001 0.001 0.001"/>
                        <geom type="mesh" mesh="pinky1x" material="visualgeom"/>
                        <joint name="j_pinky1x" type="hinge" axis="1 0 0" range="-0.17453292519943295 1.5707963267948966"/>
                        <body name="pinky2" pos="-0.0009123243154268479 -0.0011282837702486126 -0.021062001859487044">
                          <inertial pos="0 0 0" mass="1.0" diaginertia="0.001 0.001 0.001"/>
                          <geom type="mesh" mesh="pinky2" material="visualgeom"/>
                          <joint name="j_pinky2" type="hinge" axis="1 0 0" range="0.0 1.7453292519943295"/>
                          <body name="pinky3" pos="-1.8952144180532274e-18 2.2152413969868993e-19 -0.01894688789602988">
                            <inertial pos="0 0 0" mass="1.0" diaginertia="0.001 0.001 0.001"/>
                            <geom type="mesh" mesh="pinky3" material="visualgeom"/>
                            <joint name="j_pinky3" type="hinge" axis="1 0 0" range="0.0 1.7453292519943295"/>
                          </body>
                        </body>
                      </body>
                    </body>
                    <!-- Ring finger -->
                    <body name="ring1y" pos="-0.08173555442881024 -0.003957421152865242 -0.026673193033088197">
                      <inertial pos="0 0 0" mass="1.0" diaginertia="0.001 0.001 0.001"/>
                      <joint name="j_ring1y" type="hinge" axis="0 1 0" range="-0.5235987755982988 0.3490658503988659"/>
                      <body name="ring1x">
                        <inertial pos="0 0 0" mass="1.0" diaginertia="0.001 0.001 0.001"/>
                        <geom type="mesh" mesh="ring1x" material="visualgeom"/>
                        <joint name="j_ring1x" type="hinge" axis="1 0 0" range="-0.17453292519943295 1.5707963267948966"/>
                        <body name="ring2" pos="0.00429786987999866 -0.003563675567715413 -0.028298309378744307">
                          <inertial pos="0 0 0" mass="1.0" diaginertia="0.001 0.001 0.001"/>
                          <geom type="mesh" mesh="ring2" material="visualgeom"/>
                          <joint name="j_ring2" type="hinge" axis="1 0 0" range="0.0 1.7453292519943295"/>
                          <body name="ring3" pos="-7.238679066856496e-20 2.4155957590579026e-19 -0.02478587029620925">
                            <inertial pos="0 0 0" mass="1.0" diaginertia="0.001 0.001 0.001"/>
                            <geom type="mesh" mesh="ring3" material="visualgeom"/>
                            <joint name="j_ring3" type="hinge" axis="1 0 0" range="0.0 1.7453292519943295"/>
                          </body>
                        </body>
                      </body>
                    </body>
                    <!-- Thumb finger -->
                    <body name="thumb1y" pos="-0.024089706802642025 -0.015522334541875703 0.025812847288082738">
                      <inertial pos="0 0 0" mass="1.0" diaginertia="0.001 0.001 0.001"/>
                      <joint name="j_thumb1y" type="hinge" axis="0 1 0" range="-0.17453292519943295 2.6179938779914944"/>
                      <body name="thumb1z">
                        <inertial pos="0 0 0" mass="1.0" diaginertia="0.001 0.001 0.001"/>
                        <geom type="mesh" mesh="thumb1z" material="visualgeom"/>
                        <joint name="j_thumb1z" type="hinge" axis="0 0 1" range="-0.6981317007977318 0.6981317007977318"/>
                        <body name="thumb2" pos="0.02526494873869172 -0.017595730026252792 1.0660017461924156e-19">
                          <inertial pos="0 0 0" mass="1.0" diaginertia="0.001 0.001 0.001"/>
                          <geom type="mesh" mesh="thumb2" material="visualgeom"/>
                          <joint name="j_thumb2" type="hinge" axis="1 0 0" range="0.0 1.7453292519943295"/>
                          <body name="thumb3" pos="1.6439906908155651e-19 1.0686676358921293e-18 -0.027094189966248017">
                            <inertial pos="0 0 0" mass="1.0" diaginertia="0.001 0.001 0.001"/>
                            <geom type="mesh" mesh="thumb3" material="visualgeom"/>
                            <joint name="j_thumb3" type="hinge" axis="1 0 0" range="0.0 1.7453292519943295"/>
                          </body>
                        </body>
                      </body>
                    </body>
                  </body>
                </body>
              </body>
            </body>
          </body>
        </body>
      </body>
      <body name="dummy_root_link">
        <inertial pos="0 0 0" mass="1.0" diaginertia="0.001 0.001 0.001"/>
        <geom type="box" size="0.01 0.01 0.01" material="visualgeom"/>
        <body name="thumb3"/>
        <body name="ring3"/>
        <body name="pinky3"/>
        <body name="middle3"/>
        <body name="index3"/>
      </body>
    </body>
  </worldbody>

  <actuator>
    <motor name="x_joint" joint="x_joint" ctrllimited="true" ctrlrange="-50 50" gear="1"/>
    <motor name="y_joint" joint="y_joint" ctrllimited="true" ctrlrange="-50 50" gear="1"/>
    <motor name="z_joint" joint="z_joint" ctrllimited="true" ctrlrange="-50 50" gear="1"/>
    <motor name="x_rotation_joint" joint="x_rotation_joint" ctrllimited="true" ctrlrange="-31.4 31.4" gear="1"/>
    <motor name="y_rotation_joint" joint="y_rotation_joint" ctrllimited="true" ctrlrange="-31.4 31.4" gear="1"/>
    <motor name="z_rotation_joint" joint="z_rotation_joint" ctrllimited="true" ctrlrange="-31.4 31.4" gear="1"/>
    <motor name="j_index1y" joint="j_index1y" ctrllimited="true" ctrlrange="-0.3490658503988659 0.3490658503988659" gear="1"/>
    <motor name="j_index1x" joint="j_index1x" ctrllimited="true" ctrlrange="-0.17453292519943295 1.5707963267948966" gear="1"/>
    <motor name="j_index2" joint="j_index2" ctrllimited="true" ctrlrange="0.0 1.7453292519943295" gear="1"/>
    <motor name="j_index3" joint="j_index3" ctrllimited="true" ctrlrange="0.0 1.7453292519943295" gear="1"/>
    <motor name="j_middle1y" joint="j_middle1y" ctrllimited="true" ctrlrange="-0.5235987755982988 0.3490658503988659" gear="1"/>
    <motor name="j_middle1x" joint="j_middle1x" ctrllimited="true" ctrlrange="-0.17453292519943295 1.5707963267948966" gear="1"/>
    <motor name="j_middle2" joint="j_middle2" ctrllimited="true" ctrlrange="0.0 1.7453292519943295" gear="1"/>
    <motor name="j_middle3" joint="j_middle3" ctrllimited="true" ctrlrange="0.0 1.7453292519943295" gear="1"/>
    <motor name="j_pinky1y" joint="j_pinky1y" ctrllimited="true" ctrlrange="-0.6981317007977318 0.3490658503988659" gear="1"/>
    <motor name="j_pinky1x" joint="j_pinky1x" ctrllimited="true" ctrlrange="-0.17453292519943295 1.5707963267948966" gear="1"/>
    <motor name="j_pinky2" joint="j_pinky2" ctrllimited="true" ctrlrange="0.0 1.7453292519943295" gear="1"/>
    <motor name="j_pinky3" joint="j_pinky3" ctrllimited="true" ctrlrange="0.0 1.7453292519943295" gear="1"/>
    <motor name="j_ring1y" joint="j_ring1y" ctrllimited="true" ctrlrange="-0.5235987755982988 0.3490658503988659" gear="1"/>
    <motor name="j_ring1x" joint="j_ring1x" ctrllimited="true" ctrlrange="-0.17453292519943295 1.5707963267948966" gear="1"/>
    <motor name="j_ring2" joint="j_ring2" ctrllimited="true" ctrlrange="0.0 1.7453292519943295" gear="1"/>
    <motor name="j_ring3" joint="j_ring3" ctrllimited="true" ctrlrange="0.0 1.7453292519943295" gear="1"/>
    <motor name="j_thumb1y" joint="j_thumb1y" ctrllimited="true" ctrlrange="-0.17453292519943295 2.6179938779914944" gear="1"/>
    <motor name="j_thumb1z" joint="j_thumb1z" ctrllimited="true" ctrlrange="-0.6981317007977318 0.6981317007977318" gear="1"/>
    <motor name="j_thumb2" joint="j_thumb2" ctrllimited="true" ctrlrange="0.0 1.7453292519943295" gear="1"/>
    <motor name="j_thumb3" joint="j_thumb3" ctrllimited="true" ctrlrange="0.0 1.7453292519943295" gear="1"/>
  </actuator>

  <sensor>
    <actuatorpos name="j_index1y_p" actuator="j_index1y" />
    <actuatorvel name="j_index1y_v" actuator="j_index1y" />
    <actuatorfrc name="j_index1y_f" actuator="j_index1y" noise="0.001" />
    <actuatorpos name="j_index1x_p" actuator="j_index1x" />
    <actuatorvel name="j_index1x_v" actuator="j_index1x" />
    <actuatorfrc name="j_index1x_f" actuator="j_index1x" noise="0.001" />
    <actuatorpos name="j_index2_p" actuator="j_index2" />
    <actuatorvel name="j_index2_v" actuator="j_index2" />
    <actuatorfrc name="j_index2_f" actuator="j_index2" noise="0.001" />
    <actuatorpos name="j_index3_p" actuator="j_index3" />
    <actuatorvel name="j_index3_v" actuator="j_index3" />
    <actuatorfrc name="j_index3_f" actuator="j_index3" noise="0.001" />
    <actuatorpos name="j_middle1y_p" actuator="j_middle1y" />
    <actuatorvel name="j_middle1y_v" actuator="j_middle1y" />
    <actuatorfrc name="j_middle1y_f" actuator="j_middle1y" noise="0.001" />
    <actuatorpos name="j_middle1x_p" actuator="j_middle1x" />
    <actuatorvel name="j_middle1x_v" actuator="j_middle1x" />
    <actuatorfrc name="j_middle1x_f" actuator="j_middle1x" noise="0.001" />
    <actuatorpos name="j_middle2_p" actuator="j_middle2" />
    <actuatorvel name="j_middle2_v" actuator="j_middle2" />
    <actuatorfrc name="j_middle2_f" actuator="j_middle2" noise="0.001" />
    <actuatorpos name="j_middle3_p" actuator="j_middle3" />
    <actuatorvel name="j_middle3_v" actuator="j_middle3" />
    <actuatorfrc name="j_middle3_f" actuator="j_middle3" noise="0.001" />
    <actuatorpos name="j_pinky1y_p" actuator="j_pinky1y" />
    <actuatorvel name="j_pinky1y_v" actuator="j_pinky1y" />
    <actuatorfrc name="j_pinky1y_f" actuator="j_pinky1y" noise="0.001" />
    <actuatorpos name="j_pinky1x_p" actuator="j_pinky1x" />
    <actuatorvel name="j_pinky1x_v" actuator="j_pinky1x" />
    <actuatorfrc name="j_pinky1x_f" actuator="j_pinky1x" noise="0.001" />
    <actuatorpos name="j_pinky2_p" actuator="j_pinky2" />
    <actuatorvel name="j_pinky2_v" actuator="j_pinky2" />
    <actuatorfrc name="j_pinky2_f" actuator="j_pinky2" noise="0.001" />
    <actuatorpos name="j_pinky3_p" actuator="j_pinky3" />
    <actuatorvel name="j_pinky3_v" actuator="j_pinky3" />
    <actuatorfrc name="j_pinky3_f" actuator="j_pinky3" noise="0.001" />
    <actuatorpos name="j_ring1y_p" actuator="j_ring1y" />
    <actuatorvel name="j_ring1y_v" actuator="j_ring1y" />
    <actuatorfrc name="j_ring1y_f" actuator="j_ring1y" noise="0.001" />
    <actuatorpos name="j_ring1x_p" actuator="j_ring1x" />
    <actuatorvel name="j_ring1x_v" actuator="j_ring1x" />
    <actuatorfrc name="j_ring1x_f" actuator="j_ring1x" noise="0.001" />
    <actuatorpos name="j_ring2_p" actuator="j_ring2" />
    <actuatorvel name="j_ring2_v" actuator="j_ring2" />
    <actuatorfrc name="j_ring2_f" actuator="j_ring2" noise="0.001" />
    <actuatorpos name="j_ring3_p" actuator="j_ring3" />
    <actuatorvel name="j_ring3_v" actuator="j_ring3" />
    <actuatorfrc name="j_ring3_f" actuator="j_ring3" noise="0.001" />
    <actuatorpos name="j_thumb1y_p" actuator="j_thumb1y" />
    <actuatorvel name="j_thumb1y_v" actuator="j_thumb1y" />
    <actuatorfrc name="j_thumb1y_f" actuator="j_thumb1y" noise="0.001" />
    <actuatorpos name="j_thumb1z_p" actuator="j_thumb1z" />
    <actuatorvel name="j_thumb1z_v" actuator="j_thumb1z" />
    <actuatorfrc name="j_thumb1z_f" actuator="j_thumb1z" noise="0.001" />
    <actuatorpos name="j_thumb2_p" actuator="j_thumb2" />
    <actuatorvel name="j_thumb2_v" actuator="j_thumb2" />
    <actuatorfrc name="j_thumb2_f" actuator="j_thumb2" noise="0.001" />
    <actuatorpos name="j_thumb3_p" actuator="j_thumb3" />
    <actuatorvel name="j_thumb3_v" actuator="j_thumb3" />
    <actuatorfrc name="j_thumb3_f" actuator="j_thumb3" noise="0.001" />
  </sensor>
</mujoco>