<mujoco model="shadowhand_motor">
  <option iterations="50" timestep="0.001" solver="PGS" gravity="0 0 -9.81" />

  <compiler angle="radian" meshdir="meshes" eulerseq="zyx" autolimits="true" />

  <default>
    <joint limited="true" damping="0.01" armature="0.01" frictionloss="0.01" />
    <geom condim="4" contype="1" conaffinity="15" friction="0.9 0.2 0.2" solref="0.001 2" />
    <motor ctrllimited="true" />
    <equality solref="0.001 2" />
    <default class="visualgeom">
      <geom material="visualgeom" condim="1" contype="0" conaffinity="0" />
    </default>
  </default>

  <asset>
    <mesh name="distal_ellipsoid" content_type="model/obj" file="distal_ellipsoid.obj" />
    <texture name="texplane" type="2d" builtin="checker" rgb1=".0 .0 .0" rgb2=".8 .8 .8" width="100" height="100" />
    <material name="matplane" reflectance="0." texture="texplane" texrepeat="1 1" texuniform="true" />
    <material name="visualgeom" rgba="0.5 0.9 0.2 1" />
  </asset>

  <worldbody>
    <light directional="true" diffuse="0.4 0.4 0.4" specular="0.1 0.1 0.1" pos="0 0 5.0" dir="0 0 -1" castshadow="false" />
    <light directional="true" diffuse="0.6 0.6 0.6" specular="0.2 0.2 0.2" pos="0 0 4" dir="0 0 -1" />
    <geom name="ground" type="plane" pos="0 0 0" size="100 100 0.001" quat="1 0 0 0" material="matplane" condim="3" conaffinity="15" />
    <camera name="fixed" pos="0 -3.0 0.41000000000000003" xyaxes="1 0 0 0 0 1" />
    <camera name="track" mode="trackcom" pos="0 -3.0 0.41000000000000003" xyaxes="1 0 0 0 0 1" />
    <body name="root" pos="0 0 -0.09" quat="1 0 0 0">
      <freejoint name="root" />
      <site name="imu" size="0.01" pos="0 0 0" />
      <geom size="0.06 0.09" pos="0 0 0.09" type="cylinder" rgba="0.2 0.2 0.2 1" contype="1" conaffinity="0" density="0" group="1" class="visualgeom" />
      <geom type="cylinder" rgba="0.2 0.2 0.2 1" pos="0 0 0.09" />
      <body name="wrist" pos="0 -0.01 0.213">
        <inertial pos="0 0 0" mass="1" diaginertia="0.001 0.001 0.001" />
        <joint name="WRJ2" pos="0 0 0" axis="0 1 0" range="-0.523599 0.174533" actuatorfrcrange="-5 5" damping="100.5" />
        <geom size="0.01 0.01 0.01" type="box" rgba="0.6 0.6 0.6 1" contype="1" conaffinity="0" density="0" group="1" class="visualgeom" />
        <geom type="box" rgba="0.6 0.6 0.6 1" size="0.01 0.01 0.01" />
        <body name="palm" pos="0 0 0.034">
          <inertial pos="0 0 0" mass="1" diaginertia="0.001 0.001 0.001" />
          <joint name="WRJ1" pos="0 0 0" axis="1 0 0" range="-0.785398 0.610865" actuatorfrcrange="-5 5" damping="100.5" />
          <geom size="0.025 0.01 0.035" pos="0.005 0 0.035" type="box" rgba="0.2 0.2 0.2 1" contype="1" conaffinity="0" density="0" group="1" class="visualgeom" />
          <geom type="box" rgba="0.2 0.2 0.2 1" size="0.025 0.01 0.035" pos="0.005 0 0.035" />
          <body name="ffknuckle" pos="0.033 0 0.095">
            <inertial pos="0 0 0" mass="1" diaginertia="0.001 0.001 0.001" />
            <joint name="FFJ4" pos="0 0 0" axis="0 -1 0" range="-0.436332 0.436332" actuatorfrcrange="-10 10" damping="50.5" />
            <geom size="0.0025 0.0025 0.0025" type="box" rgba="0.6 0.6 0.6 1" contype="1" conaffinity="0" density="0" group="1" class="visualgeom" />
            <geom type="box" rgba="0.6 0.6 0.6 1" size="0.0025 0.0025 0.0025" />
            <body name="ffproximal">
              <inertial pos="0 0 0" mass="1" diaginertia="0.001 0.001 0.001" />
              <joint name="FFJ3" pos="0 0 0" axis="1 0 0" range="0 1.5708" actuatorfrcrange="-10 10" damping="50.5" />
              <geom size="0.004 0.004 0.02" pos="0 0 0.025" type="box" rgba="0.2 0.2 0.2 1" contype="1" conaffinity="0" density="0" group="1" class="visualgeom" />
              <geom type="box" rgba="0.2 0.2 0.2 1" size="0.004 0.004 0.02" pos="0 0 0.025" />
              <body name="ffmiddle" pos="0 0 0.045">
                <inertial pos="0 0 0" mass="1" diaginertia="0.001 0.001 0.001" />
                <joint name="FFJ2" pos="0 0 0" axis="1 0 0" range="0 1.5708" actuatorfrcrange="-10 10" damping="50.5" />
                <geom size="0.004 0.004 0.0075" pos="0 0 0.0125" type="box" rgba="0.2 0.2 0.2 1" contype="1" conaffinity="0" density="0" group="1" class="visualgeom" />
                <geom type="box" rgba="0.2 0.2 0.2 1" size="0.004 0.004 0.0075" pos="0 0 0.0125" />
                <body name="ffdistal" pos="0 0 0.025">
                  <inertial pos="0 0 0" mass="1" diaginertia="0.001 0.001 0.001" />
                  <joint name="FFJ1" pos="0 0 0" axis="1 0 0" range="0 1.5708" actuatorfrcrange="-10 10" damping="50.5" />
                  <geom type="mesh" rgba="0.2 0.2 0.2 1" mesh="distal_ellipsoid" contype="1" conaffinity="0" density="0" group="1" class="visualgeom" />
                  <geom type="mesh" rgba="0.2 0.2 0.2 1" mesh="distal_ellipsoid" />
                </body>
              </body>
            </body>
          </body>
          <body name="mfknuckle" pos="0.011 0 0.099">
            <inertial pos="0 0 0" mass="1" diaginertia="0.001 0.001 0.001" />
            <joint name="MFJ4" pos="0 0 0" axis="0 -1 0" range="-0.436332 0.436332" actuatorfrcrange="-10 10" damping="50.5" />
            <geom size="0.0025 0.0025 0.0025" type="box" rgba="0.6 0.6 0.6 1" contype="1" conaffinity="0" density="0" group="1" class="visualgeom" />
            <geom type="box" rgba="0.6 0.6 0.6 1" size="0.0025 0.0025 0.0025" />
            <body name="mfproximal">
              <inertial pos="0 0 0" mass="1" diaginertia="0.001 0.001 0.001" />
              <joint name="MFJ3" pos="0 0 0" axis="1 0 0" range="0 1.5708" actuatorfrcrange="-10 10" damping="50.5" />
              <geom size="0.004 0.004 0.02" pos="0 0 0.025" type="box" rgba="0.2 0.2 0.2 1" contype="1" conaffinity="0" density="0" group="1" class="visualgeom" />
              <geom type="box" rgba="0.2 0.2 0.2 1" size="0.004 0.004 0.02" pos="0 0 0.025" />
              <body name="mfmiddle" pos="0 0 0.045">
                <inertial pos="0 0 0" mass="1" diaginertia="0.001 0.001 0.001" />
                <joint name="MFJ2" pos="0 0 0" axis="1 0 0" range="0 1.5708" actuatorfrcrange="-10 10" damping="50.5" />
                <geom size="0.004 0.004 0.0075" pos="0 0 0.0125" type="box" rgba="0.2 0.2 0.2 1" contype="1" conaffinity="0" density="0" group="1" class="visualgeom" />
                <geom type="box" rgba="0.2 0.2 0.2 1" size="0.004 0.004 0.0075" pos="0 0 0.0125" />
                <body name="mfdistal" pos="0 0 0.025">
                  <inertial pos="0 0 0" mass="1" diaginertia="0.001 0.001 0.001" />
                  <joint name="MFJ1" pos="0 0 0" axis="1 0 0" range="0 1.5708" actuatorfrcrange="-10 10" damping="50.5" />
                  <geom type="mesh" rgba="0.2 0.2 0.2 1" mesh="distal_ellipsoid" contype="1" conaffinity="0" density="0" group="1" class="visualgeom" />
                  <geom type="mesh" rgba="0.2 0.2 0.2 1" mesh="distal_ellipsoid" />
                </body>
              </body>
            </body>
          </body>
          <body name="rfknuckle" pos="-0.011 0 0.095">
            <inertial pos="0 0 0" mass="1" diaginertia="0.001 0.001 0.001" />
            <joint name="RFJ4" pos="0 0 0" axis="0 1 0" range="-0.436332 0.436332" actuatorfrcrange="-10 10" damping="50.5" />
            <geom size="0.0025 0.0025 0.0025" type="box" rgba="0.6 0.6 0.6 1" contype="1" conaffinity="0" density="0" group="1" class="visualgeom" />
            <geom type="box" rgba="0.6 0.6 0.6 1" size="0.0025 0.0025 0.0025" />
            <body name="rfproximal">
              <inertial pos="0 0 0" mass="1" diaginertia="0.001 0.001 0.001" />
              <joint name="RFJ3" pos="0 0 0" axis="1 0 0" range="0 1.5708" actuatorfrcrange="-10 10" damping="50.5" />
              <geom size="0.004 0.004 0.02" pos="0 0 0.025" type="box" rgba="0.2 0.2 0.2 1" contype="1" conaffinity="0" density="0" group="1" class="visualgeom" />
              <geom type="box" rgba="0.2 0.2 0.2 1" size="0.004 0.004 0.02" pos="0 0 0.025" />
              <body name="rfmiddle" pos="0 0 0.045">
                <inertial pos="0 0 0" mass="1" diaginertia="0.001 0.001 0.001" />
                <joint name="RFJ2" pos="0 0 0" axis="1 0 0" range="0 1.5708" actuatorfrcrange="-10 10" damping="50.5" />
                <geom size="0.004 0.004 0.0075" pos="0 0 0.0125" type="box" rgba="0.2 0.2 0.2 1" contype="1" conaffinity="0" density="0" group="1" class="visualgeom" />
                <geom type="box" rgba="0.2 0.2 0.2 1" size="0.004 0.004 0.0075" pos="0 0 0.0125" />
                <body name="rfdistal" pos="0 0 0.025">
                  <inertial pos="0 0 0" mass="1" diaginertia="0.001 0.001 0.001" />
                  <joint name="RFJ1" pos="0 0 0" axis="1 0 0" range="0 1.5708" actuatorfrcrange="-10 10" damping="50.5" />
                  <geom type="mesh" rgba="0.2 0.2 0.2 1" mesh="distal_ellipsoid" contype="1" conaffinity="0" density="0" group="1" class="visualgeom" />
                  <geom type="mesh" rgba="0.2 0.2 0.2 1" mesh="distal_ellipsoid" />
                </body>
              </body>
            </body>
          </body>
          <body name="lfmetacarpal" pos="-0.033 0 0.02071">
            <inertial pos="0 0 0" mass="1" diaginertia="0.001 0.001 0.001" />
            <joint name="LFJ5" pos="0 0 0" axis="0.573576 0 0.819152" range="0 0.698132" actuatorfrcrange="-10 10" damping="50.5" />
            <geom size="0.004 0.004 0.015" pos="0 0 0.04" type="box" rgba="0.2 0.2 0.2 1" contype="1" conaffinity="0" density="0" group="1" class="visualgeom" />
            <geom type="box" rgba="0.2 0.2 0.2 1" size="0.004 0.004 0.015" pos="0 0 0.04" />
            <body name="lfknuckle" pos="0 0 0.06579">
              <inertial pos="0 0 0" mass="1" diaginertia="0.001 0.001 0.001" />
              <joint name="LFJ4" pos="0 0 0" axis="0 1 0" range="-0.436332 0.436332" actuatorfrcrange="-10 10" damping="50.5" />
              <geom size="0.0025 0.0025 0.0025" type="box" rgba="0.6 0.6 0.6 1" contype="1" conaffinity="0" density="0" group="1" class="visualgeom" />
              <geom type="box" rgba="0.6 0.6 0.6 1" size="0.0025 0.0025 0.0025" />
              <body name="lfproximal">
                <inertial pos="0 0 0" mass="1" diaginertia="0.001 0.001 0.001" />
                <joint name="LFJ3" pos="0 0 0" axis="1 0 0" range="0 1.5708" actuatorfrcrange="-10 10" damping="50.5" />
                <geom size="0.004 0.004 0.02" pos="0 0 0.025" type="box" rgba="0.2 0.2 0.2 1" contype="1" conaffinity="0" density="0" group="1" class="visualgeom" />
                <geom type="box" rgba="0.2 0.2 0.2 1" size="0.004 0.004 0.02" pos="0 0 0.025" />
                <body name="lfmiddle" pos="0 0 0.045">
                  <inertial pos="0 0 0" mass="1" diaginertia="0.001 0.001 0.001" />
                  <joint name="LFJ2" pos="0 0 0" axis="1 0 0" range="0 1.5708" actuatorfrcrange="-10 10" damping="50.5" />
                  <geom size="0.004 0.004 0.0075" pos="0 0 0.0125" type="box" rgba="0.2 0.2 0.2 1" contype="1" conaffinity="0" density="0" group="1" class="visualgeom" />
                  <geom type="box" rgba="0.2 0.2 0.2 1" size="0.004 0.004 0.0075" pos="0 0 0.0125" />
                  <body name="lfdistal" pos="0 0 0.025">
                    <inertial pos="0 0 0" mass="1" diaginertia="0.001 0.001 0.001" />
                    <joint name="LFJ1" pos="0 0 0" axis="1 0 0" range="0 1.5708" actuatorfrcrange="-10 10" damping="50.5" />
                    <geom type="mesh" rgba="0.2 0.2 0.2 1" mesh="distal_ellipsoid" contype="1" conaffinity="0" density="0" group="1" class="visualgeom" />
                    <geom type="mesh" rgba="0.2 0.2 0.2 1" mesh="distal_ellipsoid" />
                  </body>
                </body>
              </body>
            </body>
          </body>
          <body name="thbase" pos="0.034 -0.0085 0.029" quat="0.92388 0 0.382683 0">
            <inertial pos="0 0 0" mass="1" diaginertia="0.001 0.001 0.001" />
            <joint name="THJ5" pos="0 0 0" axis="0 0 -1" range="-1.047 1.047" actuatorfrcrange="-10 10" damping="50.5" />
            <geom size="0.0005 0.0005 0.0005" type="box" contype="1" conaffinity="0" density="0" group="1" class="visualgeom" />
            <geom type="box" rgba="" size="0.0005 0.0005 0.0005" />
            <body name="thproximal">
              <inertial pos="0 0 0" mass="1" diaginertia="0.001 0.001 0.001" />
              <joint name="THJ4" pos="0 0 0" axis="1 0 0" range="0 1.309" actuatorfrcrange="-10 10" damping="50.5" />
              <geom size="0.004 0.004 0.01" pos="0 0 0.019" type="box" rgba="0.2 0.2 0.2 1" contype="1" conaffinity="0" density="0" group="1" class="visualgeom" />
              <geom type="box" rgba="0.2 0.2 0.2 1" size="0.004 0.004 0.01" pos="0 0 0.019" />
              <body name="thhub" pos="0 0 0.038">
                <inertial pos="0 0 0" mass="1" diaginertia="0.001 0.001 0.001" />
                <joint name="THJ3" pos="0 0 0" axis="1 0 0" range="-0.2618 0.2618" actuatorfrcrange="-10 10" damping="50.5" />
                <geom size="0.0005 0.0005 0.0005" type="box" rgba="0.7 0.7 0.7 1" contype="1" conaffinity="0" density="0" group="1" class="visualgeom" />
                <geom type="box" rgba="0.7 0.7 0.7 1" size="0.0005 0.0005 0.0005" />
                <body name="thmiddle">
                  <inertial pos="0 0 0" mass="1" diaginertia="0.001 0.001 0.001" />
                  <joint name="THJ2" pos="0 0 0" axis="0 -1 0" range="-0.5237 0.5237" actuatorfrcrange="-10 10" damping="50.5" />
                  <geom size="0.004 0.004 0.0075" pos="0 0 0.016" type="box" rgba="0.2 0.2 0.2 1" contype="1" conaffinity="0" density="0" group="1" class="visualgeom" />
                  <geom type="box" rgba="0.2 0.2 0.2 1" size="0.004 0.004 0.0075" pos="0 0 0.016" />
                  <body name="thdistal" pos="0 0 0.032" quat="0.707107 0 0 -0.707107">
                    <inertial pos="0 0 0" mass="1" diaginertia="0.001 0.001 0.001" />
                    <joint name="THJ1" pos="0 0 0" axis="1 0 0" range="0 1.571" actuatorfrcrange="-10 10" damping="50.5" />
                    <geom pos="0 0.002 0.0025" quat="1 0 0 0" type="mesh" rgba="0.2 0.2 0.2 1" mesh="distal_ellipsoid" contype="1" conaffinity="0" density="0" group="1" class="visualgeom" />
                    <geom type="mesh" rgba="0.2 0.2 0.2 1" mesh="distal_ellipsoid" pos="0 0.002 0.0025" quat="1 0 0 0" />
                  </body>
                </body>
              </body>
            </body>
          </body>
        </body>
      </body>
    </body>
  </worldbody>

  <actuator>
    <motor name="WRJ2" joint="WRJ2" ctrllimited="true" ctrlrange="-5 5" gear="1" />
    <motor name="WRJ1" joint="WRJ1" ctrllimited="true" ctrlrange="-5 5" gear="1" />
    <motor name="FFJ4" joint="FFJ4" ctrllimited="true" ctrlrange="-10 10" gear="1" />
    <motor name="FFJ3" joint="FFJ3" ctrllimited="true" ctrlrange="-10 10" gear="1" />
    <motor name="FFJ2" joint="FFJ2" ctrllimited="true" ctrlrange="-10 10" gear="1" />
    <motor name="FFJ1" joint="FFJ1" ctrllimited="true" ctrlrange="-10 10" gear="1" />
    <motor name="MFJ4" joint="MFJ4" ctrllimited="true" ctrlrange="-10 10" gear="1" />
    <motor name="MFJ3" joint="MFJ3" ctrllimited="true" ctrlrange="-10 10" gear="1" />
    <motor name="MFJ2" joint="MFJ2" ctrllimited="true" ctrlrange="-10 10" gear="1" />
    <motor name="MFJ1" joint="MFJ1" ctrllimited="true" ctrlrange="-10 10" gear="1" />
    <motor name="RFJ4" joint="RFJ4" ctrllimited="true" ctrlrange="-10 10" gear="1" />
    <motor name="RFJ3" joint="RFJ3" ctrllimited="true" ctrlrange="-10 10" gear="1" />
    <motor name="RFJ2" joint="RFJ2" ctrllimited="true" ctrlrange="-10 10" gear="1" />
    <motor name="RFJ1" joint="RFJ1" ctrllimited="true" ctrlrange="-10 10" gear="1" />
    <motor name="LFJ5" joint="LFJ5" ctrllimited="true" ctrlrange="-10 10" gear="1" />
    <motor name="LFJ4" joint="LFJ4" ctrllimited="true" ctrlrange="-10 10" gear="1" />
    <motor name="LFJ3" joint="LFJ3" ctrllimited="true" ctrlrange="-10 10" gear="1" />
    <motor name="LFJ2" joint="LFJ2" ctrllimited="true" ctrlrange="-10 10" gear="1" />
    <motor name="LFJ1" joint="LFJ1" ctrllimited="true" ctrlrange="-10 10" gear="1" />
    <motor name="THJ5" joint="THJ5" ctrllimited="true" ctrlrange="-10 10" gear="1" />
    <motor name="THJ4" joint="THJ4" ctrllimited="true" ctrlrange="-10 10" gear="1" />
    <motor name="THJ3" joint="THJ3" ctrllimited="true" ctrlrange="-10 10" gear="1" />
    <motor name="THJ2" joint="THJ2" ctrllimited="true" ctrlrange="-10 10" gear="1" />
    <motor name="THJ1" joint="THJ1" ctrllimited="true" ctrlrange="-10 10" gear="1" />
  </actuator>

  <sensor>
    <actuatorpos name="WRJ2_p" actuator="WRJ2" />
    <actuatorvel name="WRJ2_v" actuator="WRJ2" />
    <actuatorfrc name="WRJ2_f" actuator="WRJ2" noise="0.001" />
    <actuatorpos name="WRJ1_p" actuator="WRJ1" />
    <actuatorvel name="WRJ1_v" actuator="WRJ1" />
    <actuatorfrc name="WRJ1_f" actuator="WRJ1" noise="0.001" />
    <actuatorpos name="FFJ4_p" actuator="FFJ4" />
    <actuatorvel name="FFJ4_v" actuator="FFJ4" />
    <actuatorfrc name="FFJ4_f" actuator="FFJ4" noise="0.001" />
    <actuatorpos name="FFJ3_p" actuator="FFJ3" />
    <actuatorvel name="FFJ3_v" actuator="FFJ3" />
    <actuatorfrc name="FFJ3_f" actuator="FFJ3" noise="0.001" />
    <actuatorpos name="FFJ2_p" actuator="FFJ2" />
    <actuatorvel name="FFJ2_v" actuator="FFJ2" />
    <actuatorfrc name="FFJ2_f" actuator="FFJ2" noise="0.001" />
    <actuatorpos name="FFJ1_p" actuator="FFJ1" />
    <actuatorvel name="FFJ1_v" actuator="FFJ1" />
    <actuatorfrc name="FFJ1_f" actuator="FFJ1" noise="0.001" />
    <actuatorpos name="MFJ4_p" actuator="MFJ4" />
    <actuatorvel name="MFJ4_v" actuator="MFJ4" />
    <actuatorfrc name="MFJ4_f" actuator="MFJ4" noise="0.001" />
    <actuatorpos name="MFJ3_p" actuator="MFJ3" />
    <actuatorvel name="MFJ3_v" actuator="MFJ3" />
    <actuatorfrc name="MFJ3_f" actuator="MFJ3" noise="0.001" />
    <actuatorpos name="MFJ2_p" actuator="MFJ2" />
    <actuatorvel name="MFJ2_v" actuator="MFJ2" />
    <actuatorfrc name="MFJ2_f" actuator="MFJ2" noise="0.001" />
    <actuatorpos name="MFJ1_p" actuator="MFJ1" />
    <actuatorvel name="MFJ1_v" actuator="MFJ1" />
    <actuatorfrc name="MFJ1_f" actuator="MFJ1" noise="0.001" />
    <actuatorpos name="RFJ4_p" actuator="RFJ4" />
    <actuatorvel name="RFJ4_v" actuator="RFJ4" />
    <actuatorfrc name="RFJ4_f" actuator="RFJ4" noise="0.001" />
    <actuatorpos name="RFJ3_p" actuator="RFJ3" />
    <actuatorvel name="RFJ3_v" actuator="RFJ3" />
    <actuatorfrc name="RFJ3_f" actuator="RFJ3" noise="0.001" />
    <actuatorpos name="RFJ2_p" actuator="RFJ2" />
    <actuatorvel name="RFJ2_v" actuator="RFJ2" />
    <actuatorfrc name="RFJ2_f" actuator="RFJ2" noise="0.001" />
    <actuatorpos name="RFJ1_p" actuator="RFJ1" />
    <actuatorvel name="RFJ1_v" actuator="RFJ1" />
    <actuatorfrc name="RFJ1_f" actuator="RFJ1" noise="0.001" />
    <actuatorpos name="LFJ5_p" actuator="LFJ5" />
    <actuatorvel name="LFJ5_v" actuator="LFJ5" />
    <actuatorfrc name="LFJ5_f" actuator="LFJ5" noise="0.001" />
    <actuatorpos name="LFJ4_p" actuator="LFJ4" />
    <actuatorvel name="LFJ4_v" actuator="LFJ4" />
    <actuatorfrc name="LFJ4_f" actuator="LFJ4" noise="0.001" />
    <actuatorpos name="LFJ3_p" actuator="LFJ3" />
    <actuatorvel name="LFJ3_v" actuator="LFJ3" />
    <actuatorfrc name="LFJ3_f" actuator="LFJ3" noise="0.001" />
    <actuatorpos name="LFJ2_p" actuator="LFJ2" />
    <actuatorvel name="LFJ2_v" actuator="LFJ2" />
    <actuatorfrc name="LFJ2_f" actuator="LFJ2" noise="0.001" />
    <actuatorpos name="LFJ1_p" actuator="LFJ1" />
    <actuatorvel name="LFJ1_v" actuator="LFJ1" />
    <actuatorfrc name="LFJ1_f" actuator="LFJ1" noise="0.001" />
    <actuatorpos name="THJ5_p" actuator="THJ5" />
    <actuatorvel name="THJ5_v" actuator="THJ5" />
    <actuatorfrc name="THJ5_f" actuator="THJ5" noise="0.001" />
    <actuatorpos name="THJ4_p" actuator="THJ4" />
    <actuatorvel name="THJ4_v" actuator="THJ4" />
    <actuatorfrc name="THJ4_f" actuator="THJ4" noise="0.001" />
    <actuatorpos name="THJ3_p" actuator="THJ3" />
    <actuatorvel name="THJ3_v" actuator="THJ3" />
    <actuatorfrc name="THJ3_f" actuator="THJ3" noise="0.001" />
    <actuatorpos name="THJ2_p" actuator="THJ2" />
    <actuatorvel name="THJ2_v" actuator="THJ2" />
    <actuatorfrc name="THJ2_f" actuator="THJ2" noise="0.001" />
    <actuatorpos name="THJ1_p" actuator="THJ1" />
    <actuatorvel name="THJ1_v" actuator="THJ1" />
    <actuatorfrc name="THJ1_f" actuator="THJ1" noise="0.001" />
    <framequat name="orientation" objtype="site" noise="0.001" objname="imu" />
    <gyro name="angular-velocity" site="imu" noise="0.005" cutoff="34.9" />
  </sensor>
</mujoco>