<mujoco model="shadowhand">
  <option iterations="50" timestep="0.001" solver="PGS" gravity="0 0 -9.81" />

  <compiler angle="radian" meshdir="meshes" eulerseq="zyx" autolimits="true" />

  <default>
    <joint limited="true" damping="0.01" armature="0.01" frictionloss="0.01" />
    <geom condim="4" contype="1" conaffinity="15" friction="0.9 0.2 0.2" solref="0.001 2" />
    <motor ctrllimited="true" />
    <equality solref="0.001 2" />
    <default class="visualgeom">
      <geom material="visualgeom" condim="1" contype="0" conaffinity="0" />
    </default>
  </default>

  <asset>
    <mesh name="F1" content_type="model/obj" file="F1.obj" />
    <texture name="texplane" type="2d" builtin="checker" rgb1=".0 .0 .0" rgb2=".8 .8 .8" width="100" height="100" />
    <material name="matplane" reflectance="0." texture="texplane" texrepeat="1 1" texuniform="true" />
    <material name="visualgeom" rgba="0.5 0.9 0.2 1" />
  </asset>

  <worldbody>
    <light directional="true" diffuse="0.4 0.4 0.4" specular="0.1 0.1 0.1" pos="0 0 5.0" dir="0 0 -1" castshadow="false" />
    <light directional="true" diffuse="0.6 0.6 0.6" specular="0.2 0.2 0.2" pos="0 0 4" dir="0 0 -1" />
    <geom name="ground" type="plane" pos="0 0 0" size="100 100 0.001" quat="1 0 0 0" material="matplane" condim="3" conaffinity="15" />
    <camera name="fixed" pos="0 -3.0 0.5" xyaxes="1 0 0 0 0 1" />
    <camera name="track" mode="trackcom" pos="0 -3.0 0.5" xyaxes="1 0 0 0 0 1" />
    <body name="root" pos="0 0 -0.0" quat="1 0 0 0">
      <freejoint name="root" />
      <site name="imu" size="0.01" pos="0 0 0" />
      <geom pos="0 0.002 0.0025" quat="1 0 0 0" type="mesh" rgba="0.2 0.2 0.2 1" mesh="F1" contype="1" conaffinity="0" density="0" group="1" class="visualgeom" />
      <geom type="mesh" rgba="0.2 0.2 0.2 1" mesh="F1" pos="0 0.002 0.0025" quat="1 0 0 0" />
      <geom type="mesh" rgba="0.2 0.2 0.2 1" mesh="F1" contype="1" conaffinity="0" density="0" group="1" class="visualgeom" />
      <geom type="mesh" rgba="0.2 0.2 0.2 1" mesh="F1" />
      <geom type="mesh" rgba="0.2 0.2 0.2 1" mesh="F1" contype="1" conaffinity="0" density="0" group="1" class="visualgeom" />
      <geom type="mesh" rgba="0.2 0.2 0.2 1" mesh="F1" />
      <geom type="mesh" rgba="0.2 0.2 0.2 1" mesh="F1" contype="1" conaffinity="0" density="0" group="1" class="visualgeom" />
      <geom type="mesh" rgba="0.2 0.2 0.2 1" mesh="F1" />
      <geom type="mesh" rgba="0.2 0.2 0.2 1" mesh="F1" contype="1" conaffinity="0" density="0" group="1" class="visualgeom" />
      <geom type="mesh" rgba="0.2 0.2 0.2 1" mesh="F1" />
      <body name="allegro_root1">
        <inertial pos="0 0 0" mass="1" diaginertia="0.001 0.001 0.001" />
        <joint name="x_joint" pos="0 0 0" axis="1 0 0" type="slide" range="-0.5 0.5" />
        <body name="allegro_root2">
          <inertial pos="0 0 0" mass="1" diaginertia="0.001 0.001 0.001" />
          <joint name="y_joint" pos="0 0 0" axis="0 1 0" type="slide" range="-0.5 0.5" />
          <body name="allegro_root3">
            <inertial pos="0 0 0" mass="1" diaginertia="0.001 0.001 0.001" />
            <joint name="z_joint" pos="0 0 0" axis="0 0 1" type="slide" range="-0.5 0.5" />
            <body name="allegro_root4">
              <inertial pos="0 0 0" mass="1" diaginertia="0.001 0.001 0.001" />
              <joint name="x_rotation_joint" pos="0 0 0" axis="1 0 0" range="-3.14 3.14" />
              <body name="allegro_root5">
                <inertial pos="0 0 0" mass="1" diaginertia="0.001 0.001 0.001" />
                <joint name="y_rotation_joint" pos="0 0 0" axis="0 1 0" range="-3.14 3.14" />
                <body name="wrist" quat="0.707035 0 0.707179 0">
                  <inertial pos="0 0 0" mass="2" diaginertia="0.002 0.002 0.002" />
                  <joint name="z_rotation_joint" pos="0 0 0" axis="0 0 1" range="-3.14 3.14" />
                  <geom size="0.025 0.01 0.035" pos="-0.035001 0 0.00499287" quat="0.707035 0 -0.707179 0" type="box" rgba="0.2 0.2 0.2 1" contype="1" conaffinity="0" density="0" group="1" class="visualgeom" />
                  <geom type="box" rgba="0.2 0.2 0.2 1" size="0.025 0.01 0.035" pos="-0.035001 0 0.00499287" quat="0.707035 0 -0.707179 0" />
                  <body name="ffknuckle" pos="-0.0950067 0 0.0329807" quat="0.707035 0 -0.707179 0">
                    <inertial pos="0 0 0" mass="1" diaginertia="0.001 0.001 0.001" />
                    <joint name="FFJ4" pos="0 0 0" axis="0 -1 0" range="-0.436332 0.436332" actuatorfrcrange="-100 100" damping="50.5" />
                    <geom size="0.0025 0.0025 0.0025" type="box" rgba="0.6 0.6 0.6 1" contype="1" conaffinity="0" density="0" group="1" class="visualgeom" />
                    <geom type="box" rgba="0.6 0.6 0.6 1" size="0.0025 0.0025 0.0025" />
                    <body name="ffproximal">
                      <inertial pos="0 0 0" mass="1" diaginertia="0.001 0.001 0.001" />
                      <joint name="FFJ3" pos="0 0 0" axis="1 0 0" range="0 1.5708" actuatorfrcrange="-100 100" damping="50.5" />
                      <geom size="0.004 0.004 0.02" pos="0 0 0.025" type="box" rgba="0.2 0.2 0.2 1" contype="1" conaffinity="0" density="0" group="1" class="visualgeom" />
                      <geom type="box" rgba="0.2 0.2 0.2 1" size="0.004 0.004 0.02" pos="0 0 0.025" />
                      <body name="ffmiddle" pos="0 0 0.045">
                        <inertial pos="0 0 0" mass="1" diaginertia="0.001 0.001 0.001" />
                        <joint name="FFJ2" pos="0 0 0" axis="1 0 0" range="0 1.5708" actuatorfrcrange="-100 100" damping="50.5" />
                        <geom size="0.004 0.004 0.0075" pos="0 0 0.0125" type="box" rgba="0.2 0.2 0.2 1" contype="1" conaffinity="0" density="0" group="1" class="visualgeom" />
                        <geom type="box" rgba="0.2 0.2 0.2 1" size="0.004 0.004 0.0075" pos="0 0 0.0125" />
                      </body>
                    </body>
                  </body>
                  <body name="mfknuckle" pos="-0.0990022 0 0.0109798" quat="0.707035 0 -0.707179 0">
                    <inertial pos="0 0 0" mass="1" diaginertia="0.001 0.001 0.001" />
                    <joint name="MFJ4" pos="0 0 0" axis="0 -1 0" range="-0.436332 0.436332" actuatorfrcrange="-100 100" damping="50.5" />
                    <geom size="0.0025 0.0025 0.0025" type="box" rgba="0.6 0.6 0.6 1" contype="1" conaffinity="0" density="0" group="1" class="visualgeom" />
                    <geom type="box" rgba="0.6 0.6 0.6 1" size="0.0025 0.0025 0.0025" />
                    <body name="mfproximal">
                      <inertial pos="0 0 0" mass="1" diaginertia="0.001 0.001 0.001" />
                      <joint name="MFJ3" pos="0 0 0" axis="1 0 0" range="0 1.5708" actuatorfrcrange="-100 100" damping="50.5" />
                      <geom size="0.004 0.004 0.02" pos="0 0 0.025" type="box" rgba="0.2 0.2 0.2 1" contype="1" conaffinity="0" density="0" group="1" class="visualgeom" />
                      <geom type="box" rgba="0.2 0.2 0.2 1" size="0.004 0.004 0.02" pos="0 0 0.025" />
                      <body name="mfmiddle" pos="0 0 0.045">
                        <inertial pos="0 0 0" mass="1" diaginertia="0.001 0.001 0.001" />
                        <joint name="MFJ2" pos="0 0 0" axis="1 0 0" range="0 1.5708" actuatorfrcrange="-100 100" damping="50.5" />
                        <geom size="0.004 0.004 0.0075" pos="0 0 0.0125" type="box" rgba="0.2 0.2 0.2 1" contype="1" conaffinity="0" density="0" group="1" class="visualgeom" />
                        <geom type="box" rgba="0.2 0.2 0.2 1" size="0.004 0.004 0.0075" pos="0 0 0.0125" />
                      </body>
                    </body>
                  </body>
                  <body name="rfknuckle" pos="-0.0949978 0 -0.0110193" quat="0.707035 0 -0.707179 0">
                    <inertial pos="0 0 0" mass="1" diaginertia="0.001 0.001 0.001" />
                    <joint name="RFJ4" pos="0 0 0" axis="0 1 0" range="-0.436332 0.436332" actuatorfrcrange="-100 100" damping="50.5" />
                    <geom size="0.0025 0.0025 0.0025" type="box" rgba="0.6 0.6 0.6 1" contype="1" conaffinity="0" density="0" group="1" class="visualgeom" />
                    <geom type="box" rgba="0.6 0.6 0.6 1" size="0.0025 0.0025 0.0025" />
                    <body name="rfproximal">
                      <inertial pos="0 0 0" mass="1" diaginertia="0.001 0.001 0.001" />
                      <joint name="RFJ3" pos="0 0 0" axis="1 0 0" range="0 1.5708" actuatorfrcrange="-100 100" damping="50.5" />
                      <geom size="0.004 0.004 0.02" pos="0 0 0.025" type="box" rgba="0.2 0.2 0.2 1" contype="1" conaffinity="0" density="0" group="1" class="visualgeom" />
                      <geom type="box" rgba="0.2 0.2 0.2 1" size="0.004 0.004 0.02" pos="0 0 0.025" />
                      <body name="rfmiddle" pos="0 0 0.045">
                        <inertial pos="0 0 0" mass="1" diaginertia="0.001 0.001 0.001" />
                        <joint name="RFJ2" pos="0 0 0" axis="1 0 0" range="0 1.5708" actuatorfrcrange="-100 100" damping="50.5" />
                        <geom size="0.004 0.004 0.0075" pos="0 0 0.0125" type="box" rgba="0.2 0.2 0.2 1" contype="1" conaffinity="0" density="0" group="1" class="visualgeom" />
                        <geom type="box" rgba="0.2 0.2 0.2 1" size="0.004 0.004 0.0075" pos="0 0 0.0125" />
                      </body>
                    </body>
                  </body>
                  <body name="lfmetacarpal" pos="-0.0207033 0 -0.0330042" quat="0.707035 0 -0.707179 0">
                    <inertial pos="0 0 0" mass="1" diaginertia="0.001 0.001 0.001" />
                    <joint name="LFJ5" pos="0 0 0" axis="0.573576 0 0.819152" range="0 0.698132" actuatorfrcrange="-100 100" damping="50.5" />
                    <geom size="0.004 0.004 0.015" pos="0 0 0.04" type="box" rgba="0.2 0.2 0.2 1" contype="1" conaffinity="0" density="0" group="1" class="visualgeom" />
                    <geom type="box" rgba="0.2 0.2 0.2 1" size="0.004 0.004 0.015" pos="0 0 0.04" />
                    <body name="lfknuckle" pos="0 0 0.06579">
                      <inertial pos="0 0 0" mass="1" diaginertia="0.001 0.001 0.001" />
                      <joint name="LFJ4" pos="0 0 0" axis="0 1 0" range="-0.436332 0.436332" actuatorfrcrange="-100 100" damping="50.5" />
                      <geom size="0.0025 0.0025 0.0025" type="box" rgba="0.6 0.6 0.6 1" contype="1" conaffinity="0" density="0" group="1" class="visualgeom" />
                      <geom type="box" rgba="0.6 0.6 0.6 1" size="0.0025 0.0025 0.0025" />
                      <body name="lfproximal">
                        <inertial pos="0 0 0" mass="1" diaginertia="0.001 0.001 0.001" />
                        <joint name="LFJ3" pos="0 0 0" axis="1 0 0" range="0 1.5708" actuatorfrcrange="-100 100" damping="50.5" />
                        <geom size="0.004 0.004 0.02" pos="0 0 0.025" type="box" rgba="0.2 0.2 0.2 1" contype="1" conaffinity="0" density="0" group="1" class="visualgeom" />
                        <geom type="box" rgba="0.2 0.2 0.2 1" size="0.004 0.004 0.02" pos="0 0 0.025" />
                        <body name="lfmiddle" pos="0 0 0.045">
                          <inertial pos="0 0 0" mass="1" diaginertia="0.001 0.001 0.001" />
                          <joint name="LFJ2" pos="0 0 0" axis="1 0 0" range="0 1.5708" actuatorfrcrange="-100 100" damping="50.5" />
                          <geom size="0.004 0.004 0.0075" pos="0 0 0.0125" type="box" rgba="0.2 0.2 0.2 1" contype="1" conaffinity="0" density="0" group="1" class="visualgeom" />
                          <geom type="box" rgba="0.2 0.2 0.2 1" size="0.004 0.004 0.0075" pos="0 0 0.0125" />
                        </body>
                      </body>
                    </body>
                  </body>
                  <body name="thbase" pos="-0.0290069 -0.0085 0.0339941" quat="0.923841 0 -0.382778 0">
                    <inertial pos="0 0 0" mass="1" diaginertia="0.001 0.001 0.001" />
                    <joint name="THJ5" pos="0 0 0" axis="0 0 -1" range="-1.047 1.047" actuatorfrcrange="-100 100" damping="50.5" />
                    <geom size="0.0005 0.0005 0.0005" type="box" contype="1" conaffinity="0" density="0" group="1" class="visualgeom" />
                    <geom type="box" rgba="" size="0.0005 0.0005 0.0005" />
                    <body name="thproximal">
                      <inertial pos="0 0 0" mass="1" diaginertia="0.001 0.001 0.001" />
                      <joint name="THJ4" pos="0 0 0" axis="1 0 0" range="0 1.309" actuatorfrcrange="-100 100" damping="50.5" />
                      <geom size="0.004 0.004 0.01" pos="0 0 0.019" type="box" rgba="0.2 0.2 0.2 1" contype="1" conaffinity="0" density="0" group="1" class="visualgeom" />
                      <geom type="box" rgba="0.2 0.2 0.2 1" size="0.004 0.004 0.01" pos="0 0 0.019" />
                      <body name="thhub" pos="0 0 0.038">
                        <inertial pos="0 0 0" mass="1" diaginertia="0.001 0.001 0.001" />
                        <joint name="THJ3" pos="0 0 0" axis="1 0 0" range="-0.2618 0.2618" actuatorfrcrange="-100 100" damping="50.5" />
                        <geom size="0.0005 0.0005 0.0005" type="box" rgba="0.7 0.7 0.7 1" contype="1" conaffinity="0" density="0" group="1" class="visualgeom" />
                        <geom type="box" rgba="0.7 0.7 0.7 1" size="0.0005 0.0005 0.0005" />
                        <body name="thmiddle">
                          <inertial pos="0 0 0" mass="1" diaginertia="0.001 0.001 0.001" />
                          <joint name="THJ2" pos="0 0 0" axis="0 -1 0" range="-0.5237 0.5237" actuatorfrcrange="-100 100" damping="50.5" />
                          <geom size="0.004 0.004 0.0075" pos="0 0 0.016" type="box" rgba="0.2 0.2 0.2 1" contype="1" conaffinity="0" density="0" group="1" class="visualgeom" />
                          <geom type="box" rgba="0.2 0.2 0.2 1" size="0.004 0.004 0.0075" pos="0 0 0.016" />
                        </body>
                      </body>
                    </body>
                  </body>
                </body>
              </body>
            </body>
          </body>
        </body>
      </body>
    </body>
  </worldbody>

  <actuator>
    <motor name="x_joint" joint="x_joint" ctrllimited="true" ctrlrange="-1 1" gear="1" />
    <motor name="y_joint" joint="y_joint" ctrllimited="true" ctrlrange="-1 1" gear="1" />
    <motor name="z_joint" joint="z_joint" ctrllimited="true" ctrlrange="-1 1" gear="1" />
    <motor name="x_rotation_joint" joint="x_rotation_joint" ctrllimited="true" ctrlrange="-1 1" gear="1" />
    <motor name="y_rotation_joint" joint="y_rotation_joint" ctrllimited="true" ctrlrange="-1 1" gear="1" />
    <motor name="z_rotation_joint" joint="z_rotation_joint" ctrllimited="true" ctrlrange="-1 1" gear="1" />
    <motor name="FFJ4" joint="FFJ4" ctrllimited="true" ctrlrange="-100 100" gear="1" />
    <motor name="FFJ3" joint="FFJ3" ctrllimited="true" ctrlrange="-100 100" gear="1" />
    <motor name="FFJ2" joint="FFJ2" ctrllimited="true" ctrlrange="-100 100" gear="1" />
    <motor name="MFJ4" joint="MFJ4" ctrllimited="true" ctrlrange="-100 100" gear="1" />
    <motor name="MFJ3" joint="MFJ3" ctrllimited="true" ctrlrange="-100 100" gear="1" />
    <motor name="MFJ2" joint="MFJ2" ctrllimited="true" ctrlrange="-100 100" gear="1" />
    <motor name="RFJ4" joint="RFJ4" ctrllimited="true" ctrlrange="-100 100" gear="1" />
    <motor name="RFJ3" joint="RFJ3" ctrllimited="true" ctrlrange="-100 100" gear="1" />
    <motor name="RFJ2" joint="RFJ2" ctrllimited="true" ctrlrange="-100 100" gear="1" />
    <motor name="LFJ5" joint="LFJ5" ctrllimited="true" ctrlrange="-100 100" gear="1" />
    <motor name="LFJ4" joint="LFJ4" ctrllimited="true" ctrlrange="-100 100" gear="1" />
    <motor name="LFJ3" joint="LFJ3" ctrllimited="true" ctrlrange="-100 100" gear="1" />
    <motor name="LFJ2" joint="LFJ2" ctrllimited="true" ctrlrange="-100 100" gear="1" />
    <motor name="THJ5" joint="THJ5" ctrllimited="true" ctrlrange="-100 100" gear="1" />
    <motor name="THJ4" joint="THJ4" ctrllimited="true" ctrlrange="-100 100" gear="1" />
    <motor name="THJ3" joint="THJ3" ctrllimited="true" ctrlrange="-100 100" gear="1" />
    <motor name="THJ2" joint="THJ2" ctrllimited="true" ctrlrange="-100 100" gear="1" />
  </actuator>

  <sensor>
    <actuatorpos name="x_joint_p" actuator="x_joint" />
    <actuatorvel name="x_joint_v" actuator="x_joint" />
    <actuatorfrc name="x_joint_f" actuator="x_joint" noise="0.001" />
    <actuatorpos name="y_joint_p" actuator="y_joint" />
    <actuatorvel name="y_joint_v" actuator="y_joint" />
    <actuatorfrc name="y_joint_f" actuator="y_joint" noise="0.001" />
    <actuatorpos name="z_joint_p" actuator="z_joint" />
    <actuatorvel name="z_joint_v" actuator="z_joint" />
    <actuatorfrc name="z_joint_f" actuator="z_joint" noise="0.001" />
    <actuatorpos name="x_rotation_joint_p" actuator="x_rotation_joint" />
    <actuatorvel name="x_rotation_joint_v" actuator="x_rotation_joint" />
    <actuatorfrc name="x_rotation_joint_f" actuator="x_rotation_joint" noise="0.001" />
    <actuatorpos name="y_rotation_joint_p" actuator="y_rotation_joint" />
    <actuatorvel name="y_rotation_joint_v" actuator="y_rotation_joint" />
    <actuatorfrc name="y_rotation_joint_f" actuator="y_rotation_joint" noise="0.001" />
    <actuatorpos name="z_rotation_joint_p" actuator="z_rotation_joint" />
    <actuatorvel name="z_rotation_joint_v" actuator="z_rotation_joint" />
    <actuatorfrc name="z_rotation_joint_f" actuator="z_rotation_joint" noise="0.001" />
    <actuatorpos name="FFJ4_p" actuator="FFJ4" />
    <actuatorvel name="FFJ4_v" actuator="FFJ4" />
    <actuatorfrc name="FFJ4_f" actuator="FFJ4" noise="0.001" />
    <actuatorpos name="FFJ3_p" actuator="FFJ3" />
    <actuatorvel name="FFJ3_v" actuator="FFJ3" />
    <actuatorfrc name="FFJ3_f" actuator="FFJ3" noise="0.001" />
    <actuatorpos name="FFJ2_p" actuator="FFJ2" />
    <actuatorvel name="FFJ2_v" actuator="FFJ2" />
    <actuatorfrc name="FFJ2_f" actuator="FFJ2" noise="0.001" />
    <actuatorpos name="MFJ4_p" actuator="MFJ4" />
    <actuatorvel name="MFJ4_v" actuator="MFJ4" />
    <actuatorfrc name="MFJ4_f" actuator="MFJ4" noise="0.001" />
    <actuatorpos name="MFJ3_p" actuator="MFJ3" />
    <actuatorvel name="MFJ3_v" actuator="MFJ3" />
    <actuatorfrc name="MFJ3_f" actuator="MFJ3" noise="0.001" />
    <actuatorpos name="MFJ2_p" actuator="MFJ2" />
    <actuatorvel name="MFJ2_v" actuator="MFJ2" />
    <actuatorfrc name="MFJ2_f" actuator="MFJ2" noise="0.001" />
    <actuatorpos name="RFJ4_p" actuator="RFJ4" />
    <actuatorvel name="RFJ4_v" actuator="RFJ4" />
    <actuatorfrc name="RFJ4_f" actuator="RFJ4" noise="0.001" />
    <actuatorpos name="RFJ3_p" actuator="RFJ3" />
    <actuatorvel name="RFJ3_v" actuator="RFJ3" />
    <actuatorfrc name="RFJ3_f" actuator="RFJ3" noise="0.001" />
    <actuatorpos name="RFJ2_p" actuator="RFJ2" />
    <actuatorvel name="RFJ2_v" actuator="RFJ2" />
    <actuatorfrc name="RFJ2_f" actuator="RFJ2" noise="0.001" />
    <actuatorpos name="LFJ5_p" actuator="LFJ5" />
    <actuatorvel name="LFJ5_v" actuator="LFJ5" />
    <actuatorfrc name="LFJ5_f" actuator="LFJ5" noise="0.001" />
    <actuatorpos name="LFJ4_p" actuator="LFJ4" />
    <actuatorvel name="LFJ4_v" actuator="LFJ4" />
    <actuatorfrc name="LFJ4_f" actuator="LFJ4" noise="0.001" />
    <actuatorpos name="LFJ3_p" actuator="LFJ3" />
    <actuatorvel name="LFJ3_v" actuator="LFJ3" />
    <actuatorfrc name="LFJ3_f" actuator="LFJ3" noise="0.001" />
    <actuatorpos name="LFJ2_p" actuator="LFJ2" />
    <actuatorvel name="LFJ2_v" actuator="LFJ2" />
    <actuatorfrc name="LFJ2_f" actuator="LFJ2" noise="0.001" />
    <actuatorpos name="THJ5_p" actuator="THJ5" />
    <actuatorvel name="THJ5_v" actuator="THJ5" />
    <actuatorfrc name="THJ5_f" actuator="THJ5" noise="0.001" />
    <actuatorpos name="THJ4_p" actuator="THJ4" />
    <actuatorvel name="THJ4_v" actuator="THJ4" />
    <actuatorfrc name="THJ4_f" actuator="THJ4" noise="0.001" />
    <actuatorpos name="THJ3_p" actuator="THJ3" />
    <actuatorvel name="THJ3_v" actuator="THJ3" />
    <actuatorfrc name="THJ3_f" actuator="THJ3" noise="0.001" />
    <actuatorpos name="THJ2_p" actuator="THJ2" />
    <actuatorvel name="THJ2_v" actuator="THJ2" />
    <actuatorfrc name="THJ2_f" actuator="THJ2" noise="0.001" />
    <framequat name="orientation" objtype="site" noise="0.001" objname="imu" />
    <gyro name="angular-velocity" site="imu" noise="0.005" cutoff="34.9" />
  </sensor>
</mujoco>