<mujoco model="shadow_right">
  <option iterations="50" timestep="0.001" solver="PGS" gravity="0 0 -9.81" />

  <compiler angle="radian" meshdir="meshes" eulerseq="zyx" autolimits="true" />

  <default>
    <joint limited="true" damping="0.01" armature="0.01" frictionloss="0.01" />
    <geom condim="4" contype="1" conaffinity="15" friction="0.9 0.2 0.2" solref="0.001 2" />
    <motor ctrllimited="true" />
    <equality solref="0.001 2" />
    <default class="visualgeom">
      <geom material="visualgeom" condim="1" contype="0" conaffinity="0" />
    </default>
  </default>

  <asset>
    <mesh name="th_proximal_E3M5" content_type="model/obj" file="th_proximal_E3M5.obj" scale="0.001 0.001 0.001" />
    <mesh name="th_middle_E3M5" content_type="model/obj" file="th_middle_E3M5.obj" scale="0.001 0.001 0.001" />
    <mesh name="th_distal_pst" content_type="model/obj" file="th_distal_pst.obj" scale="0.001 0.001 0.001" />
    <mesh name="f_knuckle_E3M5" content_type="model/obj" file="f_knuckle_E3M5.obj" />
    <mesh name="f_distal_pst" content_type="model/obj" file="f_distal_pst.obj" scale="0.001 0.001 0.001" />
    <texture name="texplane" type="2d" builtin="checker" rgb1=".0 .0 .0" rgb2=".8 .8 .8" width="100" height="100" />
    <material name="matplane" reflectance="0." texture="texplane" texrepeat="1 1" texuniform="true" />
    <material name="visualgeom" rgba="0.5 0.9 0.2 1" />
  </asset>

  <worldbody>
    <light directional="true" diffuse="0.4 0.4 0.4" specular="0.1 0.1 0.1" pos="0 0 5.0" dir="0 0 -1" castshadow="false" />
    <light directional="true" diffuse="0.6 0.6 0.6" specular="0.2 0.2 0.2" pos="0 0 4" dir="0 0 -1" />
    <geom name="ground" type="plane" pos="0 0 0" size="100 100 0.001" quat="1 0 0 0" material="matplane" condim="3" conaffinity="15" />
    <camera name="fixed" pos="0 -3.0 9.856704022229868" xyaxes="1 0 0 0 0 1" />
    <camera name="track" mode="trackcom" pos="0 -3.0 9.856704022229868" xyaxes="1 0 0 0 0 1" />
    <body name="root" pos="0 0 9.356704022229868" quat="1 0 0 0">
      <freejoint name="root" />
      <site name="imu" size="0.01" pos="0 0 0" />
      <geom size="0.031 0.0035 0.045" pos="-0.00200224 0.0085 -0.00900855" quat="0.707035 0 -0.707179 0" type="box" contype="1" conaffinity="0" density="0" group="1" class="visualgeom" />
      <geom type="box" rgba="" size="0.031 0.0035 0.045" pos="-0.00200224 0.0085 -0.00900855" quat="0.707035 0 -0.707179 0" />
      <geom size="0.018 0.0085 0.045" pos="-0.00199959 -0.0035 -0.0220086" quat="0.707035 0 -0.707179 0" type="box" contype="1" conaffinity="0" density="0" group="1" class="visualgeom" />
      <geom type="box" rgba="" size="0.018 0.0085 0.045" pos="-0.00199959 -0.0035 -0.0220086" quat="0.707035 0 -0.707179 0" />
      <geom size="0.013 0.0085 0.005" pos="-0.0420059 -0.0035 0.0089833" quat="0.707035 0 -0.707179 0" type="box" contype="1" conaffinity="0" density="0" group="1" class="visualgeom" />
      <geom type="box" rgba="" size="0.013 0.0085 0.005" pos="-0.0420059 -0.0035 0.0089833" quat="0.707035 0 -0.707179 0" />
      <geom size="0.013 0.007 0.009" pos="-0.0300054 -0.001 0.00648574" quat="0.706816 -0.0176919 -0.689356 0.157758" type="box" contype="1" conaffinity="0" density="0" group="1" class="visualgeom" />
      <geom type="box" rgba="" size="0.013 0.007 0.009" pos="-0.0300054 -0.001 0.00648574" quat="0.706816 -0.0176919 -0.689356 0.157758" />
      <geom size="0.0105 0.0135 0.008" pos="0.0349936 -0.0085 0.011499" quat="0.707035 0 -0.707179 0" type="box" contype="1" conaffinity="0" density="0" group="1" class="visualgeom" />
      <geom type="box" rgba="" size="0.0105 0.0135 0.008" pos="0.0349936 -0.0085 0.011499" quat="0.707035 0 -0.707179 0" />
      <geom size="0.011 0.0025 0.016" pos="0.0269975 -0.015 -0.00750265" quat="0.68677 0.168098 -0.68691 -0.168064" type="box" contype="1" conaffinity="0" density="0" group="1" class="visualgeom" />
      <geom type="box" rgba="" size="0.011 0.0025 0.016" pos="0.0269975 -0.015 -0.00750265" quat="0.68677 0.168098 -0.68691 -0.168064" />
      <geom size="0.009 0.012 0.002" pos="-0.0490022 0 -0.00901813" quat="0.707035 0 -0.707179 0" type="box" contype="1" conaffinity="0" density="0" group="1" class="visualgeom" />
      <geom type="box" rgba="" size="0.009 0.012 0.002" pos="-0.0490022 0 -0.00901813" quat="0.707035 0 -0.707179 0" />
      <geom size="0.01 0.012 0.016" pos="0.0270061 0 -0.0500026" quat="0.707035 0 -0.707179 0" type="box" contype="1" conaffinity="0" density="0" group="1" class="visualgeom" />
      <geom type="box" rgba="" size="0.01 0.012 0.016" pos="0.0270061 0 -0.0500026" quat="0.707035 0 -0.707179 0" />
      <body name="thbase" pos="0.0109931 -0.00858 0.0139941" quat="0.653254 0.270665 -0.270665 -0.653254">
        <inertial pos="0 0 0" mass="1" diaginertia="0.001 0.001 0.001" />
        <joint name="THJ5" pos="0 0 0" axis="0 0 -1" range="-1.0472 1.0472" actuatorfrcrange="-5 5" damping="0.2" />
        <geom size="0.011" contype="1" conaffinity="0" density="0" group="1" class="visualgeom" />
        <geom type="" rgba="" />
        <body name="thproximal">
          <inertial pos="0 0 0" mass="1" diaginertia="0.001 0.001 0.001" />
          <joint name="THJ4" pos="0 0 0" axis="0 1 0" range="0 1.22173" actuatorfrcrange="-3 3" damping="0.2" />
          <geom type="mesh" mesh="th_proximal_E3M5" contype="1" conaffinity="0" density="0" group="1" class="visualgeom" />
          <geom type="mesh" rgba="" mesh="th_proximal_E3M5" />
          <body name="thhub" pos="0 0 0.038">
            <inertial pos="0 0 0" mass="1" diaginertia="0.001 0.001 0.001" />
            <joint name="THJ3" pos="0 0 0" axis="0 1 0" range="-0.20944 0.20944" actuatorfrcrange="-2 2" damping="0.2" />
            <geom size="0.01" contype="1" conaffinity="0" density="0" group="1" class="visualgeom" />
            <geom type="" rgba="" />
            <body name="thmiddle">
              <inertial pos="0 0 0" mass="1" diaginertia="0.001 0.001 0.001" />
              <joint name="THJ2" pos="0 0 0" axis="1 0 0" range="-0.698132 0.698132" actuatorfrcrange="-2 2" damping="0.1" />
              <geom type="mesh" mesh="th_middle_E3M5" contype="1" conaffinity="0" density="0" group="1" class="visualgeom" />
              <geom type="mesh" rgba="" mesh="th_middle_E3M5" />
              <body name="thdistal" pos="0 0 0.032">
                <inertial pos="0 0 0" mass="1" diaginertia="0.001 0.001 0.001" />
                <joint name="THJ1" pos="0 0 0" axis="1 0 0" range="-0.261799 1.5708" actuatorfrcrange="-1 1" damping="0.2" />
                <geom type="mesh" mesh="th_distal_pst" contype="1" conaffinity="0" density="0" group="1" class="visualgeom" />
                <geom type="mesh" rgba="" mesh="th_distal_pst" />
              </body>
            </body>
          </body>
        </body>
      </body>
      <body name="ffknuckle" pos="-0.0550067 0 0.0129807" quat="0.707035 0 -0.707179 0">
        <inertial pos="0 0 0" mass="1" diaginertia="0.001 0.001 0.001" />
        <joint name="FFJ4" pos="0 0 0" axis="0 -1 0" range="-0.349066 0.349066" actuatorfrcrange="-2 2" damping="0.1" />
        <geom type="mesh" mesh="f_knuckle_E3M5" contype="1" conaffinity="0" density="0" group="1" class="visualgeom" />
        <geom type="mesh" rgba="" mesh="f_knuckle_E3M5" />
        <body name="ffproximal">
          <inertial pos="0 0 0" mass="1" diaginertia="0.001 0.001 0.001" />
          <joint name="FFJ3" pos="0 0 0" axis="1 0 0" range="-0.261799 1.5708" actuatorfrcrange="-2 2" damping="0.1" />
          <geom size="0.007 0.02" pos="0 0 0.025" type="cylinder" contype="1" conaffinity="0" density="0" group="1" class="visualgeom" />
          <geom type="cylinder" rgba="" pos="0 0 0.025" />
          <body name="ffmiddle" pos="0 0 0.045">
            <inertial pos="0 0 0" mass="1" diaginertia="0.001 0.001 0.001" />
            <joint name="FFJ2" pos="0 0 0" axis="1 0 0" range="0 1.5708" actuatorfrcrange="-2 2" damping="0.1" />
            <geom size="0.007 0.0125" pos="0 0 0.0125" type="cylinder" contype="1" conaffinity="0" density="0" group="1" class="visualgeom" />
            <geom type="cylinder" rgba="" pos="0 0 0.0125" />
            <geom size="0.007" contype="1" conaffinity="0" density="0" group="1" class="visualgeom" />
            <geom type="" rgba="" />
            <geom size="0.007" pos="0 0 0.025" contype="1" conaffinity="0" density="0" group="1" class="visualgeom" />
            <geom type="" rgba="" pos="0 0 0.025" />
            <body name="ffdistal" pos="0 0 0.025">
              <inertial pos="0 0 0" mass="1" diaginertia="0.001 0.001 0.001" />
              <joint name="FFJ1" pos="0 0 0" axis="1 0 0" range="0 1.5708" actuatorfrcrange="-2 2" damping="0.1" />
              <geom type="mesh" mesh="f_distal_pst" contype="1" conaffinity="0" density="0" group="1" class="visualgeom" />
              <geom type="mesh" rgba="" mesh="f_distal_pst" />
            </body>
          </body>
        </body>
      </body>
      <body name="mfknuckle" pos="-0.0590022 0 -0.00902016" quat="0.707035 0 -0.707179 0">
        <inertial pos="0 0 0" mass="1" diaginertia="0.001 0.001 0.001" />
        <joint name="MFJ4" pos="0 0 0" axis="0 -1 0" range="-0.349066 0.349066" actuatorfrcrange="-2 2" damping="0.1" />
        <geom type="mesh" mesh="f_knuckle_E3M5" contype="1" conaffinity="0" density="0" group="1" class="visualgeom" />
        <geom type="mesh" rgba="" mesh="f_knuckle_E3M5" />
        <body name="mfproximal">
          <inertial pos="0 0 0" mass="1" diaginertia="0.001 0.001 0.001" />
          <joint name="MFJ3" pos="0 0 0" axis="1 0 0" range="-0.261799 1.5708" actuatorfrcrange="-2 2" damping="0.1" />
          <geom size="0.007 0.02" pos="0 0 0.025" type="cylinder" contype="1" conaffinity="0" density="0" group="1" class="visualgeom" />
          <geom type="cylinder" rgba="" pos="0 0 0.025" />
          <body name="mfmiddle" pos="0 0 0.045">
            <inertial pos="0 0 0" mass="1" diaginertia="0.001 0.001 0.001" />
            <joint name="MFJ2" pos="0 0 0" axis="1 0 0" range="0 1.5708" actuatorfrcrange="-2 2" damping="0.1" />
            <geom size="0.007 0.0125" pos="0 0 0.0125" type="cylinder" contype="1" conaffinity="0" density="0" group="1" class="visualgeom" />
            <geom type="cylinder" rgba="" pos="0 0 0.0125" />
            <geom size="0.007" contype="1" conaffinity="0" density="0" group="1" class="visualgeom" />
            <geom type="" rgba="" />
            <geom size="0.007" pos="0 0 0.025" contype="1" conaffinity="0" density="0" group="1" class="visualgeom" />
            <geom type="" rgba="" pos="0 0 0.025" />
            <body name="mfdistal" pos="0 0 0.025">
              <inertial pos="0 0 0" mass="1" diaginertia="0.001 0.001 0.001" />
              <joint name="MFJ1" pos="0 0 0" axis="1 0 0" range="0 1.5708" actuatorfrcrange="-2 2" damping="0.1" />
              <geom type="mesh" mesh="f_distal_pst" contype="1" conaffinity="0" density="0" group="1" class="visualgeom" />
              <geom type="mesh" rgba="" mesh="f_distal_pst" />
            </body>
          </body>
        </body>
      </body>
      <body name="rfknuckle" pos="-0.0549978 0 -0.0310193" quat="0.707035 0 -0.707179 0">
        <inertial pos="0 0 0" mass="1" diaginertia="0.001 0.001 0.001" />
        <joint name="RFJ4" pos="0 0 0" axis="0 1 0" range="-0.349066 0.349066" actuatorfrcrange="-2 2" damping="0.1" />
        <geom type="mesh" mesh="f_knuckle_E3M5" contype="1" conaffinity="0" density="0" group="1" class="visualgeom" />
        <geom type="mesh" rgba="" mesh="f_knuckle_E3M5" />
        <body name="rfproximal">
          <inertial pos="0 0 0" mass="1" diaginertia="0.001 0.001 0.001" />
          <joint name="RFJ3" pos="0 0 0" axis="1 0 0" range="-0.261799 1.5708" actuatorfrcrange="-2 2" damping="0.1" />
          <geom size="0.007 0.02" pos="0 0 0.025" type="cylinder" contype="1" conaffinity="0" density="0" group="1" class="visualgeom" />
          <geom type="cylinder" rgba="" pos="0 0 0.025" />
          <body name="rfmiddle" pos="0 0 0.045">
            <inertial pos="0 0 0" mass="1" diaginertia="0.001 0.001 0.001" />
            <joint name="RFJ2" pos="0 0 0" axis="1 0 0" range="0 1.5708" actuatorfrcrange="-2 2" damping="0.1" />
            <geom size="0.007 0.0125" pos="0 0 0.0125" type="cylinder" contype="1" conaffinity="0" density="0" group="1" class="visualgeom" />
            <geom type="cylinder" rgba="" pos="0 0 0.0125" />
            <geom size="0.007" contype="1" conaffinity="0" density="0" group="1" class="visualgeom" />
            <geom type="" rgba="" />
            <geom size="0.007" pos="0 0 0.025" contype="1" conaffinity="0" density="0" group="1" class="visualgeom" />
            <geom type="" rgba="" pos="0 0 0.025" />
            <body name="rfdistal" pos="0 0 0.025">
              <inertial pos="0 0 0" mass="1" diaginertia="0.001 0.001 0.001" />
              <joint name="RFJ1" pos="0 0 0" axis="1 0 0" range="0 1.5708" actuatorfrcrange="-2 2" damping="0.1" />
              <geom type="mesh" mesh="f_distal_pst" contype="1" conaffinity="0" density="0" group="1" class="visualgeom" />
              <geom type="mesh" rgba="" mesh="f_distal_pst" />
            </body>
          </body>
        </body>
      </body>
      <body name="lfmetacarpal" pos="0.0192967 0 -0.0530042" quat="0.300623 0 -0.953743 0">
        <inertial pos="0 0 0" mass="1" diaginertia="0.001 0.001 0.001" />
        <joint name="LFJ5" pos="0 0 0" axis="1 0 0" range="0 0.785398" actuatorfrcrange="-2 2" damping="0.1" />
        <geom size="0.009 0.012 0.02" pos="0.0269864 0 0.019" quat="0.887018 0 0.461735 0" type="box" contype="1" conaffinity="0" density="0" group="1" class="visualgeom" />
        <geom type="box" rgba="" size="0.009 0.012 0.02" pos="0.0269864 0 0.019" quat="0.887018 0 0.461735 0" />
        <body name="lfknuckle" pos="0.0539727 0 0.0377946" quat="0.887018 0 0.461735 0">
          <inertial pos="0 0 0" mass="1" diaginertia="0.001 0.001 0.001" />
          <joint name="LFJ4" pos="0 0 0" axis="0 1 0" range="-0.349066 0.349066" actuatorfrcrange="-2 2" damping="0.1" />
          <geom type="mesh" mesh="f_knuckle_E3M5" contype="1" conaffinity="0" density="0" group="1" class="visualgeom" />
          <geom type="mesh" rgba="" mesh="f_knuckle_E3M5" />
          <body name="lfproximal">
            <inertial pos="0 0 0" mass="1" diaginertia="0.001 0.001 0.001" />
            <joint name="LFJ3" pos="0 0 0" axis="1 0 0" range="-0.261799 1.5708" actuatorfrcrange="-2 2" damping="0.1" />
            <geom size="0.007 0.02" pos="0 0 0.025" type="cylinder" contype="1" conaffinity="0" density="0" group="1" class="visualgeom" />
            <geom type="cylinder" rgba="" pos="0 0 0.025" />
            <body name="lfmiddle" pos="0 0 0.045">
              <inertial pos="0 0 0" mass="1" diaginertia="0.001 0.001 0.001" />
              <joint name="LFJ2" pos="0 0 0" axis="1 0 0" range="0 1.5708" actuatorfrcrange="-2 2" damping="0.1" />
              <geom size="0.007 0.0125" pos="0 0 0.0125" type="cylinder" contype="1" conaffinity="0" density="0" group="1" class="visualgeom" />
              <geom type="cylinder" rgba="" pos="0 0 0.0125" />
              <geom size="0.007" contype="1" conaffinity="0" density="0" group="1" class="visualgeom" />
              <geom type="" rgba="" />
              <geom size="0.007" pos="0 0 0.025" contype="1" conaffinity="0" density="0" group="1" class="visualgeom" />
              <geom type="" rgba="" pos="0 0 0.025" />
              <body name="lfdistal" pos="0 0 0.025">
                <inertial pos="0 0 0" mass="1" diaginertia="0.001 0.001 0.001" />
                <joint name="LFJ1" pos="0 0 0" axis="1 0 0" range="0 1.5708" actuatorfrcrange="-2 2" damping="0.1" />
                <geom type="mesh" mesh="f_distal_pst" contype="1" conaffinity="0" density="0" group="1" class="visualgeom" />
                <geom type="mesh" rgba="" mesh="f_distal_pst" />
              </body>
            </body>
          </body>
        </body>
      </body>
    </body>
  </worldbody>

  <actuator>
    <motor name="THJ5" joint="THJ5" ctrllimited="true" ctrlrange="-5 5" gear="1" />
    <motor name="THJ4" joint="THJ4" ctrllimited="true" ctrlrange="-3 3" gear="1" />
    <motor name="THJ3" joint="THJ3" ctrllimited="true" ctrlrange="-2 2" gear="1" />
    <motor name="THJ2" joint="THJ2" ctrllimited="true" ctrlrange="-2 2" gear="1" />
    <motor name="THJ1" joint="THJ1" ctrllimited="true" ctrlrange="-1 1" gear="1" />
    <motor name="FFJ4" joint="FFJ4" ctrllimited="true" ctrlrange="-2 2" gear="1" />
    <motor name="FFJ3" joint="FFJ3" ctrllimited="true" ctrlrange="-2 2" gear="1" />
    <motor name="FFJ2" joint="FFJ2" ctrllimited="true" ctrlrange="-2 2" gear="1" />
    <motor name="FFJ1" joint="FFJ1" ctrllimited="true" ctrlrange="-2 2" gear="1" />
    <motor name="MFJ4" joint="MFJ4" ctrllimited="true" ctrlrange="-2 2" gear="1" />
    <motor name="MFJ3" joint="MFJ3" ctrllimited="true" ctrlrange="-2 2" gear="1" />
    <motor name="MFJ2" joint="MFJ2" ctrllimited="true" ctrlrange="-2 2" gear="1" />
    <motor name="MFJ1" joint="MFJ1" ctrllimited="true" ctrlrange="-2 2" gear="1" />
    <motor name="RFJ4" joint="RFJ4" ctrllimited="true" ctrlrange="-2 2" gear="1" />
    <motor name="RFJ3" joint="RFJ3" ctrllimited="true" ctrlrange="-2 2" gear="1" />
    <motor name="RFJ2" joint="RFJ2" ctrllimited="true" ctrlrange="-2 2" gear="1" />
    <motor name="RFJ1" joint="RFJ1" ctrllimited="true" ctrlrange="-2 2" gear="1" />
    <motor name="LFJ5" joint="LFJ5" ctrllimited="true" ctrlrange="-2 2" gear="1" />
    <motor name="LFJ4" joint="LFJ4" ctrllimited="true" ctrlrange="-2 2" gear="1" />
    <motor name="LFJ3" joint="LFJ3" ctrllimited="true" ctrlrange="-2 2" gear="1" />
    <motor name="LFJ2" joint="LFJ2" ctrllimited="true" ctrlrange="-2 2" gear="1" />
    <motor name="LFJ1" joint="LFJ1" ctrllimited="true" ctrlrange="-2 2" gear="1" />
  </actuator>

  <sensor>
    <actuatorpos name="THJ5_p" actuator="THJ5" />
    <actuatorvel name="THJ5_v" actuator="THJ5" />
    <actuatorfrc name="THJ5_f" actuator="THJ5" noise="0.001" />
    <actuatorpos name="THJ4_p" actuator="THJ4" />
    <actuatorvel name="THJ4_v" actuator="THJ4" />
    <actuatorfrc name="THJ4_f" actuator="THJ4" noise="0.001" />
    <actuatorpos name="THJ3_p" actuator="THJ3" />
    <actuatorvel name="THJ3_v" actuator="THJ3" />
    <actuatorfrc name="THJ3_f" actuator="THJ3" noise="0.001" />
    <actuatorpos name="THJ2_p" actuator="THJ2" />
    <actuatorvel name="THJ2_v" actuator="THJ2" />
    <actuatorfrc name="THJ2_f" actuator="THJ2" noise="0.001" />
    <actuatorpos name="THJ1_p" actuator="THJ1" />
    <actuatorvel name="THJ1_v" actuator="THJ1" />
    <actuatorfrc name="THJ1_f" actuator="THJ1" noise="0.001" />
    <actuatorpos name="FFJ4_p" actuator="FFJ4" />
    <actuatorvel name="FFJ4_v" actuator="FFJ4" />
    <actuatorfrc name="FFJ4_f" actuator="FFJ4" noise="0.001" />
    <actuatorpos name="FFJ3_p" actuator="FFJ3" />
    <actuatorvel name="FFJ3_v" actuator="FFJ3" />
    <actuatorfrc name="FFJ3_f" actuator="FFJ3" noise="0.001" />
    <actuatorpos name="FFJ2_p" actuator="FFJ2" />
    <actuatorvel name="FFJ2_v" actuator="FFJ2" />
    <actuatorfrc name="FFJ2_f" actuator="FFJ2" noise="0.001" />
    <actuatorpos name="FFJ1_p" actuator="FFJ1" />
    <actuatorvel name="FFJ1_v" actuator="FFJ1" />
    <actuatorfrc name="FFJ1_f" actuator="FFJ1" noise="0.001" />
    <actuatorpos name="MFJ4_p" actuator="MFJ4" />
    <actuatorvel name="MFJ4_v" actuator="MFJ4" />
    <actuatorfrc name="MFJ4_f" actuator="MFJ4" noise="0.001" />
    <actuatorpos name="MFJ3_p" actuator="MFJ3" />
    <actuatorvel name="MFJ3_v" actuator="MFJ3" />
    <actuatorfrc name="MFJ3_f" actuator="MFJ3" noise="0.001" />
    <actuatorpos name="MFJ2_p" actuator="MFJ2" />
    <actuatorvel name="MFJ2_v" actuator="MFJ2" />
    <actuatorfrc name="MFJ2_f" actuator="MFJ2" noise="0.001" />
    <actuatorpos name="MFJ1_p" actuator="MFJ1" />
    <actuatorvel name="MFJ1_v" actuator="MFJ1" />
    <actuatorfrc name="MFJ1_f" actuator="MFJ1" noise="0.001" />
    <actuatorpos name="RFJ4_p" actuator="RFJ4" />
    <actuatorvel name="RFJ4_v" actuator="RFJ4" />
    <actuatorfrc name="RFJ4_f" actuator="RFJ4" noise="0.001" />
    <actuatorpos name="RFJ3_p" actuator="RFJ3" />
    <actuatorvel name="RFJ3_v" actuator="RFJ3" />
    <actuatorfrc name="RFJ3_f" actuator="RFJ3" noise="0.001" />
    <actuatorpos name="RFJ2_p" actuator="RFJ2" />
    <actuatorvel name="RFJ2_v" actuator="RFJ2" />
    <actuatorfrc name="RFJ2_f" actuator="RFJ2" noise="0.001" />
    <actuatorpos name="RFJ1_p" actuator="RFJ1" />
    <actuatorvel name="RFJ1_v" actuator="RFJ1" />
    <actuatorfrc name="RFJ1_f" actuator="RFJ1" noise="0.001" />
    <actuatorpos name="LFJ5_p" actuator="LFJ5" />
    <actuatorvel name="LFJ5_v" actuator="LFJ5" />
    <actuatorfrc name="LFJ5_f" actuator="LFJ5" noise="0.001" />
    <actuatorpos name="LFJ4_p" actuator="LFJ4" />
    <actuatorvel name="LFJ4_v" actuator="LFJ4" />
    <actuatorfrc name="LFJ4_f" actuator="LFJ4" noise="0.001" />
    <actuatorpos name="LFJ3_p" actuator="LFJ3" />
    <actuatorvel name="LFJ3_v" actuator="LFJ3" />
    <actuatorfrc name="LFJ3_f" actuator="LFJ3" noise="0.001" />
    <actuatorpos name="LFJ2_p" actuator="LFJ2" />
    <actuatorvel name="LFJ2_v" actuator="LFJ2" />
    <actuatorfrc name="LFJ2_f" actuator="LFJ2" noise="0.001" />
    <actuatorpos name="LFJ1_p" actuator="LFJ1" />
    <actuatorvel name="LFJ1_v" actuator="LFJ1" />
    <actuatorfrc name="LFJ1_f" actuator="LFJ1" noise="0.001" />
    <framequat name="orientation" objtype="site" noise="0.001" objname="imu" />
    <gyro name="angular-velocity" site="imu" noise="0.005" cutoff="34.9" />
  </sensor>
</mujoco>