<?xml version="1.0"?>
<robot name="ability_hand">
  <link name="virtual_root"><inertial>
      <origin xyz="0 0 0" rpy="0 0 0" />
      <mass value="1.0" />
      <inertia ixx="0.001" ixy="0.0" ixz="0.0" iyy="0.001" iyz="0.0" izz="0.001" />
    </inertial><visual><geometry><box size="0.01 0.01 0.01" /></geometry></visual></link><joint name="dummy_root_link_to_virtual_root" type="fixed"><parent link="virtual_root" /><child link="dummy_root_link" /></joint><joint name="base_link_to_virtual_root" type="fixed"><parent link="virtual_root" /><child link="base_link" /></joint><link name="dummy_root_link"><inertial>
      <origin xyz="0 0 0" rpy="0 0 0" />
      <mass value="1.0" />
      <inertia ixx="0.001" ixy="0.0" ixz="0.0" iyy="0.001" iyz="0.0" izz="0.001" />
    </inertial><visual><geometry><box size="0.01 0.01 0.01" /></geometry></visual></link><joint name="fix_thumb_tip_to_dummy" type="fixed"><parent link="dummy_root_link" /><child link="thumb_tip" /></joint><joint name="fix_ring_tip_to_dummy" type="fixed"><parent link="dummy_root_link" /><child link="ring_tip" /></joint><joint name="fix_pinky_tip_to_dummy" type="fixed"><parent link="dummy_root_link" /><child link="pinky_tip" /></joint><joint name="fix_middle_tip_to_dummy" type="fixed"><parent link="dummy_root_link" /><child link="middle_tip" /></joint><joint name="fix_index_tip_to_dummy" type="fixed"><parent link="dummy_root_link" /><child link="index_tip" /></joint><link name="base_link"><inertial>
      <origin xyz="0 0 0" rpy="0 0 0" />
      <mass value="1.0" />
      <inertia ixx="0.001" ixy="0.0" ixz="0.0" iyy="0.001" iyz="0.0" izz="0.001" />
    </inertial><visual><geometry><box size="0.01 0.01 0.01" /></geometry></visual></link>
  <joint name="base_joint" type="fixed">
    <parent link="base_link" />
    <child link="base" />
    <origin xyz="0 0 0" rpy="0 0 -1.57079" />
  </joint>
  <link name="base">
    <visual name="wrist_mesh">
      <origin rpy="0 0 0" xyz="0 0 0" />
      <geometry>
        <mesh filename="meshes/visual/wristmesh.glb" />
      </geometry>
    </visual>
    <collision>
      <origin xyz="0 0 0" rpy="0 0 0" />
      <geometry>
        <mesh filename="meshes/collision/wristmesh_C.obj" />
      </geometry>
    </collision>
    
  
    <inertial>
      <origin xyz="0 0 0" rpy="0 0 0" />
      <mass value="1.0" />
      <inertia ixx="0.001" ixy="0.0" ixz="0.0" iyy="0.001" iyz="0.0" izz="0.001" />
    </inertial>
</link>
  <joint name="wrist2thumb" type="fixed">
    <parent link="base" />
    <child link="thumb_base" />
    <origin xyz="24.0476665e-3 3.78124745e-3 32.32964923e-3" rpy="3.14148426 0.08848813 3.14036612" />
  </joint>
  <link name="thumb_base">
    
    <visual name="palm_mesh">
      <origin rpy="0 0 0" xyz="0 0 0" />
      <geometry>
        <mesh filename="meshes/visual/FB_palm_ref.glb" />
      </geometry>
    </visual>
    <collision>                                  
      <origin xyz="0 0 0" rpy="0 0 0" />
      <geometry>
        <mesh filename="meshes/collision/FB_palm_ref.obj" />
      </geometry>
    </collision>
  
    <inertial>
      <origin xyz="0 0 0" rpy="0 0 0" />
      <mass value="1.0" />
      <inertia ixx="0.001" ixy="0.0" ixz="0.0" iyy="0.001" iyz="0.0" izz="0.001" />
    </inertial>
</link>
  <link name="thumb_L1">
    
    <visual name="thumb_mesh_1">
      <origin xyz="27.8283501e-3 0 -14.7507000e-3" rpy="4.450589592585541 0 0" />
      <geometry>
        <mesh filename="meshes/visual/thumb-F1.glb" />
      </geometry>
    </visual>
    <collision>                            
      <origin xyz="27.8283501e-3 0 -14.7507000e-3" rpy="4.450589592585541 0 0" />
      <geometry>
        <mesh filename="meshes/collision/thumb-F1_C.obj" />
      </geometry>
    </collision>
  
    <inertial>
      <origin xyz="0 0 0" rpy="0 0 0" />
      <mass value="1.0" />
      <inertia ixx="0.001" ixy="0.0" ixz="0.0" iyy="0.001" iyz="0.0" izz="0.001" />
    </inertial>
</link>
  <link name="thumb_L2">
    
    <visual name="thumb_mesh_2">
      <origin xyz="65.18669e-3 23.34021e-3 -3.93483e-3" rpy="3.141592 0 0.343830" />
      <geometry>
        <mesh filename="meshes/visual/thumb-F2.glb" />
      </geometry>
    </visual>
    <collision>                            
      <origin xyz="65.18669e-3 23.34021e-3 -3.93483e-3" rpy="3.141592 0 0.343830" />
      <geometry>
        <mesh filename="meshes/collision/thumb-F2_C.obj" />
      </geometry>
    </collision>
  
    <inertial>
      <origin xyz="0 0 0" rpy="0 0 0" />
      <mass value="1.0" />
      <inertia ixx="0.001" ixy="0.0" ixz="0.0" iyy="0.001" iyz="0.0" izz="0.001" />
    </inertial>
</link>
  <joint name="thumb_q1" type="revolute">
    <parent link="thumb_base" />
    <child link="thumb_L1" />
    <origin xyz="0 0 0" rpy="0 0 3.330437" />
    <axis xyz="0 0 1" />
    <limit lower="-2.0943951" upper="0" effort="1.2" velocity="40.338888721" />    
    <dynamics damping="0.001" friction="0.001" />  
  </joint>
  <joint name="thumb_q2" type="revolute">
    <parent link="thumb_L1" />
    <child link="thumb_L2" />
    <origin xyz="27.8283501e-3 0 -14.7507000e-3" rpy="4.450589592585541 0 0" />
    <axis xyz="0 0 1" />
    <limit lower="0" upper="2.0943951" effort="6.0" velocity="8.0677777442" />    
    <dynamics damping="0.001" friction="0.001" />  
  </joint>
  <link name="thumb_tip"><inertial>
      <origin xyz="0 0 0" rpy="0 0 0" />
      <mass value="1.0" />
      <inertia ixx="0.001" ixy="0.0" ixz="0.0" iyy="0.001" iyz="0.0" izz="0.001" />
    </inertial><visual><geometry><box size="0.01 0.01 0.01" /></geometry></visual></link>
  <joint name="thumb_tip_joint" type="fixed">
    <parent link="thumb_L2" />
    <child link="thumb_tip" />
    <origin rpy="0 0 0" xyz="0.065 0.016 0" />
  </joint>
  <link name="index_L1">
    
    <visual name="index_mesh_1">
      <origin xyz="38.472723e-3 3.257695e-3 0.000000" rpy="0 0 0.084474" />
      <geometry>
        <mesh filename="meshes/visual/idx-F1.glb" />
      </geometry>
    </visual>
    <collision>                                  
      <origin xyz="0.036 -0.00175 0" rpy="0 0 0" />
      <geometry>
        <sphere radius="0.0085" />
      </geometry>
    </collision>
    <collision>
      <origin xyz="0.019 -0.0045 0" rpy="0 0 0.0845" />
      <geometry>
        <box size="0.028 0.012 0.016" />
      </geometry>
    </collision>
    <collision>
      <origin xyz="0.018 0.006 0" rpy="0 0 0.0845" />
      <geometry>
        <box size="0.02 0.01 0.016" />
      </geometry>
    </collision>
    <collision>
      <origin xyz="-0.001 0 0.007" rpy="0 0 0.0845" />
      <geometry>
        <box size="0.012 0.012 0.002" />
      </geometry>
    </collision>
    <collision>
      <origin xyz="-0.001 0 -0.007" rpy="0 0 0.0845" />
      <geometry>
        <box size="0.012 0.012 0.002" />
      </geometry>
    </collision>
  
    <inertial>
      <origin xyz="0 0 0" rpy="0 0 0" />
      <mass value="1.0" />
      <inertia ixx="0.001" ixy="0.0" ixz="0.0" iyy="0.001" iyz="0.0" izz="0.001" />
    </inertial>
</link>
  <link name="index_L2">
    
    <visual name="index_mesh_2">
      <origin rpy="0 0 0" xyz="9.1241e-3 0 0" />
      <geometry>
        <mesh filename="meshes/visual/idx-F2.glb" />
      </geometry>
    </visual>
    <collision>                            
      <origin xyz="0 0 0" rpy="0 0 0" />
      <geometry>
        <mesh filename="meshes/collision/idx-F2_C.obj" />
      </geometry>
    </collision>
    <collision>
      <origin xyz="0.03 -0.016 0" rpy="0 0 0" />
      <geometry>
        <sphere radius="0.007" />
      </geometry>
    </collision>
  
    <inertial>
      <origin xyz="0 0 0" rpy="0 0 0" />
      <mass value="1.0" />
      <inertia ixx="0.001" ixy="0.0" ixz="0.0" iyy="0.001" iyz="0.0" izz="0.001" />
    </inertial>
</link>
  <joint name="index_q1" type="revolute">
    <parent link="thumb_base" />
    <child link="index_L1" />
    <origin xyz="-9.49e-3 -13.04e-3 -62.95e-3" rpy="-1.982050 1.284473 -2.090591" />
    <axis xyz="0 0 1" />
    <limit lower="0" upper="2.0943951" effort="6.0" velocity="8.0677777442" />    
    <dynamics damping="0.001" friction="0.001" />  
  </joint>
  <joint name="index_q2" type="revolute">
    <parent link="index_L1" />
    <child link="index_L2" />
    <origin xyz="38.472723e-3 3.257695e-3 0.000000e-3" rpy="0 0 0.084474" />
    <axis xyz="0 0 1" />
    <limit lower="0.0" upper="2.6586" effort="6.0" velocity="8.0677777442" />    
    <dynamics damping="0.001" friction="0.001" />  
    <mimic joint="index_q1" multiplier="1.05851325" offset="0.72349796" />
  </joint>
  <link name="index_tip"><inertial>
      <origin xyz="0 0 0" rpy="0 0 0" />
      <mass value="1.0" />
      <inertia ixx="0.001" ixy="0.0" ixz="0.0" iyy="0.001" iyz="0.0" izz="0.001" />
    </inertial><visual><geometry><box size="0.01 0.01 0.01" /></geometry></visual></link>
  <joint name="index_tip_joint" type="fixed">
    <parent link="index_L2" />
    <child link="index_tip" />
    <origin rpy="0 0 0" xyz="0.035  -0.018 0" />
  </joint>
  <link name="middle_L1">
    
    <visual name="middle_mesh_1">
      <origin xyz="38.472723e-3 3.257695e-3 0.000000" rpy="0 0 0.084474" />
      <geometry>
        <mesh filename="meshes/visual/idx-F1.glb" />
      </geometry>
    </visual>
    <collision>                                  
      <origin xyz="0.036 -0.00175 0" rpy="0 0 0" />
      <geometry>
        <sphere radius="0.0085" />
      </geometry>
    </collision>
    <collision>
      <origin xyz="0.019 -0.0045 0" rpy="0 0 0.0845" />
      <geometry>
        <box size="0.028 0.012 0.016" />
      </geometry>
    </collision>
    <collision>
      <origin xyz="0.018 0.006 0" rpy="0 0 0.0845" />
      <geometry>
        <box size="0.02 0.01 0.016" />
      </geometry>
    </collision>
    <collision>
      <origin xyz="-0.001 0 0.007" rpy="0 0 0.0845" />
      <geometry>
        <box size="0.012 0.012 0.002" />
      </geometry>
    </collision>
    <collision>
      <origin xyz="-0.001 0 -0.007" rpy="0 0 0.0845" />
      <geometry>
        <box size="0.012 0.012 0.002" />
      </geometry>
    </collision>
  
    <inertial>
      <origin xyz="0 0 0" rpy="0 0 0" />
      <mass value="1.0" />
      <inertia ixx="0.001" ixy="0.0" ixz="0.0" iyy="0.001" iyz="0.0" izz="0.001" />
    </inertial>
</link>
  <link name="middle_L2">
    
    <visual name="middle_mesh_2">
      <origin rpy="0 0 0" xyz="9.1241e-3 0 0" />
      <geometry>
        <mesh filename="meshes/visual/idx-F2.glb" />
      </geometry>
    </visual>
    <collision>                            
      <origin xyz="0 0 0" rpy="0 0 0" />
      <geometry>
        <mesh filename="meshes/collision/idx-F2_C.obj" />
      </geometry>
    </collision>
    <collision>
      <origin xyz="0.03 -0.016 0" rpy="0 0 0" />
      <geometry>
        <sphere radius="0.007" />
      </geometry>
    </collision>
  
    <inertial>
      <origin xyz="0 0 0" rpy="0 0 0" />
      <mass value="1.0" />
      <inertia ixx="0.001" ixy="0.0" ixz="0.0" iyy="0.001" iyz="0.0" izz="0.001" />
    </inertial>
</link>
  <joint name="middle_q1" type="revolute">
    <parent link="thumb_base" />
    <child link="middle_L1" />
    <origin xyz="9.653191e-3 -15.310271e-3 -67.853949e-3" rpy="-1.860531 1.308458 -1.896217" />
    <limit lower="0" upper="2.0943951" effort="6.0" velocity="8.0677777442" />    
    <dynamics damping="0.001" friction="0.001" />  
    <axis xyz="0 0 1" />
  </joint>
  <joint name="middle_q2" type="revolute">
    <parent link="middle_L1" />
    <child link="middle_L2" />
    <origin xyz="38.472723e-3 3.257695e-3 0.000000" rpy="0 0 0.084474" />
    <axis xyz="0 0 1" />
    <limit lower="0.0" upper="2.6586" effort="6.0" velocity="8.0677777442" />    
    <dynamics damping="0.001" friction="0.001" />  
    <mimic joint="middle_q1" multiplier="1.05851325" offset="0.72349796" />
  </joint>
  <link name="middle_tip"><inertial>
      <origin xyz="0 0 0" rpy="0 0 0" />
      <mass value="1.0" />
      <inertia ixx="0.001" ixy="0.0" ixz="0.0" iyy="0.001" iyz="0.0" izz="0.001" />
    </inertial><visual><geometry><box size="0.01 0.01 0.01" /></geometry></visual></link>
  <joint name="middle_tip_joint" type="fixed">
    <parent link="middle_L2" />
    <child link="middle_tip" />
    <origin rpy="0 0 0" xyz="0.035  -0.018 0" />
  </joint>
  <link name="ring_L1">
    
    <visual name="ring_mesh_1">
      <origin xyz="38.472723e-3 3.257695e-3 0.000000" rpy="0 0 0.084474" />
      <geometry>
        <mesh filename="meshes/visual/idx-F1.glb" />
      </geometry>
    </visual>
    <collision>                                  
      <origin xyz="0.036 -0.00175 0" rpy="0 0 0" />
      <geometry>
        <sphere radius="0.0085" />
      </geometry>
    </collision>
    <collision>
      <origin xyz="0.019 -0.0045 0" rpy="0 0 0.0845" />
      <geometry>
        <box size="0.028 0.012 0.016" />
      </geometry>
    </collision>
    <collision>
      <origin xyz="0.018 0.006 0" rpy="0 0 0.0845" />
      <geometry>
        <box size="0.02 0.01 0.016" />
      </geometry>
    </collision>
    <collision>
      <origin xyz="-0.001 0 0.007" rpy="0 0 0.0845" />
      <geometry>
        <box size="0.012 0.012 0.002" />
      </geometry>
    </collision>
    <collision>
      <origin xyz="-0.001 0 -0.007" rpy="0 0 0.0845" />
      <geometry>
        <box size="0.012 0.012 0.002" />
      </geometry>
    </collision>
  
    <inertial>
      <origin xyz="0 0 0" rpy="0 0 0" />
      <mass value="1.0" />
      <inertia ixx="0.001" ixy="0.0" ixz="0.0" iyy="0.001" iyz="0.0" izz="0.001" />
    </inertial>
</link>
  <link name="ring_L2">
    
    <visual name="ring_mesh_2">
      <origin rpy="0 0 0" xyz="9.1241e-3 0 0" />
      <geometry>
        <mesh filename="meshes/visual/idx-F2.glb" />
      </geometry>
    </visual>
    <collision>                            
      <origin xyz="0 0 0" rpy="0 0 0" />
      <geometry>
        <mesh filename="meshes/collision/idx-F2_C.obj" />
      </geometry>
    </collision>
    <collision>
      <origin xyz="0.03 -0.016 0" rpy="0 0 0" />
      <geometry>
        <sphere radius="0.007" />
      </geometry>
    </collision>
  
    <inertial>
      <origin xyz="0 0 0" rpy="0 0 0" />
      <mass value="1.0" />
      <inertia ixx="0.001" ixy="0.0" ixz="0.0" iyy="0.001" iyz="0.0" izz="0.001" />
    </inertial>
</link>
  <joint name="ring_q1" type="revolute">
    <parent link="thumb_base" />
    <child link="ring_L1" />
    <origin xyz="29.954260e-3 -14.212492e-3 -67.286105e-3" rpy="-1.716598 1.321452 -1.675862" />
    <limit lower="0" upper="2.0943951" effort="6.0" velocity="8.0677777442" />    
    <dynamics damping="0.001" friction="0.001" />  
    <axis xyz="0 0 1" />
  </joint>
  <joint name="ring_q2" type="revolute">
    <parent link="ring_L1" />
    <child link="ring_L2" />
    <origin xyz="38.472723e-3 3.257695e-3 0.000000" rpy="0 0 0.084474" />
    <axis xyz="0 0 1" />
    <limit lower="0.0" upper="2.6586" effort="6.0" velocity="8.0677777442" />    
    <dynamics damping="0.001" friction="0.001" />  
    <mimic joint="ring_q1" multiplier="1.05851325" offset="0.72349796" />
  </joint>
  <link name="ring_tip"><inertial>
      <origin xyz="0 0 0" rpy="0 0 0" />
      <mass value="1.0" />
      <inertia ixx="0.001" ixy="0.0" ixz="0.0" iyy="0.001" iyz="0.0" izz="0.001" />
    </inertial><visual><geometry><box size="0.01 0.01 0.01" /></geometry></visual></link>
  <joint name="ring_tip_joint" type="fixed">
    <parent link="ring_L2" />
    <child link="ring_tip" />
    <origin rpy="0 0 0" xyz="0.035  -0.018 0" />
  </joint>
  <link name="pinky_L1">
    
    <visual name="pinky_mesh_1">
      <origin xyz="38.472723e-3 3.257695e-3 0.000000" rpy="0 0 0.084474" />
      <geometry>
        <mesh filename="meshes/visual/idx-F1.glb" />
      </geometry>
    </visual>
    <collision>                                  
      <origin xyz="0.036 -0.00175 0" rpy="0 0 0" />
      <geometry>
        <sphere radius="0.0085" />
      </geometry>
    </collision>
    <collision>
      <origin xyz="0.019 -0.0045 0" rpy="0 0 0.0845" />
      <geometry>
        <box size="0.028 0.012 0.016" />
      </geometry>
    </collision>
    <collision>
      <origin xyz="0.018 0.006 0" rpy="0 0 0.0845" />
      <geometry>
        <box size="0.02 0.01 0.016" />
      </geometry>
    </collision>
    <collision>
      <origin xyz="-0.001 0 0.007" rpy="0 0 0.0845" />
      <geometry>
        <box size="0.012 0.012 0.002" />
      </geometry>
    </collision>
    <collision>
      <origin xyz="-0.001 0 -0.007" rpy="0 0 0.0845" />
      <geometry>
        <box size="0.012 0.012 0.002" />
      </geometry>
    </collision>
  
    <inertial>
      <origin xyz="0 0 0" rpy="0 0 0" />
      <mass value="1.0" />
      <inertia ixx="0.001" ixy="0.0" ixz="0.0" iyy="0.001" iyz="0.0" izz="0.001" />
    </inertial>
</link>
  <link name="pinky_L2">
    
    <visual name="pinky_mesh_2">
      <origin rpy="0 0 0" xyz="9.1241e-3 0 0" />
      <geometry>
        <mesh filename="meshes/visual/idx-F2.glb" />
      </geometry>
    </visual>
    <collision>                            
      <origin xyz="0 0 0" rpy="0 0 0" />
      <geometry>
        <mesh filename="meshes/collision/idx-F2_C.obj" />
      </geometry>
    </collision>
    <collision>
      <origin xyz="0.03 -0.016 0" rpy="0 0 0" />
      <geometry>
        <sphere radius="0.007" />
      </geometry>
    </collision>
  
    <inertial>
      <origin xyz="0 0 0" rpy="0 0 0" />
      <mass value="1.0" />
      <inertia ixx="0.001" ixy="0.0" ixz="0.0" iyy="0.001" iyz="0.0" izz="0.001" />
    </inertial>
</link>
  <joint name="pinky_q1" type="revolute">
    <parent link="thumb_base" />
    <child link="pinky_L1" />
    <origin xyz="49.521293e-3 -11.004583e-3 -63.029065e-3" rpy="-1.765110 1.322220 -1.658383" />
    <limit lower="0" upper="2.0943951" effort="6.0" velocity="8.0677777442" />    
    <dynamics damping="0.001" friction="0.001" />  
    <axis xyz="0 0 1" />
  </joint>
  <joint name="pinky_q2" type="revolute">
    <parent link="pinky_L1" />
    <child link="pinky_L2" />
    <origin xyz="38.472723e-3 3.257695e-3 0.000000" rpy="0 0 0.084474" />
    <limit lower="0.0" upper="2.6586" effort="6.0" velocity="8.0677777442" />    
    <dynamics damping="0.001" friction="0.001" />  
    <axis xyz="0 0 1" />
    <mimic joint="pinky_q1" multiplier="1.05851325" offset="0.72349796" />
  </joint>
  <link name="pinky_tip"><inertial>
      <origin xyz="0 0 0" rpy="0 0 0" />
      <mass value="1.0" />
      <inertia ixx="0.001" ixy="0.0" ixz="0.0" iyy="0.001" iyz="0.0" izz="0.001" />
    </inertial><visual><geometry><box size="0.01 0.01 0.01" /></geometry></visual></link>
  <joint name="pinky_tip_joint" type="fixed">
    <parent link="pinky_L2" />
    <child link="pinky_tip" />
    <origin rpy="0 0 0" xyz="0.035  -0.018 0" />
  </joint>
</robot>