<mujoco model="g1_fingers">
  <!-- ============================ ASSETS ============================ -->
    <asset>
        <!-- Main gauche -->
        <mesh name="left_thumb_0_mesh"  file="/content/HumanoidHand/assets/hands/meshes/left_thumb_1.STL"/>
        <mesh name="left_thumb_1_mesh"  file="/content/HumanoidHand/assets/hands/meshes/left_thumb_2.STL"/>

        <mesh name="left_index_0_mesh"  file="/content/HumanoidHand/assets/hands/meshes/left_index_1.STL"/>
        <mesh name="left_index_1_mesh"  file="/content/HumanoidHand/assets/hands/meshes/left_index_2.STL"/>

        <mesh name="left_middle_0_mesh" file="/content/HumanoidHand/assets/hands/meshes/left_middle_1.STL"/>
        <mesh name="left_middle_1_mesh" file="/content/HumanoidHand/assets/hands/meshes/left_middle_2.STL"/>

        <mesh name="left_ring_0_mesh"   file="/content/HumanoidHand/assets/hands/meshes/left_ring_1.STL"/>
        <mesh name="left_ring_1_mesh"   file="/content/HumanoidHand/assets/hands/meshes/left_ring_2.STL"/>

        <!-- Main droite -->
        <mesh name="right_thumb_0_mesh"  file="/content/HumanoidHand/assets/hands/meshes/right_thumb_1.STL"/>
        <mesh name="right_thumb_1_mesh"  file="/content/HumanoidHand/assets/hands/meshes/right_thumb_2.STL"/>

        <mesh name="right_index_0_mesh"  file="/content/HumanoidHand/assets/hands/meshes/right_index_1.STL"/>
        <mesh name="right_index_1_mesh"  file="/content/HumanoidHand/assets/hands/meshes/right_index_2.STL"/>

        <mesh name="right_middle_0_mesh" file="/content/HumanoidHand/assets/hands/meshes/right_middle_1.STL"/>
        <mesh name="right_middle_1_mesh" file="/content/HumanoidHand/assets/hands/meshes/right_middle_2.STL"/>

        <mesh name="right_ring_0_mesh"   file="/content/HumanoidHand/assets/hands/meshes/right_ring_1.STL"/>
        <mesh name="right_ring_1_mesh"   file="/content/HumanoidHand/assets/hands/meshes/right_ring_2.STL"/>

        <mesh name="left_thumb_force_sensor_0_mesh"  file="/content/HumanoidHand/assets/hands/meshes/left_thumb_force_sensor_1.STL"/>
        <mesh name="left_thumb_force_sensor_1_mesh"  file="/content/HumanoidHand/assets/hands/meshes/left_thumb_force_sensor_2.STL"/>
        <mesh name="left_thumb_force_sensor_2_mesh"  file="/content/HumanoidHand/assets/hands/meshes/left_thumb_force_sensor_3.STL"/>

        <mesh name="left_index_force_sensor_0_mesh"  file="/content/HumanoidHand/assets/hands/meshes/left_index_force_sensor_1.STL"/>
        <mesh name="left_index_force_sensor_1_mesh"  file="/content/HumanoidHand/assets/hands/meshes/left_index_force_sensor_2.STL"/>
        <mesh name="left_index_force_sensor_2_mesh"  file="/content/HumanoidHand/assets/hands/meshes/left_index_force_sensor_3.STL"/>

        <mesh name="left_middle_force_sensor_0_mesh" file="/content/HumanoidHand/assets/hands/meshes/left_middle_force_sensor_1.STL"/>
        <mesh name="left_middle_force_sensor_1_mesh" file="/content/HumanoidHand/assets/hands/meshes/left_middle_force_sensor_2.STL"/>
        <mesh name="left_middle_force_sensor_2_mesh" file="/content/HumanoidHand/assets/hands/meshes/left_middle_force_sensor_3.STL"/>

        <mesh name="left_ring_force_sensor_0_mesh"   file="/content/HumanoidHand/assets/hands/meshes/left_ring_force_sensor_1.STL"/>
        <mesh name="left_ring_force_sensor_1_mesh"   file="/content/HumanoidHand/assets/hands/meshes/left_ring_force_sensor_2.STL"/>
        <mesh name="left_ring_force_sensor_2_mesh"   file="/content/HumanoidHand/assets/hands/meshes/left_ring_force_sensor_3.STL"/>

        <!-- Main droite -->
        <mesh name="right_thumb_force_sensor_0_mesh"  file="/content/HumanoidHand/assets/hands/meshes/right_thumb_force_sensor_1.STL"/>
        <mesh name="right_thumb_force_sensor_1_mesh"  file="/content/HumanoidHand/assets/hands/meshes/right_thumb_force_sensor_2.STL"/>
        <mesh name="right_thumb_force_sensor_2_mesh"  file="/content/HumanoidHand/assets/hands/meshes/right_thumb_force_sensor_3.STL"/>

        <mesh name="right_index_force_sensor_0_mesh"  file="/content/HumanoidHand/assets/hands/meshes/right_index_force_sensor_1.STL"/>
        <mesh name="right_index_force_sensor_1_mesh"  file="/content/HumanoidHand/assets/hands/meshes/right_index_force_sensor_2.STL"/>
        <mesh name="right_index_force_sensor_2_mesh"  file="/content/HumanoidHand/assets/hands/meshes/right_index_force_sensor_3.STL"/>

        <mesh name="right_middle_force_sensor_0_mesh" file="/content/HumanoidHand/assets/hands/meshes/right_middle_force_sensor_1.STL"/>
        <mesh name="right_middle_force_sensor_1_mesh" file="/content/HumanoidHand/assets/hands/meshes/right_middle_force_sensor_2.STL"/>
        <mesh name="right_middle_force_sensor_2_mesh" file="/content/HumanoidHand/assets/hands/meshes/right_middle_force_sensor_3.STL"/>

        <mesh name="right_ring_force_sensor_0_mesh"   file="/content/HumanoidHand/assets/hands/meshes/right_ring_force_sensor_1.STL"/>
        <mesh name="right_ring_force_sensor_1_mesh"   file="/content/HumanoidHand/assets/hands/meshes/right_ring_force_sensor_2.STL"/>
        <mesh name="right_ring_force_sensor_2_mesh"   file="/content/HumanoidHand/assets/hands/meshes/right_ring_force_sensor_3.STL"/>
    </asset>


<worldbody>
  <!-- ========== INDEX GAUCHE ========== -->
  <body name="left_index_0" pos="0.03 0.05 0.02">
    <joint name="left_index_joint_0" type="hinge" axis="0 1 0"
           range="0 1.5" damping="0.01"/>
    <geom  type="mesh" mesh="left_index_0_mesh"
           contype="1" conaffinity="1"/>
    <body name="left_index_1" pos="0.02 0 0">
      <joint name="left_index_joint_1" type="hinge" axis="0 1 0"
             range="0 1.5" damping="0.01"/>
      <geom  type="mesh" mesh="left_index_1_mesh"
             contype="1" conaffinity="1"/>
      <site name="left_index_tip_site"
            pos="0.02 0 0"
            size="0.003"
            type="sphere"/>
    </body>
  </body>

  <!-- ========== MAJEUR GAUCHE ========== -->
  <body name="left_middle_0" pos="0.035 0.05 0.025">
    <joint name="left_middle_joint_0" type="hinge" axis="0 1 0"
           range="0 1.5" damping="0.01"/>
    <geom  type="mesh" mesh="left_middle_0_mesh"
           contype="1" conaffinity="1"/>
    <body name="left_middle_1" pos="0.02 0 0">
      <joint name="left_middle_joint_1" type="hinge" axis="0 1 0"
             range="0 1.5" damping="0.01"/>
      <geom  type="mesh" mesh="left_middle_1_mesh"
             contype="1" conaffinity="1"/>
      <site name="left_middle_tip_site"
            pos="0.02 0 0"
            size="0.003"
            type="sphere"/>
    </body>
  </body>

  <!-- ========== ANNULAIRE GAUCHE ========== -->
  <body name="left_ring_0" pos="0.04 0.05 0.025">
    <joint name="left_ring_joint_0" type="hinge" axis="0 1 0"
           range="0 1.5" damping="0.01"/>
    <geom  type="mesh" mesh="left_ring_0_mesh"
           contype="1" conaffinity="1"/>
    <body name="left_ring_1" pos="0.02 0 0">
      <joint name="left_ring_joint_1" type="hinge" axis="0 1 0"
             range="0 1.5" damping="0.01"/>
      <geom  type="mesh" mesh="left_ring_1_mesh"
             contype="1" conaffinity="1"/>
      <site name="left_ring_tip_site"
            pos="0.02 0 0"
            size="0.003"
            type="sphere"/>
    </body>
  </body>

  <!-- ========== POUCE GAUCHE ========== -->
  <body name="left_thumb_0" pos="0.02 0.04 0.015">
    <joint name="left_thumb_joint_0" type="hinge" axis="0 1 0"
           range="0 1.5" damping="0.01"/>
    <geom  type="mesh" mesh="left_thumb_0_mesh"
           contype="1" conaffinity="1"/>
    <body name="left_thumb_1" pos="0.02 0 0">
      <joint name="left_thumb_joint_1" type="hinge" axis="0 1 0"
             range="0 1.5" damping="0.01"/>
      <geom  type="mesh" mesh="left_thumb_1_mesh"
             contype="1" conaffinity="1"/>
      <site name="left_thumb_tip_site"
            pos="0.02 0 0"
            size="0.003"
            type="sphere"/>
    </body>
  </body>

  <!-- ========== INDEX DROIT ========== -->
  <body name="right_index_0" pos="-0.03 -0.05 0.02">
    <joint name="right_index_joint_0" type="hinge" axis="0 1 0"
           range="0 1.5" damping="0.01"/>
    <geom  type="mesh" mesh="right_index_0_mesh"
           contype="1" conaffinity="1"/>
    <body name="right_index_1" pos="0.02 0 0">
      <joint name="right_index_joint_1" type="hinge" axis="0 1 0"
             range="0 1.5" damping="0.01"/>
      <geom  type="mesh" mesh="right_index_1_mesh"
             contype="1" conaffinity="1"/>
      <site name="right_index_tip_site"
            pos="0.02 0 0"
            size="0.003"
            type="sphere"/>
    </body>
  </body>

  <!-- ========== MAJEUR DROIT ========== -->
  <body name="right_middle_0" pos="-0.035 -0.05 0.025">
    <joint name="right_middle_joint_0" type="hinge" axis="0 1 0"
           range="0 1.5" damping="0.01"/>
    <geom  type="mesh" mesh="right_middle_0_mesh"
           contype="1" conaffinity="1"/>
    <body name="right_middle_1" pos="0.02 0 0">
      <joint name="right_middle_joint_1" type="hinge" axis="0 1 0"
             range="0 1.5" damping="0.01"/>
      <geom  type="mesh" mesh="right_middle_1_mesh"
             contype="1" conaffinity="1"/>
      <site name="right_middle_tip_site"
            pos="0.02 0 0"
            size="0.003"
            type="sphere"/>
    </body>
  </body>

  <!-- ========== ANNULAIRE DROIT ========== -->
  <body name="right_ring_0" pos="-0.04 -0.05 0.025">
    <joint name="right_ring_joint_0" type="hinge" axis="0 1 0"
           range="0 1.5" damping="0.01"/>
    <geom  type="mesh" mesh="right_ring_0_mesh"
           contype="1" conaffinity="1"/>
    <body name="right_ring_1" pos="0.02 0 0">
      <joint name="right_ring_joint_1" type="hinge" axis="0 1 0"
             range="0 1.5" damping="0.01"/>
      <geom  type="mesh" mesh="right_ring_1_mesh"
             contype="1" conaffinity="1"/>
      <site name="right_ring_tip_site"
            pos="0.02 0 0"
            size="0.003"
            type="sphere"/>
    </body>
  </body>
  <body name="right_thumb_0" pos="-0.02 -0.05 0.015">
  <joint name="right_thumb_joint_0"
         type="hinge"
         axis="0 1 0"
         range="0 1.5"
         damping="0.01"/>
  <geom type="mesh"
        mesh="right_thumb_0_mesh"
        contype="1"
        conaffinity="1"/>
  
  <body name="right_thumb_1" pos="0.02 0 0">
    <joint name="right_thumb_joint_1"
           type="hinge"
           axis="0 1 0"
           range="0 1.5"
           damping="0.01"/>
    <geom type="mesh"
          mesh="right_thumb_1_mesh"
          contype="1"
          conaffinity="1"/>

    <site name="right_thumb_tip_site"
          pos="0.02 0 0"
          size="0.003"
          type="sphere"/>
  </body>
</body>


  <!-- ===================== FORCE SENSOR SITES ===================== -->
  <!-- Gauche -->
  <body name="left_thumb_force_sensors" pos="0.02 0 0">
    <site name="left_thumb_force_sensor_0_site"
          pos="0 0 0"
          size="0.003"
          type="sphere"/>
    <geom type="mesh"
          mesh="left_thumb_force_sensor_0_mesh"
          rgba="0.8 0.2 0.2 0.3"
          contype="0"
          conaffinity="0"/>
    <site name="left_thumb_force_sensor_1_site"
          pos="0 0 0"
          size="0.003"
          type="sphere"/>
    <geom type="mesh"
          mesh="left_thumb_force_sensor_1_mesh"
          rgba="0.2 0.8 0.2 0.3"
          contype="0"
          conaffinity="0"/>
    <site name="left_thumb_force_sensor_2_site"
          pos="0 0 0"
          size="0.003"
          type="sphere"/>
    <geom type="mesh"
          mesh="left_thumb_force_sensor_2_mesh"
          rgba="0.2 0.2 0.8 0.3"
          contype="0"
          conaffinity="0"/>
  </body>

  <body name="left_index_force_sensors" pos="0.02 0 0">
    <site name="left_index_force_sensor_0_site"
          pos="0 0 0"
          size="0.003"
          type="sphere"/>
    <geom type="mesh"
          mesh="left_index_force_sensor_0_mesh"
          rgba="0.8 0.2 0.2 0.3"
          contype="0"
          conaffinity="0"/>
    <site name="left_index_force_sensor_1_site"
          pos="0 0 0"
          size="0.003"
          type="sphere"/>
    <geom type="mesh"
          mesh="left_index_force_sensor_1_mesh"
          rgba="0.2 0.8 0.2 0.3"
          contype="0"
          conaffinity="0"/>
    <site name="left_index_force_sensor_2_site"
          pos="0 0 0"
          size="0.003"
          type="sphere"/>
    <geom type="mesh"
          mesh="left_index_force_sensor_2_mesh"
          rgba="0.2 0.2 0.8 0.3"
          contype="0"
          conaffinity="0"/>
  </body>

  <body name="left_middle_force_sensors" pos="0.02 0 0">
    <site name="left_middle_force_sensor_0_site"
          pos="0 0 0"
          size="0.003"
          type="sphere"/>
    <geom type="mesh"
          mesh="left_middle_force_sensor_0_mesh"
          rgba="0.8 0.2 0.2 0.3"
          contype="0"
          conaffinity="0"/>
    <site name="left_middle_force_sensor_1_site"
          pos="0 0 0"
          size="0.003"
          type="sphere"/>
    <geom type="mesh"
          mesh="left_middle_force_sensor_1_mesh"
          rgba="0.2 0.8 0.2 0.3"
          contype="0"
          conaffinity="0"/>
    <site name="left_middle_force_sensor_2_site"
          pos="0 0 0"
          size="0.003"
          type="sphere"/>
    <geom type="mesh"
          mesh="left_middle_force_sensor_2_mesh"
          rgba="0.2 0.2 0.8 0.3"
          contype="0"
          conaffinity="0"/>
  </body>

  <body name="left_ring_force_sensors" pos="0.02 0 0">
    <site name="left_ring_force_sensor_0_site"
          pos="0 0 0"
          size="0.003"
          type="sphere"/>
    <geom type="mesh"
          mesh="left_ring_force_sensor_0_mesh"
          rgba="0.8 0.2 0.2 0.3"
          contype="0"
          conaffinity="0"/>
    <site name="left_ring_force_sensor_1_site"
          pos="0 0 0"
          size="0.003"
          type="sphere"/>
    <geom type="mesh"
          mesh="left_ring_force_sensor_1_mesh"
          rgba="0.2 0.8 0.2 0.3"
          contype="0"
          conaffinity="0"/>
    <site name="left_ring_force_sensor_2_site"
          pos="0 0 0"
          size="0.003"
          type="sphere"/>
    <geom type="mesh"
          mesh="left_ring_force_sensor_2_mesh"
          rgba="0.2 0.2 0.8 0.3"
          contype="0"
          conaffinity="0"/>
  </body>

  <!-- Droite -->
  <body name="right_thumb_force_sensors" pos="0.02 0 0">
    <site name="right_thumb_force_sensor_0_site"
          pos="0 0 0"
          size="0.003"
          type="sphere"/>
    <geom type="mesh"
          mesh="right_thumb_force_sensor_0_mesh"
          rgba="0.8 0.2 0.2 0.3"
          contype="0"
          conaffinity="0"/>
    <site name="right_thumb_force_sensor_1_site"
          pos="0 0 0"
          size="0.003"
          type="sphere"/>
    <geom type="mesh"
          mesh="right_thumb_force_sensor_1_mesh"
          rgba="0.2 0.8 0.2 0.3"
          contype="0"
          conaffinity="0"/>
    <site name="right_thumb_force_sensor_2_site"
          pos="0 0 0"
          size="0.003"
          type="sphere"/>
    <geom type="mesh"
          mesh="right_thumb_force_sensor_2_mesh"
          rgba="0.2 0.2 0.8 0.3"
          contype="0"
          conaffinity="0"/>
  </body>

  <body name="right_index_force_sensors" pos="0.02 0 0">
    <site name="right_index_force_sensor_0_site"
          pos="0 0 0"
          size="0.003"
          type="sphere"/>
    <geom type="mesh"
          mesh="right_index_force_sensor_0_mesh"
          rgba="0.8 0.2 0.2 0.3"
          contype="0"
          conaffinity="0"/>
    <site name="right_index_force_sensor_1_site"
          pos="0 0 0"
          size="0.003"
          type="sphere"/>
    <geom type="mesh"
          mesh="right_index_force_sensor_1_mesh"
          rgba="0.2 0.8 0.2 0.3"
          contype="0"
          conaffinity="0"/>
    <site name="right_index_force_sensor_2_site"
          pos="0 0 0"
          size="0.003"
          type="sphere"/>
    <geom type="mesh"
          mesh="right_index_force_sensor_2_mesh"
          rgba="0.2 0.2 0.8 0.3"
          contype="0"
          conaffinity="0"/>
  </body>

  <body name="right_middle_force_sensors" pos="0.02 0 0">
    <site name="right_middle_force_sensor_0_site"
          pos="0 0 0"
          size="0.003"
          type="sphere"/>
    <geom type="mesh"
          mesh="right_middle_force_sensor_0_mesh"
          rgba="0.8 0.2 0.2 0.3"
          contype="0"
          conaffinity="0"/>
    <site name="right_middle_force_sensor_1_site"
          pos="0 0 0"
          size="0.003"
          type="sphere"/>
    <geom type="mesh"
          mesh="right_middle_force_sensor_1_mesh"
          rgba="0.2 0.8 0.2 0.3"
          contype="0"
          conaffinity="0"/>
    <site name="right_middle_force_sensor_2_site"
          pos="0 0 0"
          size="0.003"
          type="sphere"/>
    <geom type="mesh"
          mesh="right_middle_force_sensor_2_mesh"
          rgba="0.2 0.2 0.8 0.3"
          contype="0"
          conaffinity="0"/>
  </body>

  <body name="right_ring_force_sensors" pos="0.02 0 0">
    <site name="right_ring_force_sensor_0_site"
          pos="0 0 0"
          size="0.003"
          type="sphere"/>
    <geom type="mesh"
          mesh="right_ring_force_sensor_0_mesh"
          rgba="0.8 0.2 0.2 0.3"
          contype="0"
          conaffinity="0"/>
    <site name="right_ring_force_sensor_1_site"
          pos="0 0 0"
          size="0.003"
          type="sphere"/>
    <geom type="mesh"
          mesh="right_ring_force_sensor_1_mesh"
          rgba="0.2 0.8 0.2 0.3"
          contype="0"
          conaffinity="0"/>
    <site name="right_ring_force_sensor_2_site"
          pos="0 0 0"
          size="0.003"
          type="sphere"/>
    <geom type="mesh"
          mesh="right_ring_force_sensor_2_mesh"
          rgba="0.2 0.2 0.8 0.3"
          contype="0"
          conaffinity="0"/>
  </body>
</worldbody>
    <!-- ============================ SENSORS ============================ -->
    <sensor>
        <!-- Capteurs gauche -->
        <touch name="left_thumb_tip_sensor"  site="left_thumb_tip_site"/>
        <touch name="left_index_tip_sensor"  site="left_index_tip_site"/>
        <touch name="left_middle_tip_sensor" site="left_middle_tip_site"/>
        <touch name="left_ring_tip_sensor"   site="left_ring_tip_site"/>

        <!-- Capteurs droite -->
        <touch name="right_thumb_tip_sensor"  site="right_thumb_tip_site"/>
        <touch name="right_index_tip_sensor"  site="right_index_tip_site"/>
        <touch name="right_middle_tip_sensor" site="right_middle_tip_site"/>
        <touch name="right_ring_tip_sensor"   site="right_ring_tip_site"/>


        <force name="left_thumb_force_sensor_0"  site="left_thumb_force_sensor_0_site"  />
        <force name="left_thumb_force_sensor_1"  site="left_thumb_force_sensor_1_site"   />
        <force name="left_thumb_force_sensor_2"  site="left_thumb_force_sensor_2_site"   />

        <force name="left_index_force_sensor_0"  site="left_index_force_sensor_0_site" />
        <force name="left_index_force_sensor_1"  site="left_index_force_sensor_1_site"  />
        <force name="left_index_force_sensor_2"  site="left_index_force_sensor_2_site"   />

        <force name="left_middle_force_sensor_0" site="left_middle_force_sensor_0_site"/>
        <force name="left_middle_force_sensor_1" site="left_middle_force_sensor_1_site"  />
        <force name="left_middle_force_sensor_2" site="left_middle_force_sensor_2_site" />

        <force name="left_ring_force_sensor_0"   site="left_ring_force_sensor_0_site"    />
        <force name="left_ring_force_sensor_1"   site="left_ring_force_sensor_1_site"    />
        <force name="left_ring_force_sensor_2"   site="left_ring_force_sensor_2_site"    />

        <!-- Main droite -->
        <force name="right_thumb_force_sensor_0"  site="right_thumb_force_sensor_0_site"  />
        <force name="right_thumb_force_sensor_1"  site="right_thumb_force_sensor_1_site"  />
        <force name="right_thumb_force_sensor_2"  site="right_thumb_force_sensor_2_site" />

        <force name="right_index_force_sensor_0"  site="right_index_force_sensor_0_site"  />
        <force name="right_index_force_sensor_1"  site="right_index_force_sensor_1_site"  />
        <force name="right_index_force_sensor_2"  site="right_index_force_sensor_2_site"/>

        <force name="right_middle_force_sensor_0" site="right_middle_force_sensor_0_site"/>
        <force name="right_middle_force_sensor_1" site="right_middle_force_sensor_1_site" />
        <force name="right_middle_force_sensor_2" site="right_middle_force_sensor_2_site"/>

        <force name="right_ring_force_sensor_0"   site="right_ring_force_sensor_0_site" />
        <force name="right_ring_force_sensor_1"   site="right_ring_force_sensor_1_site" />
        <force name="right_ring_force_sensor_2"   site="right_ring_force_sensor_2_site"  />

    </sensor>

    <!-- ============================ ACTUATORS ============================ -->
    <actuator>
        <!-- Gauche : 4 doigts × 2 articulations -->
        <position name="act_left_thumb_0"  joint="left_thumb_joint_0" kp="100"/>
        <position name="act_left_thumb_1"  joint="left_thumb_joint_1" kp="100"/>

        <position name="act_left_index_0"  joint="left_index_joint_0" kp="100"/>
        <position name="act_left_index_1"  joint="left_index_joint_1" kp="100"/>

        <position name="act_left_middle_0" joint="left_middle_joint_0" kp="100"/>
        <position name="act_left_middle_1" joint="left_middle_joint_1" kp="100"/>

        <position name="act_left_ring_0"   joint="left_ring_joint_0" kp="100"/>
        <position name="act_left_ring_1"   joint="left_ring_joint_1" kp="100"/>

        <!-- Droite : idem -->
        <position name="act_right_thumb_0"  joint="right_thumb_joint_0" kp="100"/>
        <position name="act_right_thumb_1"  joint="right_thumb_joint_1" kp="100"/>

        <position name="act_right_index_0"  joint="right_index_joint_0" kp="100"/>
        <position name="act_right_index_1"  joint="right_index_joint_1" kp="100"/>

        <position name="act_right_middle_0" joint="right_middle_joint_0" kp="100"/>
        <position name="act_right_middle_1" joint="right_middle_joint_1" kp="100"/>

        <position name="act_right_ring_0"   joint="right_ring_joint_0" kp="100"/>
        <position name="act_right_ring_1"   joint="right_ring_joint_1" kp="100"/>
    </actuator>
</mujoco>

