<mujoco model="ability_hand">
  <option iterations="50" timestep="0.001" solver="PGS" gravity="0 0 -9.81" />

  <compiler angle="radian" meshdir="meshes" eulerseq="zyx" autolimits="true" />

  <default>
    <joint limited="true" damping="0.01" armature="0.01" frictionloss="0.01" />
    <geom condim="4" contype="1" conaffinity="15" friction="0.9 0.2 0.2" solref="0.001 2" />
    <motor ctrllimited="true" />
    <equality solref="0.001 2" />
    <default class="visualgeom">
      <geom material="visualgeom" condim="1" contype="0" conaffinity="0" />
    </default>
  </default>

  <asset>
    <mesh name="wristmesh_C" content_type="model/obj" file="wristmesh_C.obj" />
    <mesh name="FB_palm_ref" content_type="model/obj" file="FB_palm_ref.obj" />
    <mesh name="thumb-F1_C" content_type="model/obj" file="thumb-F1_C.obj" />
    <mesh name="thumb-F2_C" content_type="model/obj" file="thumb-F2_C.obj" />
    <mesh name="idx-F2_C" content_type="model/obj" file="idx-F2_C.obj" />
    <texture name="texplane" type="2d" builtin="checker" rgb1=".0 .0 .0" rgb2=".8 .8 .8" width="100" height="100" />
    <material name="matplane" reflectance="0." texture="texplane" texrepeat="1 1" texuniform="true" />
    <material name="visualgeom" rgba="0.5 0.9 0.2 1" />
  </asset>

  <worldbody>
    <light directional="true" diffuse="0.4 0.4 0.4" specular="0.1 0.1 0.1" pos="0 0 5.0" dir="0 0 -1" castshadow="false" />
    <light directional="true" diffuse="0.6 0.6 0.6" specular="0.2 0.2 0.2" pos="0 0 4" dir="0 0 -1" />
    <geom name="ground" type="plane" pos="0 0 0" size="100 100 0.001" quat="1 0 0 0" material="matplane" condim="3" conaffinity="15" />
    <camera name="fixed" pos="0 -3.0 0.5276301723684765" xyaxes="1 0 0 0 0 1" />
    <camera name="track" mode="trackcom" pos="0 -3.0 0.5276301723684765" xyaxes="1 0 0 0 0 1" />
    <body name="root" pos="0 0 0.027630172368476556" quat="1 0 0 0">
      <freejoint name="root" />
      <site name="imu" size="0.01" pos="0 0 0" />
      <geom quat="0.707109 0 0 -0.707105" type="mesh" mesh="wristmesh_C" contype="1" conaffinity="0" density="0" group="1" class="visualgeom" />
      <geom type="mesh" rgba="" mesh="wristmesh_C" quat="0.707109 0 0 -0.707105" />
      <geom pos="0.0037814 -0.0240476 0.0323296" quat="0.0312943 0.706844 0.705985 -0.0312559" type="mesh" mesh="FB_palm_ref" contype="1" conaffinity="0" density="0" group="1" class="visualgeom" />
      <geom type="mesh" rgba="" mesh="FB_palm_ref" pos="0.0037814 -0.0240476 0.0323296" quat="0.0312943 0.706844 0.705985 -0.0312559" />
      <body name="thumb_L1" pos="0.0037814 -0.0240476 0.0323296" quat="0.0281662 0.636198 -0.770257 0.0341018">
        <inertial pos="0 0 0" mass="1" diaginertia="0.001 0.001 0.001" />
        <joint name="thumb_q1" pos="0 0 0" axis="0 0 1" range="-2.0944 0" actuatorfrcrange="-1.2 1.2" damping="0.001" frictionloss="0.001" />
        <geom pos="0.0278284 0 -0.0147507" quat="-0.608761 0.793353 0 0" type="mesh" mesh="thumb-F1_C" contype="1" conaffinity="0" density="0" group="1" class="visualgeom" />
        <geom type="mesh" rgba="" mesh="thumb-F1_C" pos="0.0278284 0 -0.0147507" quat="-0.608761 0.793353 0 0" />
        <body name="thumb_L2" pos="0.0278284 0 -0.0147507" quat="-0.608761 0.793353 0 0">
          <inertial pos="0 0 0" mass="1" diaginertia="0.001 0.001 0.001" />
          <joint name="thumb_q2" pos="0 0 0" axis="0 0 1" range="0 2.0944" actuatorfrcrange="-6 6" damping="0.001" frictionloss="0.001" />
          <geom pos="0.0651867 0.0233402 -0.00393483" quat="3.21978e-07 0.985259 0.171069 5.59046e-08" type="mesh" mesh="thumb-F2_C" contype="1" conaffinity="0" density="0" group="1" class="visualgeom" />
          <geom type="mesh" rgba="" mesh="thumb-F2_C" pos="0.0651867 0.0233402 -0.00393483" quat="3.21978e-07 0.985259 0.171069 5.59046e-08" />
        </body>
      </body>
      <body name="index_L1" pos="-0.00927016 -0.0279217 0.0958706" quat="-0.472009 0.393141 0.576875 0.538389">
        <inertial pos="0 0 0" mass="1" diaginertia="0.001 0.001 0.001" />
        <joint name="index_q1" pos="0 0 0" axis="0 0 1" range="0 2.0944" actuatorfrcrange="-6 6" damping="0.001" frictionloss="0.001" />
        <geom size="0.0085" pos="0.036 -0.00175 0" contype="1" conaffinity="0" density="0" group="1" class="visualgeom" />
        <geom type="" rgba="" pos="0.036 -0.00175 0" />
        <geom size="0.014 0.006 0.008" pos="0.019 -0.0045 0" quat="0.999108 0 0 0.0422374" type="box" contype="1" conaffinity="0" density="0" group="1" class="visualgeom" />
        <geom type="box" rgba="" size="0.014 0.006 0.008" pos="0.019 -0.0045 0" quat="0.999108 0 0 0.0422374" />
        <geom size="0.01 0.005 0.008" pos="0.018 0.006 0" quat="0.999108 0 0 0.0422374" type="box" contype="1" conaffinity="0" density="0" group="1" class="visualgeom" />
        <geom type="box" rgba="" size="0.01 0.005 0.008" pos="0.018 0.006 0" quat="0.999108 0 0 0.0422374" />
        <geom size="0.006 0.006 0.001" pos="-0.001 0 0.007" quat="0.999108 0 0 0.0422374" type="box" contype="1" conaffinity="0" density="0" group="1" class="visualgeom" />
        <geom type="box" rgba="" size="0.006 0.006 0.001" pos="-0.001 0 0.007" quat="0.999108 0 0 0.0422374" />
        <geom size="0.006 0.006 0.001" pos="-0.001 0 -0.007" quat="0.999108 0 0 0.0422374" type="box" contype="1" conaffinity="0" density="0" group="1" class="visualgeom" />
        <geom type="box" rgba="" size="0.006 0.006 0.001" pos="-0.001 0 -0.007" quat="0.999108 0 0 0.0422374" />
        <body name="index_L2" pos="0.0384727 0.0032577 0" quat="0.999108 0 0 0.0422244">
          <inertial pos="0 0 0" mass="1" diaginertia="0.001 0.001 0.001" />
          <joint name="index_q2" pos="0 0 0" axis="0 0 1" range="0 2.6586" actuatorfrcrange="-6 6" damping="0.001" frictionloss="0.001" />
          <geom type="mesh" mesh="idx-F2_C" contype="1" conaffinity="0" density="0" group="1" class="visualgeom" />
          <geom type="mesh" rgba="" mesh="idx-F2_C" />
          <geom size="0.007" pos="0.03 -0.016 0" contype="1" conaffinity="0" density="0" group="1" class="visualgeom" />
          <geom type="" rgba="" pos="0.03 -0.016 0" />
        </body>
      </body>
      <body name="middle_L1" pos="-0.0115172 -0.00841725 0.0990634" quat="-0.443231 0.425007 0.571393 0.544449">
        <inertial pos="0 0 0" mass="1" diaginertia="0.001 0.001 0.001" />
        <joint name="middle_q1" pos="0 0 0" axis="0 0 1" range="0 2.0944" actuatorfrcrange="-6 6" damping="0.001" frictionloss="0.001" />
        <geom size="0.0085" pos="0.036 -0.00175 0" contype="1" conaffinity="0" density="0" group="1" class="visualgeom" />
        <geom type="" rgba="" pos="0.036 -0.00175 0" />
        <geom size="0.014 0.006 0.008" pos="0.019 -0.0045 0" quat="0.999108 0 0 0.0422374" type="box" contype="1" conaffinity="0" density="0" group="1" class="visualgeom" />
        <geom type="box" rgba="" size="0.014 0.006 0.008" pos="0.019 -0.0045 0" quat="0.999108 0 0 0.0422374" />
        <geom size="0.01 0.005 0.008" pos="0.018 0.006 0" quat="0.999108 0 0 0.0422374" type="box" contype="1" conaffinity="0" density="0" group="1" class="visualgeom" />
        <geom type="box" rgba="" size="0.01 0.005 0.008" pos="0.018 0.006 0" quat="0.999108 0 0 0.0422374" />
        <geom size="0.006 0.006 0.001" pos="-0.001 0 0.007" quat="0.999108 0 0 0.0422374" type="box" contype="1" conaffinity="0" density="0" group="1" class="visualgeom" />
        <geom type="box" rgba="" size="0.006 0.006 0.001" pos="-0.001 0 0.007" quat="0.999108 0 0 0.0422374" />
        <geom size="0.006 0.006 0.001" pos="-0.001 0 -0.007" quat="0.999108 0 0 0.0422374" type="box" contype="1" conaffinity="0" density="0" group="1" class="visualgeom" />
        <geom type="box" rgba="" size="0.006 0.006 0.001" pos="-0.001 0 -0.007" quat="0.999108 0 0 0.0422374" />
        <body name="middle_L2" pos="0.0384727 0.0032577 0" quat="0.999108 0 0 0.0422244">
          <inertial pos="0 0 0" mass="1" diaginertia="0.001 0.001 0.001" />
          <joint name="middle_q2" pos="0 0 0" axis="0 0 1" range="0 2.6586" actuatorfrcrange="-6 6" damping="0.001" frictionloss="0.001" />
          <geom type="mesh" mesh="idx-F2_C" contype="1" conaffinity="0" density="0" group="1" class="visualgeom" />
          <geom type="mesh" rgba="" mesh="idx-F2_C" />
          <geom size="0.007" pos="0.03 -0.016 0" contype="1" conaffinity="0" density="0" group="1" class="visualgeom" />
          <geom type="" rgba="" pos="0.03 -0.016 0" />
        </body>
      </body>
      <body name="ring_L1" pos="-0.0103947 0.0117529 0.0967038" quat="-0.411904 0.455648 0.564496 0.55142">
        <inertial pos="0 0 0" mass="1" diaginertia="0.001 0.001 0.001" />
        <joint name="ring_q1" pos="0 0 0" axis="0 0 1" range="0 2.0944" actuatorfrcrange="-6 6" damping="0.001" frictionloss="0.001" />
        <geom size="0.0085" pos="0.036 -0.00175 0" contype="1" conaffinity="0" density="0" group="1" class="visualgeom" />
        <geom type="" rgba="" pos="0.036 -0.00175 0" />
        <geom size="0.014 0.006 0.008" pos="0.019 -0.0045 0" quat="0.999108 0 0 0.0422374" type="box" contype="1" conaffinity="0" density="0" group="1" class="visualgeom" />
        <geom type="box" rgba="" size="0.014 0.006 0.008" pos="0.019 -0.0045 0" quat="0.999108 0 0 0.0422374" />
        <geom size="0.01 0.005 0.008" pos="0.018 0.006 0" quat="0.999108 0 0 0.0422374" type="box" contype="1" conaffinity="0" density="0" group="1" class="visualgeom" />
        <geom type="box" rgba="" size="0.01 0.005 0.008" pos="0.018 0.006 0" quat="0.999108 0 0 0.0422374" />
        <geom size="0.006 0.006 0.001" pos="-0.001 0 0.007" quat="0.999108 0 0 0.0422374" type="box" contype="1" conaffinity="0" density="0" group="1" class="visualgeom" />
        <geom type="box" rgba="" size="0.006 0.006 0.001" pos="-0.001 0 0.007" quat="0.999108 0 0 0.0422374" />
        <geom size="0.006 0.006 0.001" pos="-0.001 0 -0.007" quat="0.999108 0 0 0.0422374" type="box" contype="1" conaffinity="0" density="0" group="1" class="visualgeom" />
        <geom type="box" rgba="" size="0.006 0.006 0.001" pos="-0.001 0 -0.007" quat="0.999108 0 0 0.0422374" />
        <body name="ring_L2" pos="0.0384727 0.0032577 0" quat="0.999108 0 0 0.0422244">
          <inertial pos="0 0 0" mass="1" diaginertia="0.001 0.001 0.001" />
          <joint name="ring_q2" pos="0 0 0" axis="0 0 1" range="0 2.6586" actuatorfrcrange="-6 6" damping="0.001" frictionloss="0.001" />
          <geom type="mesh" mesh="idx-F2_C" contype="1" conaffinity="0" density="0" group="1" class="visualgeom" />
          <geom type="mesh" rgba="" mesh="idx-F2_C" />
          <geom size="0.007" pos="0.03 -0.016 0" contype="1" conaffinity="0" density="0" group="1" class="visualgeom" />
          <geom type="" rgba="" pos="0.03 -0.016 0" />
        </body>
      </body>
      <body name="pinky_L1" pos="-0.00716302 0.0308632 0.0907346" quat="-0.395547 0.470095 0.547045 0.568591">
        <inertial pos="0 0 0" mass="1" diaginertia="0.001 0.001 0.001" />
        <joint name="pinky_q1" pos="0 0 0" axis="0 0 1" range="0 2.0944" actuatorfrcrange="-6 6" damping="0.001" frictionloss="0.001" />
        <geom size="0.0085" pos="0.036 -0.00175 0" contype="1" conaffinity="0" density="0" group="1" class="visualgeom" />
        <geom type="" rgba="" pos="0.036 -0.00175 0" />
        <geom size="0.014 0.006 0.008" pos="0.019 -0.0045 0" quat="0.999108 0 0 0.0422374" type="box" contype="1" conaffinity="0" density="0" group="1" class="visualgeom" />
        <geom type="box" rgba="" size="0.014 0.006 0.008" pos="0.019 -0.0045 0" quat="0.999108 0 0 0.0422374" />
        <geom size="0.01 0.005 0.008" pos="0.018 0.006 0" quat="0.999108 0 0 0.0422374" type="box" contype="1" conaffinity="0" density="0" group="1" class="visualgeom" />
        <geom type="box" rgba="" size="0.01 0.005 0.008" pos="0.018 0.006 0" quat="0.999108 0 0 0.0422374" />
        <geom size="0.006 0.006 0.001" pos="-0.001 0 0.007" quat="0.999108 0 0 0.0422374" type="box" contype="1" conaffinity="0" density="0" group="1" class="visualgeom" />
        <geom type="box" rgba="" size="0.006 0.006 0.001" pos="-0.001 0 0.007" quat="0.999108 0 0 0.0422374" />
        <geom size="0.006 0.006 0.001" pos="-0.001 0 -0.007" quat="0.999108 0 0 0.0422374" type="box" contype="1" conaffinity="0" density="0" group="1" class="visualgeom" />
        <geom type="box" rgba="" size="0.006 0.006 0.001" pos="-0.001 0 -0.007" quat="0.999108 0 0 0.0422374" />
        <body name="pinky_L2" pos="0.0384727 0.0032577 0" quat="0.999108 0 0 0.0422244">
          <inertial pos="0 0 0" mass="1" diaginertia="0.001 0.001 0.001" />
          <joint name="pinky_q2" pos="0 0 0" axis="0 0 1" range="0 2.6586" actuatorfrcrange="-6 6" damping="0.001" frictionloss="0.001" />
          <geom type="mesh" mesh="idx-F2_C" contype="1" conaffinity="0" density="0" group="1" class="visualgeom" />
          <geom type="mesh" rgba="" mesh="idx-F2_C" />
          <geom size="0.007" pos="0.03 -0.016 0" contype="1" conaffinity="0" density="0" group="1" class="visualgeom" />
          <geom type="" rgba="" pos="0.03 -0.016 0" />
        </body>
      </body>
    </body>
  </worldbody>

  <actuator>
    <motor name="thumb_q1" joint="thumb_q1" ctrllimited="true" ctrlrange="-1.2 1.2" gear="1" />
    <motor name="thumb_q2" joint="thumb_q2" ctrllimited="true" ctrlrange="-6 6" gear="1" />
    <motor name="index_q1" joint="index_q1" ctrllimited="true" ctrlrange="-6 6" gear="1" />
    <motor name="index_q2" joint="index_q2" ctrllimited="true" ctrlrange="-6 6" gear="1" />
    <motor name="middle_q1" joint="middle_q1" ctrllimited="true" ctrlrange="-6 6" gear="1" />
    <motor name="middle_q2" joint="middle_q2" ctrllimited="true" ctrlrange="-6 6" gear="1" />
    <motor name="ring_q1" joint="ring_q1" ctrllimited="true" ctrlrange="-6 6" gear="1" />
    <motor name="ring_q2" joint="ring_q2" ctrllimited="true" ctrlrange="-6 6" gear="1" />
    <motor name="pinky_q1" joint="pinky_q1" ctrllimited="true" ctrlrange="-6 6" gear="1" />
    <motor name="pinky_q2" joint="pinky_q2" ctrllimited="true" ctrlrange="-6 6" gear="1" />
  </actuator>

  <sensor>
    <actuatorpos name="thumb_q1_p" actuator="thumb_q1" />
    <actuatorvel name="thumb_q1_v" actuator="thumb_q1" />
    <actuatorfrc name="thumb_q1_f" actuator="thumb_q1" noise="0.001" />
    <actuatorpos name="thumb_q2_p" actuator="thumb_q2" />
    <actuatorvel name="thumb_q2_v" actuator="thumb_q2" />
    <actuatorfrc name="thumb_q2_f" actuator="thumb_q2" noise="0.001" />
    <actuatorpos name="index_q1_p" actuator="index_q1" />
    <actuatorvel name="index_q1_v" actuator="index_q1" />
    <actuatorfrc name="index_q1_f" actuator="index_q1" noise="0.001" />
    <actuatorpos name="index_q2_p" actuator="index_q2" />
    <actuatorvel name="index_q2_v" actuator="index_q2" />
    <actuatorfrc name="index_q2_f" actuator="index_q2" noise="0.001" />
    <actuatorpos name="middle_q1_p" actuator="middle_q1" />
    <actuatorvel name="middle_q1_v" actuator="middle_q1" />
    <actuatorfrc name="middle_q1_f" actuator="middle_q1" noise="0.001" />
    <actuatorpos name="middle_q2_p" actuator="middle_q2" />
    <actuatorvel name="middle_q2_v" actuator="middle_q2" />
    <actuatorfrc name="middle_q2_f" actuator="middle_q2" noise="0.001" />
    <actuatorpos name="ring_q1_p" actuator="ring_q1" />
    <actuatorvel name="ring_q1_v" actuator="ring_q1" />
    <actuatorfrc name="ring_q1_f" actuator="ring_q1" noise="0.001" />
    <actuatorpos name="ring_q2_p" actuator="ring_q2" />
    <actuatorvel name="ring_q2_v" actuator="ring_q2" />
    <actuatorfrc name="ring_q2_f" actuator="ring_q2" noise="0.001" />
    <actuatorpos name="pinky_q1_p" actuator="pinky_q1" />
    <actuatorvel name="pinky_q1_v" actuator="pinky_q1" />
    <actuatorfrc name="pinky_q1_f" actuator="pinky_q1" noise="0.001" />
    <actuatorpos name="pinky_q2_p" actuator="pinky_q2" />
    <actuatorvel name="pinky_q2_v" actuator="pinky_q2" />
    <actuatorfrc name="pinky_q2_f" actuator="pinky_q2" noise="0.001" />
    <framequat name="orientation" objtype="site" noise="0.001" objname="imu" />
    <gyro name="angular-velocity" site="imu" noise="0.005" cutoff="34.9" />
  </sensor>
</mujoco>