<?xml version="1.0"?>
<robot name="kuka_allegro">
  <link name="virtual_root"><inertial>
      <origin xyz="0 0 0" rpy="0 0 0" />
      <mass value="1.0" />
      <inertia ixx="0.001" ixy="0.0" ixz="0.0" iyy="0.001" iyz="0.0" izz="0.001" />
    </inertial><visual><geometry><box size="0.01 0.01 0.01" /></geometry></visual></link><joint name="iiwa7_base_link_to_virtual_root" type="fixed"><parent link="virtual_root" /><child link="iiwa7_base_link" /></joint><joint name="dummy_root_link_to_virtual_root" type="fixed"><parent link="virtual_root" /><child link="dummy_root_link" /></joint><link name="dummy_root_link"><inertial>
      <origin xyz="0 0 0" rpy="0 0 0" />
      <mass value="1.0" />
      <inertia ixx="0.001" ixy="0.0" ixz="0.0" iyy="0.001" iyz="0.0" izz="0.001" />
    </inertial><visual><geometry><box size="0.01 0.01 0.01" /></geometry></visual></link><joint name="fix_thdistal_to_dummy" type="fixed"><parent link="dummy_root_link" /><child link="thdistal" /></joint><joint name="fix_rfdistal_to_dummy" type="fixed"><parent link="dummy_root_link" /><child link="rfdistal" /></joint><joint name="fix_mfdistal_to_dummy" type="fixed"><parent link="dummy_root_link" /><child link="mfdistal" /></joint><joint name="fix_lfdistal_to_dummy" type="fixed"><parent link="dummy_root_link" /><child link="lfdistal" /></joint><joint name="fix_ffdistal_to_dummy" type="fixed"><parent link="dummy_root_link" /><child link="ffdistal" /></joint><material name="Black">
    <color rgba="0.0 0.0 0.0 1.0" />
  </material>
  <material name="Blue">
    <color rgba="0.0 0.0 0.8 1.0" />
  </material>
  <material name="Green">
    <color rgba="0.0 0.8 0.0 1.0" />
  </material>
  <material name="Grey">
    <color rgba="0.4 0.4 0.4 1.0" />
  </material>
  <material name="Orange">
    <color rgba="1.0 0.423529411765 0.0392156862745 1.0" />
  </material>
  <material name="Brown">
    <color rgba="0.870588235294 0.811764705882 0.764705882353 1.0" />
  </material>
  <material name="Red">
    <color rgba="0.8 0.0 0.0 1.0" />
  </material>
  <material name="White">
    <color rgba="1.0 1.0 1.0 1.0" />
  </material>
  <link name="iiwa7_base_link"><inertial>
      <origin xyz="0 0 0" rpy="0 0 0" />
      <mass value="1.0" />
      <inertia ixx="0.001" ixy="0.0" ixz="0.0" iyy="0.001" iyz="0.0" izz="0.001" />
    </inertial><visual><geometry><box size="0.01 0.01 0.01" /></geometry></visual></link>
  
  <joint name="iiwa7_base_link_iiwa7_joint" type="fixed">
    <origin rpy="0 0 0" xyz="0 0 0" />
    <parent link="iiwa7_base_link" />
    <child link="iiwa7_link_0" />
  </joint>
  <link name="iiwa7_link_0">
    
    <visual>
      <origin rpy="0 0 0" xyz="0 0 0" />
      <geometry>
        <mesh filename="kuka_allegro_description/meshes/iiwa7/visual/link_0.obj" />
      </geometry>
      <material name="Grey" />
    </visual>
    <collision>
      <origin rpy="0 0 0" xyz="0 0 0" />
      <geometry>
        <mesh filename="kuka_allegro_description/meshes/iiwa7/collision/link_0.obj" />
      </geometry>
      <material name="Grey" />
    </collision>
    <self_collision_checking>
      <origin rpy="0 0 0" xyz="0 0 0" />
      <geometry>
        <capsule length="0.25" radius="0.15" />
      </geometry>
    </self_collision_checking>
  
    <inertial>
      <origin xyz="0 0 0" rpy="0 0 0" />
      <mass value="1.0" />
      <inertia ixx="0.001" ixy="0.0" ixz="0.0" iyy="0.001" iyz="0.0" izz="0.001" />
    </inertial>
</link>
  
  <joint name="iiwa7_joint_1" type="revolute">
    <parent link="iiwa7_link_0" />
    <child link="iiwa7_link_1" />
    <origin rpy="0 0 0" xyz="0 0 0.15" />
    <axis xyz="0 0 1" />
    <limit effort="300" lower="-2.96705972839" upper="2.96705972839" velocity="10" />
    <safety_controller k_position="100" k_velocity="2" soft_lower_limit="-2.93215314335" soft_upper_limit="2.93215314335" />
    <dynamics damping="5.5" friction="0.025" />
  </joint>
  <link name="iiwa7_link_1">
    
    <visual>
      <origin rpy="0 0 0" xyz="0 0 0.0075" />
      <geometry>
        <mesh filename="kuka_allegro_description/meshes/iiwa7/visual/link_1.obj" />
      </geometry>
      <material name="Orange" />
    </visual>
    <collision>
      <origin rpy="0 0 0" xyz="0 0 0.0075" />
      <geometry>
        <mesh filename="kuka_allegro_description/meshes/iiwa7/collision/link_1.obj" />
      </geometry>
      <material name="Orange" />
    </collision>
  
    <inertial>
      <origin xyz="0 0 0" rpy="0 0 0" />
      <mass value="1.0" />
      <inertia ixx="0.001" ixy="0.0" ixz="0.0" iyy="0.001" iyz="0.0" izz="0.001" />
    </inertial>
</link>
  <joint name="iiwa7_joint_2" type="revolute">
    <parent link="iiwa7_link_1" />
    <child link="iiwa7_link_2" />
    <origin rpy="1.57079632679   0 3.14159265359" xyz="0 0 0.19" />
    <axis xyz="0 0 1" />
    <limit effort="300" lower="-2.09439510239" upper="2.09439510239" velocity="10" />
    <safety_controller k_position="100" k_velocity="2" soft_lower_limit="-2.05948851735" soft_upper_limit="2.05948851735" />
    <dynamics damping="5.55" friction="0.025" />
  </joint>
  <link name="iiwa7_link_2">
    
    <visual>
      <origin rpy="0 0 0" xyz="0 0 0" />
      <geometry>
        <mesh filename="kuka_allegro_description/meshes/iiwa7/visual/link_2.obj" />
      </geometry>
      <material name="Orange" />
    </visual>
    <collision>
      <origin rpy="0 0 0" xyz="0 0 0" />
      <geometry>
        <mesh filename="kuka_allegro_description/meshes/iiwa7/collision/link_2.obj" />
      </geometry>
      <material name="Orange" />
    </collision>
  
    <inertial>
      <origin xyz="0 0 0" rpy="0 0 0" />
      <mass value="1.0" />
      <inertia ixx="0.001" ixy="0.0" ixz="0.0" iyy="0.001" iyz="0.0" izz="0.001" />
    </inertial>
</link>
  <joint name="iiwa7_joint_3" type="revolute">
    <parent link="iiwa7_link_2" />
    <child link="iiwa7_link_3" />
    <origin rpy="1.57079632679 0 3.14159265359" xyz="0 0.21 0" />
    <axis xyz="0 0 1" />
    <limit effort="300" lower="-2.96705972839" upper="2.96705972839" velocity="10" />
    <safety_controller k_position="100" k_velocity="2" soft_lower_limit="-2.93215314335" soft_upper_limit="2.93215314335" />
    <dynamics damping="5.5" friction="0.025" />
  </joint>
  <link name="iiwa7_link_3">
    
    <visual>
      <origin rpy="0 0 0" xyz="0 0 -0.026" />
      <geometry>
        <mesh filename="kuka_allegro_description/meshes/iiwa7/visual/link_3.obj" />
      </geometry>
      <material name="Orange" />
    </visual>
    <collision>
      <origin rpy="0 0 0" xyz="0 0 -0.026" />
      <geometry>
        <mesh filename="kuka_allegro_description/meshes/iiwa7/collision/link_3.obj" />
      </geometry>
      <material name="Orange" />
    </collision>
  
    <inertial>
      <origin xyz="0 0 0" rpy="0 0 0" />
      <mass value="1.0" />
      <inertia ixx="0.001" ixy="0.0" ixz="0.0" iyy="0.001" iyz="0.0" izz="0.001" />
    </inertial>
</link>
  <joint name="iiwa7_joint_4" type="revolute">
    <parent link="iiwa7_link_3" />
    <child link="iiwa7_link_4" />
    <origin rpy="1.57079632679 0 0" xyz="0 0 0.19" />
    <axis xyz="0 0 1" />
    <limit effort="300" lower="-2.09439510239" upper="2.09439510239" velocity="10" />
    <safety_controller k_position="100" k_velocity="2" soft_lower_limit="-2.05948851735" soft_upper_limit="2.05948851735" />
    <dynamics damping="5.5" friction="0.025" />
  </joint>
  <link name="iiwa7_link_4">
    
    <visual>
      <origin rpy="0 0 0" xyz="0 0 0" />
      <geometry>
        <mesh filename="kuka_allegro_description/meshes/iiwa7/visual/link_4.obj" />
      </geometry>
      <material name="Orange" />
    </visual>
    <collision>
      <origin rpy="0 0 0" xyz="0 0 0" />
      <geometry>
        <mesh filename="kuka_allegro_description/meshes/iiwa7/collision/link_4.obj" />
      </geometry>
      <material name="Orange" />
    </collision>
  
    <inertial>
      <origin xyz="0 0 0" rpy="0 0 0" />
      <mass value="1.0" />
      <inertia ixx="0.001" ixy="0.0" ixz="0.0" iyy="0.001" iyz="0.0" izz="0.001" />
    </inertial>
</link>
  <joint name="iiwa7_joint_5" type="revolute">
    <parent link="iiwa7_link_4" />
    <child link="iiwa7_link_5" />
    <origin rpy="-1.57079632679 3.14159265359 0" xyz="0 0.21 0" />
    <axis xyz="0 0 1" />
    <limit effort="300" lower="-2.96705972839" upper="2.96705972839" velocity="10" />
    <safety_controller k_position="100" k_velocity="2" soft_lower_limit="-2.93215314335" soft_upper_limit="2.93215314335" />
    <dynamics damping="5.5" friction="0.025" />
  </joint>
  <link name="iiwa7_link_5">
    
    <visual>
      <origin rpy="0 0 0" xyz="0 0 -0.026" />
      <geometry>
        <mesh filename="kuka_allegro_description/meshes/iiwa7/visual/link_5.obj" />
      </geometry>
      <material name="Orange" />
    </visual>
    <collision>
      <origin rpy="0 0 0" xyz="0 0 -0.026" />
      <geometry>
        <mesh filename="kuka_allegro_description/meshes/iiwa7/collision/link_5.obj" />
      </geometry>
      <material name="Orange" />
    </collision>
  
    <inertial>
      <origin xyz="0 0 0" rpy="0 0 0" />
      <mass value="1.0" />
      <inertia ixx="0.001" ixy="0.0" ixz="0.0" iyy="0.001" iyz="0.0" izz="0.001" />
    </inertial>
</link>
  <joint name="iiwa7_joint_6" type="revolute">
    <parent link="iiwa7_link_5" />
    <child link="iiwa7_link_6" />
    <origin rpy="1.57079632679 0 0" xyz="0 0.06070 0.19" />
    <axis xyz="0 0 1" />
    <limit effort="300" lower="-2.09439510239" upper="2.09439510239" velocity="10" />
    <safety_controller k_position="100" k_velocity="2" soft_lower_limit="-2.05948851735" soft_upper_limit="2.05948851735" />
    <dynamics damping="0.5" friction="0.025" />
  </joint>
  <link name="iiwa7_link_6">
    
    <visual>
      <origin rpy="0 0 0" xyz="0 0 0" />
      <geometry>
        <mesh filename="kuka_allegro_description/meshes/iiwa7/visual/link_6.obj" />
      </geometry>
      <material name="Orange" />
    </visual>
    <collision>
      <origin rpy="0 0 0" xyz="0 0 0" />
      <geometry>
        <mesh filename="kuka_allegro_description/meshes/iiwa7/collision/link_6.obj" />
      </geometry>
      <material name="Orange" />
    </collision>
  
    <inertial>
      <origin xyz="0 0 0" rpy="0 0 0" />
      <mass value="1.0" />
      <inertia ixx="0.001" ixy="0.0" ixz="0.0" iyy="0.001" iyz="0.0" izz="0.001" />
    </inertial>
</link>
  <joint name="iiwa7_joint_7" type="revolute">
    <parent link="iiwa7_link_6" />
    <child link="iiwa7_link_7" />
    <origin rpy="-1.57079632679 3.14159265359 0" xyz="0 0.081 0.06070" />
    <axis xyz="0 0 1" />
    <limit effort="300" lower="-3.05432619099" upper="3.05432619099" velocity="10" />
    <safety_controller k_position="100" k_velocity="2" soft_lower_limit="-3.01941960595" soft_upper_limit="3.01941960595" />
    <dynamics damping="5.5" friction="0.025" />
  </joint>
  <link name="iiwa7_link_7">
    
    <visual>
      <origin rpy="0 0 0" xyz="0 0 -0.0005" />
      <geometry>
        <mesh filename="kuka_allegro_description/meshes/iiwa7/visual/link_7.obj" />
      </geometry>
      <material name="Grey" />
    </visual>
    <collision>
      <origin rpy="0 0 0" xyz="0 0 -0.0005" />
      <geometry>
        <mesh filename="kuka_allegro_description/meshes/iiwa7/collision/link_7.obj" />
      </geometry>
      <material name="Grey" />
    </collision>
  
    <inertial>
      <origin xyz="0 0 0" rpy="0 0 0" />
      <mass value="1.0" />
      <inertia ixx="0.001" ixy="0.0" ixz="0.0" iyy="0.001" iyz="0.0" izz="0.001" />
    </inertial>
</link>
  <joint name="iiwa7_joint_ee" type="fixed">
    <parent link="iiwa7_link_7" />
    <child link="iiwa7_link_ee" />
    <origin rpy="0 0 0" xyz="0 0 0.071" />
    <dynamics damping="5.5" friction="0.025" />
  </joint>
  <link name="iiwa7_link_ee">
    
  
    <inertial>
      <origin xyz="0 0 0" rpy="0 0 0" />
      <mass value="1.0" />
      <inertia ixx="0.001" ixy="0.0" ixz="0.0" iyy="0.001" iyz="0.0" izz="0.001" />
    </inertial>
<visual><geometry><box size="0.01 0.01 0.01" /></geometry></visual></link>
  
  
  
  
  <gazebo reference="iiwa7_link_0">
    <material>Gazebo/Grey</material>
    <mu1>0.2</mu1>
    <mu2>0.2</mu2>
  </gazebo>
  
  <gazebo reference="iiwa7_link_1">
    <material>Gazebo/Orange</material>
    <mu1>0.2</mu1>
    <mu2>0.2</mu2>
  </gazebo>
  
  <gazebo reference="iiwa7_link_2">
    <material>Gazebo/Orange</material>
    <mu1>0.2</mu1>
    <mu2>0.2</mu2>
  </gazebo>
  
  <gazebo reference="iiwa7_link_3">
    <material>Gazebo/Orange</material>
    <mu1>0.2</mu1>
    <mu2>0.2</mu2>
  </gazebo>
  
  <gazebo reference="iiwa7_link_4">
    <material>Gazebo/Orange</material>
    <mu1>0.2</mu1>
    <mu2>0.2</mu2>
  </gazebo>
  
  <gazebo reference="iiwa7_link_5">
    <material>Gazebo/Orange</material>
    <mu1>0.2</mu1>
    <mu2>0.2</mu2>
  </gazebo>
  
  <gazebo reference="iiwa7_link_6">
    <material>Gazebo/Orange</material>
    <mu1>0.2</mu1>
    <mu2>0.2</mu2>
  </gazebo>
  
  <gazebo reference="iiwa7_link_7">
    <material>Gazebo/Grey</material>
    <mu1>0.2</mu1>
    <mu2>0.2</mu2>
  </gazebo>
  <transmission name="iiwa7_tran_1">
    <robotNamespace>/iiwa7</robotNamespace>
    <type>transmission_interface/SimpleTransmission</type>
    <joint name="iiwa7_joint_1">
      <hardwareInterface>PositionJointInterface</hardwareInterface>
    </joint>
    <actuator name="iiwa7_motor_1">
      <hardwareInterface>PositionJointInterface</hardwareInterface>
      <mechanicalReduction>1</mechanicalReduction>
    </actuator>
  </transmission>
  <transmission name="iiwa7_tran_2">
    <robotNamespace>/iiwa7</robotNamespace>
    <type>transmission_interface/SimpleTransmission</type>
    <joint name="iiwa7_joint_2">
      <hardwareInterface>PositionJointInterface</hardwareInterface>
    </joint>
    <actuator name="iiwa7_motor_2">
      <hardwareInterface>PositionJointInterface</hardwareInterface>
      <mechanicalReduction>1</mechanicalReduction>
    </actuator>
  </transmission>
  <transmission name="iiwa7_tran_3">
    <robotNamespace>/iiwa7</robotNamespace>
    <type>transmission_interface/SimpleTransmission</type>
    <joint name="iiwa7_joint_3">
      <hardwareInterface>PositionJointInterface</hardwareInterface>
    </joint>
    <actuator name="iiwa7_motor_3">
      <hardwareInterface>PositionJointInterface</hardwareInterface>
      <mechanicalReduction>1</mechanicalReduction>
    </actuator>
  </transmission>
  <transmission name="iiwa7_tran_4">
    <robotNamespace>/iiwa7</robotNamespace>
    <type>transmission_interface/SimpleTransmission</type>
    <joint name="iiwa7_joint_4">
      <hardwareInterface>PositionJointInterface</hardwareInterface>
    </joint>
    <actuator name="iiwa7_motor_4">
      <hardwareInterface>PositionJointInterface</hardwareInterface>
      <mechanicalReduction>1</mechanicalReduction>
    </actuator>
  </transmission>
  <transmission name="iiwa7_tran_5">
    <robotNamespace>/iiwa7</robotNamespace>
    <type>transmission_interface/SimpleTransmission</type>
    <joint name="iiwa7_joint_5">
      <hardwareInterface>PositionJointInterface</hardwareInterface>
    </joint>
    <actuator name="iiwa7_motor_5">
      <hardwareInterface>PositionJointInterface</hardwareInterface>
      <mechanicalReduction>1</mechanicalReduction>
    </actuator>
  </transmission>
  <transmission name="iiwa7_tran_6">
    <robotNamespace>/iiwa7</robotNamespace>
    <type>transmission_interface/SimpleTransmission</type>
    <joint name="iiwa7_joint_6">
      <hardwareInterface>PositionJointInterface</hardwareInterface>
    </joint>
    <actuator name="iiwa7_motor_6">
      <hardwareInterface>PositionJointInterface</hardwareInterface>
      <mechanicalReduction>1</mechanicalReduction>
    </actuator>
  </transmission>
  <transmission name="iiwa7_tran_7">
    <robotNamespace>/iiwa7</robotNamespace>
    <type>transmission_interface/SimpleTransmission</type>
    <joint name="iiwa7_joint_7">
      <hardwareInterface>PositionJointInterface</hardwareInterface>
    </joint>
    <actuator name="iiwa7_motor_7">
      <hardwareInterface>PositionJointInterface</hardwareInterface>
      <mechanicalReduction>1</mechanicalReduction>
    </actuator>
  </transmission>
  
  
  
  
  
  
  

  <link name="forearm">
    
    <visual>
      <origin rpy="0 0 0" xyz="0 0 0" />
      <geometry name="shadow_forearm_geom">
        <mesh filename="meshes/forearm.obj" />
      </geometry>
      <material name="Grey" />
    </visual>
    <collision>
      <origin rpy="0 0 0" xyz="0 0 0.09" />
      <geometry name="shadow_forearm_collision">
        <cylinder length="0.180" radius="0.06" />
      </geometry>
    </collision>
  
    <inertial>
      <origin xyz="0 0 0" rpy="0 0 0" />
      <mass value="1.0" />
      <inertia ixx="0.001" ixy="0.0" ixz="0.0" iyy="0.001" iyz="0.0" izz="0.001" />
    </inertial>
</link>
  <link name="wrist">
    
    <visual>
      <origin rpy="0 0 0" xyz="0 0 0" />
      <geometry name="wrist_visual">
        <mesh filename="meshes/wrist.obj" />
      </geometry>
      <material name="LightGrey" />
    </visual>
    <collision>
      <origin rpy="0 0 0" xyz="0 0 0" />
      <geometry name="wrist_collision_geom">
        <box size="0.02 0.02 0.02" />
      </geometry>
    </collision>
  
    <inertial>
      <origin xyz="0 0 0" rpy="0 0 0" />
      <mass value="1.0" />
      <inertia ixx="0.001" ixy="0.0" ixz="0.0" iyy="0.001" iyz="0.0" izz="0.001" />
    </inertial>
</link>
  <joint name="WRJ2" type="revolute">
    <parent link="forearm" />
    <child link="wrist" />

    <origin rpy="0 0 0" xyz="0 -0.010 0.213" />
    <axis xyz="0 1 0" />
    <limit effort="5" lower="-0.52359877559829882" upper="0.17453292519943295" velocity="1.0" />
    <dynamics damping="100.5" />
  </joint>
  <link name="palm">
    
    <visual>
      <origin rpy="0 0 0" xyz="0 0 0" />
      <geometry name="palm_visual">
        <mesh filename="meshes/palm.obj" />
      </geometry>
      <material name="Grey" />
    </visual>
    <collision>
      <origin rpy="0 0 0" xyz="0.005 0 0.035" />
      <geometry name="palm_collision_geom">
        <box size="0.05 0.02 0.07" />
      </geometry>
    </collision>
  
    <inertial>
      <origin xyz="0 0 0" rpy="0 0 0" />
      <mass value="1.0" />
      <inertia ixx="0.001" ixy="0.0" ixz="0.0" iyy="0.001" iyz="0.0" izz="0.001" />
    </inertial>
</link>
  <joint name="WRJ1" type="revolute">
    <parent link="wrist" />
    <child link="palm" />
    <origin rpy="0 0 0" xyz="0 0 0.034" />
    <axis xyz="1 0 0" />
    <limit effort="5" lower="-0.78539816339744828" upper="0.6108652381980153" velocity="1.0" />
    <dynamics damping="100.5" />
  </joint>
  <link name="ffknuckle">
    
    <visual>
      <origin rpy="0 0 0" xyz="0 0 0.0005" />
      <geometry name="knuckle_visual">
        <mesh filename="meshes/knuckle.obj" />
      </geometry>
      <material name="LightGrey" />
    </visual>
    <collision>
      <origin rpy="0 0 0" xyz="0 0 0" />
      <geometry name="knuckle_collision_geom">
        <box size="0.005 0.005 0.005" />
      </geometry>
    </collision>
  
    <inertial>
      <origin xyz="0 0 0" rpy="0 0 0" />
      <mass value="1.0" />
      <inertia ixx="0.001" ixy="0.0" ixz="0.0" iyy="0.001" iyz="0.0" izz="0.001" />
    </inertial>
</link>
  <joint name="FFJ4" type="revolute">
    <parent link="palm" />
    <child link="ffknuckle" />

    <origin rpy="0 0 0" xyz="0.033 0 0.095" />
    <axis xyz="0 -1 0" />
    <limit effort="100" lower="-0.43633231299858238" upper="0.43633231299858238" velocity="1.0" />
    <dynamics damping="50.5" />
  </joint>
  <link name="ffproximal">
    
    <visual>
      <origin rpy="0 0 0" xyz="0 0 0" />
      <geometry name="proximal_visual">
        <mesh filename="meshes/F3.obj" />
      </geometry>
      <material name="Grey" />
    </visual>
    <collision>
      <origin rpy="0 0 0 " xyz="0 0 0.025" />
      <geometry name="proximal_collision_geom">
        <box size="0.008 0.008 0.04" />
      </geometry>
    </collision>
  
    <inertial>
      <origin xyz="0 0 0" rpy="0 0 0" />
      <mass value="1.0" />
      <inertia ixx="0.001" ixy="0.0" ixz="0.0" iyy="0.001" iyz="0.0" izz="0.001" />
    </inertial>
</link>
  <joint name="FFJ3" type="revolute">
    <parent link="ffknuckle" />
    <child link="ffproximal" />
    <origin rpy="0 0 0" xyz="0 0 0" />
    <axis xyz="1 0 0" />
    <limit effort="100" lower="0" upper="1.57079632679" velocity="1.0" />
    <dynamics damping="50.5" />
  </joint>
  <link name="ffmiddle">
    
    <visual>
      <origin rpy="0 0 0" xyz="0 0 0" />
      <geometry name="middle_visual">
        <mesh filename="meshes/F2.obj" />
      </geometry>
      <material name="Grey" />
    </visual>
    <collision>
      <origin rpy="0 0 0" xyz="0 0 0.0125" />
      <geometry name="middle_collision_geom">
        <box size="0.008 0.008 0.015" />
      </geometry>
    </collision>
  
    <inertial>
      <origin xyz="0 0 0" rpy="0 0 0" />
      <mass value="1.0" />
      <inertia ixx="0.001" ixy="0.0" ixz="0.0" iyy="0.001" iyz="0.0" izz="0.001" />
    </inertial>
</link>
  <joint name="FFJ2" type="revolute">
    <parent link="ffproximal" />
    <child link="ffmiddle" />
    <origin rpy="0 0 0" xyz="0 0 0.045" />
    <axis xyz="1 0 0" />
    <limit effort="100" lower="0" upper="1.57079632679" velocity="1.0" />
    <dynamics damping="50.5" />
  </joint>
  <link name="ffdistal">
    
    <visual>
      <origin rpy="0 0 0" xyz="0 0 0" />
      <geometry name="distal_visual">
        <mesh filename="meshes/F1.obj" />
      </geometry>
      <material name="Grey" />
    </visual>

    <collision>
      <origin rpy="0 0 0" xyz="0 0 0" />
      <geometry name="distal_collision_geom">
        <mesh filename="meshes/F1.obj" />
      </geometry>
    </collision>
  
    <inertial>
      <origin xyz="0 0 0" rpy="0 0 0" />
      <mass value="1.0" />
      <inertia ixx="0.001" ixy="0.0" ixz="0.0" iyy="0.001" iyz="0.0" izz="0.001" />
    </inertial>
</link>
  <joint name="FFJ1" type="revolute">
    <parent link="ffmiddle" />
    <child link="ffdistal" />
    <origin rpy="0 0 0" xyz="0 0 0.025" />
    <axis xyz="1 0 0" />
    <limit effort="100" lower="0" upper="1.57079632679" velocity="1.0" />
    <dynamics damping="50.5" />
  </joint>
  <link name="mfknuckle">
    
    <visual>
      <origin rpy="0 0 0" xyz="0 0 0.0005" />
      <geometry name="knuckle_visual">
        <mesh filename="meshes/knuckle.obj" />
      </geometry>
      <material name="LightGrey" />
    </visual>
    <collision>
      <origin rpy="0 0 0" xyz="0 0 0" />
      <geometry name="knuckle_collision_geom">
        <box size="0.005 0.005 0.005" />
      </geometry>
    </collision>
  
    <inertial>
      <origin xyz="0 0 0" rpy="0 0 0" />
      <mass value="1.0" />
      <inertia ixx="0.001" ixy="0.0" ixz="0.0" iyy="0.001" iyz="0.0" izz="0.001" />
    </inertial>
</link>
  <joint name="MFJ4" type="revolute">
    <parent link="palm" />
    <child link="mfknuckle" />

    <origin rpy="0 0 0" xyz="0.011 0 0.099" />
    <axis xyz="0 -1 0" />
    <limit effort="100" lower="-0.43633231299858238" upper="0.43633231299858238" velocity="1.0" />
    <dynamics damping="50.5" />
  </joint>
  <link name="mfproximal">
    
    <visual>
      <origin rpy="0 0 0" xyz="0 0 0" />
      <geometry name="proximal_visual">
        <mesh filename="meshes/F3.obj" />
      </geometry>
      <material name="Grey" />
    </visual>
    <collision>
      <origin rpy="0 0 0 " xyz="0 0 0.025" />
      <geometry name="proximal_collision_geom">
        <box size="0.008 0.008 0.04" />
      </geometry>
    </collision>
  
    <inertial>
      <origin xyz="0 0 0" rpy="0 0 0" />
      <mass value="1.0" />
      <inertia ixx="0.001" ixy="0.0" ixz="0.0" iyy="0.001" iyz="0.0" izz="0.001" />
    </inertial>
</link>
  <joint name="MFJ3" type="revolute">
    <parent link="mfknuckle" />
    <child link="mfproximal" />
    <origin rpy="0 0 0" xyz="0 0 0" />
    <axis xyz="1 0 0" />
    <limit effort="100" lower="0" upper="1.57079632679" velocity="1.0" />
    <dynamics damping="50.5" />
  </joint>
  <link name="mfmiddle">
    
    <visual>
      <origin rpy="0 0 0" xyz="0 0 0" />
      <geometry name="middle_visual">
        <mesh filename="meshes/F2.obj" />
      </geometry>
      <material name="Grey" />
    </visual>
    <collision>
      <origin rpy="0 0 0" xyz="0 0 0.0125" />
      <geometry name="middle_collision_geom">
        <box size="0.008 0.008 0.015" />
      </geometry>
    </collision>
  
    <inertial>
      <origin xyz="0 0 0" rpy="0 0 0" />
      <mass value="1.0" />
      <inertia ixx="0.001" ixy="0.0" ixz="0.0" iyy="0.001" iyz="0.0" izz="0.001" />
    </inertial>
</link>
  <joint name="MFJ2" type="revolute">
    <parent link="mfproximal" />
    <child link="mfmiddle" />
    <origin rpy="0 0 0" xyz="0 0 0.045" />
    <axis xyz="1 0 0" />
    <limit effort="100" lower="0" upper="1.57079632679" velocity="1.0" />
    <dynamics damping="50.5" />
  </joint>
  <link name="mfdistal">
    
    <visual>
      <origin rpy="0 0 0" xyz="0 0 0" />
      <geometry name="distal_visual">
        <mesh filename="meshes/F1.obj" />
      </geometry>
      <material name="Grey" />
    </visual>

    <collision>
      <origin rpy="0 0 0" xyz="0 0 0" />
      <geometry name="distal_collision_geom">
        <mesh filename="meshes/F1.obj" />
      </geometry>
    </collision>
  
    <inertial>
      <origin xyz="0 0 0" rpy="0 0 0" />
      <mass value="1.0" />
      <inertia ixx="0.001" ixy="0.0" ixz="0.0" iyy="0.001" iyz="0.0" izz="0.001" />
    </inertial>
</link>
  <joint name="MFJ1" type="revolute">
    <parent link="mfmiddle" />
    <child link="mfdistal" />
    <origin rpy="0 0 0" xyz="0 0 0.025" />
    <axis xyz="1 0 0" />
    <limit effort="100" lower="0" upper="1.57079632679" velocity="1.0" />
    <dynamics damping="50.5" />
  </joint>
  <link name="rfknuckle">
    
    <visual>
      <origin rpy="0 0 0" xyz="0 0 0.0005" />
      <geometry name="knuckle_visual">
        <mesh filename="meshes/knuckle.obj" />
      </geometry>
      <material name="LightGrey" />
    </visual>
    <collision>
      <origin rpy="0 0 0" xyz="0 0 0" />
      <geometry name="knuckle_collision_geom">
        <box size="0.005 0.005 0.005" />
      </geometry>
    </collision>
  
    <inertial>
      <origin xyz="0 0 0" rpy="0 0 0" />
      <mass value="1.0" />
      <inertia ixx="0.001" ixy="0.0" ixz="0.0" iyy="0.001" iyz="0.0" izz="0.001" />
    </inertial>
</link>
  <joint name="RFJ4" type="revolute">
    <parent link="palm" />
    <child link="rfknuckle" />

    <origin rpy="0 0 0" xyz="-0.011 0 0.095" />
    <axis xyz="0 1 0" />
    <limit effort="100" lower="-0.43633231299858238" upper="0.43633231299858238" velocity="1.0" />
    <dynamics damping="50.5" />
  </joint>
  <link name="rfproximal">
    
    <visual>
      <origin rpy="0 0 0" xyz="0 0 0" />
      <geometry name="proximal_visual">
        <mesh filename="meshes/F3.obj" />
      </geometry>
      <material name="Grey" />
    </visual>
    <collision>
      <origin rpy="0 0 0 " xyz="0 0 0.025" />
      <geometry name="proximal_collision_geom">
        <box size="0.008 0.008 0.04" />
      </geometry>
    </collision>
  
    <inertial>
      <origin xyz="0 0 0" rpy="0 0 0" />
      <mass value="1.0" />
      <inertia ixx="0.001" ixy="0.0" ixz="0.0" iyy="0.001" iyz="0.0" izz="0.001" />
    </inertial>
</link>
  <joint name="RFJ3" type="revolute">
    <parent link="rfknuckle" />
    <child link="rfproximal" />
    <origin rpy="0 0 0" xyz="0 0 0" />
    <axis xyz="1 0 0" />
    <limit effort="100" lower="0" upper="1.57079632679" velocity="1.0" />
    <dynamics damping="50.5" />
  </joint>
  <link name="rfmiddle">
    
    <visual>
      <origin rpy="0 0 0" xyz="0 0 0" />
      <geometry name="middle_visual">
        <mesh filename="meshes/F2.obj" />
      </geometry>
      <material name="Grey" />
    </visual>
    <collision>
      <origin rpy="0 0 0" xyz="0 0 0.0125" />
      <geometry name="middle_collision_geom">
        <box size="0.008 0.008 0.015" />
      </geometry>
    </collision>
  
    <inertial>
      <origin xyz="0 0 0" rpy="0 0 0" />
      <mass value="1.0" />
      <inertia ixx="0.001" ixy="0.0" ixz="0.0" iyy="0.001" iyz="0.0" izz="0.001" />
    </inertial>
</link>
  <joint name="RFJ2" type="revolute">
    <parent link="rfproximal" />
    <child link="rfmiddle" />
    <origin rpy="0 0 0" xyz="0 0 0.045" />
    <axis xyz="1 0 0" />
    <limit effort="100" lower="0" upper="1.57079632679" velocity="1.0" />
    <dynamics damping="50.5" />
  </joint>
  <link name="rfdistal">
    
    <visual>
      <origin rpy="0 0 0" xyz="0 0 0" />
      <geometry name="distal_visual">
        <mesh filename="meshes/F1.obj" />
      </geometry>
      <material name="Grey" />
    </visual>

    <collision>
      <origin rpy="0 0 0" xyz="0 0 0" />
      <geometry name="distal_collision_geom">
        <mesh filename="meshes/F1.obj" />
      </geometry>
    </collision>
  
    <inertial>
      <origin xyz="0 0 0" rpy="0 0 0" />
      <mass value="1.0" />
      <inertia ixx="0.001" ixy="0.0" ixz="0.0" iyy="0.001" iyz="0.0" izz="0.001" />
    </inertial>
</link>
  <joint name="RFJ1" type="revolute">
    <parent link="rfmiddle" />
    <child link="rfdistal" />
    <origin rpy="0 0 0" xyz="0 0 0.025" />
    <axis xyz="1 0 0" />
    <limit effort="100" lower="0" upper="1.57079632679" velocity="1.0" />
    <dynamics damping="50.5" />
  </joint>
  <link name="lfmetacarpal">
    
    <visual>
      <origin rpy="0 0 0" xyz="0 0 0" />
      <geometry name="lfmetacarpal_visual">
        <mesh filename="meshes/lfmetacarpal.obj" />
      </geometry>
      <material name="Grey" />
    </visual>
    <collision>
      <origin rpy="0 0 0" xyz="0 0 0.04" />
      <geometry name="lfmetacarpal_collision_geom">
        <box size="0.008 0.008 0.03" />
      </geometry>
    </collision>
  
    <inertial>
      <origin xyz="0 0 0" rpy="0 0 0" />
      <mass value="1.0" />
      <inertia ixx="0.001" ixy="0.0" ixz="0.0" iyy="0.001" iyz="0.0" izz="0.001" />
    </inertial>
</link>
  <joint name="LFJ5" type="revolute">
    <parent link="palm" />
    <child link="lfmetacarpal" />
    <origin rpy="0 0 0" xyz="-0.033 0 0.02071" />
    <axis xyz="0.573576436 0 0.819152044" />
    <limit effort="100" lower="0" upper="0.69813170079773179" velocity="1.0" />
    <dynamics damping="50.5" />
  </joint>
  <link name="lfknuckle">
    
    <visual>
      <origin rpy="0 0 0" xyz="0 0 0" />
      <geometry name="knuckle_visual">
        <mesh filename="meshes/knuckle.obj" />
      </geometry>
      <material name="LightGrey" />
    </visual>
    <collision>
      <origin rpy="0 0 0" xyz="0 0 0" />
      <geometry name="knuckle_collision_geom">
        <box size="0.005 0.005 0.005" />
      </geometry>
    </collision>
  
    <inertial>
      <origin xyz="0 0 0" rpy="0 0 0" />
      <mass value="1.0" />
      <inertia ixx="0.001" ixy="0.0" ixz="0.0" iyy="0.001" iyz="0.0" izz="0.001" />
    </inertial>
</link>
  <joint name="LFJ4" type="revolute">
    <parent link="lfmetacarpal" />
    <child link="lfknuckle" />
    <origin rpy="0 0 0" xyz="0 0 0.06579" />
    <axis xyz="0 1 0" />
    <limit effort="100" lower="-0.43633231299858238" upper="0.43633231299858238" velocity="1.0" />
    <dynamics damping="50.5" />
  </joint>
  <link name="lfproximal">
    
    <visual>
      <origin rpy="0 0 0" xyz="0 0 0" />
      <geometry name="proximal_visual">
        <mesh filename="meshes/F3.obj" />
      </geometry>
      <material name="Grey" />
    </visual>
    <collision>
      <origin rpy="0 0 0 " xyz="0 0 0.025" />
      <geometry name="proximal_collision_geom">
        <box size="0.008 0.008 0.04" />
      </geometry>
    </collision>
  
    <inertial>
      <origin xyz="0 0 0" rpy="0 0 0" />
      <mass value="1.0" />
      <inertia ixx="0.001" ixy="0.0" ixz="0.0" iyy="0.001" iyz="0.0" izz="0.001" />
    </inertial>
</link>
  <joint name="LFJ3" type="revolute">
    <parent link="lfknuckle" />
    <child link="lfproximal" />
    <origin rpy="0 0 0" xyz="0 0 0" />
    <axis xyz="1 0 0" />
    <limit effort="100" lower="0" upper="1.57079632679" velocity="1.0" />
    <dynamics damping="50.5" />
  </joint>
  <link name="lfmiddle">
    
    <visual>
      <origin rpy="0 0 0" xyz="0 0 0" />
      <geometry name="middle_visual">
        <mesh filename="meshes/F2.obj" />
      </geometry>
      <material name="Grey" />
    </visual>
    <collision>
      <origin rpy="0 0 0" xyz="0 0 0.0125" />
      <geometry name="middle_collision_geom">
        <box size="0.008 0.008 0.015" />
      </geometry>
    </collision>
  
    <inertial>
      <origin xyz="0 0 0" rpy="0 0 0" />
      <mass value="1.0" />
      <inertia ixx="0.001" ixy="0.0" ixz="0.0" iyy="0.001" iyz="0.0" izz="0.001" />
    </inertial>
</link>
  <joint name="LFJ2" type="revolute">
    <parent link="lfproximal" />
    <child link="lfmiddle" />
    <origin rpy="0 0 0" xyz="0 0 0.045" />
    <axis xyz="1 0 0" />
    <limit effort="100" lower="0" upper="1.57079632679" velocity="1.0" />
    <dynamics damping="50.5" />
  </joint>
  <link name="lfdistal">
    
    <visual>
      <origin rpy="0 0 0" xyz="0 0 0" />
      <geometry name="distal_visual">
        <mesh filename="meshes/F1.obj" />
      </geometry>
      <material name="Grey" />
    </visual>

    <collision>
      <origin rpy="0 0 0" xyz="0 0 0" />
      <geometry name="distal_collision_geom">
        <mesh filename="meshes/F1.obj" />
      </geometry>
    </collision>
  
    <inertial>
      <origin xyz="0 0 0" rpy="0 0 0" />
      <mass value="1.0" />
      <inertia ixx="0.001" ixy="0.0" ixz="0.0" iyy="0.001" iyz="0.0" izz="0.001" />
    </inertial>
</link>
  <joint name="LFJ1" type="revolute">
    <parent link="lfmiddle" />
    <child link="lfdistal" />
    <origin rpy="0 0 0" xyz="0 0 0.025" />
    <axis xyz="1 0 0" />
    <limit effort="100" lower="0" upper="1.57079632679" velocity="1.0" />
    <dynamics damping="50.5" />
  </joint>
  <link name="thbase">
    
    <visual>
      <origin rpy="0 0 0" xyz="0 0 0" />
      <geometry name="thbase_visual">
        <box size="0.001 0.001 0.001" />
      </geometry>
      <material name="shadow_thbase_material">
        <color rgba="0.5 0.5 0.5 1.0" />
      </material>
    </visual>
    <collision>
      <origin rpy="0 0 0 " xyz="0 0 0" />
      <geometry name="thbase_collision_geom">
        <box size="0.001 0.001 0.001" />
      </geometry>
    </collision>
  
    <inertial>
      <origin xyz="0 0 0" rpy="0 0 0" />
      <mass value="1.0" />
      <inertia ixx="0.001" ixy="0.0" ixz="0.0" iyy="0.001" iyz="0.0" izz="0.001" />
    </inertial>
</link>
  <joint name="THJ5" type="revolute">
    <parent link="palm" />
    <child link="thbase" />
    <origin rpy="0 0.785398163397 0" xyz="0.034 -0.0085 0.029" />
    <axis xyz="0 0 -1.0" />
    <limit effort="100" lower="-1.047" upper="1.047" velocity="1.0" />
    <dynamics damping="50.5" />
  </joint>
  <link name="thproximal">
    
    <visual>
      <origin rpy="0 0 0" xyz="0 0 0" />
      <geometry name="thproximal_visual">
        <mesh filename="meshes/TH3_z.obj" />
      </geometry>
      <material name="shadow_thproximal_material">
        <color rgba="0.2 0.2 0.2 1.0" />
      </material>
    </visual>
    <collision>
      <origin rpy="0 0 0" xyz="0 0 0.019" />
      <geometry name="thproximal_collision_geom">
        <box size="0.008 0.008 0.020" />
      </geometry>
    </collision>
  
    <inertial>
      <origin xyz="0 0 0" rpy="0 0 0" />
      <mass value="1.0" />
      <inertia ixx="0.001" ixy="0.0" ixz="0.0" iyy="0.001" iyz="0.0" izz="0.001" />
    </inertial>
</link>
  <joint name="THJ4" type="revolute">
    <parent link="thbase" />
    <child link="thproximal" />
    <origin rpy="0 0 0" xyz="0 0 0" />
    <axis xyz="1.0 0 0" />
    <limit effort="100" lower="0" upper="1.309" velocity="1.0" />
    <dynamics damping="50.5" />
  </joint>
  <link name="thhub">
    
    <visual>
      <origin rpy="0 0 0" xyz="0 0 0" />
      <geometry name="thhub_visual">
        <box size="0.001 0.001 0.001" />
      </geometry>
      <material name="shadow_thhub_material">
        <color rgba="0.7 0.7 0.7 1.0" />
      </material>
    </visual>
    <collision>
      <origin rpy="0 0 0 " xyz="0 0 0" />
      <geometry name="thhub_collision_geom">
        <box size="0.001 0.001 0.001" />
      </geometry>
    </collision>
  
    <inertial>
      <origin xyz="0 0 0" rpy="0 0 0" />
      <mass value="1.0" />
      <inertia ixx="0.001" ixy="0.0" ixz="0.0" iyy="0.001" iyz="0.0" izz="0.001" />
    </inertial>
</link>
  <joint name="THJ3" type="revolute">
    <parent link="thproximal" />
    <child link="thhub" />
    <origin rpy="0 0 0" xyz="0 0 0.038" />
    <axis xyz="1 0 0" />
    <limit effort="100" lower="-0.2618" upper="0.2618" velocity="1.0" />
    <dynamics damping="50.5" />
  </joint>
  <link name="thmiddle">
    
    <visual>
      <origin rpy="0 0 0" xyz="0 0 0" />
      <geometry name="thmiddle_visual">
        <mesh filename="meshes/TH2_z.obj" />
      </geometry>
      <material name="shadow_thmiddle_material">
        <color rgba="0.2 0.2 0.2 1.0" />
      </material>
    </visual>
    <collision>
      <origin rpy="0 0 0 " xyz="0 0 0.016" />
      <geometry name="thmiddle_collision_geom">
        <box size="0.008 0.008 0.015" />
      </geometry>
    </collision>
  
    <inertial>
      <origin xyz="0 0 0" rpy="0 0 0" />
      <mass value="1.0" />
      <inertia ixx="0.001" ixy="0.0" ixz="0.0" iyy="0.001" iyz="0.0" izz="0.001" />
    </inertial>
</link>
  <joint name="THJ2" type="revolute">
    <parent link="thhub" />
    <child link="thmiddle" />
    <origin rpy="0 0 0" xyz="0 0 0" />
    <axis xyz="0 -1 0" />
    <limit effort="100" lower="-0.5237" upper="0.5237" velocity="1.0" />
    <dynamics damping="50.5" />
  </joint>
  <link name="thdistal">
    
    <visual>
      <origin rpy="0 0 0" xyz="0 0.002 0.0025" />
      <geometry name="thdistal_visual">
        <mesh filename="meshes/F1.obj" />
      </geometry>
      <material name="shadow_thmiddle_material">
        <color rgba="0.2 0.2 0.2 1.0" />
      </material>
    </visual>
    <collision>
      <origin rpy="0 0 0 " xyz="0 0.002 0.0025" />
      <geometry name="thmiddle_collision_geom">
        <mesh filename="meshes/F1.obj" />
      </geometry>
    </collision>
  
    <inertial>
      <origin xyz="0 0 0" rpy="0 0 0" />
      <mass value="1.0" />
      <inertia ixx="0.001" ixy="0.0" ixz="0.0" iyy="0.001" iyz="0.0" izz="0.001" />
    </inertial>
</link>
  <joint name="THJ1" type="revolute">
    <parent link="thmiddle" />
    <child link="thdistal" />
    <origin rpy="0 0 -1.570796327" xyz="0 0 0.032" />
    <axis xyz="1 0 0" />
    <limit effort="100" lower="0" upper="1.571" velocity="1.0" />
    <dynamics damping="50.5" />
  </joint>
  

  
  
  <joint name="iiwa7_allegro" type="fixed">
    <parent link="iiwa7_link_ee" />
    <child link="forearm" />
    <origin rpy="0 0 0" xyz="0 0 0" />
  </joint>
  
</robot>