<?xml version="1.0"?>
<robot name="shadowhand">
  <link name="virtual_root"><inertial>
      <origin xyz="0 0 0" rpy="0 0 0" />
      <mass value="1.0" />
      <inertia ixx="0.001" ixy="0.0" ixz="0.0" iyy="0.001" iyz="0.0" izz="0.001" />
    </inertial><visual><geometry><box size="0.01 0.01 0.01" /></geometry></visual></link><joint name="dummy_root_link_to_virtual_root" type="fixed"><parent link="virtual_root" /><child link="dummy_root_link" /></joint><joint name="world_to_virtual_root" type="fixed"><parent link="virtual_root" /><child link="world" /></joint><link name="dummy_root_link"><inertial>
      <origin xyz="0 0 0" rpy="0 0 0" />
      <mass value="1.0" />
      <inertia ixx="0.001" ixy="0.0" ixz="0.0" iyy="0.001" iyz="0.0" izz="0.001" />
    </inertial><visual><geometry><box size="0.01 0.01 0.01" /></geometry></visual></link><joint name="fix_palm_center_to_dummy" type="fixed"><parent link="dummy_root_link" /><child link="palm_center" /></joint><joint name="fix_palm_to_dummy" type="fixed"><parent link="dummy_root_link" /><child link="palm" /></joint><joint name="fix_link_7.0_tip_to_dummy" type="fixed"><parent link="dummy_root_link" /><child link="link_7.0_tip" /></joint><joint name="fix_link_3.0_tip_to_dummy" type="fixed"><parent link="dummy_root_link" /><child link="link_3.0_tip" /></joint><joint name="fix_link_15.0_tip_to_dummy" type="fixed"><parent link="dummy_root_link" /><child link="link_15.0_tip" /></joint><joint name="fix_link_11.0_tip_to_dummy" type="fixed"><parent link="dummy_root_link" /><child link="link_11.0_tip" /></joint><material name="Blue">
    <color rgba="0.0 0.0 0.8 1.0" />
  </material>
  <material name="Green">
    <color rgba="0.0 0.8 0.0 1.0" />
  </material>
  <material name="Grey">
    <color rgba="0.2 0.2 0.2 1.0" />
  </material>
  <material name="LightGrey">
    <color rgba="0.6 0.6 0.6 1.0" />
  </material>
  <material name="Red">
    <color rgba="0.8 0.0 0.0 1.0" />
  </material>
  <material name="White">
    <color rgba="1.0 1.0 1.0 1.0" />
  </material>

  <link name="world"><inertial>
      <origin xyz="0 0 0" rpy="0 0 0" />
      <mass value="1.0" />
      <inertia ixx="0.001" ixy="0.0" ixz="0.0" iyy="0.001" iyz="0.0" izz="0.001" />
    </inertial><visual><geometry><box size="0.01 0.01 0.01" /></geometry></visual></link>
  <joint name="robot_base_joint" type="fixed">
    <origin rpy="0.0 0.0 3.14159265" xyz="0 0 0" />
    <parent link="world" />
    <child link="base_link" />
  </joint>
  <link name="base_link">
    <visual>
      <geometry>
        <mesh filename="package://ur_e_description/meshes/ur10e/visual/base.dae" />
      </geometry>

      <origin rpy="1.571 0 0" xyz="0.0 0.0 0.0" />
    </visual>
    <collision>
      <geometry>
        <mesh filename="package://ur_e_description/meshes/ur10e/collision/base.stl" />
      </geometry>
    </collision>
    
  
    <inertial>
      <origin xyz="0 0 0" rpy="0 0 0" />
      <mass value="1.0" />
      <inertia ixx="0.001" ixy="0.0" ixz="0.0" iyy="0.001" iyz="0.0" izz="0.001" />
    </inertial>
</link>
  <joint name="shoulder_pan_joint" type="revolute">
    <parent link="base_link" />
    <child link="shoulder_link" />
    <origin rpy="0.0 0.0 0.0" xyz="0.0 0.0 0.181" />
    <axis xyz="0 0 1" />
    <limit effort="330.0" lower="-6.2831853" upper="6.2831853" velocity="3.14" />
    <dynamics damping="0.0" friction="0.0" />
  </joint>
  <link name="shoulder_link">
    <visual>
      <geometry>
        <mesh filename="package://ur_e_description/meshes/ur10e/visual/shoulder.dae" />
      </geometry>

      <origin rpy="1.571 0 0" xyz="0.0 0.0 0.0" />
    </visual>
    <collision>
      <geometry>
        <mesh filename="package://ur_e_description/meshes/ur10e/collision/shoulder.stl" />
      </geometry>
    </collision>
    
  
    <inertial>
      <origin xyz="0 0 0" rpy="0 0 0" />
      <mass value="1.0" />
      <inertia ixx="0.001" ixy="0.0" ixz="0.0" iyy="0.001" iyz="0.0" izz="0.001" />
    </inertial>
</link>
  <joint name="shoulder_lift_joint" type="revolute">
    <parent link="shoulder_link" />
    <child link="upper_arm_link" />
    <origin rpy="0.0 1.570796325 0.0" xyz="0.0 0.176 0.0" />
    <axis xyz="0 1 0" />
    <limit effort="330.0" lower="-6.2831853" upper="6.2831853" velocity="3.14" />
    <dynamics damping="0.0" friction="0.0" />
  </joint>
  <link name="upper_arm_link">
    <visual>
      <geometry>
        <mesh filename="package://ur_e_description/meshes/ur10e/visual/upperarm.dae" />
      </geometry>

      <origin rpy="1.571 0 0" xyz="0.0 0.0 0.0" />
    </visual>
    <collision>
      <geometry>
        <mesh filename="package://ur_e_description/meshes/ur10e/collision/upperarm.stl" />
      </geometry>
    </collision>
    
  
    <inertial>
      <origin xyz="0 0 0" rpy="0 0 0" />
      <mass value="1.0" />
      <inertia ixx="0.001" ixy="0.0" ixz="0.0" iyy="0.001" iyz="0.0" izz="0.001" />
    </inertial>
</link>
  <joint name="elbow_joint" type="revolute">
    <parent link="upper_arm_link" />
    <child link="forearm_link" />
    <origin rpy="0.0 0.0 0.0" xyz="0.0 -0.137 0.613" />
    <axis xyz="0 1 0" />
    <limit effort="150.0" lower="-6.2831853" upper="6.2831853" velocity="3.14" />
    <dynamics damping="0.0" friction="0.0" />
  </joint>
  <link name="forearm_link">
    <visual>
      <geometry>
        <mesh filename="package://ur_e_description/meshes/ur10e/visual/forearm.dae" />
      </geometry>

      <origin rpy="1.571 0 0" xyz="0.0 0.0 0.0" />
    </visual>
    <collision>
      <geometry>
        <mesh filename="package://ur_e_description/meshes/ur10e/collision/forearm.stl" />
      </geometry>
    </collision>
    
  
    <inertial>
      <origin xyz="0 0 0" rpy="0 0 0" />
      <mass value="1.0" />
      <inertia ixx="0.001" ixy="0.0" ixz="0.0" iyy="0.001" iyz="0.0" izz="0.001" />
    </inertial>
</link>
  <joint name="wrist_1_joint" type="revolute">
    <parent link="forearm_link" />
    <child link="wrist_1_link" />
    <origin rpy="0.0 1.570796325 0.0" xyz="0.0 0.0 0.571" />
    <axis xyz="0 1 0" />
    <limit effort="54.0" lower="-6.2831853" upper="6.2831853" velocity="6.28" />
    <dynamics damping="0.0" friction="0.0" />
  </joint>
  <link name="wrist_1_link">
    <visual>
      <geometry>
        <mesh filename="package://ur_e_description/meshes/ur10e/visual/wrist1.dae" />
      </geometry>

      <origin rpy="1.571 0 0" xyz="0.0 0.0 0.0" />
    </visual>
    <collision>
      <geometry>
        <mesh filename="package://ur_e_description/meshes/ur10e/collision/wrist1.stl" />
      </geometry>
    </collision>
    
  
    <inertial>
      <origin xyz="0 0 0" rpy="0 0 0" />
      <mass value="1.0" />
      <inertia ixx="0.001" ixy="0.0" ixz="0.0" iyy="0.001" iyz="0.0" izz="0.001" />
    </inertial>
</link>
  <joint name="wrist_2_joint" type="revolute">
    <parent link="wrist_1_link" />
    <child link="wrist_2_link" />
    <origin rpy="0.0 0.0 0.0" xyz="0.0 0.135 0.0" />
    <axis xyz="0 0 1" />
    <limit effort="54.0" lower="-6.2831853" upper="6.2831853" velocity="6.28" />
    <dynamics damping="0.0" friction="0.0" />
  </joint>
  <link name="wrist_2_link">
    <visual>
      <geometry>
        <mesh filename="package://ur_e_description/meshes/ur10e/visual/wrist2.dae" />
      </geometry>
      <origin rpy="1.571 0 0" xyz="0.0 0.0 0.0" />
    </visual>
    <collision>
      <geometry>
        <mesh filename="package://ur_e_description/meshes/ur10e/collision/wrist2.stl" />
      </geometry>
    </collision>
    
  
    <inertial>
      <origin xyz="0 0 0" rpy="0 0 0" />
      <mass value="1.0" />
      <inertia ixx="0.001" ixy="0.0" ixz="0.0" iyy="0.001" iyz="0.0" izz="0.001" />
    </inertial>
</link>
  <joint name="wrist_3_joint" type="revolute">
    <parent link="wrist_2_link" />
    <child link="wrist_3_link" />
    <origin rpy="0.0 0.0 0.0" xyz="0.0 0.0 0.12" />
    <axis xyz="0 1 0" />
    <limit effort="54.0" lower="-6.2831853" upper="6.2831853" velocity="6.28" />
    <dynamics damping="0.0" friction="0.0" />
  </joint>
  <link name="wrist_3_link">
    <visual>
      <geometry>
        <mesh filename="package://ur_e_description/meshes/ur10e/visual/wrist3.dae" />
      </geometry>
      <origin rpy="1.571 0 0" xyz="0.0 0.0 0.0" />
    </visual>
    <collision>
      <geometry>
        <mesh filename="package://ur_e_description/meshes/ur10e/collision/wrist3.stl" />
      </geometry>
    </collision>
    
  
    <inertial>
      <origin xyz="0 0 0" rpy="0 0 0" />
      <mass value="1.0" />
      <inertia ixx="0.001" ixy="0.0" ixz="0.0" iyy="0.001" iyz="0.0" izz="0.001" />
    </inertial>
</link>
  <joint name="ee_fixed_joint" type="fixed">
    <origin rpy="0.0 3.1415 0" xyz="0.0 0.15 0.02" />
    <parent link="wrist_3_link" />
    <child link="part_studio_link" />
  </joint>

   <link name="part_studio_link">
    <visual>
      <origin rpy="-1.571 0 0" />
      <geometry>
        
        <mesh filename="package://franka_description/meshes/visual/mount_v6.stl" scale="0.001 0.001 0.001" />
      </geometry>
    </visual>
    <collision>
      <origin rpy="-1.571 0 0" />
      <geometry>
        
        <mesh filename="package://franka_description/meshes/collision/mount_v6.stl" scale="0.0001 0.0001 0.0001" />
      </geometry>
    </collision>
  
    <inertial>
      <origin xyz="0 0 0" rpy="0 0 0" />
      <mass value="1.0" />
      <inertia ixx="0.001" ixy="0.0" ixz="0.0" iyy="0.001" iyz="0.0" izz="0.001" />
    </inertial>
</link>

  <joint name="part_studio_joint" type="fixed">
    
    <parent link="part_studio_link" />
    <child link="hand_base_link" />
    
    
    <origin rpy="0 -1.5707 -1.5707" xyz="0.00 0.12 0.025" />
   
  </joint>

  <link name="hand_base_link">
    
    <visual>
      <geometry>
        
        <mesh filename="allegro_hand_description/meshes/base_link.STL" />
        
        
      </geometry>
      <material name="black">
        <color rgba="0.2 0.2 0.2 1" />
      </material>
      
      <origin rpy="0 0 0" xyz="0 0 0 " />
      
      
    </visual>
    
    <collision>
      <origin rpy="0 0 0" xyz="-0.0000 0 -0.0" />
      
      <geometry>
        
        <mesh filename="allegro_hand_description/meshes/base_link.STL" />
            </geometry>
    </collision>
  
    <inertial>
      <origin xyz="0 0 0" rpy="0 0 0" />
      <mass value="1.0" />
      <inertia ixx="0.001" ixy="0.0" ixz="0.0" iyy="0.001" iyz="0.0" izz="0.001" />
    </inertial>
</link>
  
  
  
  
  <link name="link_0.0">
    <visual>
      <geometry>
        <mesh filename="allegro_hand_description/meshes/link_0.0.STL" />
      </geometry>
      <material name="black" />
    </visual>
    <collision>
      <geometry>
        <box size="0.0196 0.0275 0.0164" />
      </geometry>
        
      <origin rpy="0 0 0" xyz="0 0 0.0082" />
        
    </collision>
    
  
    <inertial>
      <origin xyz="0 0 0" rpy="0 0 0" />
      <mass value="1.0" />
      <inertia ixx="0.001" ixy="0.0" ixz="0.0" iyy="0.001" iyz="0.0" izz="0.001" />
    </inertial>
</link>
  <joint name="joint_0.0" type="revolute">
    <axis xyz="0 0 1" />
    <limit effort="10" lower="-0.47" upper="0.47" velocity="0" />
    <parent link="hand_base_link" />
    <child link="link_0.0" />
    <origin rpy="0.08726646255 0 0" xyz="0 -0.0435 -0.001542" />
  </joint>
  <link name="link_1.0">
    
    <visual>
      <geometry>
        <mesh filename="allegro_hand_description/meshes/link_1.0.STL" />
      </geometry>
      <material name="black" />
    </visual>
    <collision>
      <geometry>
        <box size="0.0196 0.0275 0.054" />
      </geometry>
        
      <origin rpy="0 0 0" xyz="0 0 0.027" />
        
    </collision>
  
    <inertial>
      <origin xyz="0 0 0" rpy="0 0 0" />
      <mass value="1.0" />
      <inertia ixx="0.001" ixy="0.0" ixz="0.0" iyy="0.001" iyz="0.0" izz="0.001" />
    </inertial>
</link>
  <joint name="joint_1.0" type="revolute">
    <limit effort="10" lower="-0.196" upper="1.61" velocity="0" />
    <axis xyz="0 1 0" />
    <parent link="link_0.0" />
    <child link="link_1.0" />
    <origin xyz="0 0 0.0164" />
  </joint>

  <link name="link_2.0">
    
    <visual>
      <geometry>
        <mesh filename="allegro_hand_description/meshes/link_2.0.STL" />
      </geometry>
      <material name="black" />
    </visual>
    <collision>
      <geometry>
        <box size="0.0196 0.0275 0.0384" />
      </geometry>
        
      <origin rpy="0 0 0" xyz="0 0 0.0192" />
        
    </collision>
  
    <inertial>
      <origin xyz="0 0 0" rpy="0 0 0" />
      <mass value="1.0" />
      <inertia ixx="0.001" ixy="0.0" ixz="0.0" iyy="0.001" iyz="0.0" izz="0.001" />
    </inertial>
</link>
  <joint name="joint_2.0" type="revolute">
    <axis xyz="0 1 0" />
    <limit effort="10" lower="-0.174" upper="1.709" velocity="0" />
    <parent link="link_1.0" />
    <child link="link_2.0" />
    <origin xyz="0 0 0.054" />
  </joint>

  <link name="link_3.0">
    
    <visual>
      <geometry>
        <mesh filename="allegro_hand_description/meshes/link_3.0.STL" />
      </geometry>
      <material name="black" />
    </visual>
    <collision>
      <geometry>
        <box size="0.0196 0.0275 0.0267" />
      </geometry>
        
      <origin rpy="0 0 0" xyz="0 0 0.01335" />
        
    </collision>
    
  
    <inertial>
      <origin xyz="0 0 0" rpy="0 0 0" />
      <mass value="1.0" />
      <inertia ixx="0.001" ixy="0.0" ixz="0.0" iyy="0.001" iyz="0.0" izz="0.001" />
    </inertial>
</link>
  <joint name="joint_3.0" type="revolute">
    <axis xyz="0 1 0" />
    <limit effort="10" lower="-0.227" upper="1.618" velocity="0" />
    <parent link="link_2.0" />
    <child link="link_3.0" />
    <origin xyz="0 0 0.0384" />
  </joint>
  <link name="link_3.0_tip">
    <visual>
      <origin rpy="0 0 1.570795" xyz="0 0 -0.020" />
      <geometry>
        <mesh filename="allegro_hand_description/meshes/modified_tip.STL" scale="0.001 0.001 0.001" />
      </geometry>
      <material name="white" />
    </visual>
    <collision>
      <origin rpy="0 0 1.570795" xyz="0 0 -0.020" />
      <geometry>
        <mesh filename="allegro_hand_description/meshes/modified_tip.STL" scale="0.001 0.001 0.001" />
            </geometry>
    
        
    </collision>
  
    <inertial>
      <origin xyz="0 0 0" rpy="0 0 0" />
      <mass value="1.0" />
      <inertia ixx="0.001" ixy="0.0" ixz="0.0" iyy="0.001" iyz="0.0" izz="0.001" />
    </inertial>
</link>
  <joint name="joint_3.0_tip" type="fixed">
    <parent link="link_3.0" />
    <child link="link_3.0_tip" />
    <origin rpy="0 0 0" xyz="0 0 0.060" />
  </joint>

        
  <link name="link_4.0">
    
    <visual>
      <geometry>
        <mesh filename="allegro_hand_description/meshes/link_0.0.STL" />
      </geometry>
      <material name="black" />
    </visual>
    <collision>
      <geometry>
        <box size="0.0196 0.0275 0.0164" />
      </geometry>
        
      <origin rpy="0 0 0" xyz="0 0 0.0082" />
        
    </collision>
  
    <inertial>
      <origin xyz="0 0 0" rpy="0 0 0" />
      <mass value="1.0" />
      <inertia ixx="0.001" ixy="0.0" ixz="0.0" iyy="0.001" iyz="0.0" izz="0.001" />
    </inertial>
</link>
  <joint name="joint_4.0" type="revolute">
    <axis xyz="0 0 1" />
    <limit effort="10" lower="-0.47" upper="0.47" velocity="0" />
    <parent link="hand_base_link" />
    <child link="link_4.0" />
    <origin rpy="0.0 0 0" xyz="0 0 0.0007" />
  </joint>
  <link name="link_5.0">
    
    <visual>
      <geometry>
        <mesh filename="allegro_hand_description/meshes/link_1.0.STL" />
      </geometry>
      <material name="black" />
    </visual>
    <collision>
      <geometry>
        <box size="0.0196 0.0275 0.054" />
      </geometry>
        
      <origin rpy="0 0 0" xyz="0 0 0.027" />
        
    </collision>
  
    <inertial>
      <origin xyz="0 0 0" rpy="0 0 0" />
      <mass value="1.0" />
      <inertia ixx="0.001" ixy="0.0" ixz="0.0" iyy="0.001" iyz="0.0" izz="0.001" />
    </inertial>
</link>
  <joint name="joint_5.0" type="revolute">
    <limit effort="10" lower="-0.196" upper="1.61" velocity="0" />
    <axis xyz="0 1 0" />
    <parent link="link_4.0" />
    <child link="link_5.0" />
    <origin xyz="0 0 0.0164" />
  </joint>

  <link name="link_6.0">
    
    <visual>
      <geometry>
        <mesh filename="allegro_hand_description/meshes/link_2.0.STL" />
      </geometry>
      <material name="black" />
    </visual>
    <collision>
      <geometry>
        <box size="0.0196 0.0275 0.0384" />
      </geometry>
        
      <origin rpy="0 0 0" xyz="0 0 0.0192" />
        
    </collision>
  
    <inertial>
      <origin xyz="0 0 0" rpy="0 0 0" />
      <mass value="1.0" />
      <inertia ixx="0.001" ixy="0.0" ixz="0.0" iyy="0.001" iyz="0.0" izz="0.001" />
    </inertial>
</link>
  <joint name="joint_6.0" type="revolute">
    <axis xyz="0 1 0" />
    <limit effort="10" lower="-0.174" upper="1.709" velocity="0" />
    <parent link="link_5.0" />
    <child link="link_6.0" />
    <origin xyz="0 0 0.054" />
  </joint>

  <link name="link_7.0">
    
    
    <visual>
      <geometry>
        <mesh filename="allegro_hand_description/meshes/link_3.0.STL" />
      </geometry>
      <material name="black" />
    </visual>
    <collision>
      <geometry>
        <box size="0.0196 0.0275 0.0267" />
      </geometry>
        
      <origin rpy="0 0 0" xyz="0 0 0.01335" />
        
    </collision>
  
    <inertial>
      <origin xyz="0 0 0" rpy="0 0 0" />
      <mass value="1.0" />
      <inertia ixx="0.001" ixy="0.0" ixz="0.0" iyy="0.001" iyz="0.0" izz="0.001" />
    </inertial>
</link>
  <joint name="joint_7.0" type="revolute">
    <axis xyz="0 1 0" />
    <limit effort="10" lower="-0.227" upper="1.618" velocity="0" />
    <parent link="link_6.0" />
    <child link="link_7.0" />
    <origin xyz="0 0 0.0384" />
  </joint>
  <link name="link_7.0_tip">
    <visual>
      <origin rpy="0 0 1.570795" xyz="0 0 -0.020" />
      <geometry>
        <mesh filename="allegro_hand_description/meshes/modified_tip.STL" scale="0.001 0.001 0.001" />
      </geometry>
      <material name="white" />
    </visual>
    <collision>
      <origin rpy="0 0 1.570795" xyz="0 0 -0.020" />
      <geometry>
        <mesh filename="allegro_hand_description/meshes/modified_tip.STL" scale="0.001 0.001 0.001" />
            </geometry>
    
        
    </collision>
  
    <inertial>
      <origin xyz="0 0 0" rpy="0 0 0" />
      <mass value="1.0" />
      <inertia ixx="0.001" ixy="0.0" ixz="0.0" iyy="0.001" iyz="0.0" izz="0.001" />
    </inertial>
</link>
  <joint name="joint_7.0_tip" type="fixed">
    <parent link="link_7.0" />
    <child link="link_7.0_tip" />
    <origin rpy="0 0 0" xyz="0 0 0.060" />
  </joint>


  <link name="link_8.0">
    
    <visual>
      <geometry>
        <mesh filename="allegro_hand_description/meshes/link_0.0.STL" />
      </geometry>
      <material name="black" />
    </visual>
    <collision>
      <geometry>
        <box size="0.0196 0.0275 0.0164" />
      </geometry>
        
      <origin rpy="0 0 0" xyz="0 0 0.0082" />
        
    </collision>
  
    <inertial>
      <origin xyz="0 0 0" rpy="0 0 0" />
      <mass value="1.0" />
      <inertia ixx="0.001" ixy="0.0" ixz="0.0" iyy="0.001" iyz="0.0" izz="0.001" />
    </inertial>
</link>
  <joint name="joint_8.0" type="revolute">
    <axis xyz="0 0 1" />
    <limit effort="10" lower="-0.47" upper="0.47" velocity="0" />
    <parent link="hand_base_link" />
    <child link="link_8.0" />
    <origin rpy="-0.08726646255 0 0" xyz="0 0.0435 -0.001542" />
  </joint>
  <link name="link_9.0">
    
    <visual>
      <geometry>
        <mesh filename="allegro_hand_description/meshes/link_1.0.STL" />
      </geometry>
      <material name="black" />
    </visual>
    <collision>
      <geometry>
        <box size="0.0196 0.0275 0.054" />
      </geometry>
        
      <origin rpy="0 0 0" xyz="0 0 0.027" />
        
    </collision>
  
    <inertial>
      <origin xyz="0 0 0" rpy="0 0 0" />
      <mass value="1.0" />
      <inertia ixx="0.001" ixy="0.0" ixz="0.0" iyy="0.001" iyz="0.0" izz="0.001" />
    </inertial>
</link>
  <joint name="joint_9.0" type="revolute">
    <limit effort="10" lower="-0.196" upper="1.61" velocity="0" />
    <axis xyz="0 1 0" />
    <parent link="link_8.0" />
    <child link="link_9.0" />
    <origin xyz="0 0 0.0164" />
  </joint>


  <link name="link_10.0">
    
    <visual>
      <geometry>
        <mesh filename="allegro_hand_description/meshes/link_2.0.STL" />
      </geometry>
      <material name="black" />
    </visual>
    <collision>
      <geometry>
        <box size="0.0196 0.0275 0.0384" />
      </geometry>
        
      <origin rpy="0 0 0" xyz="0 0 0.0192" />
        
    </collision>
  
    <inertial>
      <origin xyz="0 0 0" rpy="0 0 0" />
      <mass value="1.0" />
      <inertia ixx="0.001" ixy="0.0" ixz="0.0" iyy="0.001" iyz="0.0" izz="0.001" />
    </inertial>
</link>
  <joint name="joint_10.0" type="revolute">
    <axis xyz="0 1 0" />
    <limit effort="10" lower="-0.174" upper="1.709" velocity="0" />
    <parent link="link_9.0" />
    <child link="link_10.0" />
    <origin xyz="0 0 0.054" />
  </joint>


  <link name="link_11.0">
    
    
    <visual>
      <geometry>
        <mesh filename="allegro_hand_description/meshes/link_3.0.STL" />
      </geometry>
      <material name="black" />
    </visual>
    <collision>
      <geometry>
        <box size="0.0196 0.0275 0.0267" />
      </geometry>
        
      <origin rpy="0 0 0" xyz="0 0 0.01335" />
        
    </collision>
  
    <inertial>
      <origin xyz="0 0 0" rpy="0 0 0" />
      <mass value="1.0" />
      <inertia ixx="0.001" ixy="0.0" ixz="0.0" iyy="0.001" iyz="0.0" izz="0.001" />
    </inertial>
</link>
  <joint name="joint_11.0" type="revolute">
    <axis xyz="0 1 0" />
    <limit effort="10" lower="-0.227" upper="1.618" velocity="0" />
    <parent link="link_10.0" />
    <child link="link_11.0" />
    <origin xyz="0 0 0.0384" />
  </joint>

  <link name="link_11.0_tip">
    <visual>
      <origin rpy="0 0 1.570795" xyz="0 0 -0.020" />
      <geometry>
        <mesh filename="allegro_hand_description/meshes/modified_tip.STL" scale="0.001 0.001 0.001" />
      </geometry>
      <material name="white" />
    </visual>
    <collision>
      <origin rpy="0 0 1.570795" xyz="0 0 -0.020" />
      <geometry>
        <mesh filename="allegro_hand_description/meshes/modified_tip.STL" scale="0.001 0.001 0.001" />
            </geometry>
    
        
    </collision>
  
    <inertial>
      <origin xyz="0 0 0" rpy="0 0 0" />
      <mass value="1.0" />
      <inertia ixx="0.001" ixy="0.0" ixz="0.0" iyy="0.001" iyz="0.0" izz="0.001" />
    </inertial>
</link>
  <joint name="joint_11.0_tip" type="fixed">
    <parent link="link_11.0" />
    <child link="link_11.0_tip" />
    <origin rpy="0 0 0" xyz="0 0 0.060" />
  </joint>

  
  <link name="link_12.0">
    
    <visual>
      <geometry>
        
        <mesh filename="allegro_hand_description/meshes/link_12.0_right.STL" />
        
        
      </geometry>
      <material name="black" />
      <origin rpy="0.0 0 0" xyz="0 0 0" />
    </visual>
    <collision>
      <geometry>
        
        <mesh filename="allegro_hand_description/meshes/link_12.0_right.STL" scale="0.99 0.99 0.99" />
      </geometry>
      
      <origin rpy="0 0 0" xyz="-0.0 0.00 0.0" />
      
      
        
    </collision>
  
    <inertial>
      <origin xyz="0 0 0" rpy="0 0 0" />
      <mass value="1.0" />
      <inertia ixx="0.001" ixy="0.0" ixz="0.0" iyy="0.001" iyz="0.0" izz="0.001" />
    </inertial>
</link>
  <joint name="joint_12.0" type="revolute">
    <axis xyz="-1 0 0" />
    <limit effort="10" lower="0.263" upper="1.396" velocity="0" />
    <parent link="hand_base_link" />
    <child link="link_12.0" />
    
    <origin rpy="0 -1.65806278845 -1.5707963259" xyz="-0.0182 0.019333 -0.045987" />
    
    
  </joint>
  <link name="link_13.0">
    
    <visual>
      <geometry>
        <mesh filename="allegro_hand_description/meshes/link_13.0.STL" />
      </geometry>
      <material name="black" />
    </visual>
    <collision>
      <geometry>
        <box size="0.0196 0.0275 0.0177" />
      </geometry>
        
      <origin rpy="0 0 0" xyz="0 0 0.00885" />
        
    </collision>
  
    <inertial>
      <origin xyz="0 0 0" rpy="0 0 0" />
      <mass value="1.0" />
      <inertia ixx="0.001" ixy="0.0" ixz="0.0" iyy="0.001" iyz="0.0" izz="0.001" />
    </inertial>
</link>
  <joint name="joint_13.0" type="revolute">
    <axis xyz="0 0 1" />
    <limit effort="10" lower="-0.105" upper="1.163" velocity="0" />
    <parent link="link_12.0" />
    <child link="link_13.0" />
    
    <origin xyz="-0.027 0.005 0.0399" />
    
    
  </joint>
  <link name="link_14.0">
    
    <visual>
      <geometry>
        <mesh filename="allegro_hand_description/meshes/link_14.0.STL" />
      </geometry>
      <material name="black" />
    </visual>
    <collision>
      <geometry>
        <box size="0.0196 0.0275 0.0514" />
      </geometry>
        
      <origin rpy="0 0 0" xyz="0 0 0.0257" />
        
    </collision>
  
    <inertial>
      <origin xyz="0 0 0" rpy="0 0 0" />
      <mass value="1.0" />
      <inertia ixx="0.001" ixy="0.0" ixz="0.0" iyy="0.001" iyz="0.0" izz="0.001" />
    </inertial>
</link>
  <joint name="joint_14.0" type="revolute">
    <axis xyz="0 1 0" />
    <limit effort="10" lower="-0.189" upper="1.644" velocity="0" />
    <parent link="link_13.0" />
    <child link="link_14.0" />
    <origin xyz="0 0 0.0177" />
  </joint>


  <link name="link_15.0">
    
    <visual>
      <geometry>
        <mesh filename="allegro_hand_description/meshes/link_15.0.STL" />
      </geometry>
      <material name="black">
      </material>
    </visual>
    <collision>
      <geometry>
        <box size="0.0196 0.0275 0.0423" />
      </geometry>
        
      <origin rpy="0 0 0" xyz="0 0 0.02115" />
        
    </collision>
  
    <inertial>
      <origin xyz="0 0 0" rpy="0 0 0" />
      <mass value="1.0" />
      <inertia ixx="0.001" ixy="0.0" ixz="0.0" iyy="0.001" iyz="0.0" izz="0.001" />
    </inertial>
</link>
  <joint name="joint_15.0" type="revolute">
    <axis xyz="0 1 0" />
    <limit effort="10" lower="-0.162" upper="1.719" velocity="0" />
    <parent link="link_14.0" />
    <child link="link_15.0" />
    <origin xyz="0 0 0.0514" />
  </joint>


  <link name="link_15.0_tip">
    <visual>
      <origin rpy="0 0 1.570795" xyz="0 0 -0.020" />
      <geometry>
        <mesh filename="allegro_hand_description/meshes/modified_tip.STL" scale="0.001 0.001 0.001" />
      </geometry>
      <material name="white" />
    </visual>
    <collision>
      
      <origin rpy="0 0 1.570795" xyz="0 0 -0.020" />
      <geometry>
        <mesh filename="allegro_hand_description/meshes/modified_tip.STL" scale="0.001 0.001 0.001" />
            </geometry>
    
        
    </collision>
  
    <inertial>
      <origin xyz="0 0 0" rpy="0 0 0" />
      <mass value="1.0" />
      <inertia ixx="0.001" ixy="0.0" ixz="0.0" iyy="0.001" iyz="0.0" izz="0.001" />
    </inertial>
</link>
  <joint name="joint_15.0_tip" type="fixed">
    <parent link="link_15.0" />
    <child link="link_15.0_tip" />
    <origin rpy="0 0 0" xyz="0 0 0.075" />
  </joint>

  
  <link name="palm">
  
    <inertial>
      <origin xyz="0 0 0" rpy="0 0 0" />
      <mass value="1.0" />
      <inertia ixx="0.001" ixy="0.0" ixz="0.0" iyy="0.001" iyz="0.0" izz="0.001" />
    </inertial>
<visual><geometry><box size="0.01 0.01 0.01" /></geometry></visual></link>
  <joint name="palm_joint" type="fixed">
    <parent link="hand_base_link" />
    <child link="palm" />
    <origin rpy="0.00000 -0.00000 0.00000" xyz="0 0 -0.065" />
  </joint>
  <link name="palm_center">
  
    <inertial>
      <origin xyz="0 0 0" rpy="0 0 0" />
      <mass value="1.0" />
      <inertia ixx="0.001" ixy="0.0" ixz="0.0" iyy="0.001" iyz="0.0" izz="0.001" />
    </inertial>
<visual><geometry><box size="0.01 0.01 0.01" /></geometry></visual></link>
  <joint name="palm_center_joint" type="fixed">
    <parent link="hand_base_link" />
    <child link="palm_center" />
    <origin rpy="0.00000 -0.00000 0.00000" xyz="0 0 -0.03" />
  </joint>
  
  
  
  

</robot>