<?xml version="1.0"?>
<robot name="shadowhand">
  <link name="virtual_root"><inertial>
      <origin xyz="0 0 0" rpy="0 0 0" />
      <mass value="1.0" />
      <inertia ixx="0.001" ixy="0.0" ixz="0.0" iyy="0.001" iyz="0.0" izz="0.001" />
    </inertial><visual><geometry><box size="0.01 0.01 0.01" /></geometry></visual></link><joint name="dummy_root_link_to_virtual_root" type="fixed"><parent link="virtual_root" /><child link="dummy_root_link" /></joint><joint name="world_to_virtual_root" type="fixed"><parent link="virtual_root" /><child link="world" /></joint><link name="dummy_root_link"><inertial>
      <origin xyz="0 0 0" rpy="0 0 0" />
      <mass value="1.0" />
      <inertia ixx="0.001" ixy="0.0" ixz="0.0" iyy="0.001" iyz="0.0" izz="0.001" />
    </inertial><visual><geometry><box size="0.01 0.01 0.01" /></geometry></visual></link><joint name="fix_thdistal_to_dummy" type="fixed"><parent link="dummy_root_link" /><child link="thdistal" /></joint><joint name="fix_rfdistal_to_dummy" type="fixed"><parent link="dummy_root_link" /><child link="rfdistal" /></joint><joint name="fix_mfdistal_to_dummy" type="fixed"><parent link="dummy_root_link" /><child link="mfdistal" /></joint><joint name="fix_lfdistal_to_dummy" type="fixed"><parent link="dummy_root_link" /><child link="lfdistal" /></joint><joint name="fix_ffdistal_to_dummy" type="fixed"><parent link="dummy_root_link" /><child link="ffdistal" /></joint><material name="Blue">
    <color rgba="0.0 0.0 0.8 1.0" />
  </material>
  <material name="Green">
    <color rgba="0.0 0.8 0.0 1.0" />
  </material>
  <material name="Grey">
    <color rgba="0.2 0.2 0.2 1.0" />
  </material>
  <material name="LightGrey">
    <color rgba="0.6 0.6 0.6 1.0" />
  </material>
  <material name="Red">
    <color rgba="0.8 0.0 0.0 1.0" />
  </material>
  <material name="White">
    <color rgba="1.0 1.0 1.0 1.0" />
  </material>

  <link name="world"><inertial>
      <origin xyz="0 0 0" rpy="0 0 0" />
      <mass value="1.0" />
      <inertia ixx="0.001" ixy="0.0" ixz="0.0" iyy="0.001" iyz="0.0" izz="0.001" />
    </inertial><visual><geometry><box size="0.01 0.01 0.01" /></geometry></visual></link>
  <joint name="robot_base_joint" type="fixed">
    <origin rpy="0.0 0.0 3.14159265" xyz="0 0 0" />
    <parent link="world" />
    <child link="base_link" />
  </joint>
  <link name="base_link">
    <visual>
      <geometry>
        <mesh filename="package://ur_e_description/meshes/ur10e/visual/base.dae" />
      </geometry>
      <origin rpy="1.571 0 0" xyz="0.0 0.0 0.0" />
    </visual>
    <collision>
      <geometry>
        <mesh filename="package://ur_e_description/meshes/ur10e/collision/base.stl" />
      </geometry>
    </collision>
    
  
    <inertial>
      <origin xyz="0 0 0" rpy="0 0 0" />
      <mass value="1.0" />
      <inertia ixx="0.001" ixy="0.0" ixz="0.0" iyy="0.001" iyz="0.0" izz="0.001" />
    </inertial>
</link>
  <joint name="shoulder_pan_joint" type="revolute">
    <parent link="base_link" />
    <child link="shoulder_link" />
    <origin rpy="0.0 0.0 0.0" xyz="0.0 0.0 0.181" />
    <axis xyz="0 0 1" />
    <limit effort="330.0" lower="-6.2831853" upper="6.2831853" velocity="3.14" />
    <dynamics damping="0.0" friction="0.0" />
  </joint>
  <link name="shoulder_link">
    <visual>
      <geometry>
        <mesh filename="package://ur_e_description/meshes/ur10e/visual/shoulder.dae" />
      </geometry>
      <origin rpy="1.571 0 0" xyz="0.0 0.0 0.0" />
    </visual>
    <collision>
      <geometry>
        <mesh filename="package://ur_e_description/meshes/ur10e/collision/shoulder.stl" />
      </geometry>
    </collision>
    
  
    <inertial>
      <origin xyz="0 0 0" rpy="0 0 0" />
      <mass value="1.0" />
      <inertia ixx="0.001" ixy="0.0" ixz="0.0" iyy="0.001" iyz="0.0" izz="0.001" />
    </inertial>
</link>
  <joint name="shoulder_lift_joint" type="revolute">
    <parent link="shoulder_link" />
    <child link="upper_arm_link" />
    <origin rpy="0.0 1.570796325 0.0" xyz="0.0 0.176 0.0" />
    <axis xyz="0 1 0" />
    <limit effort="330.0" lower="-6.2831853" upper="6.2831853" velocity="3.14" />
    <dynamics damping="0.0" friction="0.0" />
  </joint>
  <link name="upper_arm_link">
    <visual>
      <geometry>
        <mesh filename="package://ur_e_description/meshes/ur10e/visual/upperarm.dae" />
      </geometry>
      <origin rpy="1.571 0 0" xyz="0.0 0.0 0.0" />
    </visual>
    <collision>
      <geometry>
        <mesh filename="package://ur_e_description/meshes/ur10e/collision/upperarm.stl" />
      </geometry>
    </collision>
    
  
    <inertial>
      <origin xyz="0 0 0" rpy="0 0 0" />
      <mass value="1.0" />
      <inertia ixx="0.001" ixy="0.0" ixz="0.0" iyy="0.001" iyz="0.0" izz="0.001" />
    </inertial>
</link>
  <joint name="elbow_joint" type="revolute">
    <parent link="upper_arm_link" />
    <child link="forearm_link" />
    <origin rpy="0.0 0.0 0.0" xyz="0.0 -0.137 0.613" />
    <axis xyz="0 1 0" />
    <limit effort="150.0" lower="-6.2831853" upper="6.2831853" velocity="3.14" />
    <dynamics damping="0.0" friction="0.0" />
  </joint>
  <link name="forearm_link">
    <visual>
      <geometry>
        <mesh filename="package://ur_e_description/meshes/ur10e/visual/forearm.dae" />
      </geometry>
      <origin rpy="1.571 0 0" xyz="0.0 0.0 0.0" />
    </visual>
    <collision>
      <geometry>
        <mesh filename="package://ur_e_description/meshes/ur10e/collision/forearm.stl" />
      </geometry>
    </collision>
    
  
    <inertial>
      <origin xyz="0 0 0" rpy="0 0 0" />
      <mass value="1.0" />
      <inertia ixx="0.001" ixy="0.0" ixz="0.0" iyy="0.001" iyz="0.0" izz="0.001" />
    </inertial>
</link>
  <joint name="wrist_1_joint" type="revolute">
    <parent link="forearm_link" />
    <child link="wrist_1_link" />
    <origin rpy="0.0 1.570796325 0.0" xyz="0.0 0.0 0.571" />
    <axis xyz="0 1 0" />
    <limit effort="54.0" lower="-6.2831853" upper="6.2831853" velocity="6.28" />
    <dynamics damping="0.0" friction="0.0" />
  </joint>
  <link name="wrist_1_link">
    <visual>
      <geometry>
        <mesh filename="package://ur_e_description/meshes/ur10e/visual/wrist1.dae" />
      </geometry>
      <origin rpy="1.571 0 0" xyz="0.0 0.0 0.0" />
    </visual>
    <collision>
      <geometry>
        <mesh filename="package://ur_e_description/meshes/ur10e/collision/wrist1.stl" />
      </geometry>
    </collision>
    
  
    <inertial>
      <origin xyz="0 0 0" rpy="0 0 0" />
      <mass value="1.0" />
      <inertia ixx="0.001" ixy="0.0" ixz="0.0" iyy="0.001" iyz="0.0" izz="0.001" />
    </inertial>
</link>
  <joint name="wrist_2_joint" type="revolute">
    <parent link="wrist_1_link" />
    <child link="wrist_2_link" />
    <origin rpy="0.0 0.0 0.0" xyz="0.0 0.135 0.0" />
    <axis xyz="0 0 1" />
    <limit effort="54.0" lower="-6.2831853" upper="6.2831853" velocity="6.28" />
    <dynamics damping="0.0" friction="0.0" />
  </joint>
  <link name="wrist_2_link">
    <visual>
      <geometry>
        <mesh filename="package://ur_e_description/meshes/ur10e/visual/wrist2.dae" />
      </geometry>
      <origin rpy="1.571 0 0" xyz="0.0 0.0 0.0" />
    </visual>
    <collision>
      <geometry>
        <mesh filename="package://ur_e_description/meshes/ur10e/collision/wrist2.stl" />
      </geometry>
    </collision>
    
  
    <inertial>
      <origin xyz="0 0 0" rpy="0 0 0" />
      <mass value="1.0" />
      <inertia ixx="0.001" ixy="0.0" ixz="0.0" iyy="0.001" iyz="0.0" izz="0.001" />
    </inertial>
</link>
  <joint name="wrist_3_joint" type="revolute">
    <parent link="wrist_2_link" />
    <child link="wrist_3_link" />
    <origin rpy="0.0 0.0 0.0" xyz="0.0 0.0 0.12" />
    <axis xyz="0 1 0" />
    <limit effort="54.0" lower="-6.2831853" upper="6.2831853" velocity="6.28" />
    <dynamics damping="0.0" friction="0.0" />
  </joint>
  <link name="wrist_3_link">
    <visual>
      <geometry>
        <mesh filename="package://ur_e_description/meshes/ur10e/visual/wrist3.dae" />
      </geometry>
      <origin rpy="1.571 0 0" xyz="0.0 0.0 0.0" />
    </visual>
    <collision>
      <geometry>
        <mesh filename="package://ur_e_description/meshes/ur10e/collision/wrist3.stl" />
      </geometry>
    </collision>
    
  
    <inertial>
      <origin xyz="0 0 0" rpy="0 0 0" />
      <mass value="1.0" />
      <inertia ixx="0.001" ixy="0.0" ixz="0.0" iyy="0.001" iyz="0.0" izz="0.001" />
    </inertial>
</link>
  <joint name="ee_fixed_joint" type="fixed">
    <parent link="wrist_3_link" />
    <child link="ee_link" />
    <origin rpy="0.0 0.0 1.570796325" xyz="0.0 0.117 0.0" />
  </joint>
  <link name="ee_link">
    <collision>
      <geometry>
        <box size="0.01 0.01 0.01" />
      </geometry>
      <origin rpy="0 0 0" xyz="-0.01 0 0" />
    </collision>
  
    <inertial>
      <origin xyz="0 0 0" rpy="0 0 0" />
      <mass value="1.0" />
      <inertia ixx="0.001" ixy="0.0" ixz="0.0" iyy="0.001" iyz="0.0" izz="0.001" />
    </inertial>
</link>

  <joint name="connector_joint" type="fixed">
    <parent link="ee_link" />
    <child link="forearm" />
    <origin rpy="1.571 0.0 1.571" xyz="0.0 0.0 0.0" />
  </joint>

  <link name="forearm">
    
    <visual>
      <origin rpy="0 0 0" xyz="0 0 0" />
      <geometry name="shadow_forearm_geom">
        <mesh filename="meshes/forearm.obj" />
      </geometry>
      <material name="Grey" />
    </visual>
    <collision>
      <origin rpy="0 0 0" xyz="0 0 0.0" />
      <geometry name="shadow_forearm_collision">
        <mesh filename="meshes/forearm.obj" />
      </geometry>
    </collision>
  
    <inertial>
      <origin xyz="0 0 0" rpy="0 0 0" />
      <mass value="1.0" />
      <inertia ixx="0.001" ixy="0.0" ixz="0.0" iyy="0.001" iyz="0.0" izz="0.001" />
    </inertial>
</link>

  <joint name="WRJ2" type="revolute">
    <parent link="forearm" />
    <child link="wrist" />

    <origin rpy="0 0 0" xyz="0 -0.010 0.213" />
    <axis xyz="0 1 0" />
    
    <limit effort="5" lower="-0.07453292519943295" upper="0.07453292519943295" velocity="1.0" />
    <dynamics damping="100.5" />
  </joint>

  <link name="wrist">
    
    <visual>
      <origin rpy="0 0 0" xyz="0 0 0" />
      <geometry name="wrist_visual">
        <mesh filename="meshes/wrist.obj" />
      </geometry>
      <material name="LightGrey" />
    </visual>
    <collision>
      <origin rpy="0 0 0" xyz="0 0 0" />
      <geometry name="wrist_collision_geom">
        <mesh filename="meshes/wrist.obj" />
      </geometry>
    </collision>
  
    <inertial>
      <origin xyz="0 0 0" rpy="0 0 0" />
      <mass value="1.0" />
      <inertia ixx="0.001" ixy="0.0" ixz="0.0" iyy="0.001" iyz="0.0" izz="0.001" />
    </inertial>
</link>

  <link name="palm">
    
    <visual>
      <origin rpy="0 0 3.1415" xyz="0 0 0" />
      <geometry name="palm_visual">
        <mesh filename="meshes/palm_left.stl" scale="0.001 0.001 0.001" />
      </geometry>
      <material name="Grey" />
    </visual>
    <collision>
      <origin rpy="0 0 3.1415" xyz="0.00 0 0.0" />
      <geometry name="palm_collision_geom">
        <mesh filename="meshes/palm_left.stl" scale="0.001 0.001 0.001" />
        
      </geometry>
    </collision>
  
    <inertial>
      <origin xyz="0 0 0" rpy="0 0 0" />
      <mass value="1.0" />
      <inertia ixx="0.001" ixy="0.0" ixz="0.0" iyy="0.001" iyz="0.0" izz="0.001" />
    </inertial>
</link>

  <joint name="WRJ1" type="revolute">
    <parent link="wrist" />
    <child link="palm" />
    <origin rpy="0 0 0" xyz="0 0 0.034" />
    <axis xyz="1 0 0" />
    
    <limit effort="5" lower="-0.08539816339744828" upper="0.0108652381980153" velocity="1.0" />
    <dynamics damping="100.5" />
  </joint>

  <link name="ffknuckle">
    
    <visual>
      <origin rpy="0 0 3.1415" xyz="0 0 0.000" />
      <geometry name="knuckle_visual">
        <mesh filename="meshes/knuckle.obj" />
      </geometry>
      <material name="LightGrey" />
    </visual>
    <collision>
      <origin rpy="0 0 3.1415" xyz="0 0 0" />
      <geometry name="knuckle_collision_geom">
        <mesh filename="meshes/knuckle.obj" />
      </geometry>
    </collision>
  
    <inertial>
      <origin xyz="0 0 0" rpy="0 0 0" />
      <mass value="1.0" />
      <inertia ixx="0.001" ixy="0.0" ixz="0.0" iyy="0.001" iyz="0.0" izz="0.001" />
    </inertial>
</link>
  <joint name="FFJ4" type="revolute">
    <parent link="palm" />
    <child link="ffknuckle" />

    <origin rpy="0 0 0" xyz="0.033 0 0.095" />
    <axis xyz="0 1 0" />
    <limit effort="100" lower="-0.43633231299858238" upper="0.43633231299858238" velocity="1.0" />
    <dynamics damping="50.5" />
  </joint>
  <link name="ffproximal">
    
    <visual>
      <origin rpy="0 0 3.1415" xyz="0 0 0" />
      <geometry name="proximal_visual">
        <mesh filename="meshes/F3.obj" />
      </geometry>
      <material name="Grey" />
    </visual>
    <collision>
      <origin rpy="0 0 3.1415" xyz="0 0 0.0" />
      <geometry name="proximal_collision_geom">
        <mesh filename="meshes/F3.obj" />
      </geometry>
    </collision>
  
    <inertial>
      <origin xyz="0 0 0" rpy="0 0 0" />
      <mass value="1.0" />
      <inertia ixx="0.001" ixy="0.0" ixz="0.0" iyy="0.001" iyz="0.0" izz="0.001" />
    </inertial>
</link>
  <joint name="FFJ3" type="revolute">
    <parent link="ffknuckle" />
    <child link="ffproximal" />
    <origin rpy="0 0 0" xyz="0 0 0" />
    <axis xyz="-1 0 0" />
    <limit effort="100" lower="0" upper="1.57079632679" velocity="1.0" />
    <dynamics damping="50.5" />
  </joint>
  <link name="ffmiddle">
    
    <visual>
      <origin rpy="0 0 3.1415" xyz="0 0 0" />
      <geometry name="middle_visual">
        <mesh filename="meshes/F2.obj" />
      </geometry>
      <material name="Grey" />
    </visual>
    <collision>
      <origin rpy="0 0 3.1415" xyz="0 0 0.0" />
      <geometry name="middle_collision_geom">
        <mesh filename="meshes/F2.obj" />
      </geometry>
    </collision>
  
    <inertial>
      <origin xyz="0 0 0" rpy="0 0 0" />
      <mass value="1.0" />
      <inertia ixx="0.001" ixy="0.0" ixz="0.0" iyy="0.001" iyz="0.0" izz="0.001" />
    </inertial>
</link>
  <joint name="FFJ2" type="revolute">
    <parent link="ffproximal" />
    <child link="ffmiddle" />
    <origin rpy="0 0 0" xyz="0 0 0.045" />
    <axis xyz="-1 0 0" />
    <limit effort="100" lower="0" upper="1.57079632679" velocity="1.0" />
    <dynamics damping="50.5" />
  </joint>
  <link name="ffdistal">
    
    <visual>
      <origin rpy="0 0 3.1415" xyz="0 0 0" />
      <geometry name="distal_visual">
        <mesh filename="meshes/F1.obj" />
      </geometry>
      <material name="Grey" />
    </visual>

    <collision>
      <origin rpy="0 0 3.1415" xyz="0 0 0" />
      <geometry name="distal_collision_geom">
        <mesh filename="meshes/F1.obj" />
      </geometry>
    </collision>
  
    <inertial>
      <origin xyz="0 0 0" rpy="0 0 0" />
      <mass value="1.0" />
      <inertia ixx="0.001" ixy="0.0" ixz="0.0" iyy="0.001" iyz="0.0" izz="0.001" />
    </inertial>
</link>
  <joint name="FFJ1" type="revolute">
    <parent link="ffmiddle" />
    <child link="ffdistal" />
    <origin rpy="0 0 0" xyz="0 0 0.025" />
    <axis xyz="-1 0 0" />
    <limit effort="100" lower="0" upper="1.57079632679" velocity="1.0" />
    <dynamics damping="50.5" />
  </joint>
  <link name="mfknuckle">
    
    <visual>
      <origin rpy="0 0 3.1415" xyz="0 0 0.0005" />
      <geometry name="knuckle_visual">
        <mesh filename="meshes/knuckle.obj" />
      </geometry>
      <material name="LightGrey" />
    </visual>
    <collision>
      <origin rpy="0 0 3.1415" xyz="0 0 0.0005" />
      <geometry name="knuckle_collision_geom">
        <mesh filename="meshes/knuckle.obj" />
      </geometry>
    </collision>
  
    <inertial>
      <origin xyz="0 0 0" rpy="0 0 0" />
      <mass value="1.0" />
      <inertia ixx="0.001" ixy="0.0" ixz="0.0" iyy="0.001" iyz="0.0" izz="0.001" />
    </inertial>
</link>
  <joint name="MFJ4" type="revolute">
    <parent link="palm" />
    <child link="mfknuckle" />

    <origin rpy="0 0 0" xyz="0.011 0 0.099" />
    <axis xyz="0 1 0" />
    <limit effort="100" lower="-0.43633231299858238" upper="0.43633231299858238" velocity="1.0" />
    <dynamics damping="50.5" />
  </joint>
  <link name="mfproximal">
    
    <visual>
      <origin rpy="0 0 3.1415" xyz="0 0 0" />
      <geometry name="proximal_visual">
        <mesh filename="meshes/F3.obj" />
      </geometry>
      <material name="Grey" />
    </visual>
    <collision>
      <origin rpy="0 0 3.1415" xyz="0 0 0.0" />
      <geometry name="proximal_collision_geom">
        <mesh filename="meshes/F3.obj" />
      </geometry>
    </collision>
  
    <inertial>
      <origin xyz="0 0 0" rpy="0 0 0" />
      <mass value="1.0" />
      <inertia ixx="0.001" ixy="0.0" ixz="0.0" iyy="0.001" iyz="0.0" izz="0.001" />
    </inertial>
</link>
  <joint name="MFJ3" type="revolute">
    <parent link="mfknuckle" />
    <child link="mfproximal" />
    <origin rpy="0 0 0" xyz="0 0 0" />
    <axis xyz="-1 0 0" />
    <limit effort="100" lower="0" upper="1.57079632679" velocity="1.0" />
    <dynamics damping="50.5" />
  </joint>
  <link name="mfmiddle">
    
    <visual>
      <origin rpy="0 0 3.1415" xyz="0 0 0" />
      <geometry name="middle_visual">
        <mesh filename="meshes/F2.obj" />
      </geometry>
      <material name="Grey" />
    </visual>
    <collision>
      <origin rpy="0 0 3.1415" xyz="0 0 0.0" />
      <geometry name="middle_collision_geom">
        <mesh filename="meshes/F2.obj" />
      </geometry>
    </collision>
  
    <inertial>
      <origin xyz="0 0 0" rpy="0 0 0" />
      <mass value="1.0" />
      <inertia ixx="0.001" ixy="0.0" ixz="0.0" iyy="0.001" iyz="0.0" izz="0.001" />
    </inertial>
</link>
  <joint name="MFJ2" type="revolute">
    <parent link="mfproximal" />
    <child link="mfmiddle" />
    <origin rpy="0 0 0" xyz="0 0 0.045" />
    <axis xyz="-1 0 0" />
    <limit effort="100" lower="0" upper="1.57079632679" velocity="1.0" />
    <dynamics damping="50.5" />
  </joint>
  <link name="mfdistal">
    
    <visual>
      <origin rpy="0 0 3.1415" xyz="0 0 0" />
      <geometry name="distal_visual">
        <mesh filename="meshes/F1.obj" />
      </geometry>
      <material name="Grey" />
    </visual>

    <collision>
      <origin rpy="0 0 3.1415" xyz="0 0 0" />
      <geometry name="distal_collision_geom">
        <mesh filename="meshes/F1.obj" />
      </geometry>
    </collision>
  
    <inertial>
      <origin xyz="0 0 0" rpy="0 0 0" />
      <mass value="1.0" />
      <inertia ixx="0.001" ixy="0.0" ixz="0.0" iyy="0.001" iyz="0.0" izz="0.001" />
    </inertial>
</link>
  <joint name="MFJ1" type="revolute">
    <parent link="mfmiddle" />
    <child link="mfdistal" />
    <origin rpy="0 0 0" xyz="0 0 0.025" />
    <axis xyz="-1 0 0" />
    <limit effort="100" lower="0" upper="1.57079632679" velocity="1.0" />
    <dynamics damping="50.5" />
  </joint>
  <link name="rfknuckle">
    
    <visual>
      <origin rpy="0 0 3.1415" xyz="0 0 0.0005" />
      <geometry name="knuckle_visual">
        <mesh filename="meshes/knuckle.obj" />
      </geometry>
      <material name="LightGrey" />
    </visual>
    <collision>
      <origin rpy="0 0 3.1415" xyz="0 0 0.0005" />
      <geometry name="knuckle_collision_geom">
        <mesh filename="meshes/knuckle.obj" />
      </geometry>
    </collision>
  
    <inertial>
      <origin xyz="0 0 0" rpy="0 0 0" />
      <mass value="1.0" />
      <inertia ixx="0.001" ixy="0.0" ixz="0.0" iyy="0.001" iyz="0.0" izz="0.001" />
    </inertial>
</link>
  <joint name="RFJ4" type="revolute">
    <parent link="palm" />
    <child link="rfknuckle" />

    <origin rpy="0 0 0" xyz="-0.011 0 0.095" />
    <axis xyz="0 -1 0" />
    <limit effort="100" lower="-0.43633231299858238" upper="0.43633231299858238" velocity="1.0" />
    <dynamics damping="50.5" />
  </joint>
  <link name="rfproximal">
    
    <visual>
      <origin rpy="0 0 3.1415" xyz="0 0 0" />
      <geometry name="proximal_visual">
        <mesh filename="meshes/F3.obj" />
      </geometry>
      <material name="Grey" />
    </visual>
    <collision>
      <origin rpy="0 0 3.1415" xyz="0 0 0.0" />
      <geometry name="proximal_collision_geom">
        <mesh filename="meshes/F3.obj" />
      </geometry>
    </collision>
  
    <inertial>
      <origin xyz="0 0 0" rpy="0 0 0" />
      <mass value="1.0" />
      <inertia ixx="0.001" ixy="0.0" ixz="0.0" iyy="0.001" iyz="0.0" izz="0.001" />
    </inertial>
</link>
  <joint name="RFJ3" type="revolute">
    <parent link="rfknuckle" />
    <child link="rfproximal" />
    <origin rpy="0 0 0" xyz="0 0 0" />
    <axis xyz="-1 0 0" />
    <limit effort="100" lower="0" upper="1.57079632679" velocity="1.0" />
    <dynamics damping="50.5" />
  </joint>
  <link name="rfmiddle">
    
    <visual>
      <origin rpy="0 0 3.1415" xyz="0 0 0" />
      <geometry name="middle_visual">
        <mesh filename="meshes/F2.obj" />
      </geometry>
      <material name="Grey" />
    </visual>
    <collision>
      <origin rpy="0 0 3.1415" xyz="0 0 0.0" />
      <geometry name="middle_collision_geom">
        <mesh filename="meshes/F2.obj" />
      </geometry>
    </collision>
  
    <inertial>
      <origin xyz="0 0 0" rpy="0 0 0" />
      <mass value="1.0" />
      <inertia ixx="0.001" ixy="0.0" ixz="0.0" iyy="0.001" iyz="0.0" izz="0.001" />
    </inertial>
</link>
  <joint name="RFJ2" type="revolute">
    <parent link="rfproximal" />
    <child link="rfmiddle" />
    <origin rpy="0 0 0" xyz="0 0 0.045" />
    <axis xyz="-1 0 0" />
    <limit effort="100" lower="0" upper="1.57079632679" velocity="1.0" />
    <dynamics damping="50.5" />
  </joint>
  <link name="rfdistal">
    
    <visual>
      <origin rpy="0 0 3.1415" xyz="0 0 0" />
      <geometry name="distal_visual">
        <mesh filename="meshes/F1.obj" />
      </geometry>
      <material name="Grey" />
    </visual>

    <collision>
      <origin rpy="0 0 3.1415" xyz="0 0 0" />
      <geometry name="distal_collision_geom">
        <mesh filename="meshes/F1.obj" />
      </geometry>
    </collision>
  
    <inertial>
      <origin xyz="0 0 0" rpy="0 0 0" />
      <mass value="1.0" />
      <inertia ixx="0.001" ixy="0.0" ixz="0.0" iyy="0.001" iyz="0.0" izz="0.001" />
    </inertial>
</link>
  <joint name="RFJ1" type="revolute">
    <parent link="rfmiddle" />
    <child link="rfdistal" />
    <origin rpy="0 0 0" xyz="0 0 0.025" />
    <axis xyz="-1 0 0" />
    <limit effort="100" lower="0" upper="1.57079632679" velocity="1.0" />
    <dynamics damping="50.5" />
  </joint>
  <link name="lfmetacarpal">
    
    <visual>
      <origin rpy="0 0 0" xyz="0 0 0" />
      <geometry name="lfmetacarpal_visual">
        <mesh filename="meshes/lfmetacarpal.obj" />
      </geometry>
      <material name="Grey" />
    </visual>
    <collision>
      <origin rpy="0 0 0" xyz="0 0 0.0" />
      <geometry name="lfmetacarpal_collision_geom">
        <mesh filename="meshes/lfmetacarpal.obj" />
      </geometry>
    </collision>
  
    <inertial>
      <origin xyz="0 0 0" rpy="0 0 0" />
      <mass value="1.0" />
      <inertia ixx="0.001" ixy="0.0" ixz="0.0" iyy="0.001" iyz="0.0" izz="0.001" />
    </inertial>
</link>
  <joint name="LFJ5" type="revolute">
    <parent link="palm" />
    <child link="lfmetacarpal" />
    <origin rpy="0 0 0" xyz="-0.033 0 0.02071" />
    <axis xyz="-0.573576436 0 -0.819152044" />
    <limit effort="100" lower="0" upper="0.69813170079773179" velocity="1.0" />
    <dynamics damping="50.5" />
  </joint>
  <link name="lfknuckle">
    
    <visual>
      <origin rpy="0 0 3.1415" xyz="0 0 0" />
      <geometry name="knuckle_visual">
        <mesh filename="meshes/knuckle.obj" />
      </geometry>
      <material name="LightGrey" />
    </visual>
    <collision>
      <origin rpy="0 0 3.1415" xyz="0 0 0" />
      <geometry name="knuckle_collision_geom">
        <mesh filename="meshes/knuckle.obj" />
      </geometry>
    </collision>
  
    <inertial>
      <origin xyz="0 0 0" rpy="0 0 0" />
      <mass value="1.0" />
      <inertia ixx="0.001" ixy="0.0" ixz="0.0" iyy="0.001" iyz="0.0" izz="0.001" />
    </inertial>
</link>
  <joint name="LFJ4" type="revolute">
    <parent link="lfmetacarpal" />
    <child link="lfknuckle" />
    <origin rpy="0 0 0" xyz="0 0 0.06579" />
    <axis xyz="0 -1 0" />
    <limit effort="100" lower="-0.43633231299858238" upper="0.43633231299858238" velocity="1.0" />
    <dynamics damping="50.5" />
  </joint>
  <link name="lfproximal">
    
    <visual>
      <origin rpy="0 0 3.1415" xyz="0 0 0" />
      <geometry name="proximal_visual">
        <mesh filename="meshes/F3.obj" />
      </geometry>
      <material name="Grey" />
    </visual>
    <collision>
      <origin rpy="0 0 3.1415" xyz="0 0 0.0" />
      <geometry name="proximal_collision_geom">
        <mesh filename="meshes/F3.obj" />
      </geometry>
    </collision>
  
    <inertial>
      <origin xyz="0 0 0" rpy="0 0 0" />
      <mass value="1.0" />
      <inertia ixx="0.001" ixy="0.0" ixz="0.0" iyy="0.001" iyz="0.0" izz="0.001" />
    </inertial>
</link>
  <joint name="LFJ3" type="revolute">
    <parent link="lfknuckle" />
    <child link="lfproximal" />
    <origin rpy="0 0 0" xyz="0 0 0" />
    <axis xyz="-1 0 0" />
    <limit effort="100" lower="0" upper="1.57079632679" velocity="1.0" />
    <dynamics damping="50.5" />
  </joint>
  <link name="lfmiddle">
    
    <visual>
      <origin rpy="0 0 3.1415" xyz="0 0 0" />
      <geometry name="middle_visual">
        <mesh filename="meshes/F2.obj" />
      </geometry>
      <material name="Grey" />
    </visual>
    <collision>
      <origin rpy="0 0 3.1415" xyz="0 0 0.0" />
      <geometry name="middle_collision_geom">
        <mesh filename="meshes/F2.obj" />
      </geometry>
    </collision>
  
    <inertial>
      <origin xyz="0 0 0" rpy="0 0 0" />
      <mass value="1.0" />
      <inertia ixx="0.001" ixy="0.0" ixz="0.0" iyy="0.001" iyz="0.0" izz="0.001" />
    </inertial>
</link>
  <joint name="LFJ2" type="revolute">
    <parent link="lfproximal" />
    <child link="lfmiddle" />
    <origin rpy="0 0 0" xyz="0 0 0.045" />
    <axis xyz="-1 0 0" />
    <limit effort="100" lower="0" upper="1.57079632679" velocity="1.0" />
    <dynamics damping="50.5" />
  </joint>
  <link name="lfdistal">
    
    <visual>
      <origin rpy="0 0 3.1415" xyz="0 0 0" />
      <geometry name="distal_visual">
        <mesh filename="meshes/F1.obj" />
      </geometry>
      <material name="Grey" />
    </visual>

    <collision>
      <origin rpy="0 0 3.1415" xyz="0 0 0" />
      <geometry name="distal_collision_geom">
        <mesh filename="meshes/F1.obj" />
      </geometry>
    </collision>
  
    <inertial>
      <origin xyz="0 0 0" rpy="0 0 0" />
      <mass value="1.0" />
      <inertia ixx="0.001" ixy="0.0" ixz="0.0" iyy="0.001" iyz="0.0" izz="0.001" />
    </inertial>
</link>
  <joint name="LFJ1" type="revolute">
    <parent link="lfmiddle" />
    <child link="lfdistal" />
    <origin rpy="0 0 0" xyz="0 0 0.025" />
    <axis xyz="-1 0 0" />
    <limit effort="100" lower="0" upper="1.57079632679" velocity="1.0" />
    <dynamics damping="50.5" />
  </joint>
  <link name="thbase">
    
    <visual>
      <origin rpy="0 0 3.1415" xyz="0 0 0" />
      <geometry name="thbase_visual">
        <box size="0.001 0.001 0.001" />
      </geometry>
      <material name="shadow_thbase_material">
        <color rgba="0.5 0.5 0.5 1.0" />
      </material>
    </visual>
    <collision>
      <origin rpy="0 0 3.1415" xyz="0 0 0" />
      <geometry name="thbase_collision_geom">
        <box size="0.001 0.001 0.001" />
      </geometry>
    </collision>
  
    <inertial>
      <origin xyz="0 0 0" rpy="0 0 0" />
      <mass value="1.0" />
      <inertia ixx="0.001" ixy="0.0" ixz="0.0" iyy="0.001" iyz="0.0" izz="0.001" />
    </inertial>
</link>
  <joint name="THJ5" type="revolute">
    <parent link="palm" />
    <child link="thbase" />
    <origin rpy="0 0.785398163397 0" xyz="0.034 0.0085 0.029" />
    <axis xyz="0 0 1.0" />
    <limit effort="100" lower="-0.001" upper="0.001" velocity="1.0" />
    
    <dynamics damping="50.5" />
  </joint>
  <link name="thproximal">
    
    <visual>
      <origin rpy="0 0 3.1415" xyz="0 0 0" />
      <geometry name="thproximal_visual">
        <mesh filename="meshes/TH3_z.obj" />
      </geometry>
      <material name="shadow_thproximal_material">
        <color rgba="0.2 0.2 0.2 1.0" />
      </material>
    </visual>
    <collision>
      <origin rpy="0 0 3.1415" xyz="0 0 0.0" />
      <geometry name="thproximal_collision_geom">
        <mesh filename="meshes/TH3_z.obj" />
      </geometry>
    </collision>
  
    <inertial>
      <origin xyz="0 0 0" rpy="0 0 0" />
      <mass value="1.0" />
      <inertia ixx="0.001" ixy="0.0" ixz="0.0" iyy="0.001" iyz="0.0" izz="0.001" />
    </inertial>
</link>
  <joint name="THJ4" type="revolute">
    <parent link="thbase" />
    <child link="thproximal" />
    <origin rpy="0 0 0" xyz="0 0 0" />
    <axis xyz="-1.0 0 0" />
    <limit effort="100" lower="0" upper="1.309" velocity="1.0" />
    <dynamics damping="50.5" />
  </joint>
  <link name="thhub">
    
    <visual>
      <origin rpy="0 0 3.1415" xyz="0 0 0" />
      <geometry name="thhub_visual">
        <box size="0.001 0.001 0.001" />
      </geometry>
      <material name="shadow_thhub_material">
        <color rgba="0.7 0.7 0.7 1.0" />
      </material>
    </visual>
    <collision>
      <origin rpy="0 0 3.1415" xyz="0 0 0" />
      <geometry name="thhub_collision_geom">
        <box size="0.001 0.001 0.001" />
      </geometry>
    </collision>
  
    <inertial>
      <origin xyz="0 0 0" rpy="0 0 0" />
      <mass value="1.0" />
      <inertia ixx="0.001" ixy="0.0" ixz="0.0" iyy="0.001" iyz="0.0" izz="0.001" />
    </inertial>
</link>
  <joint name="THJ3" type="revolute">
    <parent link="thproximal" />
    <child link="thhub" />
    <origin rpy="0 0 0" xyz="0 0 0.038" />
    <axis xyz="-1 0 0" />
    <limit effort="100" lower="-0.2618" upper="0.2618" velocity="1.0" />
    <dynamics damping="50.5" />
  </joint>
  <link name="thmiddle">
    
    <visual>
      <origin rpy="0 0 3.1415" xyz="0 0 0" />
      <geometry name="thmiddle_visual">
        <mesh filename="meshes/TH2_z.obj" />
      </geometry>
      <material name="shadow_thmiddle_material">
        <color rgba="0.2 0.2 0.2 1.0" />
      </material>
    </visual>
    <collision>
      <origin rpy="0 0 3.1415" xyz="0 0 0.0" />
      <geometry name="thmiddle_collision_geom">
        <mesh filename="meshes/TH2_z.obj" />
      </geometry>
    </collision>
  
    <inertial>
      <origin xyz="0 0 0" rpy="0 0 0" />
      <mass value="1.0" />
      <inertia ixx="0.001" ixy="0.0" ixz="0.0" iyy="0.001" iyz="0.0" izz="0.001" />
    </inertial>
</link>
  <joint name="THJ2" type="revolute">
    <parent link="thhub" />
    <child link="thmiddle" />
    <origin rpy="0 0 0" xyz="0 0 0" />
    <axis xyz="0 1 0" />
    <limit effort="100" lower="-0.5237" upper="0.5237" velocity="1.0" />
    <dynamics damping="50.5" />
  </joint>
  <link name="thdistal">
    
    <visual>
      <origin rpy="0 0 3.1415" xyz="0 0.002 0.0025" />
      <geometry name="thdistal_visual">
        <mesh filename="meshes/F1.obj" />
      </geometry>
      <material name="shadow_thmiddle_material">
        <color rgba="0.2 0.2 0.2 1.0" />
      </material>
    </visual>
    <collision>
      <origin rpy="0 0 3.1415" xyz="0 0.002 0.0025" />
      <geometry name="thmiddle_collision_geom">
        <mesh filename="meshes/F1.obj" />
      </geometry>
    </collision>
  
    <inertial>
      <origin xyz="0 0 0" rpy="0 0 0" />
      <mass value="1.0" />
      <inertia ixx="0.001" ixy="0.0" ixz="0.0" iyy="0.001" iyz="0.0" izz="0.001" />
    </inertial>
</link>
  <joint name="THJ1" type="revolute">
    <parent link="thmiddle" />
    <child link="thdistal" />
    <origin rpy="0 0 -1.570796327" xyz="0 0 0.032" />
    <axis xyz="1 0 0" />
    <limit effort="100" lower="-0.262" upper="1.571" velocity="1.0" />
    <dynamics damping="50.5" />
  </joint>
</robot>