<?xml version="1.0"?>
<robot name="shadowhand">
  <link name="virtual_root"><inertial>
      <origin xyz="0 0 0" rpy="0 0 0" />
      <mass value="1.0" />
      <inertia ixx="0.001" ixy="0.0" ixz="0.0" iyy="0.001" iyz="0.0" izz="0.001" />
    </inertial><visual><geometry><box size="0.01 0.01 0.01" /></geometry></visual></link><joint name="dummy_root_link_to_virtual_root" type="fixed"><parent link="virtual_root" /><child link="dummy_root_link" /></joint><joint name="world_to_virtual_root" type="fixed"><parent link="virtual_root" /><child link="world" /></joint><link name="dummy_root_link"><inertial>
      <origin xyz="0 0 0" rpy="0 0 0" />
      <mass value="1.0" />
      <inertia ixx="0.001" ixy="0.0" ixz="0.0" iyy="0.001" iyz="0.0" izz="0.001" />
    </inertial><visual><geometry><box size="0.01 0.01 0.01" /></geometry></visual></link><joint name="fix_thumb_tip_to_dummy" type="fixed"><parent link="dummy_root_link" /><child link="thumb_tip" /></joint><joint name="fix_ring_tip_to_dummy" type="fixed"><parent link="dummy_root_link" /><child link="ring_tip" /></joint><joint name="fix_pinky_tip_to_dummy" type="fixed"><parent link="dummy_root_link" /><child link="pinky_tip" /></joint><joint name="fix_middle_tip_to_dummy" type="fixed"><parent link="dummy_root_link" /><child link="middle_tip" /></joint><joint name="fix_index_tip_to_dummy" type="fixed"><parent link="dummy_root_link" /><child link="index_tip" /></joint><material name="Blue">
    <color rgba="0.0 0.0 0.8 1.0" />
  </material>
  <material name="Green">
    <color rgba="0.0 0.8 0.0 1.0" />
  </material>
  <material name="Grey">
    <color rgba="0.2 0.2 0.2 1.0" />
  </material>
  <material name="LightGrey">
    <color rgba="0.6 0.6 0.6 1.0" />
  </material>
  <material name="Red">
    <color rgba="0.8 0.0 0.0 1.0" />
  </material>
  <material name="White">
    <color rgba="1.0 1.0 1.0 1.0" />
  </material>

  <link name="world"><inertial>
      <origin xyz="0 0 0" rpy="0 0 0" />
      <mass value="1.0" />
      <inertia ixx="0.001" ixy="0.0" ixz="0.0" iyy="0.001" iyz="0.0" izz="0.001" />
    </inertial><visual><geometry><box size="0.01 0.01 0.01" /></geometry></visual></link>
  <joint name="robot_base_joint" type="fixed">
    <origin rpy="0.0 0.0 3.14159265" xyz="0 0 0" />
    <parent link="world" />
    <child link="base_link" />
  </joint>
  <link name="base_link">
    <visual>
      <geometry>
        <mesh filename="package://ur_e_description/meshes/ur10e/visual/base.dae" />
      </geometry>

      <origin rpy="1.571 0 0" xyz="0.0 0.0 0.0" />
    </visual>
    <collision>
      <geometry>
        <mesh filename="package://ur_e_description/meshes/ur10e/collision/base.stl" />
      </geometry>
    </collision>
    
  
    <inertial>
      <origin xyz="0 0 0" rpy="0 0 0" />
      <mass value="1.0" />
      <inertia ixx="0.001" ixy="0.0" ixz="0.0" iyy="0.001" iyz="0.0" izz="0.001" />
    </inertial>
</link>
  <joint name="shoulder_pan_joint" type="revolute">
    <parent link="base_link" />
    <child link="shoulder_link" />
    <origin rpy="0.0 0.0 0.0" xyz="0.0 0.0 0.181" />
    <axis xyz="0 0 1" />
    <limit effort="330.0" lower="-6.2831853" upper="6.2831853" velocity="3.14" />
    <dynamics damping="0.0" friction="0.0" />
  </joint>
  <link name="shoulder_link">
    <visual>
      <geometry>
        <mesh filename="package://ur_e_description/meshes/ur10e/visual/shoulder.dae" />
      </geometry>

      <origin rpy="1.571 0 0" xyz="0.0 0.0 0.0" />
    </visual>
    <collision>
      <geometry>
        <mesh filename="package://ur_e_description/meshes/ur10e/collision/shoulder.stl" />
      </geometry>
    </collision>
    
  
    <inertial>
      <origin xyz="0 0 0" rpy="0 0 0" />
      <mass value="1.0" />
      <inertia ixx="0.001" ixy="0.0" ixz="0.0" iyy="0.001" iyz="0.0" izz="0.001" />
    </inertial>
</link>
  <joint name="shoulder_lift_joint" type="revolute">
    <parent link="shoulder_link" />
    <child link="upper_arm_link" />
    <origin rpy="0.0 1.570796325 0.0" xyz="0.0 0.176 0.0" />
    <axis xyz="0 1 0" />
    <limit effort="330.0" lower="-6.2831853" upper="6.2831853" velocity="3.14" />
    <dynamics damping="0.0" friction="0.0" />
  </joint>
  <link name="upper_arm_link">
    <visual>
      <geometry>
        <mesh filename="package://ur_e_description/meshes/ur10e/visual/upperarm.dae" />
      </geometry>

      <origin rpy="1.571 0 0" xyz="0.0 0.0 0.0" />
    </visual>
    <collision>
      <geometry>
        <mesh filename="package://ur_e_description/meshes/ur10e/collision/upperarm.stl" />
      </geometry>
    </collision>
    
  
    <inertial>
      <origin xyz="0 0 0" rpy="0 0 0" />
      <mass value="1.0" />
      <inertia ixx="0.001" ixy="0.0" ixz="0.0" iyy="0.001" iyz="0.0" izz="0.001" />
    </inertial>
</link>
  <joint name="elbow_joint" type="revolute">
    <parent link="upper_arm_link" />
    <child link="forearm_link" />
    <origin rpy="0.0 0.0 0.0" xyz="0.0 -0.137 0.613" />
    <axis xyz="0 1 0" />
    <limit effort="150.0" lower="-6.2831853" upper="6.2831853" velocity="3.14" />
    <dynamics damping="0.0" friction="0.0" />
  </joint>
  <link name="forearm_link">
    <visual>
      <geometry>
        <mesh filename="package://ur_e_description/meshes/ur10e/visual/forearm.dae" />
      </geometry>

      <origin rpy="1.571 0 0" xyz="0.0 0.0 0.0" />
    </visual>
    <collision>
      <geometry>
        <mesh filename="package://ur_e_description/meshes/ur10e/collision/forearm.stl" />
      </geometry>
    </collision>
    
  
    <inertial>
      <origin xyz="0 0 0" rpy="0 0 0" />
      <mass value="1.0" />
      <inertia ixx="0.001" ixy="0.0" ixz="0.0" iyy="0.001" iyz="0.0" izz="0.001" />
    </inertial>
</link>
  <joint name="wrist_1_joint" type="revolute">
    <parent link="forearm_link" />
    <child link="wrist_1_link" />
    <origin rpy="0.0 1.570796325 0.0" xyz="0.0 0.0 0.571" />
    <axis xyz="0 1 0" />
    <limit effort="54.0" lower="-6.2831853" upper="6.2831853" velocity="6.28" />
    <dynamics damping="0.0" friction="0.0" />
  </joint>
  <link name="wrist_1_link">
    <visual>
      <geometry>
        <mesh filename="package://ur_e_description/meshes/ur10e/visual/wrist1.dae" />
      </geometry>

      <origin rpy="1.571 0 0" xyz="0.0 0.0 0.0" />
    </visual>
    <collision>
      <geometry>
        <mesh filename="package://ur_e_description/meshes/ur10e/collision/wrist1.stl" />
      </geometry>
    </collision>
    
  
    <inertial>
      <origin xyz="0 0 0" rpy="0 0 0" />
      <mass value="1.0" />
      <inertia ixx="0.001" ixy="0.0" ixz="0.0" iyy="0.001" iyz="0.0" izz="0.001" />
    </inertial>
</link>
  <joint name="wrist_2_joint" type="revolute">
    <parent link="wrist_1_link" />
    <child link="wrist_2_link" />
    <origin rpy="0.0 0.0 0.0" xyz="0.0 0.135 0.0" />
    <axis xyz="0 0 1" />
    <limit effort="54.0" lower="-6.2831853" upper="6.2831853" velocity="6.28" />
    <dynamics damping="0.0" friction="0.0" />
  </joint>
  <link name="wrist_2_link">
    <visual>
      <geometry>
        <mesh filename="package://ur_e_description/meshes/ur10e/visual/wrist2.dae" />
      </geometry>
      <origin rpy="1.571 0 0" xyz="0.0 0.0 0.0" />
    </visual>
    <collision>
      <geometry>
        <mesh filename="package://ur_e_description/meshes/ur10e/collision/wrist2.stl" />
      </geometry>
    </collision>
    
  
    <inertial>
      <origin xyz="0 0 0" rpy="0 0 0" />
      <mass value="1.0" />
      <inertia ixx="0.001" ixy="0.0" ixz="0.0" iyy="0.001" iyz="0.0" izz="0.001" />
    </inertial>
</link>
  <joint name="wrist_3_joint" type="revolute">
    <parent link="wrist_2_link" />
    <child link="wrist_3_link" />
    <origin rpy="0.0 0.0 0.0" xyz="0.0 0.0 0.12" />
    <axis xyz="0 1 0" />
    <limit effort="54.0" lower="-6.2831853" upper="6.2831853" velocity="6.28" />
    <dynamics damping="0.0" friction="0.0" />
  </joint>
  <link name="wrist_3_link">
    <visual>
      <geometry>
        <mesh filename="package://ur_e_description/meshes/ur10e/visual/wrist3.dae" />
      </geometry>
      <origin rpy="1.571 0 0" xyz="0.0 0.0 0.0" />
    </visual>
    <collision>
      <geometry>
        <mesh filename="package://ur_e_description/meshes/ur10e/collision/wrist3.stl" />
      </geometry>
    </collision>
    
  
    <inertial>
      <origin xyz="0 0 0" rpy="0 0 0" />
      <mass value="1.0" />
      <inertia ixx="0.001" ixy="0.0" ixz="0.0" iyy="0.001" iyz="0.0" izz="0.001" />
    </inertial>
</link>
  <joint name="ee_fixed_joint" type="fixed">
    <origin rpy="1.571 1.571 3.1415" xyz="0.0 0.118 0.0" />
    <parent link="wrist_3_link" />
    <child link="right_hand_base_link" />
  </joint>

  <link name="right_hand_base_link"><inertial>
      <origin xyz="0 0 0" rpy="0 0 0" />
      <mass value="1.0" />
      <inertia ixx="0.001" ixy="0.0" ixz="0.0" iyy="0.001" iyz="0.0" izz="0.001" />
    </inertial><visual><geometry><box size="0.01 0.01 0.01" /></geometry></visual></link>
  <joint name="base_joint" type="fixed">
    <parent link="right_hand_base_link" />
    <child link="base" />
    <origin xyz="0 0 0" rpy="0 0 -1.57079" />
  </joint>
  <link name="base">
    <visual name="wrist_mesh">
      <origin rpy="0 0 0" xyz="0 0 0" />
      <geometry>
        <mesh filename="ability_hand/meshes/visual/wristmesh.obj" />
      </geometry>
    </visual>
    <collision>
      <origin xyz="0 0 0" rpy="0 0 0" />
      <geometry>
        <mesh filename="ability_hand/meshes/collision/wristmesh_C.obj" />
      </geometry>
    </collision>
    
  
    <inertial>
      <origin xyz="0 0 0" rpy="0 0 0" />
      <mass value="1.0" />
      <inertia ixx="0.001" ixy="0.0" ixz="0.0" iyy="0.001" iyz="0.0" izz="0.001" />
    </inertial>
</link>
  <joint name="wrist2thumb" type="fixed">
    <parent link="base" />
    <child link="thumb_base" />
    <origin xyz="-24.0476665e-3 3.78124745e-3 32.32964923e-3" rpy="3.14148426 -0.08848813 -3.14036612" />
  </joint>
  <link name="thumb_base">
    
    <visual name="palm_mesh">
      <origin rpy="0 0 0" xyz="0 0 0" />
      <geometry>
        <mesh filename="ability_hand/meshes/visual/FB_palm_ref_MIR.obj" />
      </geometry>
    </visual>
    <collision>                                  
      <origin xyz="0 0 0" rpy="0 0 0" />
      <geometry>
        <mesh filename="ability_hand/meshes/collision/FB_palm_ref_MIR.obj" />
      </geometry>
    </collision>
  
    <inertial>
      <origin xyz="0 0 0" rpy="0 0 0" />
      <mass value="1.0" />
      <inertia ixx="0.001" ixy="0.0" ixz="0.0" iyy="0.001" iyz="0.0" izz="0.001" />
    </inertial>
</link>
  <link name="thumb_L1">
    
    <visual name="thumb_mesh_1">
      <origin xyz=" 27.8283501e-3 1.7436510745838653e-19 14.7507e-3 " rpy=" 1.832595714594045 -0.0 5.366520605522463e-18 " />
      <geometry>
        <mesh filename="ability_hand/meshes/visual/thumb-F1-MIR.obj" />
      </geometry>
    </visual>
    <collision>                            
      <origin xyz="27.8283501e-3 1.7436510745838653e-19 14.7507e-3" rpy="1.832595714594045 -0.0 5.366520605522463e-18" />
      <geometry>
        <mesh filename="ability_hand/meshes/collision/thumb-F1-MIR_C.obj" />
      </geometry>
    </collision>
  
    <inertial>
      <origin xyz="0 0 0" rpy="0 0 0" />
      <mass value="1.0" />
      <inertia ixx="0.001" ixy="0.0" ixz="0.0" iyy="0.001" iyz="0.0" izz="0.001" />
    </inertial>
</link>
  <link name="thumb_L2">
    
    <visual name="thumb_mesh_2">
      <origin xyz="65.18669e-3 23.34021e-3 3.93483e-3" rpy="-3.141592 0 0.343830" />
      <geometry>
        <mesh filename="ability_hand/meshes/visual/thumb-F2.obj" />
      </geometry>
    </visual>
    <collision>                            
      <origin xyz="65.18669e-3 23.34021e-3 3.93483e-3" rpy="-3.141592 0 0.343830" />
      <geometry>
        <mesh filename="ability_hand/meshes/collision/thumb-F2_C.obj" />
      </geometry>
    </collision>
  
    <inertial>
      <origin xyz="0 0 0" rpy="0 0 0" />
      <mass value="1.0" />
      <inertia ixx="0.001" ixy="0.0" ixz="0.0" iyy="0.001" iyz="0.0" izz="0.001" />
    </inertial>
</link>
  <joint name="thumb_q1" type="revolute">
    <parent link="thumb_base" />
    <child link="thumb_L1" />
    <origin xyz=" 0.0 0.0 0.0 " rpy=" 3.141592653589793 -0.0 -0.18884434641020664 " />
    <axis xyz="0 0 1" />
    <limit lower="-2.0943951" upper="0" effort="1.2" velocity="40.338888721" />    
    <dynamics damping="0.001" friction="0.001" />  
  </joint>
  <joint name="thumb_q2" type="revolute">
    <parent link="thumb_L1" />
    <child link="thumb_L2" />
    <origin xyz=" 27.8283501e-3 1.7436510745838653e-19 14.7507e-3 " rpy=" 1.832595714594045 -0.0 5.366520605522463e-18 " />
    <axis xyz="0 0 1" />
    <limit lower="0" upper="2.0943951" effort="6.0" velocity="8.0677777442" />    
    <dynamics damping="0.001" friction="0.001" />  
  </joint>
  <link name="thumb_tip"><inertial>
      <origin xyz="0 0 0" rpy="0 0 0" />
      <mass value="1.0" />
      <inertia ixx="0.001" ixy="0.0" ixz="0.0" iyy="0.001" iyz="0.0" izz="0.001" />
    </inertial><visual><geometry><box size="0.01 0.01 0.01" /></geometry></visual></link>
  <joint name="thumb_tip_joint" type="fixed">
    <parent link="thumb_L2" />
    <child link="thumb_tip" />
    <origin rpy="0 0 0" xyz="0.065 0.016 0" />
  </joint>
  <link name="index_L1">
    
    <visual name="index_mesh_1">
      <origin xyz="38.472723e-3 3.257695e-3 0.000000" rpy="0 0 0.084474" />
      <geometry>
        <mesh filename="ability_hand/meshes/visual/idx-F1.obj" />
      </geometry>
    </visual>
    <collision>                                  
      <origin xyz="0.036 -0.00175 0" rpy="0 0 0" />
      <geometry>
        <sphere radius="0.0085" />
      </geometry>
    </collision>
    <collision>
      <origin xyz="0.019 -0.0045 0" rpy="0 0 0.0845" />
      <geometry>
        <box size="0.028 0.012 0.016" />
      </geometry>
    </collision>
    <collision>
      <origin xyz="0.018 0.006 0" rpy="0 0 0.0845" />
      <geometry>
        <box size="0.02 0.01 0.016" />
      </geometry>
    </collision>
    <collision>
      <origin xyz="-0.001 0 0.007" rpy="0 0 0.0845" />
      <geometry>
        <box size="0.012 0.012 0.002" />
      </geometry>
    </collision>
    <collision>
      <origin xyz="-0.001 0 -0.007" rpy="0 0 0.0845" />
      <geometry>
        <box size="0.012 0.012 0.002" />
      </geometry>
    </collision>
  
    <inertial>
      <origin xyz="0 0 0" rpy="0 0 0" />
      <mass value="1.0" />
      <inertia ixx="0.001" ixy="0.0" ixz="0.0" iyy="0.001" iyz="0.0" izz="0.001" />
    </inertial>
</link>
  <link name="index_L2">
    
    <visual name="index_mesh_2">
      <origin rpy="0 0 0" xyz="9.1241e-3 0 0" />
      <geometry>
        <mesh filename="ability_hand/meshes/visual/idx-F2.obj" />
      </geometry>
    </visual>
    <collision>                            
      <origin xyz="0 0 0" rpy="0 0 0" />
      <geometry>
        <mesh filename="ability_hand/meshes/collision/idx-F2_C.obj" />
      </geometry>
    </collision>
    <collision>
      <origin xyz="0.03 -0.016 0" rpy="0 0 0" />
      <geometry>
        <sphere radius="0.007" />
      </geometry>
    </collision>
  
    <inertial>
      <origin xyz="0 0 0" rpy="0 0 0" />
      <mass value="1.0" />
      <inertia ixx="0.001" ixy="0.0" ixz="0.0" iyy="0.001" iyz="0.0" izz="0.001" />
    </inertial>
</link>
  <joint name="index_q1" type="revolute">
    <parent link="thumb_base" />
    <child link="index_L1" />
    <origin xyz=" 9.49e-3 -13.04e-3 -62.95e-3 " rpy=" -1.1595426535897932 1.284473 -1.0510016535897932 " />
    <axis xyz="0 0 1" />
    <limit lower="0" upper="2.0943951" effort="6.0" velocity="8.0677777442" />    
    <dynamics damping="0.001" friction="0.001" />  
  </joint>
  <joint name="index_q2" type="revolute">
    <parent link="index_L1" />
    <child link="index_L2" />
    <origin xyz="38.472723e-3 3.257695e-3 0.000000e-3" rpy="0 0 0.084474" />
    <axis xyz="0 0 1" />
    <limit lower="0.0" upper="2.6586" effort="6.0" velocity="8.0677777442" />    
    <dynamics damping="0.001" friction="0.001" />  
    <mimic joint="index_q1" multiplier="1.05851325" offset="0.72349796" />
  </joint>
  <link name="index_tip"><inertial>
      <origin xyz="0 0 0" rpy="0 0 0" />
      <mass value="1.0" />
      <inertia ixx="0.001" ixy="0.0" ixz="0.0" iyy="0.001" iyz="0.0" izz="0.001" />
    </inertial><visual><geometry><box size="0.01 0.01 0.01" /></geometry></visual></link>
  <joint name="index_tip_joint" type="fixed">
    <parent link="index_L2" />
    <child link="index_tip" />
    <origin rpy="0 0 0" xyz="0.035  -0.018 0" />
  </joint>
  <link name="middle_L1">
    
    <visual name="middle_mesh_1">
      <origin xyz="38.472723e-3 3.257695e-3 0.000000" rpy="0 0 0.084474" />
      <geometry>
        <mesh filename="ability_hand/meshes/visual/idx-F1.obj" />
      </geometry>
    </visual>
    <collision>                                  
      <origin xyz="0.036 -0.00175 0" rpy="0 0 0" />
      <geometry>
        <sphere radius="0.0085" />
      </geometry>
    </collision>
    <collision>
      <origin xyz="0.019 -0.0045 0" rpy="0 0 0.0845" />
      <geometry>
        <box size="0.028 0.012 0.016" />
      </geometry>
    </collision>
    <collision>
      <origin xyz="0.018 0.006 0" rpy="0 0 0.0845" />
      <geometry>
        <box size="0.02 0.01 0.016" />
      </geometry>
    </collision>
    <collision>
      <origin xyz="-0.001 0 0.007" rpy="0 0 0.0845" />
      <geometry>
        <box size="0.012 0.012 0.002" />
      </geometry>
    </collision>
    <collision>
      <origin xyz="-0.001 0 -0.007" rpy="0 0 0.0845" />
      <geometry>
        <box size="0.012 0.012 0.002" />
      </geometry>
    </collision>
  
    <inertial>
      <origin xyz="0 0 0" rpy="0 0 0" />
      <mass value="1.0" />
      <inertia ixx="0.001" ixy="0.0" ixz="0.0" iyy="0.001" iyz="0.0" izz="0.001" />
    </inertial>
</link>
  <link name="middle_L2">
    
    <visual name="middle_mesh_2">
      <origin rpy="0 0 0" xyz="9.1241e-3 0 0" />
      <geometry>
        <mesh filename="ability_hand/meshes/visual/idx-F2.obj" />
      </geometry>
    </visual>
    <collision>                            
      <origin xyz="0 0 0" rpy="0 0 0" />
      <geometry>
        <mesh filename="ability_hand/meshes/collision/idx-F2_C.obj" />
      </geometry>
    </collision>
    <collision>
      <origin xyz="0.03 -0.016 0" rpy="0 0 0" />
      <geometry>
        <sphere radius="0.007" />
      </geometry>
    </collision>
  
    <inertial>
      <origin xyz="0 0 0" rpy="0 0 0" />
      <mass value="1.0" />
      <inertia ixx="0.001" ixy="0.0" ixz="0.0" iyy="0.001" iyz="0.0" izz="0.001" />
    </inertial>
</link>
  <joint name="middle_q1" type="revolute">
    <parent link="thumb_base" />
    <child link="middle_L1" />
    <origin xyz=" -9.653191e-3 -15.310271e-3 -67.853949e-3 " rpy=" -1.2810616535897934 1.308458 -1.2453756535897933 " />
    <limit lower="0" upper="2.0943951" effort="6.0" velocity="8.0677777442" />    
    <dynamics damping="0.001" friction="0.001" />  
    <axis xyz="0 0 1" />
  </joint>
  <joint name="middle_q2" type="revolute">
    <parent link="middle_L1" />
    <child link="middle_L2" />
    <origin xyz="38.472723e-3 3.257695e-3 0.000000" rpy="0 0 0.084474" />
    <axis xyz="0 0 1" />
    <limit lower="0.0" upper="2.6586" effort="6.0" velocity="8.0677777442" />    
    <dynamics damping="0.001" friction="0.001" />  
    <mimic joint="middle_q1" multiplier="1.05851325" offset="0.72349796" />
  </joint>
  <link name="middle_tip"><inertial>
      <origin xyz="0 0 0" rpy="0 0 0" />
      <mass value="1.0" />
      <inertia ixx="0.001" ixy="0.0" ixz="0.0" iyy="0.001" iyz="0.0" izz="0.001" />
    </inertial><visual><geometry><box size="0.01 0.01 0.01" /></geometry></visual></link>
  <joint name="middle_tip_joint" type="fixed">
    <parent link="middle_L2" />
    <child link="middle_tip" />
    <origin rpy="0 0 0" xyz="0.035  -0.018 0" />
  </joint>
  <link name="ring_L1">
    
    <visual name="ring_mesh_1">
      <origin xyz="38.472723e-3 3.257695e-3 0.000000" rpy="0 0 0.084474" />
      <geometry>
        <mesh filename="ability_hand/meshes/visual/idx-F1.obj" />
      </geometry>
    </visual>
    <collision>                                  
      <origin xyz="0.036 -0.00175 0" rpy="0 0 0" />
      <geometry>
        <sphere radius="0.0085" />
      </geometry>
    </collision>
    <collision>
      <origin xyz="0.019 -0.0045 0" rpy="0 0 0.0845" />
      <geometry>
        <box size="0.028 0.012 0.016" />
      </geometry>
    </collision>
    <collision>
      <origin xyz="0.018 0.006 0" rpy="0 0 0.0845" />
      <geometry>
        <box size="0.02 0.01 0.016" />
      </geometry>
    </collision>
    <collision>
      <origin xyz="-0.001 0 0.007" rpy="0 0 0.0845" />
      <geometry>
        <box size="0.012 0.012 0.002" />
      </geometry>
    </collision>
    <collision>
      <origin xyz="-0.001 0 -0.007" rpy="0 0 0.0845" />
      <geometry>
        <box size="0.012 0.012 0.002" />
      </geometry>
    </collision>
  
    <inertial>
      <origin xyz="0 0 0" rpy="0 0 0" />
      <mass value="1.0" />
      <inertia ixx="0.001" ixy="0.0" ixz="0.0" iyy="0.001" iyz="0.0" izz="0.001" />
    </inertial>
</link>
  <link name="ring_L2">
    
    <visual name="ring_mesh_2">
      <origin rpy="0 0 0" xyz="9.1241e-3 0 0" />
      <geometry>
        <mesh filename="ability_hand/meshes/visual/idx-F2.obj" />
      </geometry>
    </visual>
    <collision>                            
      <origin xyz="0 0 0" rpy="0 0 0" />
      <geometry>
        <mesh filename="ability_hand/meshes/collision/idx-F2_C.obj" />
      </geometry>
    </collision>
    <collision>
      <origin xyz="0.03 -0.016 0" rpy="0 0 0" />
      <geometry>
        <sphere radius="0.007" />
      </geometry>
    </collision>
  
    <inertial>
      <origin xyz="0 0 0" rpy="0 0 0" />
      <mass value="1.0" />
      <inertia ixx="0.001" ixy="0.0" ixz="0.0" iyy="0.001" iyz="0.0" izz="0.001" />
    </inertial>
</link>
  <joint name="ring_q1" type="revolute">
    <parent link="thumb_base" />
    <child link="ring_L1" />
    <origin xyz=" -29.95426e-3 -14.212492e-3 -67.286105e-3 " rpy=" -1.424994653589793 1.321452 -1.4657306535897934 " />
    <limit lower="0" upper="2.0943951" effort="6.0" velocity="8.0677777442" />    
    <dynamics damping="0.001" friction="0.001" />  
    <axis xyz="0 0 1" />
  </joint>
  <joint name="ring_q2" type="revolute">
    <parent link="ring_L1" />
    <child link="ring_L2" />
    <origin xyz="38.472723e-3 3.257695e-3 0.000000" rpy="0 0 0.084474" />
    <axis xyz="0 0 1" />
    <limit lower="0.0" upper="2.6586" effort="6.0" velocity="8.0677777442" />    
    <dynamics damping="0.001" friction="0.001" />  
    <mimic joint="ring_q1" multiplier="1.05851325" offset="0.72349796" />
  </joint>
  <link name="ring_tip"><inertial>
      <origin xyz="0 0 0" rpy="0 0 0" />
      <mass value="1.0" />
      <inertia ixx="0.001" ixy="0.0" ixz="0.0" iyy="0.001" iyz="0.0" izz="0.001" />
    </inertial><visual><geometry><box size="0.01 0.01 0.01" /></geometry></visual></link>
  <joint name="ring_tip_joint" type="fixed">
    <parent link="ring_L2" />
    <child link="ring_tip" />
    <origin rpy="0 0 0" xyz="0.035  -0.018 0" />
  </joint>
  <link name="pinky_L1">
    
    <visual name="pinky_mesh_1">
      <origin xyz="38.472723e-3 3.257695e-3 0.000000" rpy="0 0 0.084474" />
      <geometry>
        <mesh filename="ability_hand/meshes/visual/idx-F1.obj" />
      </geometry>
    </visual>
    <collision>                                  
      <origin xyz="0.036 -0.00175 0" rpy="0 0 0" />
      <geometry>
        <sphere radius="0.0085" />
      </geometry>
    </collision>
    <collision>
      <origin xyz="0.019 -0.0045 0" rpy="0 0 0.0845" />
      <geometry>
        <box size="0.028 0.012 0.016" />
      </geometry>
    </collision>
    <collision>
      <origin xyz="0.018 0.006 0" rpy="0 0 0.0845" />
      <geometry>
        <box size="0.02 0.01 0.016" />
      </geometry>
    </collision>
    <collision>
      <origin xyz="-0.001 0 0.007" rpy="0 0 0.0845" />
      <geometry>
        <box size="0.012 0.012 0.002" />
      </geometry>
    </collision>
    <collision>
      <origin xyz="-0.001 0 -0.007" rpy="0 0 0.0845" />
      <geometry>
        <box size="0.012 0.012 0.002" />
      </geometry>
    </collision>
  
    <inertial>
      <origin xyz="0 0 0" rpy="0 0 0" />
      <mass value="1.0" />
      <inertia ixx="0.001" ixy="0.0" ixz="0.0" iyy="0.001" iyz="0.0" izz="0.001" />
    </inertial>
</link>
  <link name="pinky_L2">
    
    <visual name="pinky_mesh_2">
      <origin rpy="0 0 0" xyz="9.1241e-3 0 0" />
      <geometry>
        <mesh filename="ability_hand/meshes/visual/idx-F2.obj" />
      </geometry>
    </visual>
    <collision>                            
      <origin xyz="0 0 0" rpy="0 0 0" />
      <geometry>
        <mesh filename="ability_hand/meshes/collision/idx-F2_C.obj" />
      </geometry>
    </collision>
    <collision>
      <origin xyz="0.03 -0.016 0" rpy="0 0 0" />
      <geometry>
        <sphere radius="0.007" />
      </geometry>
    </collision>
  
    <inertial>
      <origin xyz="0 0 0" rpy="0 0 0" />
      <mass value="1.0" />
      <inertia ixx="0.001" ixy="0.0" ixz="0.0" iyy="0.001" iyz="0.0" izz="0.001" />
    </inertial>
</link>
  <joint name="pinky_q1" type="revolute">
    <parent link="thumb_base" />
    <child link="pinky_L1" />
    <origin xyz=" -49.521293e-3 -11.004583e-3 -63.029065e-3 " rpy=" -1.3764826535897934 1.32222 -1.4832096535897932 " />
    <limit lower="0" upper="2.0943951" effort="6.0" velocity="8.0677777442" />    
    <dynamics damping="0.001" friction="0.001" />  
    <axis xyz="0 0 1" />
  </joint>
  <joint name="pinky_q2" type="revolute">
    <parent link="pinky_L1" />
    <child link="pinky_L2" />
    <origin xyz="38.472723e-3 3.257695e-3 0.000000" rpy="0 0 0.084474" />
    <limit lower="0.0" upper="2.6586" effort="6.0" velocity="8.0677777442" />    
    <dynamics damping="0.001" friction="0.001" />  
    <axis xyz="0 0 1" />
    <mimic joint="pinky_q1" multiplier="1.05851325" offset="0.72349796" />
  </joint>
  <link name="pinky_tip"><inertial>
      <origin xyz="0 0 0" rpy="0 0 0" />
      <mass value="1.0" />
      <inertia ixx="0.001" ixy="0.0" ixz="0.0" iyy="0.001" iyz="0.0" izz="0.001" />
    </inertial><visual><geometry><box size="0.01 0.01 0.01" /></geometry></visual></link>
  <joint name="pinky_tip_joint" type="fixed">
    <parent link="pinky_L2" />
    <child link="pinky_tip" />
    <origin rpy="0 0 0" xyz="0.035  -0.018 0" />
  </joint>
</robot>