<mujoco model="allegro_hand_right">
  <option iterations="50" timestep="0.001" solver="PGS" gravity="0 0 -9.81" />

  <compiler angle="radian" meshdir="meshes" eulerseq="zyx" autolimits="true" />

  <default>
    <joint limited="true" damping="0.01" armature="0.01" frictionloss="0.01" />
    <geom condim="4" contype="1" conaffinity="15" friction="0.9 0.2 0.2" solref="0.001 2" />
    <motor ctrllimited="true" />
    <equality solref="0.001 2" />
    <default class="visualgeom">
      <geom material="visualgeom" condim="1" contype="0" conaffinity="0" />
    </default>
  </default>

  <worldbody>
    <light directional="true" diffuse="0.4 0.4 0.4" specular="0.1 0.1 0.1" pos="0 0 5.0" dir="0 0 -1" castshadow="false" />
    <light directional="true" diffuse="0.6 0.6 0.6" specular="0.2 0.2 0.2" pos="0 0 4" dir="0 0 -1" />
    <geom name="ground" type="plane" pos="0 0 0" size="100 100 0.001" quat="1 0 0 0" material="matplane" condim="3" conaffinity="15" />
    <camera name="fixed" pos="0 -3.0 0.605844330143193" xyaxes="1 0 0 0 0 1" />
    <camera name="track" mode="trackcom" pos="0 -3.0 0.605844330143193" xyaxes="1 0 0 0 0 1" />
    <body name="root" pos="0 0 0.10584433014319308" quat="1 0 0 0">
      <freejoint name="root" />
      <site name="imu" size="0.01" pos="0 0 0" />
      <geom size="0.012" rgba="0.9 0.9 0.9 1" contype="1" conaffinity="0" density="0" group="1" class="visualgeom" />
      <geom type="" rgba="0.9 0.9 0.9 1" />
      <geom size="0.012" rgba="0.9 0.9 0.9 1" contype="1" conaffinity="0" density="0" group="1" class="visualgeom" />
      <geom type="" rgba="0.9 0.9 0.9 1" />
      <geom size="0.012" rgba="0.9 0.9 0.9 1" contype="1" conaffinity="0" density="0" group="1" class="visualgeom" />
      <geom type="" rgba="0.9 0.9 0.9 1" />
      <geom size="0.012" rgba="0.9 0.9 0.9 1" contype="1" conaffinity="0" density="0" group="1" class="visualgeom" />
      <geom type="" rgba="0.9 0.9 0.9 1" />
      <body name="allegro_root1">
        <inertial pos="0 0 0" mass="1" diaginertia="0.001 0.001 0.001" />
        <joint name="x_joint" pos="0 0 0" axis="1 0 0" type="slide" range="-0.5 0.5" />
        <body name="allegro_root2">
          <inertial pos="0 0 0" mass="1" diaginertia="0.001 0.001 0.001" />
          <joint name="y_joint" pos="0 0 0" axis="0 1 0" type="slide" range="-0.5 0.5" />
          <body name="allegro_root3">
            <inertial pos="0 0 0" mass="1" diaginertia="0.001 0.001 0.001" />
            <joint name="z_joint" pos="0 0 0" axis="0 0 1" type="slide" range="-0.5 0.5" />
            <body name="allegro_root4">
              <inertial pos="0 0 0" mass="1" diaginertia="0.001 0.001 0.001" />
              <joint name="x_rotation_joint" pos="0 0 0" axis="1 0 0" range="-3.14 3.14" />
              <body name="allegro_root5">
                <inertial pos="0 0 0" mass="1" diaginertia="0.001 0.001 0.001" />
                <joint name="y_rotation_joint" pos="0 0 0" axis="0 1 0" range="-3.14 3.14" />
                <body name="base_link">
                  <inertial pos="0 0 0" mass="1" diaginertia="0.001 0.001 0.001" />
                  <joint name="z_rotation_joint" pos="0 0 0" axis="0 0 1" range="-3.14 3.14" />
                  <geom size="0.0204 0.0565 0.0475" pos="-0.0093 0 -0.0475" type="box" rgba="0.2 0.2 0.2 1" contype="1" conaffinity="0" density="0" group="1" class="visualgeom" />
                  <geom type="box" rgba="0.2 0.2 0.2 1" size="0.0204 0.0565 0.0475" pos="-0.0093 0 -0.0475" />
                  <body name="link_0.0" pos="0 0.0435 -0.001542" quat="0.999048 -0.0436194 0 0">
                    <inertial pos="0 0 0" mass="1" diaginertia="0.001 0.001 0.001" />
                    <joint name="joint_0.0" pos="0 0 0" axis="0 0 1" range="-0.47 0.47" actuatorfrcrange="-10 10" />
                    <geom size="0.0098 0.01375 0.0082" pos="0 0 0.0082" type="box" rgba="0.2 0.2 0.2 1" contype="1" conaffinity="0" density="0" group="1" class="visualgeom" />
                    <geom type="box" rgba="0.2 0.2 0.2 1" size="0.0098 0.01375 0.0082" pos="0 0 0.0082" />
                    <body name="link_1.0" pos="0 0 0.0164">
                      <inertial pos="0 0 0" mass="1" diaginertia="0.001 0.001 0.001" />
                      <joint name="joint_1.0" pos="0 0 0" axis="0 1 0" range="-0.196 1.61" actuatorfrcrange="-10 10" />
                      <geom size="0.0098 0.01375 0.027" pos="0 0 0.027" type="box" rgba="0.2 0.2 0.2 1" contype="1" conaffinity="0" density="0" group="1" class="visualgeom" />
                      <geom type="box" rgba="0.2 0.2 0.2 1" size="0.0098 0.01375 0.027" pos="0 0 0.027" />
                      <body name="link_2.0" pos="0 0 0.054">
                        <inertial pos="0 0 0" mass="1" diaginertia="0.001 0.001 0.001" />
                        <joint name="joint_2.0" pos="0 0 0" axis="0 1 0" range="-0.174 1.709" actuatorfrcrange="-10 10" />
                        <geom size="0.0098 0.01375 0.0192" pos="0 0 0.0192" type="box" rgba="0.2 0.2 0.2 1" contype="1" conaffinity="0" density="0" group="1" class="visualgeom" />
                        <geom type="box" rgba="0.2 0.2 0.2 1" size="0.0098 0.01375 0.0192" pos="0 0 0.0192" />
                        <body name="link_3.0" pos="0 0 0.0384">
                          <inertial pos="0 0 0" mass="1" diaginertia="0.001 0.001 0.001" />
                          <joint name="joint_3.0" pos="0 0 0" axis="0 1 0" range="-0.227 1.618" actuatorfrcrange="-10 10" />
                          <geom size="0.0098 0.01375 0.01335" pos="0 0 0.01335" type="box" rgba="0.2 0.2 0.2 1" contype="1" conaffinity="0" density="0" group="1" class="visualgeom" />
                          <geom type="box" rgba="0.2 0.2 0.2 1" size="0.0098 0.01375 0.01335" pos="0 0 0.01335" />
                        </body>
                      </body>
                    </body>
                  </body>
                  <body name="link_4.0" pos="0 0 0.0007">
                    <inertial pos="0 0 0" mass="1" diaginertia="0.001 0.001 0.001" />
                    <joint name="joint_4.0" pos="0 0 0" axis="0 0 1" range="-0.47 0.47" actuatorfrcrange="-10 10" />
                    <geom size="0.0098 0.01375 0.0082" pos="0 0 0.0082" type="box" rgba="0.2 0.2 0.2 1" contype="1" conaffinity="0" density="0" group="1" class="visualgeom" />
                    <geom type="box" rgba="0.2 0.2 0.2 1" size="0.0098 0.01375 0.0082" pos="0 0 0.0082" />
                    <body name="link_5.0" pos="0 0 0.0164">
                      <inertial pos="0 0 0" mass="1" diaginertia="0.001 0.001 0.001" />
                      <joint name="joint_5.0" pos="0 0 0" axis="0 1 0" range="-0.196 1.61" actuatorfrcrange="-10 10" />
                      <geom size="0.0098 0.01375 0.027" pos="0 0 0.027" type="box" rgba="0.2 0.2 0.2 1" contype="1" conaffinity="0" density="0" group="1" class="visualgeom" />
                      <geom type="box" rgba="0.2 0.2 0.2 1" size="0.0098 0.01375 0.027" pos="0 0 0.027" />
                      <body name="link_6.0" pos="0 0 0.054">
                        <inertial pos="0 0 0" mass="1" diaginertia="0.001 0.001 0.001" />
                        <joint name="joint_6.0" pos="0 0 0" axis="0 1 0" range="-0.174 1.709" actuatorfrcrange="-10 10" />
                        <geom size="0.0098 0.01375 0.0192" pos="0 0 0.0192" type="box" rgba="0.2 0.2 0.2 1" contype="1" conaffinity="0" density="0" group="1" class="visualgeom" />
                        <geom type="box" rgba="0.2 0.2 0.2 1" size="0.0098 0.01375 0.0192" pos="0 0 0.0192" />
                        <body name="link_7.0" pos="0 0 0.0384">
                          <inertial pos="0 0 0" mass="1" diaginertia="0.001 0.001 0.001" />
                          <joint name="joint_7.0" pos="0 0 0" axis="0 1 0" range="-0.227 1.618" actuatorfrcrange="-10 10" />
                          <geom size="0.0098 0.01375 0.01335" pos="0 0 0.01335" type="box" rgba="0.2 0.2 0.2 1" contype="1" conaffinity="0" density="0" group="1" class="visualgeom" />
                          <geom type="box" rgba="0.2 0.2 0.2 1" size="0.0098 0.01375 0.01335" pos="0 0 0.01335" />
                        </body>
                      </body>
                    </body>
                  </body>
                  <body name="link_8.0" pos="0 -0.0435 -0.001542" quat="0.999048 0.0436194 0 0">
                    <inertial pos="0 0 0" mass="1" diaginertia="0.001 0.001 0.001" />
                    <joint name="joint_8.0" pos="0 0 0" axis="0 0 1" range="-0.47 0.47" actuatorfrcrange="-10 10" />
                    <geom size="0.0098 0.01375 0.0082" pos="0 0 0.0082" type="box" rgba="0.2 0.2 0.2 1" contype="1" conaffinity="0" density="0" group="1" class="visualgeom" />
                    <geom type="box" rgba="0.2 0.2 0.2 1" size="0.0098 0.01375 0.0082" pos="0 0 0.0082" />
                    <body name="link_9.0" pos="0 0 0.0164">
                      <inertial pos="0 0 0" mass="1" diaginertia="0.001 0.001 0.001" />
                      <joint name="joint_9.0" pos="0 0 0" axis="0 1 0" range="-0.196 1.61" actuatorfrcrange="-10 10" />
                      <geom size="0.0098 0.01375 0.027" pos="0 0 0.027" type="box" rgba="0.2 0.2 0.2 1" contype="1" conaffinity="0" density="0" group="1" class="visualgeom" />
                      <geom type="box" rgba="0.2 0.2 0.2 1" size="0.0098 0.01375 0.027" pos="0 0 0.027" />
                      <body name="link_10.0" pos="0 0 0.054">
                        <inertial pos="0 0 0" mass="1" diaginertia="0.001 0.001 0.001" />
                        <joint name="joint_10.0" pos="0 0 0" axis="0 1 0" range="-0.174 1.709" actuatorfrcrange="-10 10" />
                        <geom size="0.0098 0.01375 0.0192" pos="0 0 0.0192" type="box" rgba="0.2 0.2 0.2 1" contype="1" conaffinity="0" density="0" group="1" class="visualgeom" />
                        <geom type="box" rgba="0.2 0.2 0.2 1" size="0.0098 0.01375 0.0192" pos="0 0 0.0192" />
                        <body name="link_11.0" pos="0 0 0.0384">
                          <inertial pos="0 0 0" mass="1" diaginertia="0.001 0.001 0.001" />
                          <joint name="joint_11.0" pos="0 0 0" axis="0 1 0" range="-0.227 1.618" actuatorfrcrange="-10 10" />
                          <geom size="0.0098 0.01375 0.01335" pos="0 0 0.01335" type="box" rgba="0.2 0.2 0.2 1" contype="1" conaffinity="0" density="0" group="1" class="visualgeom" />
                          <geom type="box" rgba="0.2 0.2 0.2 1" size="0.0098 0.01375 0.01335" pos="0 0 0.01335" />
                        </body>
                      </body>
                    </body>
                  </body>
                  <body name="link_12.0" pos="-0.0182 0.019333 -0.045987" quat="0.477714 -0.521334 -0.521334 -0.477714">
                    <inertial pos="0 0 0" mass="1" diaginertia="0.001 0.001 0.001" />
                    <joint name="joint_12.0" pos="0 0 0" axis="-1 0 0" range="0.263 1.396" actuatorfrcrange="-10 10" />
                    <geom size="0.0179 0.017 0.02275" pos="-0.0179 0.009 0.0145" type="box" rgba="0.2 0.2 0.2 1" contype="1" conaffinity="0" density="0" group="1" class="visualgeom" />
                    <geom type="box" rgba="0.2 0.2 0.2 1" size="0.0179 0.017 0.02275" pos="-0.0179 0.009 0.0145" />
                    <body name="link_13.0" pos="-0.027 0.005 0.0399">
                      <inertial pos="0 0 0" mass="1" diaginertia="0.001 0.001 0.001" />
                      <joint name="joint_13.0" pos="0 0 0" axis="0 0 1" range="-0.105 1.163" actuatorfrcrange="-10 10" />
                      <geom size="0.0098 0.01375 0.00885" pos="0 0 0.00885" type="box" rgba="0.2 0.2 0.2 1" contype="1" conaffinity="0" density="0" group="1" class="visualgeom" />
                      <geom type="box" rgba="0.2 0.2 0.2 1" size="0.0098 0.01375 0.00885" pos="0 0 0.00885" />
                      <body name="link_14.0" pos="0 0 0.0177">
                        <inertial pos="0 0 0" mass="1" diaginertia="0.001 0.001 0.001" />
                        <joint name="joint_14.0" pos="0 0 0" axis="0 1 0" range="-0.189 1.644" actuatorfrcrange="-10 10" />
                        <geom size="0.0098 0.01375 0.0257" pos="0 0 0.0257" type="box" rgba="0.2 0.2 0.2 1" contype="1" conaffinity="0" density="0" group="1" class="visualgeom" />
                        <geom type="box" rgba="0.2 0.2 0.2 1" size="0.0098 0.01375 0.0257" pos="0 0 0.0257" />
                        <body name="link_15.0" pos="0 0 0.0514">
                          <inertial pos="0 0 0" mass="1" diaginertia="0.001 0.001 0.001" />
                          <joint name="joint_15.0" pos="0 0 0" axis="0 1 0" range="-0.162 1.719" actuatorfrcrange="-10 10" />
                          <geom size="0.0098 0.01375 0.02115" pos="0 0 0.02115" type="box" rgba="0.2 0.2 0.2 1" contype="1" conaffinity="0" density="0" group="1" class="visualgeom" />
                          <geom type="box" rgba="0.2 0.2 0.2 1" size="0.0098 0.01375 0.02115" pos="0 0 0.02115" />
                        </body>
                      </body>
                    </body>
                  </body>
                </body>
              </body>
            </body>
          </body>
        </body>
      </body>
    </body>
  </worldbody>

  <asset>
    <texture name="texplane" type="2d" builtin="checker" rgb1=".0 .0 .0" rgb2=".8 .8 .8" width="100" height="100" />
    <material name="matplane" reflectance="0." texture="texplane" texrepeat="1 1" texuniform="true" />
    <material name="visualgeom" rgba="0.5 0.9 0.2 1" />
  </asset>

  <actuator>
    <motor name="x_joint" joint="x_joint" ctrllimited="true" ctrlrange="-1 1" gear="1" />
    <motor name="y_joint" joint="y_joint" ctrllimited="true" ctrlrange="-1 1" gear="1" />
    <motor name="z_joint" joint="z_joint" ctrllimited="true" ctrlrange="-1 1" gear="1" />
    <motor name="x_rotation_joint" joint="x_rotation_joint" ctrllimited="true" ctrlrange="-1 1" gear="1" />
    <motor name="y_rotation_joint" joint="y_rotation_joint" ctrllimited="true" ctrlrange="-1 1" gear="1" />
    <motor name="z_rotation_joint" joint="z_rotation_joint" ctrllimited="true" ctrlrange="-1 1" gear="1" />
    <motor name="joint_0.0" joint="joint_0.0" ctrllimited="true" ctrlrange="-10 10" gear="1" />
    <motor name="joint_1.0" joint="joint_1.0" ctrllimited="true" ctrlrange="-10 10" gear="1" />
    <motor name="joint_2.0" joint="joint_2.0" ctrllimited="true" ctrlrange="-10 10" gear="1" />
    <motor name="joint_3.0" joint="joint_3.0" ctrllimited="true" ctrlrange="-10 10" gear="1" />
    <motor name="joint_4.0" joint="joint_4.0" ctrllimited="true" ctrlrange="-10 10" gear="1" />
    <motor name="joint_5.0" joint="joint_5.0" ctrllimited="true" ctrlrange="-10 10" gear="1" />
    <motor name="joint_6.0" joint="joint_6.0" ctrllimited="true" ctrlrange="-10 10" gear="1" />
    <motor name="joint_7.0" joint="joint_7.0" ctrllimited="true" ctrlrange="-10 10" gear="1" />
    <motor name="joint_8.0" joint="joint_8.0" ctrllimited="true" ctrlrange="-10 10" gear="1" />
    <motor name="joint_9.0" joint="joint_9.0" ctrllimited="true" ctrlrange="-10 10" gear="1" />
    <motor name="joint_10.0" joint="joint_10.0" ctrllimited="true" ctrlrange="-10 10" gear="1" />
    <motor name="joint_11.0" joint="joint_11.0" ctrllimited="true" ctrlrange="-10 10" gear="1" />
    <motor name="joint_12.0" joint="joint_12.0" ctrllimited="true" ctrlrange="-10 10" gear="1" />
    <motor name="joint_13.0" joint="joint_13.0" ctrllimited="true" ctrlrange="-10 10" gear="1" />
    <motor name="joint_14.0" joint="joint_14.0" ctrllimited="true" ctrlrange="-10 10" gear="1" />
    <motor name="joint_15.0" joint="joint_15.0" ctrllimited="true" ctrlrange="-10 10" gear="1" />
  </actuator>

  <sensor>
    <actuatorpos name="x_joint_p" actuator="x_joint" />
    <actuatorvel name="x_joint_v" actuator="x_joint" />
    <actuatorfrc name="x_joint_f" actuator="x_joint" noise="0.001" />
    <actuatorpos name="y_joint_p" actuator="y_joint" />
    <actuatorvel name="y_joint_v" actuator="y_joint" />
    <actuatorfrc name="y_joint_f" actuator="y_joint" noise="0.001" />
    <actuatorpos name="z_joint_p" actuator="z_joint" />
    <actuatorvel name="z_joint_v" actuator="z_joint" />
    <actuatorfrc name="z_joint_f" actuator="z_joint" noise="0.001" />
    <actuatorpos name="x_rotation_joint_p" actuator="x_rotation_joint" />
    <actuatorvel name="x_rotation_joint_v" actuator="x_rotation_joint" />
    <actuatorfrc name="x_rotation_joint_f" actuator="x_rotation_joint" noise="0.001" />
    <actuatorpos name="y_rotation_joint_p" actuator="y_rotation_joint" />
    <actuatorvel name="y_rotation_joint_v" actuator="y_rotation_joint" />
    <actuatorfrc name="y_rotation_joint_f" actuator="y_rotation_joint" noise="0.001" />
    <actuatorpos name="z_rotation_joint_p" actuator="z_rotation_joint" />
    <actuatorvel name="z_rotation_joint_v" actuator="z_rotation_joint" />
    <actuatorfrc name="z_rotation_joint_f" actuator="z_rotation_joint" noise="0.001" />
    <actuatorpos name="joint_0.0_p" actuator="joint_0.0" />
    <actuatorvel name="joint_0.0_v" actuator="joint_0.0" />
    <actuatorfrc name="joint_0.0_f" actuator="joint_0.0" noise="0.001" />
    <actuatorpos name="joint_1.0_p" actuator="joint_1.0" />
    <actuatorvel name="joint_1.0_v" actuator="joint_1.0" />
    <actuatorfrc name="joint_1.0_f" actuator="joint_1.0" noise="0.001" />
    <actuatorpos name="joint_2.0_p" actuator="joint_2.0" />
    <actuatorvel name="joint_2.0_v" actuator="joint_2.0" />
    <actuatorfrc name="joint_2.0_f" actuator="joint_2.0" noise="0.001" />
    <actuatorpos name="joint_3.0_p" actuator="joint_3.0" />
    <actuatorvel name="joint_3.0_v" actuator="joint_3.0" />
    <actuatorfrc name="joint_3.0_f" actuator="joint_3.0" noise="0.001" />
    <actuatorpos name="joint_4.0_p" actuator="joint_4.0" />
    <actuatorvel name="joint_4.0_v" actuator="joint_4.0" />
    <actuatorfrc name="joint_4.0_f" actuator="joint_4.0" noise="0.001" />
    <actuatorpos name="joint_5.0_p" actuator="joint_5.0" />
    <actuatorvel name="joint_5.0_v" actuator="joint_5.0" />
    <actuatorfrc name="joint_5.0_f" actuator="joint_5.0" noise="0.001" />
    <actuatorpos name="joint_6.0_p" actuator="joint_6.0" />
    <actuatorvel name="joint_6.0_v" actuator="joint_6.0" />
    <actuatorfrc name="joint_6.0_f" actuator="joint_6.0" noise="0.001" />
    <actuatorpos name="joint_7.0_p" actuator="joint_7.0" />
    <actuatorvel name="joint_7.0_v" actuator="joint_7.0" />
    <actuatorfrc name="joint_7.0_f" actuator="joint_7.0" noise="0.001" />
    <actuatorpos name="joint_8.0_p" actuator="joint_8.0" />
    <actuatorvel name="joint_8.0_v" actuator="joint_8.0" />
    <actuatorfrc name="joint_8.0_f" actuator="joint_8.0" noise="0.001" />
    <actuatorpos name="joint_9.0_p" actuator="joint_9.0" />
    <actuatorvel name="joint_9.0_v" actuator="joint_9.0" />
    <actuatorfrc name="joint_9.0_f" actuator="joint_9.0" noise="0.001" />
    <actuatorpos name="joint_10.0_p" actuator="joint_10.0" />
    <actuatorvel name="joint_10.0_v" actuator="joint_10.0" />
    <actuatorfrc name="joint_10.0_f" actuator="joint_10.0" noise="0.001" />
    <actuatorpos name="joint_11.0_p" actuator="joint_11.0" />
    <actuatorvel name="joint_11.0_v" actuator="joint_11.0" />
    <actuatorfrc name="joint_11.0_f" actuator="joint_11.0" noise="0.001" />
    <actuatorpos name="joint_12.0_p" actuator="joint_12.0" />
    <actuatorvel name="joint_12.0_v" actuator="joint_12.0" />
    <actuatorfrc name="joint_12.0_f" actuator="joint_12.0" noise="0.001" />
    <actuatorpos name="joint_13.0_p" actuator="joint_13.0" />
    <actuatorvel name="joint_13.0_v" actuator="joint_13.0" />
    <actuatorfrc name="joint_13.0_f" actuator="joint_13.0" noise="0.001" />
    <actuatorpos name="joint_14.0_p" actuator="joint_14.0" />
    <actuatorvel name="joint_14.0_v" actuator="joint_14.0" />
    <actuatorfrc name="joint_14.0_f" actuator="joint_14.0" noise="0.001" />
    <actuatorpos name="joint_15.0_p" actuator="joint_15.0" />
    <actuatorvel name="joint_15.0_v" actuator="joint_15.0" />
    <actuatorfrc name="joint_15.0_f" actuator="joint_15.0" noise="0.001" />
    <framequat name="orientation" objtype="site" noise="0.001" objname="imu" />
    <gyro name="angular-velocity" site="imu" noise="0.005" cutoff="34.9" />
  </sensor>
</mujoco>