<mujoco model="mano">
  <option iterations="50" timestep="0.001" solver="PGS" gravity="0 0 -9.81" />

  <compiler angle="radian" meshdir="meshes" eulerseq="zyx" autolimits="true" />

  <default>
    <joint limited="true" damping="0.01" armature="0.01" frictionloss="0.01" />
    <geom condim="4" contype="1" conaffinity="15" friction="0.9 0.2 0.2" solref="0.001 2" />
    <motor ctrllimited="true" />
    <equality solref="0.001 2" />
    <default class="visualgeom">
      <geom material="visualgeom" condim="1" contype="0" conaffinity="0" />
    </default>
  </default>

  <asset>
    <mesh name="palm" content_type="model/stl" file="palm.stl" />
    <mesh name="index1x" content_type="model/stl" file="index1x.stl" />
    <mesh name="index2" content_type="model/stl" file="index2.stl" />
    <mesh name="index3" content_type="model/stl" file="index3.stl" />
    <mesh name="middle1x" content_type="model/stl" file="middle1x.stl" />
    <mesh name="middle2" content_type="model/stl" file="middle2.stl" />
    <mesh name="middle3" content_type="model/stl" file="middle3.stl" />
    <mesh name="pinky1x" content_type="model/stl" file="pinky1x.stl" />
    <mesh name="pinky2" content_type="model/stl" file="pinky2.stl" />
    <mesh name="pinky3" content_type="model/stl" file="pinky3.stl" />
    <mesh name="ring1x" content_type="model/stl" file="ring1x.stl" />
    <mesh name="ring2" content_type="model/stl" file="ring2.stl" />
    <mesh name="ring3" content_type="model/stl" file="ring3.stl" />
    <mesh name="thumb1z" content_type="model/stl" file="thumb1z.stl" />
    <mesh name="thumb2" content_type="model/stl" file="thumb2.stl" />
    <mesh name="thumb3" content_type="model/stl" file="thumb3.stl" />
    <texture name="texplane" type="2d" builtin="checker" rgb1=".0 .0 .0" rgb2=".8 .8 .8" width="100" height="100" />
    <material name="matplane" reflectance="0." texture="texplane" texrepeat="1 1" texuniform="true" />
    <material name="visualgeom" rgba="0.5 0.9 0.2 1" />
  </asset>

  <worldbody>
    <light directional="true" diffuse="0.4 0.4 0.4" specular="0.1 0.1 0.1" pos="0 0 5.0" dir="0 0 -1" castshadow="false" />
    <light directional="true" diffuse="0.6 0.6 0.6" specular="0.2 0.2 0.2" pos="0 0 4" dir="0 0 -1" />
    <geom name="ground" type="plane" pos="0 0 0" size="100 100 0.001" quat="1 0 0 0" material="matplane" condim="3" conaffinity="15" />
    <camera name="fixed" pos="0 -3.0 0.5353048372504001" xyaxes="1 0 0 0 0 1" />
    <camera name="track" mode="trackcom" pos="0 -3.0 0.5353048372504001" xyaxes="1 0 0 0 0 1" />
    <body name="root" pos="0 0 0.03530483725040007" quat="1 0 0 0">
      <freejoint name="root" />
      <site name="imu" size="0.01" pos="0 0 0" />
      <geom name="c_thumb3" quat="0.303832 0.79185 -0.375505 0.373706" type="mesh" mesh="thumb3" contype="1" conaffinity="0" density="0" group="1" class="visualgeom" />
      <geom type="mesh" rgba="" mesh="thumb3" quat="0.303832 0.79185 -0.375505 0.373706" />
      <geom name="c_ring3" quat="-0.0233679 0.585251 0.0590453 0.808362" type="mesh" mesh="ring3" contype="1" conaffinity="0" density="0" group="1" class="visualgeom" />
      <geom type="mesh" rgba="" mesh="ring3" quat="-0.0233679 0.585251 0.0590453 0.808362" />
      <geom name="c_pinky3" quat="0.114604 -0.469585 -0.0826793 -0.871505" type="mesh" mesh="pinky3" contype="1" conaffinity="0" density="0" group="1" class="visualgeom" />
      <geom type="mesh" rgba="" mesh="pinky3" quat="0.114604 -0.469585 -0.0826793 -0.871505" />
      <geom name="c_middle3" quat="0.0280283 0.644307 0.0115664 0.764166" type="mesh" mesh="middle3" contype="1" conaffinity="0" density="0" group="1" class="visualgeom" />
      <geom type="mesh" rgba="" mesh="middle3" quat="0.0280283 0.644307 0.0115664 0.764166" />
      <geom name="c_index3" quat="0.0207461 0.704984 0.0206397 0.708619" type="mesh" mesh="index3" contype="1" conaffinity="0" density="0" group="1" class="visualgeom" />
      <geom type="mesh" rgba="" mesh="index3" quat="0.0207461 0.704984 0.0206397 0.708619" />
      <body name="allegro_root1">
        <inertial pos="0 0 0" mass="1" diaginertia="0.001 0.001 0.001" />
        <joint name="x_joint" pos="0 0 0" axis="1 0 0" type="slide" range="-50 50" />
        <body name="allegro_root2">
          <inertial pos="0 0 0" mass="1" diaginertia="0.001 0.001 0.001" />
          <joint name="y_joint" pos="0 0 0" axis="0 1 0" type="slide" range="-50 50" />
          <body name="allegro_root3">
            <inertial pos="0 0 0" mass="1" diaginertia="0.001 0.001 0.001" />
            <joint name="z_joint" pos="0 0 0" axis="0 0 1" type="slide" range="-50 50" />
            <body name="allegro_root4">
              <inertial pos="0 0 0" mass="1" diaginertia="0.001 0.001 0.001" />
              <joint name="x_rotation_joint" pos="0 0 0" axis="1 0 0" range="-31.4 31.4" />
              <body name="allegro_root5">
                <inertial pos="0 0 0" mass="1" diaginertia="0.001 0.001 0.001" />
                <joint name="y_rotation_joint" pos="0 0 0" axis="0 1 0" range="-31.4 31.4" />
                <body name="palm" quat="3.27547e-05 0.707035 3.27613e-05 -0.707179">
                  <inertial pos="0 0 0" mass="1" diaginertia="0.001 0.001 0.001" />
                  <joint name="z_rotation_joint" pos="0 0 0" axis="0 0 1" range="-31.4 31.4" />
                  <geom name="c_palm" type="mesh" mesh="palm" contype="1" conaffinity="0" density="0" group="1" class="visualgeom" />
                  <geom type="mesh" rgba="" mesh="palm" />
                  <body name="index1y" pos="-0.0880972 -0.00520036 0.020686" quat="0.0207461 -0.704984 -0.0206397 -0.708619">
                    <inertial pos="0 0 0" mass="1" diaginertia="0.001 0.001 0.001" />
                    <joint name="j_index1y" pos="0 0 0" axis="0 1 0" range="-0.349066 0.349066" actuatorfrcrange="-100 100" />
                    <body name="index1x">
                      <inertial pos="0 0 0" mass="1" diaginertia="0.001 0.001 0.001" />
                      <joint name="j_index1x" pos="0 0 0" axis="1 0 0" range="-0.174533 1.5708" actuatorfrcrange="-100 100" />
                      <geom name="c_index1x" quat="0.0207461 0.704984 0.0206397 0.708619" type="mesh" mesh="index1x" contype="1" conaffinity="0" density="0" group="1" class="visualgeom" />
                      <geom type="mesh" rgba="" mesh="index1x" quat="0.0207461 0.704984 0.0206397 0.708619" />
                      <body name="index2" pos="0.00238357 -0.00591432 -0.0323765">
                        <inertial pos="0 0 0" mass="1" diaginertia="0.001 0.001 0.001" />
                        <joint name="j_index2" pos="0 0 0" axis="1 0 0" range="0 1.74533" actuatorfrcrange="-100 100" />
                        <geom name="c_index2" quat="0.0207461 0.704984 0.0206397 0.708619" type="mesh" mesh="index2" contype="1" conaffinity="0" density="0" group="1" class="visualgeom" />
                        <geom type="mesh" rgba="" mesh="index2" quat="0.0207461 0.704984 0.0206397 0.708619" />
                      </body>
                    </body>
                  </body>
                  <body name="middle1y" pos="-0.0946604 -0.00147896 -0.00335754" quat="0.0280283 -0.644307 -0.0115664 -0.764166">
                    <inertial pos="0 0 0" mass="1" diaginertia="0.001 0.001 0.001" />
                    <joint name="j_middle1y" pos="0 0 0" axis="0 1 0" range="-0.523599 0.349066" actuatorfrcrange="-100 100" />
                    <body name="middle1x">
                      <inertial pos="0 0 0" mass="1" diaginertia="0.001 0.001 0.001" />
                      <joint name="j_middle1x" pos="0 0 0" axis="1 0 0" range="-0.174533 1.5708" actuatorfrcrange="-100 100" />
                      <geom name="c_middle1x" quat="0.0280283 0.644307 0.0115664 0.764166" type="mesh" mesh="middle1x" contype="1" conaffinity="0" density="0" group="1" class="visualgeom" />
                      <geom type="mesh" rgba="" mesh="middle1x" quat="0.0280283 0.644307 0.0115664 0.764166" />
                      <body name="middle2" pos="-0.000320716 -0.00355526 -0.0315338">
                        <inertial pos="0 0 0" mass="1" diaginertia="0.001 0.001 0.001" />
                        <joint name="j_middle2" pos="0 0 0" axis="1 0 0" range="0 1.74533" actuatorfrcrange="-100 100" />
                        <geom name="c_middle2" quat="0.0280283 0.644307 0.0115664 0.764166" type="mesh" mesh="middle2" contype="1" conaffinity="0" density="0" group="1" class="visualgeom" />
                        <geom type="mesh" rgba="" mesh="middle2" quat="0.0280283 0.644307 0.0115664 0.764166" />
                      </body>
                    </body>
                  </body>
                  <body name="pinky1y" pos="-0.068787 -0.00994033 -0.0432093" quat="0.114604 0.469585 0.0826793 0.871505">
                    <inertial pos="0 0 0" mass="1" diaginertia="0.001 0.001 0.001" />
                    <joint name="j_pinky1y" pos="0 0 0" axis="0 1 0" range="-0.698132 0.349066" actuatorfrcrange="-100 100" />
                    <body name="pinky1x">
                      <inertial pos="0 0 0" mass="1" diaginertia="0.001 0.001 0.001" />
                      <joint name="j_pinky1x" pos="0 0 0" axis="1 0 0" range="-0.174533 1.5708" actuatorfrcrange="-100 100" />
                      <geom name="c_pinky1x" quat="0.114604 -0.469585 -0.0826793 -0.871505" type="mesh" mesh="pinky1x" contype="1" conaffinity="0" density="0" group="1" class="visualgeom" />
                      <geom type="mesh" rgba="" mesh="pinky1x" quat="0.114604 -0.469585 -0.0826793 -0.871505" />
                      <body name="pinky2" pos="-0.000912324 -0.00112828 -0.021062">
                        <inertial pos="0 0 0" mass="1" diaginertia="0.001 0.001 0.001" />
                        <joint name="j_pinky2" pos="0 0 0" axis="1 0 0" range="0 1.74533" actuatorfrcrange="-100 100" />
                        <geom name="c_pinky2" quat="0.114604 -0.469585 -0.0826793 -0.871505" type="mesh" mesh="pinky2" contype="1" conaffinity="0" density="0" group="1" class="visualgeom" />
                        <geom type="mesh" rgba="" mesh="pinky2" quat="0.114604 -0.469585 -0.0826793 -0.871505" />
                      </body>
                    </body>
                  </body>
                  <body name="ring1y" pos="-0.0817356 -0.00395742 -0.0266732" quat="0.0233679 0.585251 0.0590453 0.808362">
                    <inertial pos="0 0 0" mass="1" diaginertia="0.001 0.001 0.001" />
                    <joint name="j_ring1y" pos="0 0 0" axis="0 1 0" range="-0.523599 0.349066" actuatorfrcrange="-100 100" />
                    <body name="ring1x">
                      <inertial pos="0 0 0" mass="1" diaginertia="0.001 0.001 0.001" />
                      <joint name="j_ring1x" pos="0 0 0" axis="1 0 0" range="-0.174533 1.5708" actuatorfrcrange="-100 100" />
                      <geom name="c_ring1x" quat="-0.0233679 0.585251 0.0590453 0.808362" type="mesh" mesh="ring1x" contype="1" conaffinity="0" density="0" group="1" class="visualgeom" />
                      <geom type="mesh" rgba="" mesh="ring1x" quat="-0.0233679 0.585251 0.0590453 0.808362" />
                      <body name="ring2" pos="0.00429787 -0.00356368 -0.0282983">
                        <inertial pos="0 0 0" mass="1" diaginertia="0.001 0.001 0.001" />
                        <joint name="j_ring2" pos="0 0 0" axis="1 0 0" range="0 1.74533" actuatorfrcrange="-100 100" />
                        <geom name="c_ring2" quat="-0.0233679 0.585251 0.0590453 0.808362" type="mesh" mesh="ring2" contype="1" conaffinity="0" density="0" group="1" class="visualgeom" />
                        <geom type="mesh" rgba="" mesh="ring2" quat="-0.0233679 0.585251 0.0590453 0.808362" />
                      </body>
                    </body>
                  </body>
                  <body name="thumb1y" pos="-0.0240897 -0.0155223 0.0258128" quat="0.457776 -0.494578 -0.459441 -0.578574">
                    <inertial pos="0 0 0" mass="1" diaginertia="0.001 0.001 0.001" />
                    <joint name="j_thumb1y" pos="0 0 0" axis="0 1 0" range="-0.174533 2.61799" actuatorfrcrange="-100 100" />
                    <body name="thumb1z">
                      <inertial pos="0 0 0" mass="1" diaginertia="0.001 0.001 0.001" />
                      <joint name="j_thumb1z" pos="0 0 0" axis="0 0 1" range="-0.698132 0.698132" actuatorfrcrange="-100 100" />
                      <geom name="c_thumb1z" quat="0.457776 0.494578 0.459441 0.578574" type="mesh" mesh="thumb1z" contype="1" conaffinity="0" density="0" group="1" class="visualgeom" />
                      <geom type="mesh" rgba="" mesh="thumb1z" quat="0.457776 0.494578 0.459441 0.578574" />
                      <body name="thumb2" pos="0.0252649 -0.0175957 0" quat="0.574412 -0.601175 0.038173 0.554241">
                        <inertial pos="0 0 0" mass="1" diaginertia="0.001 0.001 0.001" />
                        <joint name="j_thumb2" pos="0 0 0" axis="1 0 0" range="0 1.74533" actuatorfrcrange="-100 100" />
                        <geom name="c_thumb2" quat="0.303832 0.79185 -0.375505 0.373706" type="mesh" mesh="thumb2" contype="1" conaffinity="0" density="0" group="1" class="visualgeom" />
                        <geom type="mesh" rgba="" mesh="thumb2" quat="0.303832 0.79185 -0.375505 0.373706" />
                      </body>
                    </body>
                  </body>
                </body>
              </body>
            </body>
          </body>
        </body>
      </body>
    </body>
  </worldbody>

  <actuator>
    <motor name="x_joint" joint="x_joint" ctrllimited="true" ctrlrange="-1 1" gear="1" />
    <motor name="y_joint" joint="y_joint" ctrllimited="true" ctrlrange="-1 1" gear="1" />
    <motor name="z_joint" joint="z_joint" ctrllimited="true" ctrlrange="-1 1" gear="1" />
    <motor name="x_rotation_joint" joint="x_rotation_joint" ctrllimited="true" ctrlrange="-1 1" gear="1" />
    <motor name="y_rotation_joint" joint="y_rotation_joint" ctrllimited="true" ctrlrange="-1 1" gear="1" />
    <motor name="z_rotation_joint" joint="z_rotation_joint" ctrllimited="true" ctrlrange="-1 1" gear="1" />
    <motor name="j_index1y" joint="j_index1y" ctrllimited="true" ctrlrange="-100 100" gear="1" />
    <motor name="j_index1x" joint="j_index1x" ctrllimited="true" ctrlrange="-100 100" gear="1" />
    <motor name="j_index2" joint="j_index2" ctrllimited="true" ctrlrange="-100 100" gear="1" />
    <motor name="j_middle1y" joint="j_middle1y" ctrllimited="true" ctrlrange="-100 100" gear="1" />
    <motor name="j_middle1x" joint="j_middle1x" ctrllimited="true" ctrlrange="-100 100" gear="1" />
    <motor name="j_middle2" joint="j_middle2" ctrllimited="true" ctrlrange="-100 100" gear="1" />
    <motor name="j_pinky1y" joint="j_pinky1y" ctrllimited="true" ctrlrange="-100 100" gear="1" />
    <motor name="j_pinky1x" joint="j_pinky1x" ctrllimited="true" ctrlrange="-100 100" gear="1" />
    <motor name="j_pinky2" joint="j_pinky2" ctrllimited="true" ctrlrange="-100 100" gear="1" />
    <motor name="j_ring1y" joint="j_ring1y" ctrllimited="true" ctrlrange="-100 100" gear="1" />
    <motor name="j_ring1x" joint="j_ring1x" ctrllimited="true" ctrlrange="-100 100" gear="1" />
    <motor name="j_ring2" joint="j_ring2" ctrllimited="true" ctrlrange="-100 100" gear="1" />
    <motor name="j_thumb1y" joint="j_thumb1y" ctrllimited="true" ctrlrange="-100 100" gear="1" />
    <motor name="j_thumb1z" joint="j_thumb1z" ctrllimited="true" ctrlrange="-100 100" gear="1" />
    <motor name="j_thumb2" joint="j_thumb2" ctrllimited="true" ctrlrange="-100 100" gear="1" />
  </actuator>

  <sensor>
    <actuatorpos name="x_joint_p" actuator="x_joint" />
    <actuatorvel name="x_joint_v" actuator="x_joint" />
    <actuatorfrc name="x_joint_f" actuator="x_joint" noise="0.001" />
    <actuatorpos name="y_joint_p" actuator="y_joint" />
    <actuatorvel name="y_joint_v" actuator="y_joint" />
    <actuatorfrc name="y_joint_f" actuator="y_joint" noise="0.001" />
    <actuatorpos name="z_joint_p" actuator="z_joint" />
    <actuatorvel name="z_joint_v" actuator="z_joint" />
    <actuatorfrc name="z_joint_f" actuator="z_joint" noise="0.001" />
    <actuatorpos name="x_rotation_joint_p" actuator="x_rotation_joint" />
    <actuatorvel name="x_rotation_joint_v" actuator="x_rotation_joint" />
    <actuatorfrc name="x_rotation_joint_f" actuator="x_rotation_joint" noise="0.001" />
    <actuatorpos name="y_rotation_joint_p" actuator="y_rotation_joint" />
    <actuatorvel name="y_rotation_joint_v" actuator="y_rotation_joint" />
    <actuatorfrc name="y_rotation_joint_f" actuator="y_rotation_joint" noise="0.001" />
    <actuatorpos name="z_rotation_joint_p" actuator="z_rotation_joint" />
    <actuatorvel name="z_rotation_joint_v" actuator="z_rotation_joint" />
    <actuatorfrc name="z_rotation_joint_f" actuator="z_rotation_joint" noise="0.001" />
    <actuatorpos name="j_index1y_p" actuator="j_index1y" />
    <actuatorvel name="j_index1y_v" actuator="j_index1y" />
    <actuatorfrc name="j_index1y_f" actuator="j_index1y" noise="0.001" />
    <actuatorpos name="j_index1x_p" actuator="j_index1x" />
    <actuatorvel name="j_index1x_v" actuator="j_index1x" />
    <actuatorfrc name="j_index1x_f" actuator="j_index1x" noise="0.001" />
    <actuatorpos name="j_index2_p" actuator="j_index2" />
    <actuatorvel name="j_index2_v" actuator="j_index2" />
    <actuatorfrc name="j_index2_f" actuator="j_index2" noise="0.001" />
    <actuatorpos name="j_middle1y_p" actuator="j_middle1y" />
    <actuatorvel name="j_middle1y_v" actuator="j_middle1y" />
    <actuatorfrc name="j_middle1y_f" actuator="j_middle1y" noise="0.001" />
    <actuatorpos name="j_middle1x_p" actuator="j_middle1x" />
    <actuatorvel name="j_middle1x_v" actuator="j_middle1x" />
    <actuatorfrc name="j_middle1x_f" actuator="j_middle1x" noise="0.001" />
    <actuatorpos name="j_middle2_p" actuator="j_middle2" />
    <actuatorvel name="j_middle2_v" actuator="j_middle2" />
    <actuatorfrc name="j_middle2_f" actuator="j_middle2" noise="0.001" />
    <actuatorpos name="j_pinky1y_p" actuator="j_pinky1y" />
    <actuatorvel name="j_pinky1y_v" actuator="j_pinky1y" />
    <actuatorfrc name="j_pinky1y_f" actuator="j_pinky1y" noise="0.001" />
    <actuatorpos name="j_pinky1x_p" actuator="j_pinky1x" />
    <actuatorvel name="j_pinky1x_v" actuator="j_pinky1x" />
    <actuatorfrc name="j_pinky1x_f" actuator="j_pinky1x" noise="0.001" />
    <actuatorpos name="j_pinky2_p" actuator="j_pinky2" />
    <actuatorvel name="j_pinky2_v" actuator="j_pinky2" />
    <actuatorfrc name="j_pinky2_f" actuator="j_pinky2" noise="0.001" />
    <actuatorpos name="j_ring1y_p" actuator="j_ring1y" />
    <actuatorvel name="j_ring1y_v" actuator="j_ring1y" />
    <actuatorfrc name="j_ring1y_f" actuator="j_ring1y" noise="0.001" />
    <actuatorpos name="j_ring1x_p" actuator="j_ring1x" />
    <actuatorvel name="j_ring1x_v" actuator="j_ring1x" />
    <actuatorfrc name="j_ring1x_f" actuator="j_ring1x" noise="0.001" />
    <actuatorpos name="j_ring2_p" actuator="j_ring2" />
    <actuatorvel name="j_ring2_v" actuator="j_ring2" />
    <actuatorfrc name="j_ring2_f" actuator="j_ring2" noise="0.001" />
    <actuatorpos name="j_thumb1y_p" actuator="j_thumb1y" />
    <actuatorvel name="j_thumb1y_v" actuator="j_thumb1y" />
    <actuatorfrc name="j_thumb1y_f" actuator="j_thumb1y" noise="0.001" />
    <actuatorpos name="j_thumb1z_p" actuator="j_thumb1z" />
    <actuatorvel name="j_thumb1z_v" actuator="j_thumb1z" />
    <actuatorfrc name="j_thumb1z_f" actuator="j_thumb1z" noise="0.001" />
    <actuatorpos name="j_thumb2_p" actuator="j_thumb2" />
    <actuatorvel name="j_thumb2_v" actuator="j_thumb2" />
    <actuatorfrc name="j_thumb2_f" actuator="j_thumb2" noise="0.001" />
    <framequat name="orientation" objtype="site" noise="0.001" objname="imu" />
    <gyro name="angular-velocity" site="imu" noise="0.005" cutoff="34.9" />
  </sensor>
</mujoco>