<?xml version="1.0"?>
<robot name="etasl_vision_scene">
  
  
  
  <link name="world"><inertial>
      <origin xyz="0 0 0" rpy="0 0 0" />
      <mass value="1.0" />
      <inertia ixx="0.001" ixy="0.0" ixz="0.0" iyy="0.001" iyz="0.0" izz="0.001" />
    </inertial><visual><geometry><box size="0.01 0.01 0.01" /></geometry></visual></link>
  <joint name="robot_base_joint" type="fixed">
    <origin rpy="0.0 0.0 3.14159265" xyz="0 0 0" />
    <parent link="world" />
    <child link="base_link" />
  </joint>
  <link name="base_link">
    <inertial>
      <origin xyz="0 0 0" rpy="0 0 0" />
      <mass value="1.0" />
      <inertia ixx="0.001" ixy="0.0" ixz="0.0" iyy="0.001" iyz="0.0" izz="0.001" />
    </inertial><visual>
      <geometry>
        <mesh filename="package://ur_e_description/meshes/ur10e/visual/base.dae" />
      </geometry>
      <material name="LightGrey">
        <color rgba="0.7 0.7 0.7 1.0" />
      </material>
    </visual>
    <collision>
      <geometry>
        <mesh filename="package://ur_e_description/meshes/ur10e/collision/base.stl" />
      </geometry>
    </collision>
    
  
    </link>
  <joint name="shoulder_pan_joint" type="revolute">
    <parent link="base_link" />
    <child link="shoulder_link" />
    <origin rpy="0.0 0.0 0.0" xyz="0.0 0.0 0.181" />
    <axis xyz="0 0 1" />
    <limit effort="330.0" lower="-6.2831853" upper="6.2831853" velocity="3.14" />
    <dynamics damping="0.0" friction="0.0" />
  </joint>
  <link name="shoulder_link">
    <inertial>
      <origin xyz="0 0 0" rpy="0 0 0" />
      <mass value="1.0" />
      <inertia ixx="0.001" ixy="0.0" ixz="0.0" iyy="0.001" iyz="0.0" izz="0.001" />
    </inertial><visual>
      <geometry>
        <mesh filename="package://ur_e_description/meshes/ur10e/visual/shoulder.dae" />
      </geometry>
      <material name="LightGrey">
        <color rgba="0.7 0.7 0.7 1.0" />
      </material>
    </visual>
    <collision>
      <geometry>
        <mesh filename="package://ur_e_description/meshes/ur10e/collision/shoulder.stl" />
      </geometry>
    </collision>
    
  
    </link>
  <joint name="shoulder_lift_joint" type="revolute">
    <parent link="shoulder_link" />
    <child link="upper_arm_link" />
    <origin rpy="0.0 1.570796325 0.0" xyz="0.0 0.176 0.0" />
    <axis xyz="0 1 0" />
    <limit effort="330.0" lower="-6.2831853" upper="6.2831853" velocity="3.14" />
    <dynamics damping="0.0" friction="0.0" />
  </joint>
  <link name="upper_arm_link">
    <inertial>
      <origin xyz="0 0 0" rpy="0 0 0" />
      <mass value="1.0" />
      <inertia ixx="0.001" ixy="0.0" ixz="0.0" iyy="0.001" iyz="0.0" izz="0.001" />
    </inertial><visual>
      <geometry>
        <mesh filename="package://ur_e_description/meshes/ur10e/visual/upperarm.dae" />
      </geometry>
      <material name="LightGrey">
        <color rgba="0.7 0.7 0.7 1.0" />
      </material>
    </visual>
    <collision>
      <geometry>
        <mesh filename="package://ur_e_description/meshes/ur10e/collision/upperarm.stl" />
      </geometry>
    </collision>
    
  
    </link>
  <joint name="elbow_joint" type="revolute">
    <parent link="upper_arm_link" />
    <child link="forearm_link" />
    <origin rpy="0.0 0.0 0.0" xyz="0.0 -0.137 0.613" />
    <axis xyz="0 1 0" />
    <limit effort="150.0" lower="-3.14159265" upper="3.14159265" velocity="3.14" />
    <dynamics damping="0.0" friction="0.0" />
  </joint>
  <link name="forearm_link">
    <inertial>
      <origin xyz="0 0 0" rpy="0 0 0" />
      <mass value="1.0" />
      <inertia ixx="0.001" ixy="0.0" ixz="0.0" iyy="0.001" iyz="0.0" izz="0.001" />
    </inertial><visual>
      <geometry>
        <mesh filename="package://ur_e_description/meshes/ur10e/visual/forearm.dae" />
      </geometry>
      <material name="LightGrey">
        <color rgba="0.7 0.7 0.7 1.0" />
      </material>
    </visual>
    <collision>
      <geometry>
        <mesh filename="package://ur_e_description/meshes/ur10e/collision/forearm.stl" />
      </geometry>
    </collision>
    
  
    </link>
  <joint name="wrist_1_joint" type="revolute">
    <parent link="forearm_link" />
    <child link="wrist_1_link" />
    <origin rpy="0.0 1.570796325 0.0" xyz="0.0 0.0 0.571" />
    <axis xyz="0 1 0" />
    <limit effort="54.0" lower="-6.2831853" upper="6.2831853" velocity="6.28" />
    <dynamics damping="0.0" friction="0.0" />
  </joint>
  <link name="wrist_1_link">
    <inertial>
      <origin xyz="0 0 0" rpy="0 0 0" />
      <mass value="1.0" />
      <inertia ixx="0.001" ixy="0.0" ixz="0.0" iyy="0.001" iyz="0.0" izz="0.001" />
    </inertial><visual>
      <geometry>
        <mesh filename="package://ur_e_description/meshes/ur10e/visual/wrist1.dae" />
      </geometry>
      <material name="LightGrey">
        <color rgba="0.7 0.7 0.7 1.0" />
      </material>
    </visual>
    <collision>
      <geometry>
        <mesh filename="package://ur_e_description/meshes/ur10e/collision/wrist1.stl" />
      </geometry>
    </collision>
    
  
    </link>
  <joint name="wrist_2_joint" type="revolute">
    <parent link="wrist_1_link" />
    <child link="wrist_2_link" />
    <origin rpy="0.0 0.0 0.0" xyz="0.0 0.135 0.0" />
    <axis xyz="0 0 1" />
    <limit effort="54.0" lower="-6.2831853" upper="6.2831853" velocity="6.28" />
    <dynamics damping="0.0" friction="0.0" />
  </joint>
  <link name="wrist_2_link">
    <inertial>
      <origin xyz="0 0 0" rpy="0 0 0" />
      <mass value="1.0" />
      <inertia ixx="0.001" ixy="0.0" ixz="0.0" iyy="0.001" iyz="0.0" izz="0.001" />
    </inertial><visual>
      <geometry>
        <mesh filename="package://ur_e_description/meshes/ur10e/visual/wrist2.dae" />
      </geometry>
      <material name="LightGrey">
        <color rgba="0.7 0.7 0.7 1.0" />
      </material>
    </visual>
    <collision>
      <geometry>
        <mesh filename="package://ur_e_description/meshes/ur10e/collision/wrist2.stl" />
      </geometry>
    </collision>
    
  
    </link>
  <joint name="wrist_3_joint" type="revolute">
    <parent link="wrist_2_link" />
    <child link="wrist_3_link" />
    <origin rpy="0.0 0.0 0.0" xyz="0.0 0.0 0.12" />
    <axis xyz="0 1 0" />
    <limit effort="54.0" lower="-6.2831853" upper="6.2831853" velocity="6.28" />
    <dynamics damping="0.0" friction="0.0" />
  </joint>
  <link name="wrist_3_link">
    <inertial>
      <origin xyz="0 0 0" rpy="0 0 0" />
      <mass value="1.0" />
      <inertia ixx="0.001" ixy="0.0" ixz="0.0" iyy="0.001" iyz="0.0" izz="0.001" />
    </inertial><visual>
      <geometry>
        <mesh filename="package://ur_e_description/meshes/ur10e/visual/wrist3.dae" />
      </geometry>
      <material name="LightGrey">
        <color rgba="0.7 0.7 0.7 1.0" />
      </material>
    </visual>
    <collision>
      <geometry>
        <mesh filename="package://ur_e_description/meshes/ur10e/collision/wrist3.stl" />
      </geometry>
    </collision>
    
  
    </link>
  <joint name="ee_fixed_joint" type="fixed">
    <parent link="wrist_3_link" />
    <child link="ee_link" />
    <origin rpy="0.0 0.0 1.570796325" xyz="0.0 0.117 0.0" />
  </joint>
  <link name="ee_link">
    <inertial>
      <origin xyz="0 0 0" rpy="0 0 0" />
      <mass value="1.0" />
      <inertia ixx="0.001" ixy="0.0" ixz="0.0" iyy="0.001" iyz="0.0" izz="0.001" />
    </inertial><collision>
      <geometry>
        <box size="0.01 0.01 0.01" />
      </geometry>
      <origin rpy="0 0 0" xyz="-0.01 0 0" />
    </collision>
  
    </link>
</robot>