<?xml version="1.0"?>
<robot name="allegro_hand_right">
  <link name="virtual_root"><inertial>
      <origin xyz="0 0 0" rpy="0 0 0" />
      <mass value="1.0" />
      <inertia ixx="0.001" ixy="0.0" ixz="0.0" iyy="0.001" iyz="0.0" izz="0.001" />
    </inertial><visual><geometry><box size="0.01 0.01 0.01" /></geometry></visual></link><joint name="allegro_root0_to_virtual_root" type="fixed"><parent link="virtual_root" /><child link="allegro_root0" /></joint><joint name="dummy_root_link_to_virtual_root" type="fixed"><parent link="virtual_root" /><child link="dummy_root_link" /></joint><link name="dummy_root_link"><inertial>
      <origin xyz="0 0 0" rpy="0 0 0" />
      <mass value="1.0" />
      <inertia ixx="0.001" ixy="0.0" ixz="0.0" iyy="0.001" iyz="0.0" izz="0.001" />
    </inertial><visual><geometry><box size="0.01 0.01 0.01" /></geometry></visual></link><joint name="fix_palm_center_to_dummy" type="fixed"><parent link="dummy_root_link" /><child link="palm_center" /></joint><joint name="fix_palm_to_dummy" type="fixed"><parent link="dummy_root_link" /><child link="palm" /></joint><joint name="fix_link_7.0_tip_to_dummy" type="fixed"><parent link="dummy_root_link" /><child link="link_7.0_tip" /></joint><joint name="fix_link_3.0_tip_to_dummy" type="fixed"><parent link="dummy_root_link" /><child link="link_3.0_tip" /></joint><joint name="fix_link_15.0_tip_to_dummy" type="fixed"><parent link="dummy_root_link" /><child link="link_15.0_tip" /></joint><joint name="fix_link_11.0_tip_to_dummy" type="fixed"><parent link="dummy_root_link" /><child link="link_11.0_tip" /></joint><material name="black">
    <color rgba="0.2 0.2 0.2 1" />
  </material>
  <material name="white">
    <color rgba=".9 .9 .9 1" />
  </material>
  <link name="allegro_root0">
    
  
    <inertial>
      <origin xyz="0 0 0" rpy="0 0 0" />
      <mass value="1.0" />
      <inertia ixx="0.001" ixy="0.0" ixz="0.0" iyy="0.001" iyz="0.0" izz="0.001" />
    </inertial>
<visual><geometry><box size="0.01 0.01 0.01" /></geometry></visual></link>
  <link name="allegro_root1">
    
  
    <inertial>
      <origin xyz="0 0 0" rpy="0 0 0" />
      <mass value="1.0" />
      <inertia ixx="0.001" ixy="0.0" ixz="0.0" iyy="0.001" iyz="0.0" izz="0.001" />
    </inertial>
<visual><geometry><box size="0.01 0.01 0.01" /></geometry></visual></link>
  <link name="allegro_root2">
    
  
    <inertial>
      <origin xyz="0 0 0" rpy="0 0 0" />
      <mass value="1.0" />
      <inertia ixx="0.001" ixy="0.0" ixz="0.0" iyy="0.001" iyz="0.0" izz="0.001" />
    </inertial>
<visual><geometry><box size="0.01 0.01 0.01" /></geometry></visual></link>
  <link name="allegro_root3">
    
  
    <inertial>
      <origin xyz="0 0 0" rpy="0 0 0" />
      <mass value="1.0" />
      <inertia ixx="0.001" ixy="0.0" ixz="0.0" iyy="0.001" iyz="0.0" izz="0.001" />
    </inertial>
<visual><geometry><box size="0.01 0.01 0.01" /></geometry></visual></link>
  <link name="allegro_root4">
    
  
    <inertial>
      <origin xyz="0 0 0" rpy="0 0 0" />
      <mass value="1.0" />
      <inertia ixx="0.001" ixy="0.0" ixz="0.0" iyy="0.001" iyz="0.0" izz="0.001" />
    </inertial>
<visual><geometry><box size="0.01 0.01 0.01" /></geometry></visual></link>
  <link name="allegro_root5">
    
  
    <inertial>
      <origin xyz="0 0 0" rpy="0 0 0" />
      <mass value="1.0" />
      <inertia ixx="0.001" ixy="0.0" ixz="0.0" iyy="0.001" iyz="0.0" izz="0.001" />
    </inertial>
<visual><geometry><box size="0.01 0.01 0.01" /></geometry></visual></link>

  <joint name="x_joint" type="prismatic">
    <parent link="allegro_root0" />
    <child link="allegro_root1" />
    <axis xyz="1 0 0" />
    <limit lower="-0.5" upper="0.5" />
  </joint>
  <joint name="y_joint" type="prismatic">
    <parent link="allegro_root1" />
    <child link="allegro_root2" />
    <axis xyz="0 1 0" />
    <limit lower="-0.5" upper="0.5" />
  </joint>
  <joint name="z_joint" type="prismatic">
    <parent link="allegro_root2" />
    <child link="allegro_root3" />
    <axis xyz="0 0 1" />
    <limit lower="-0.5" upper="0.5" />
  </joint>
  <joint name="x_rotation_joint" type="revolute">
    <parent link="allegro_root3" />
    <child link="allegro_root4" />
    <axis xyz="1 0 0" />
    <limit lower="-3.14" upper="3.14" />
  </joint>
  <joint name="y_rotation_joint" type="revolute">
    <parent link="allegro_root4" />
    <child link="allegro_root5" />
    <axis xyz="0 1 0" />
    <limit lower="-3.14" upper="3.14" />
  </joint>
  <joint name="z_rotation_joint" type="revolute">
    <parent link="allegro_root5" />
    <child link="base_link" />
    <axis xyz="0 0 1" />
    <origin rpy="-0.00000 -0.00000 0" xyz="0 0 0" />
    <limit lower="-3.14" upper="3.14" />
  </joint>

  <link name="base_link">
    
    <visual>
      <geometry>
        <mesh filename="meshes/base_link.STL" />
      </geometry>
      <material name="Grey">
        <color rgba="0.2 0.2 0.2 1" />
      </material>
      <origin rpy="0 0 0" xyz="0 0 0 " />
    </visual>
    <collision>
      <origin rpy="0 0 0" xyz="-0.009300 0 -0.0475" />
      <geometry>
        <box size="0.0408 0.1130 0.095" />
      </geometry>
    </collision>
  
    <inertial>
      <origin xyz="0 0 0" rpy="0 0 0" />
      <mass value="1.0" />
      <inertia ixx="0.001" ixy="0.0" ixz="0.0" iyy="0.001" iyz="0.0" izz="0.001" />
    </inertial>
</link>
  
  
  
  
  <link name="link_0.0">
    <visual>
      <geometry>
        <mesh filename="meshes/link_0.0.STL" />
      </geometry>
      <material name="black" />
    </visual>
    <collision>
      <geometry>
        <box size="0.0196 0.0275 0.0164" />
      </geometry>
      <origin rpy="0 0 0" xyz="0 0 0.0082" />
    </collision>
    
  
    <inertial>
      <origin xyz="0 0 0" rpy="0 0 0" />
      <mass value="1.0" />
      <inertia ixx="0.001" ixy="0.0" ixz="0.0" iyy="0.001" iyz="0.0" izz="0.001" />
    </inertial>
</link>
  <joint name="joint_0.0" type="revolute">
    <axis xyz="0 0 1" />
    <limit effort="10" lower="-0.47" upper="0.47" velocity="0" />
    <parent link="base_link" />
    <child link="link_0.0" />
    <origin rpy="-0.08726646255 0 0" xyz="0 0.0435 -0.001542" />
  </joint>
  <link name="link_1.0">
    
    <visual>
      <geometry>
        <mesh filename="meshes/link_1.0.STL" />
      </geometry>
      <material name="black" />
    </visual>
    <collision>
      <geometry>
        <box size="0.0196 0.0275 0.054" />
      </geometry>
      <origin rpy="0 0 0" xyz="0 0 0.027" />
    </collision>
  
    <inertial>
      <origin xyz="0 0 0" rpy="0 0 0" />
      <mass value="1.0" />
      <inertia ixx="0.001" ixy="0.0" ixz="0.0" iyy="0.001" iyz="0.0" izz="0.001" />
    </inertial>
</link>
  <joint name="joint_1.0" type="revolute">
    <limit effort="10" lower="-0.196" upper="1.61" velocity="0" />
    <axis xyz="0 1 0" />
    <parent link="link_0.0" />
    <child link="link_1.0" />
    <origin xyz="0 0 0.0164" />
  </joint>
  <link name="link_2.0">
    
    <visual>
      <geometry>
        <mesh filename="meshes/link_2.0.STL" />
      </geometry>
      <material name="black" />
    </visual>
    <collision>
      <geometry>
        <box size="0.0196 0.0275 0.0384" />
      </geometry>
      <origin rpy="0 0 0" xyz="0 0 0.0192" />
    </collision>
  
    <inertial>
      <origin xyz="0 0 0" rpy="0 0 0" />
      <mass value="1.0" />
      <inertia ixx="0.001" ixy="0.0" ixz="0.0" iyy="0.001" iyz="0.0" izz="0.001" />
    </inertial>
</link>
  <joint name="joint_2.0" type="revolute">
    <axis xyz="0 1 0" />
    <limit effort="10" lower="-0.174" upper="1.709" velocity="0" />
    <parent link="link_1.0" />
    <child link="link_2.0" />
    <origin xyz="0 0 0.054" />
  </joint>
  <link name="link_3.0">
    
    <visual>
      <geometry>
        <mesh filename="meshes/link_3.0.STL" />
      </geometry>
      <material name="black" />
    </visual>
    <collision>
      <geometry>
        <box size="0.0196 0.0275 0.0267" />
      </geometry>
      <origin rpy="0 0 0" xyz="0 0 0.01335" />
    </collision>
    
  
    <inertial>
      <origin xyz="0 0 0" rpy="0 0 0" />
      <mass value="1.0" />
      <inertia ixx="0.001" ixy="0.0" ixz="0.0" iyy="0.001" iyz="0.0" izz="0.001" />
    </inertial>
</link>
  <joint name="joint_3.0" type="revolute">
    <axis xyz="0 1 0" />
    <limit effort="10" lower="-0.227" upper="1.618" velocity="0" />
    <parent link="link_2.0" />
    <child link="link_3.0" />
    <origin xyz="0 0 0.0384" />
  </joint>
  <link name="link_3.0_tip">
    <visual>
      <geometry>
        <mesh filename="meshes/link_3.0_tip.STL" />
      </geometry>
      <material name="white" />
    </visual>
    <collision>
      <geometry>
        <sphere radius="0.012" />
      </geometry>
    </collision>
  
    <inertial>
      <origin xyz="0 0 0" rpy="0 0 0" />
      <mass value="1.0" />
      <inertia ixx="0.001" ixy="0.0" ixz="0.0" iyy="0.001" iyz="0.0" izz="0.001" />
    </inertial>
</link>
  <joint name="joint_3.0_tip" type="fixed">
    <parent link="link_3.0" />
    <child link="link_3.0_tip" />
    <origin rpy="0 0 0" xyz="0 0 0.0267" />
  </joint>
  <link name="link_4.0">
    
    <visual>
      <geometry>
        <mesh filename="meshes/link_0.0.STL" />
      </geometry>
      <material name="black" />
    </visual>
    <collision>
      <geometry>
        <box size="0.0196 0.0275 0.0164" />
      </geometry>
      <origin rpy="0 0 0" xyz="0 0 0.0082" />
    </collision>
  
    <inertial>
      <origin xyz="0 0 0" rpy="0 0 0" />
      <mass value="1.0" />
      <inertia ixx="0.001" ixy="0.0" ixz="0.0" iyy="0.001" iyz="0.0" izz="0.001" />
    </inertial>
</link>
  <joint name="joint_4.0" type="revolute">
    <axis xyz="0 0 1" />
    <limit effort="10" lower="-0.47" upper="0.47" velocity="0" />
    <parent link="base_link" />
    <child link="link_4.0" />
    <origin rpy="0.0 0 0" xyz="0 0 0.0007" />
  </joint>
  <link name="link_5.0">
    
    <visual>
      <geometry>
        <mesh filename="meshes/link_1.0.STL" />
      </geometry>
      <material name="black" />
    </visual>
    <collision>
      <geometry>
        <box size="0.0196 0.0275 0.054" />
      </geometry>
      <origin rpy="0 0 0" xyz="0 0 0.027" />
    </collision>
  
    <inertial>
      <origin xyz="0 0 0" rpy="0 0 0" />
      <mass value="1.0" />
      <inertia ixx="0.001" ixy="0.0" ixz="0.0" iyy="0.001" iyz="0.0" izz="0.001" />
    </inertial>
</link>
  <joint name="joint_5.0" type="revolute">
    <limit effort="10" lower="-0.196" upper="1.61" velocity="0" />
    <axis xyz="0 1 0" />
    <parent link="link_4.0" />
    <child link="link_5.0" />
    <origin xyz="0 0 0.0164" />
  </joint>
  <link name="link_6.0">
    
    <visual>
      <geometry>
        <mesh filename="meshes/link_2.0.STL" />
      </geometry>
      <material name="black" />
    </visual>
    <collision>
      <geometry>
        <box size="0.0196 0.0275 0.0384" />
      </geometry>
      <origin rpy="0 0 0" xyz="0 0 0.0192" />
    </collision>
  
    <inertial>
      <origin xyz="0 0 0" rpy="0 0 0" />
      <mass value="1.0" />
      <inertia ixx="0.001" ixy="0.0" ixz="0.0" iyy="0.001" iyz="0.0" izz="0.001" />
    </inertial>
</link>
  <joint name="joint_6.0" type="revolute">
    <axis xyz="0 1 0" />
    <limit effort="10" lower="-0.174" upper="1.709" velocity="0" />
    <parent link="link_5.0" />
    <child link="link_6.0" />
    <origin xyz="0 0 0.054" />
  </joint>
  <link name="link_7.0">
    
    
    <visual>
      <geometry>
        <mesh filename="meshes/link_3.0.STL" />
      </geometry>
      <material name="black" />
    </visual>
    <collision>
      <geometry>
        <box size="0.0196 0.0275 0.0267" />
      </geometry>
      <origin rpy="0 0 0" xyz="0 0 0.01335" />
    </collision>
  
    <inertial>
      <origin xyz="0 0 0" rpy="0 0 0" />
      <mass value="1.0" />
      <inertia ixx="0.001" ixy="0.0" ixz="0.0" iyy="0.001" iyz="0.0" izz="0.001" />
    </inertial>
</link>
  <joint name="joint_7.0" type="revolute">
    <axis xyz="0 1 0" />
    <limit effort="10" lower="-0.227" upper="1.618" velocity="0" />
    <parent link="link_6.0" />
    <child link="link_7.0" />
    <origin xyz="0 0 0.0384" />
  </joint>
  <link name="link_7.0_tip">
    <visual>
      <geometry>
        <mesh filename="meshes/link_3.0_tip.STL" />
      </geometry>
      <material name="white" />
    </visual>
    <collision>
      <geometry>
        <sphere radius="0.012" />
      </geometry>
    </collision>
  
    <inertial>
      <origin xyz="0 0 0" rpy="0 0 0" />
      <mass value="1.0" />
      <inertia ixx="0.001" ixy="0.0" ixz="0.0" iyy="0.001" iyz="0.0" izz="0.001" />
    </inertial>
</link>
  <joint name="joint_7.0_tip" type="fixed">
    <parent link="link_7.0" />
    <child link="link_7.0_tip" />
    <origin rpy="0 0 0" xyz="0 0 0.0267" />
  </joint>
  <link name="link_8.0">
    
    <visual>
      <geometry>
        <mesh filename="meshes/link_0.0.STL" />
      </geometry>
      <material name="black" />
    </visual>
    <collision>
      <geometry>
        <box size="0.0196 0.0275 0.0164" />
      </geometry>
      <origin rpy="0 0 0" xyz="0 0 0.0082" />
    </collision>
  
    <inertial>
      <origin xyz="0 0 0" rpy="0 0 0" />
      <mass value="1.0" />
      <inertia ixx="0.001" ixy="0.0" ixz="0.0" iyy="0.001" iyz="0.0" izz="0.001" />
    </inertial>
</link>
  <joint name="joint_8.0" type="revolute">
    <axis xyz="0 0 1" />
    <limit effort="10" lower="-0.47" upper="0.47" velocity="0" />
    <parent link="base_link" />
    <child link="link_8.0" />
    <origin rpy="0.08726646255 0 0" xyz="0 -0.0435 -0.001542" />
  </joint>
  <link name="link_9.0">
    
    <visual>
      <geometry>
        <mesh filename="meshes/link_1.0.STL" />
      </geometry>
      <material name="black" />
    </visual>
    <collision>
      <geometry>
        <box size="0.0196 0.0275 0.054" />
      </geometry>
      <origin rpy="0 0 0" xyz="0 0 0.027" />
    </collision>
  
    <inertial>
      <origin xyz="0 0 0" rpy="0 0 0" />
      <mass value="1.0" />
      <inertia ixx="0.001" ixy="0.0" ixz="0.0" iyy="0.001" iyz="0.0" izz="0.001" />
    </inertial>
</link>
  <joint name="joint_9.0" type="revolute">
    <limit effort="10" lower="-0.196" upper="1.61" velocity="0" />
    <axis xyz="0 1 0" />
    <parent link="link_8.0" />
    <child link="link_9.0" />
    <origin xyz="0 0 0.0164" />
  </joint>
  <link name="link_10.0">
    
    <visual>
      <geometry>
        <mesh filename="meshes/link_2.0.STL" />
      </geometry>
      <material name="black" />
    </visual>
    <collision>
      <geometry>
        <box size="0.0196 0.0275 0.0384" />
      </geometry>
      <origin rpy="0 0 0" xyz="0 0 0.0192" />
    </collision>
  
    <inertial>
      <origin xyz="0 0 0" rpy="0 0 0" />
      <mass value="1.0" />
      <inertia ixx="0.001" ixy="0.0" ixz="0.0" iyy="0.001" iyz="0.0" izz="0.001" />
    </inertial>
</link>
  <joint name="joint_10.0" type="revolute">
    <axis xyz="0 1 0" />
    <limit effort="10" lower="-0.174" upper="1.709" velocity="0" />
    <parent link="link_9.0" />
    <child link="link_10.0" />
    <origin xyz="0 0 0.054" />
  </joint>
  <link name="link_11.0">
    
    
    <visual>
      <geometry>
        <mesh filename="meshes/link_3.0.STL" />
      </geometry>
      <material name="black" />
    </visual>
    <collision>
      <geometry>
        <box size="0.0196 0.0275 0.0267" />
      </geometry>
      <origin rpy="0 0 0" xyz="0 0 0.01335" />
    </collision>
  
    <inertial>
      <origin xyz="0 0 0" rpy="0 0 0" />
      <mass value="1.0" />
      <inertia ixx="0.001" ixy="0.0" ixz="0.0" iyy="0.001" iyz="0.0" izz="0.001" />
    </inertial>
</link>
  <joint name="joint_11.0" type="revolute">
    <axis xyz="0 1 0" />
    <limit effort="10" lower="-0.227" upper="1.618" velocity="0" />
    <parent link="link_10.0" />
    <child link="link_11.0" />
    <origin xyz="0 0 0.0384" />
  </joint>
  <link name="link_11.0_tip">
    <visual>
      <geometry>
        <mesh filename="meshes/link_3.0_tip.STL" />
      </geometry>
      <material name="white" />
    </visual>
    <collision>
      <geometry>
        <sphere radius="0.012" />
      </geometry>
    </collision>
  
    <inertial>
      <origin xyz="0 0 0" rpy="0 0 0" />
      <mass value="1.0" />
      <inertia ixx="0.001" ixy="0.0" ixz="0.0" iyy="0.001" iyz="0.0" izz="0.001" />
    </inertial>
</link>
  <joint name="joint_11.0_tip" type="fixed">
    <parent link="link_11.0" />
    <child link="link_11.0_tip" />
    <origin rpy="0 0 0" xyz="0 0 0.0267" />
  </joint>
  
  <link name="link_12.0">
    
    <visual>
      <geometry>
        
        <mesh filename="meshes/link_12.0_right.STL" />
        
        
      </geometry>
      <material name="black" />
    </visual>
    <collision>
      <geometry>
        <box size="0.0358 0.034 0.0455" />
      </geometry>
      
      <origin rpy="0 0 0" xyz="-0.0179 0.009 0.0145" />
      
      
    </collision>
  
    <inertial>
      <origin xyz="0 0 0" rpy="0 0 0" />
      <mass value="1.0" />
      <inertia ixx="0.001" ixy="0.0" ixz="0.0" iyy="0.001" iyz="0.0" izz="0.001" />
    </inertial>
</link>
  <joint name="joint_12.0" type="revolute">
    <axis xyz="-1 0 0" />
    <limit effort="10" lower="0.263" upper="1.396" velocity="0" />
    <parent link="base_link" />
    <child link="link_12.0" />
    <origin rpy="0 -1.65806278845 -1.5707963259" xyz="-0.0182 0.019333 -0.045987" />
  </joint>
  <link name="link_13.0">
    
    <visual>
      <geometry>
        <mesh filename="meshes/link_13.0.STL" />
      </geometry>
      <material name="black" />
    </visual>
    <collision>
      <geometry>
        <box size="0.0196 0.0275 0.0177" />
      </geometry>
      <origin rpy="0 0 0" xyz="0 0 0.00885" />
    </collision>
  
    <inertial>
      <origin xyz="0 0 0" rpy="0 0 0" />
      <mass value="1.0" />
      <inertia ixx="0.001" ixy="0.0" ixz="0.0" iyy="0.001" iyz="0.0" izz="0.001" />
    </inertial>
</link>
  <joint name="joint_13.0" type="revolute">
    <axis xyz="0 0 1" />
    <limit effort="10" lower="-0.105" upper="1.163" velocity="0" />
    <parent link="link_12.0" />
    <child link="link_13.0" />
    
    <origin xyz="-0.027 0.005 0.0399" />
    
    
  </joint>
  <link name="link_14.0">
    
    <visual>
      <geometry>
        <mesh filename="meshes/link_14.0.STL" />
      </geometry>
      <material name="black" />
    </visual>
    <collision>
      <geometry>
        <box size="0.0196 0.0275 0.0514" />
      </geometry>
      <origin rpy="0 0 0" xyz="0 0 0.0257" />
    </collision>
  
    <inertial>
      <origin xyz="0 0 0" rpy="0 0 0" />
      <mass value="1.0" />
      <inertia ixx="0.001" ixy="0.0" ixz="0.0" iyy="0.001" iyz="0.0" izz="0.001" />
    </inertial>
</link>
  <joint name="joint_14.0" type="revolute">
    <axis xyz="0 1 0" />
    <limit effort="10" lower="-0.189" upper="1.644" velocity="0" />
    <parent link="link_13.0" />
    <child link="link_14.0" />
    <origin xyz="0 0 0.0177" />
  </joint>
  <link name="link_15.0">
    
    <visual>
      <geometry>
        <mesh filename="meshes/link_15.0.STL" />
      </geometry>
      <material name="black">
      </material>
    </visual>
    <collision>
      <geometry>
        <box size="0.0196 0.0275 0.0423" />
      </geometry>
      <origin rpy="0 0 0" xyz="0 0 0.02115" />
    </collision>
  
    <inertial>
      <origin xyz="0 0 0" rpy="0 0 0" />
      <mass value="1.0" />
      <inertia ixx="0.001" ixy="0.0" ixz="0.0" iyy="0.001" iyz="0.0" izz="0.001" />
    </inertial>
</link>
  <joint name="joint_15.0" type="revolute">
    <axis xyz="0 1 0" />
    <limit effort="10" lower="-0.162" upper="1.719" velocity="0" />
    <parent link="link_14.0" />
    <child link="link_15.0" />
    <origin xyz="0 0 0.0514" />
  </joint>
  <link name="link_15.0_tip">
    <visual>
      <geometry>
        <mesh filename="meshes/link_15.0_tip.STL" />
      </geometry>
      <material name="white" />
    </visual>
    <collision>
      <geometry>
        <sphere radius="0.012" />
      </geometry>
      <origin rpy="0 0 0" xyz="0 0 0" />
    </collision>
  
    <inertial>
      <origin xyz="0 0 0" rpy="0 0 0" />
      <mass value="1.0" />
      <inertia ixx="0.001" ixy="0.0" ixz="0.0" iyy="0.001" iyz="0.0" izz="0.001" />
    </inertial>
</link>
  <joint name="joint_15.0_tip" type="fixed">
    <parent link="link_15.0" />
    <child link="link_15.0_tip" />
    <origin rpy="0 0 0" xyz="0 0 0.0423" />
    
  </joint>

  <link name="palm">
  
    <inertial>
      <origin xyz="0 0 0" rpy="0 0 0" />
      <mass value="1.0" />
      <inertia ixx="0.001" ixy="0.0" ixz="0.0" iyy="0.001" iyz="0.0" izz="0.001" />
    </inertial>
<visual><geometry><box size="0.01 0.01 0.01" /></geometry></visual></link>
  <joint name="palm_joint" type="fixed">
    <parent link="base_link" />
    <child link="palm" />
    <origin rpy="0.00000 -0.00000 0.00000" xyz="0 0 -0.065" />
  </joint>
  <link name="palm_center">
  
    <inertial>
      <origin xyz="0 0 0" rpy="0 0 0" />
      <mass value="1.0" />
      <inertia ixx="0.001" ixy="0.0" ixz="0.0" iyy="0.001" iyz="0.0" izz="0.001" />
    </inertial>
<visual><geometry><box size="0.01 0.01 0.01" /></geometry></visual></link>
  <joint name="palm_center_joint" type="fixed">
    <parent link="base_link" />
    <child link="palm_center" />
    <origin rpy="0.00000 -0.00000 0.00000" xyz="0 0 -0.03" />
  </joint>

</robot>